{"timestamp": "2025-09-27T13:44:19.390789Z", "level": "ERROR", "module": "telegram.ext.Application", "message": "No error handlers are registered, logging exception.", "correlation_id": "none", "exception": "Traceback (most recent call last):\n  File \"/home/technedict/Desktop/ViralPackage/viralcorelib/lib64/python3.13/site-packages/telegram/ext/_application.py\", line 1298, in process_update\n    await coroutine\n  File \"/home/technedict/Desktop/ViralPackage/viralcorelib/lib64/python3.13/site-packages/telegram/ext/_handlers/basehandler.py\", line 158, in handle_update\n    return await self.callback(update, context)\n           ^^^^^^^^^^^^^^^^^^^^^^^^^^^^^^^^^^^^\n  File \"/home/technedict/Desktop/ViralPackage/viralcore/handlers/message_handler.py\", line 11, in message_router\n    flags.get(\"awaiting_broadcast\"),\n    ^^^^^^^^^\nAttributeError: 'NoneType' object has no attribute 'get'"}
{"timestamp": "2025-09-27T13:47:30.372531Z", "level": "ERROR", "module": "telegram.ext.Application", "message": "No error handlers are registered, logging exception.", "correlation_id": "none", "exception": "Traceback (most recent call last):\n  File \"/home/technedict/Desktop/ViralPackage/viralcorelib/lib64/python3.13/site-packages/telegram/ext/_application.py\", line 1298, in process_update\n    await coroutine\n  File \"/home/technedict/Desktop/ViralPackage/viralcorelib/lib64/python3.13/site-packages/telegram/ext/_handlers/basehandler.py\", line 158, in handle_update\n    return await self.callback(update, context)\n           ^^^^^^^^^^^^^^^^^^^^^^^^^^^^^^^^^^^^\n  File \"/home/technedict/Desktop/ViralPackage/viralcore/handlers/admin_handlers.py\", line 471, in admin_panel_handler\n    await switch_boost_provider(update, context, provider_name)\n  File \"/home/technedict/Desktop/ViralPackage/viralcore/handlers/admin_handlers.py\", line 519, in switch_boost_provider\n    update.callback_query.bot,\n    ^^^^^^^^^^^^^^^^^^^^^^^^^\nAttributeError: 'CallbackQuery' object has no attribute 'bot'"}
{"timestamp": "2025-09-27T13:47:47.725162Z", "level": "ERROR", "module": "telegram.ext.Application", "message": "No error handlers are registered, logging exception.", "correlation_id": "none", "exception": "Traceback (most recent call last):\n  File \"/home/technedict/Desktop/ViralPackage/viralcorelib/lib64/python3.13/site-packages/telegram/ext/_application.py\", line 1298, in process_update\n    await coroutine\n  File \"/home/technedict/Desktop/ViralPackage/viralcorelib/lib64/python3.13/site-packages/telegram/ext/_handlers/basehandler.py\", line 158, in handle_update\n    return await self.callback(update, context)\n           ^^^^^^^^^^^^^^^^^^^^^^^^^^^^^^^^^^^^\n  File \"/home/technedict/Desktop/ViralPackage/viralcore/handlers/admin_handlers.py\", line 471, in admin_panel_handler\n    await switch_boost_provider(update, context, provider_name)\n  File \"/home/technedict/Desktop/ViralPackage/viralcore/handlers/admin_handlers.py\", line 519, in switch_boost_provider\n    update.callback_query.bot,\n    ^^^^^^^^^^^^^^^^^^^^^^^^^\nAttributeError: 'CallbackQuery' object has no attribute 'bot'"}
{"timestamp": "2025-09-27T13:48:09.528758Z", "level": "ERROR", "module": "telegram.ext.Application", "message": "No error handlers are registered, logging exception.", "correlation_id": "none", "exception": "Traceback (most recent call last):\n  File \"/home/technedict/Desktop/ViralPackage/viralcorelib/lib64/python3.13/site-packages/telegram/ext/_application.py\", line 1298, in process_update\n    await coroutine\n  File \"/home/technedict/Desktop/ViralPackage/viralcorelib/lib64/python3.13/site-packages/telegram/ext/_handlers/basehandler.py\", line 158, in handle_update\n    return await self.callback(update, context)\n           ^^^^^^^^^^^^^^^^^^^^^^^^^^^^^^^^^^^^\n  File \"/home/technedict/Desktop/ViralPackage/viralcore/handlers/admin_handlers.py\", line 471, in admin_panel_handler\n    await switch_boost_provider(update, context, provider_name)\n  File \"/home/technedict/Desktop/ViralPackage/viralcore/handlers/admin_handlers.py\", line 519, in switch_boost_provider\n    update.callback_query.bot,\n    ^^^^^^^^^^^^^^^^^^^^^^^^^\nAttributeError: 'CallbackQuery' object has no attribute 'bot'"}
{"timestamp": "2025-09-27T13:50:46.433724Z", "level": "WARNING", "module": "utils.graceful_shutdown", "message": "updater.shutdown() raised: This Updater is still running!", "correlation_id": "none"}
{"timestamp": "2025-09-27T13:50:46.434729Z", "level": "WARNING", "module": "utils.graceful_shutdown", "message": "Shutdown already in progress", "correlation_id": "none"}
{"timestamp": "2025-09-27T13:50:46.451437Z", "level": "ERROR", "module": "__main__", "message": "Error during app.shutdown()", "correlation_id": "none", "exception": "Traceback (most recent call last):\n  File \"/home/technedict/Desktop/ViralPackage/viralcore/main_viral_core_bot.py\", line 247, in main\n    await app.shutdown()\n  File \"/home/technedict/Desktop/ViralPackage/viralcorelib/lib64/python3.13/site-packages/telegram/ext/_application.py\", line 544, in shutdown\n    await self.updater.shutdown()\n  File \"/home/technedict/Desktop/ViralPackage/viralcorelib/lib64/python3.13/site-packages/telegram/ext/_updater.py\", line 196, in shutdown\n    raise RuntimeError(\"This Updater is still running!\")\nRuntimeError: This Updater is still running!"}
{"timestamp": "2025-09-27T13:50:46.545783Z", "level": "ERROR", "module": "asyncio", "message": "Task exception was never retrieved\nfuture: <Task finished name='Task-117' coro=<Updater._start_polling.<locals>.polling_action_cb() done, defined at /home/technedict/Desktop/ViralPackage/viralcorelib/lib64/python3.13/site-packages/telegram/ext/_updater.py:333> exception=NetworkError('httpx.ReadError: ')>", "correlation_id": "none", "exception": "Traceback (most recent call last):\n  File \"/home/technedict/Desktop/ViralPackage/viralcorelib/lib64/python3.13/site-packages/httpx/_transports/default.py\", line 101, in map_httpcore_exceptions\n  File \"/home/technedict/Desktop/ViralPackage/viralcorelib/lib64/python3.13/site-packages/httpx/_transports/default.py\", line 394, in handle_async_request\n  File \"/home/technedict/Desktop/ViralPackage/viralcorelib/lib64/python3.13/site-packages/httpcore/_async/connection_pool.py\", line 256, in handle_async_request\n  File \"/home/technedict/Desktop/ViralPackage/viralcorelib/lib64/python3.13/site-packages/httpcore/_async/connection_pool.py\", line 236, in handle_async_request\n  File \"/home/technedict/Desktop/ViralPackage/viralcorelib/lib64/python3.13/site-packages/httpcore/_async/connection.py\", line 103, in handle_async_request\n  File \"/home/technedict/Desktop/ViralPackage/viralcorelib/lib64/python3.13/site-packages/httpcore/_async/http11.py\", line 136, in handle_async_request\n  File \"/home/technedict/Desktop/ViralPackage/viralcorelib/lib64/python3.13/site-packages/httpcore/_async/http11.py\", line 106, in handle_async_request\n  File \"/home/technedict/Desktop/ViralPackage/viralcorelib/lib64/python3.13/site-packages/httpcore/_async/http11.py\", line 177, in _receive_response_headers\n  File \"/home/technedict/Desktop/ViralPackage/viralcorelib/lib64/python3.13/site-packages/httpcore/_async/http11.py\", line 217, in _receive_event\n  File \"/home/technedict/Desktop/ViralPackage/viralcorelib/lib64/python3.13/site-packages/httpcore/_backends/anyio.py\", line 32, in read\n  File \"/usr/lib64/python3.13/contextlib.py\", line 162, in __exit__\n  File \"/home/technedict/Desktop/ViralPackage/viralcorelib/lib64/python3.13/site-packages/httpcore/_exceptions.py\", line 14, in map_exceptions\nhttpcore.ReadError\n\nThe above exception was the direct cause of the following exception:\n\nTraceback (most recent call last):\n  File \"/home/technedict/Desktop/ViralPackage/viralcorelib/lib64/python3.13/site-packages/telegram/request/_httpxrequest.py\", line 277, in do_request\n  File \"/home/technedict/Desktop/ViralPackage/viralcorelib/lib64/python3.13/site-packages/httpx/_client.py\", line 1540, in request\n  File \"/home/technedict/Desktop/ViralPackage/viralcorelib/lib64/python3.13/site-packages/httpx/_client.py\", line 1629, in send\n  File \"/home/technedict/Desktop/ViralPackage/viralcorelib/lib64/python3.13/site-packages/httpx/_client.py\", line 1657, in _send_handling_auth\n  File \"/home/technedict/Desktop/ViralPackage/viralcorelib/lib64/python3.13/site-packages/httpx/_client.py\", line 1694, in _send_handling_redirects\n  File \"/home/technedict/Desktop/ViralPackage/viralcorelib/lib64/python3.13/site-packages/httpx/_client.py\", line 1730, in _send_single_request\n  File \"/home/technedict/Desktop/ViralPackage/viralcorelib/lib64/python3.13/site-packages/httpx/_transports/default.py\", line 393, in handle_async_request\n  File \"/usr/lib64/python3.13/contextlib.py\", line 162, in __exit__\n  File \"/home/technedict/Desktop/ViralPackage/viralcorelib/lib64/python3.13/site-packages/httpx/_transports/default.py\", line 118, in map_httpcore_exceptions\nhttpx.ReadError\n\nThe above exception was the direct cause of the following exception:\n\nTraceback (most recent call last):\n  File \"/home/technedict/Desktop/ViralPackage/viralcorelib/lib64/python3.13/site-packages/telegram/ext/_updater.py\", line 335, in polling_action_cb\n    updates = await self.bot.get_updates(\n              ^^^^^^^^^^^^^^^^^^^^^^^^^^^\n    ...<3 lines>...\n    )\n    ^\n  File \"/home/technedict/Desktop/ViralPackage/viralcorelib/lib64/python3.13/site-packages/telegram/ext/_extbot.py\", line 658, in get_updates\n  File \"/home/technedict/Desktop/ViralPackage/viralcorelib/lib64/python3.13/site-packages/telegram/_bot.py\", line 4593, in get_updates\n  File \"/home/technedict/Desktop/ViralPackage/viralcorelib/lib64/python3.13/site-packages/telegram/_bot.py\", line 691, in _post\n  File \"/home/technedict/Desktop/ViralPackage/viralcorelib/lib64/python3.13/site-packages/telegram/ext/_extbot.py\", line 362, in _do_post\n  File \"/home/technedict/Desktop/ViralPackage/viralcorelib/lib64/python3.13/site-packages/telegram/_bot.py\", line 720, in _do_post\n  File \"/home/technedict/Desktop/ViralPackage/viralcorelib/lib64/python3.13/site-packages/telegram/request/_baserequest.py\", line 197, in post\n  File \"/home/technedict/Desktop/ViralPackage/viralcorelib/lib64/python3.13/site-packages/telegram/request/_baserequest.py\", line 304, in _request_wrapper\n  File \"/home/technedict/Desktop/ViralPackage/viralcorelib/lib64/python3.13/site-packages/telegram/request/_httpxrequest.py\", line 301, in do_request\ntelegram.error.NetworkError: httpx.ReadError: "}
{"timestamp": "2025-09-27T13:53:33.971537Z", "level": "WARNING", "module": "utils.graceful_shutdown", "message": "updater.shutdown() raised: This Updater is still running!", "correlation_id": "none"}
{"timestamp": "2025-09-27T13:53:33.972695Z", "level": "WARNING", "module": "utils.graceful_shutdown", "message": "Shutdown already in progress", "correlation_id": "none"}
{"timestamp": "2025-09-27T13:53:33.991494Z", "level": "ERROR", "module": "__main__", "message": "Error during app.shutdown()", "correlation_id": "none", "exception": "Traceback (most recent call last):\n  File \"/home/technedict/Desktop/ViralPackage/viralcore/main_viral_core_bot.py\", line 247, in main\n    await app.shutdown()\n  File \"/home/technedict/Desktop/ViralPackage/viralcorelib/lib64/python3.13/site-packages/telegram/ext/_application.py\", line 544, in shutdown\n    await self.updater.shutdown()\n  File \"/home/technedict/Desktop/ViralPackage/viralcorelib/lib64/python3.13/site-packages/telegram/ext/_updater.py\", line 196, in shutdown\n    raise RuntimeError(\"This Updater is still running!\")\nRuntimeError: This Updater is still running!"}
{"timestamp": "2025-09-27T13:53:34.083343Z", "level": "ERROR", "module": "asyncio", "message": "Task exception was never retrieved\nfuture: <Task finished name='Task-42' coro=<Updater._start_polling.<locals>.polling_action_cb() done, defined at /home/technedict/Desktop/ViralPackage/viralcorelib/lib64/python3.13/site-packages/telegram/ext/_updater.py:333> exception=NetworkError('httpx.ReadError: ')>", "correlation_id": "none", "exception": "Traceback (most recent call last):\n  File \"/home/technedict/Desktop/ViralPackage/viralcorelib/lib64/python3.13/site-packages/httpx/_transports/default.py\", line 101, in map_httpcore_exceptions\n  File \"/home/technedict/Desktop/ViralPackage/viralcorelib/lib64/python3.13/site-packages/httpx/_transports/default.py\", line 394, in handle_async_request\n  File \"/home/technedict/Desktop/ViralPackage/viralcorelib/lib64/python3.13/site-packages/httpcore/_async/connection_pool.py\", line 256, in handle_async_request\n  File \"/home/technedict/Desktop/ViralPackage/viralcorelib/lib64/python3.13/site-packages/httpcore/_async/connection_pool.py\", line 236, in handle_async_request\n  File \"/home/technedict/Desktop/ViralPackage/viralcorelib/lib64/python3.13/site-packages/httpcore/_async/connection.py\", line 103, in handle_async_request\n  File \"/home/technedict/Desktop/ViralPackage/viralcorelib/lib64/python3.13/site-packages/httpcore/_async/http11.py\", line 136, in handle_async_request\n  File \"/home/technedict/Desktop/ViralPackage/viralcorelib/lib64/python3.13/site-packages/httpcore/_async/http11.py\", line 106, in handle_async_request\n  File \"/home/technedict/Desktop/ViralPackage/viralcorelib/lib64/python3.13/site-packages/httpcore/_async/http11.py\", line 177, in _receive_response_headers\n  File \"/home/technedict/Desktop/ViralPackage/viralcorelib/lib64/python3.13/site-packages/httpcore/_async/http11.py\", line 217, in _receive_event\n  File \"/home/technedict/Desktop/ViralPackage/viralcorelib/lib64/python3.13/site-packages/httpcore/_backends/anyio.py\", line 32, in read\n  File \"/usr/lib64/python3.13/contextlib.py\", line 162, in __exit__\n  File \"/home/technedict/Desktop/ViralPackage/viralcorelib/lib64/python3.13/site-packages/httpcore/_exceptions.py\", line 14, in map_exceptions\nhttpcore.ReadError\n\nThe above exception was the direct cause of the following exception:\n\nTraceback (most recent call last):\n  File \"/home/technedict/Desktop/ViralPackage/viralcorelib/lib64/python3.13/site-packages/telegram/request/_httpxrequest.py\", line 277, in do_request\n  File \"/home/technedict/Desktop/ViralPackage/viralcorelib/lib64/python3.13/site-packages/httpx/_client.py\", line 1540, in request\n  File \"/home/technedict/Desktop/ViralPackage/viralcorelib/lib64/python3.13/site-packages/httpx/_client.py\", line 1629, in send\n  File \"/home/technedict/Desktop/ViralPackage/viralcorelib/lib64/python3.13/site-packages/httpx/_client.py\", line 1657, in _send_handling_auth\n  File \"/home/technedict/Desktop/ViralPackage/viralcorelib/lib64/python3.13/site-packages/httpx/_client.py\", line 1694, in _send_handling_redirects\n  File \"/home/technedict/Desktop/ViralPackage/viralcorelib/lib64/python3.13/site-packages/httpx/_client.py\", line 1730, in _send_single_request\n  File \"/home/technedict/Desktop/ViralPackage/viralcorelib/lib64/python3.13/site-packages/httpx/_transports/default.py\", line 393, in handle_async_request\n  File \"/usr/lib64/python3.13/contextlib.py\", line 162, in __exit__\n  File \"/home/technedict/Desktop/ViralPackage/viralcorelib/lib64/python3.13/site-packages/httpx/_transports/default.py\", line 118, in map_httpcore_exceptions\nhttpx.ReadError\n\nThe above exception was the direct cause of the following exception:\n\nTraceback (most recent call last):\n  File \"/home/technedict/Desktop/ViralPackage/viralcorelib/lib64/python3.13/site-packages/telegram/ext/_updater.py\", line 335, in polling_action_cb\n    updates = await self.bot.get_updates(\n              ^^^^^^^^^^^^^^^^^^^^^^^^^^^\n    ...<3 lines>...\n    )\n    ^\n  File \"/home/technedict/Desktop/ViralPackage/viralcorelib/lib64/python3.13/site-packages/telegram/ext/_extbot.py\", line 658, in get_updates\n  File \"/home/technedict/Desktop/ViralPackage/viralcorelib/lib64/python3.13/site-packages/telegram/_bot.py\", line 4593, in get_updates\n  File \"/home/technedict/Desktop/ViralPackage/viralcorelib/lib64/python3.13/site-packages/telegram/_bot.py\", line 691, in _post\n  File \"/home/technedict/Desktop/ViralPackage/viralcorelib/lib64/python3.13/site-packages/telegram/ext/_extbot.py\", line 362, in _do_post\n  File \"/home/technedict/Desktop/ViralPackage/viralcorelib/lib64/python3.13/site-packages/telegram/_bot.py\", line 720, in _do_post\n  File \"/home/technedict/Desktop/ViralPackage/viralcorelib/lib64/python3.13/site-packages/telegram/request/_baserequest.py\", line 197, in post\n  File \"/home/technedict/Desktop/ViralPackage/viralcorelib/lib64/python3.13/site-packages/telegram/request/_baserequest.py\", line 304, in _request_wrapper\n  File \"/home/technedict/Desktop/ViralPackage/viralcorelib/lib64/python3.13/site-packages/telegram/request/_httpxrequest.py\", line 301, in do_request\ntelegram.error.NetworkError: httpx.ReadError: "}
{"timestamp": "2025-09-27T14:17:25.240977Z", "level": "ERROR", "module": "telegram.ext.Application", "message": "No error handlers are registered, logging exception.", "correlation_id": "none", "exception": "Traceback (most recent call last):\n  File \"/home/technedict/Desktop/ViralPackage/viralcorelib/lib64/python3.13/site-packages/telegram/ext/_application.py\", line 1335, in process_update\n    await coroutine\n  File \"/home/technedict/Desktop/ViralPackage/viralcorelib/lib64/python3.13/site-packages/telegram/ext/_handlers/basehandler.py\", line 157, in handle_update\n    return await self.callback(update, context)\n           ^^^^^^^^^^^^^^^^^^^^^^^^^^^^^^^^^^^^\n  File \"/home/technedict/Desktop/ViralPackage/viralcore/handlers/message_handler.py\", line 51, in message_router\n    await custom_order_handler(update, context) # Or a general_message_handler\n    ^^^^^^^^^^^^^^^^^^^^^^^^^^^^^^^^^^^^^^^^^^^\n  File \"/home/technedict/Desktop/ViralPackage/viralcore/handlers/custom_order_handlers.py\", line 30, in custom_order_handler\n    text = update.message.text.strip()\n           ^^^^^^^^^^^^^^^^^^^\nAttributeError: 'NoneType' object has no attribute 'text'"}
{"timestamp": "2025-09-27T14:17:36.400328Z", "level": "WARNING", "module": "utils.graceful_shutdown", "message": "updater.shutdown() raised: This Updater is still running!", "correlation_id": "none"}
{"timestamp": "2025-09-27T14:17:36.401147Z", "level": "WARNING", "module": "utils.graceful_shutdown", "message": "Shutdown already in progress", "correlation_id": "none"}
{"timestamp": "2025-09-27T14:17:36.417888Z", "level": "ERROR", "module": "__main__", "message": "Error during app.shutdown()", "correlation_id": "none", "exception": "Traceback (most recent call last):\n  File \"/home/technedict/Desktop/ViralPackage/viralcore/main_viral_core_bot.py\", line 247, in main\n    await app.shutdown()\n  File \"/home/technedict/Desktop/ViralPackage/viralcorelib/lib64/python3.13/site-packages/telegram/ext/_application.py\", line 561, in shutdown\n    await self.updater.shutdown()\n  File \"/home/technedict/Desktop/ViralPackage/viralcorelib/lib64/python3.13/site-packages/telegram/ext/_updater.py\", line 204, in shutdown\n    raise RuntimeError(\"This Updater is still running!\")\nRuntimeError: This Updater is still running!"}
{"timestamp": "2025-09-27T14:17:36.505360Z", "level": "ERROR", "module": "asyncio", "message": "Task exception was never retrieved\nfuture: <Task finished name='Task-8' coro=<Updater._start_polling.<locals>.polling_action_cb() done, defined at /home/technedict/Desktop/ViralPackage/viralcorelib/lib64/python3.13/site-packages/telegram/ext/_updater.py:375> exception=NetworkError('httpx.ReadError: ')>", "correlation_id": "none", "exception": "Traceback (most recent call last):\n  File \"/home/technedict/Desktop/ViralPackage/viralcorelib/lib64/python3.13/site-packages/httpx/_transports/default.py\", line 101, in map_httpcore_exceptions\n  File \"/home/technedict/Desktop/ViralPackage/viralcorelib/lib64/python3.13/site-packages/httpx/_transports/default.py\", line 394, in handle_async_request\n  File \"/home/technedict/Desktop/ViralPackage/viralcorelib/lib64/python3.13/site-packages/httpcore/_async/connection_pool.py\", line 256, in handle_async_request\n  File \"/home/technedict/Desktop/ViralPackage/viralcorelib/lib64/python3.13/site-packages/httpcore/_async/connection_pool.py\", line 236, in handle_async_request\n  File \"/home/technedict/Desktop/ViralPackage/viralcorelib/lib64/python3.13/site-packages/httpcore/_async/connection.py\", line 103, in handle_async_request\n  File \"/home/technedict/Desktop/ViralPackage/viralcorelib/lib64/python3.13/site-packages/httpcore/_async/http11.py\", line 136, in handle_async_request\n  File \"/home/technedict/Desktop/ViralPackage/viralcorelib/lib64/python3.13/site-packages/httpcore/_async/http11.py\", line 106, in handle_async_request\n  File \"/home/technedict/Desktop/ViralPackage/viralcorelib/lib64/python3.13/site-packages/httpcore/_async/http11.py\", line 177, in _receive_response_headers\n  File \"/home/technedict/Desktop/ViralPackage/viralcorelib/lib64/python3.13/site-packages/httpcore/_async/http11.py\", line 217, in _receive_event\n  File \"/home/technedict/Desktop/ViralPackage/viralcorelib/lib64/python3.13/site-packages/httpcore/_backends/anyio.py\", line 32, in read\n  File \"/usr/lib64/python3.13/contextlib.py\", line 162, in __exit__\n  File \"/home/technedict/Desktop/ViralPackage/viralcorelib/lib64/python3.13/site-packages/httpcore/_exceptions.py\", line 14, in map_exceptions\nhttpcore.ReadError\n\nThe above exception was the direct cause of the following exception:\n\nTraceback (most recent call last):\n  File \"/home/technedict/Desktop/ViralPackage/viralcorelib/lib64/python3.13/site-packages/telegram/request/_httpxrequest.py\", line 276, in do_request\n  File \"/home/technedict/Desktop/ViralPackage/viralcorelib/lib64/python3.13/site-packages/httpx/_client.py\", line 1540, in request\n  File \"/home/technedict/Desktop/ViralPackage/viralcorelib/lib64/python3.13/site-packages/httpx/_client.py\", line 1629, in send\n  File \"/home/technedict/Desktop/ViralPackage/viralcorelib/lib64/python3.13/site-packages/httpx/_client.py\", line 1657, in _send_handling_auth\n  File \"/home/technedict/Desktop/ViralPackage/viralcorelib/lib64/python3.13/site-packages/httpx/_client.py\", line 1694, in _send_handling_redirects\n  File \"/home/technedict/Desktop/ViralPackage/viralcorelib/lib64/python3.13/site-packages/httpx/_client.py\", line 1730, in _send_single_request\n  File \"/home/technedict/Desktop/ViralPackage/viralcorelib/lib64/python3.13/site-packages/httpx/_transports/default.py\", line 393, in handle_async_request\n  File \"/usr/lib64/python3.13/contextlib.py\", line 162, in __exit__\n  File \"/home/technedict/Desktop/ViralPackage/viralcorelib/lib64/python3.13/site-packages/httpx/_transports/default.py\", line 118, in map_httpcore_exceptions\nhttpx.ReadError\n\nThe above exception was the direct cause of the following exception:\n\nTraceback (most recent call last):\n  File \"/home/technedict/Desktop/ViralPackage/viralcorelib/lib64/python3.13/site-packages/telegram/ext/_updater.py\", line 377, in polling_action_cb\n    updates = await self.bot.get_updates(\n              ^^^^^^^^^^^^^^^^^^^^^^^^^^^\n    ...<7 lines>...\n    )\n    ^\n  File \"/home/technedict/Desktop/ViralPackage/viralcorelib/lib64/python3.13/site-packages/telegram/ext/_extbot.py\", line 649, in get_updates\n  File \"/home/technedict/Desktop/ViralPackage/viralcorelib/lib64/python3.13/site-packages/telegram/_bot.py\", line 4366, in get_updates\n  File \"/home/technedict/Desktop/ViralPackage/viralcorelib/lib64/python3.13/site-packages/telegram/_bot.py\", line 623, in _post\n  File \"/home/technedict/Desktop/ViralPackage/viralcorelib/lib64/python3.13/site-packages/telegram/ext/_extbot.py\", line 355, in _do_post\n  File \"/home/technedict/Desktop/ViralPackage/viralcorelib/lib64/python3.13/site-packages/telegram/_bot.py\", line 652, in _do_post\n  File \"/home/technedict/Desktop/ViralPackage/viralcorelib/lib64/python3.13/site-packages/telegram/request/_baserequest.py\", line 201, in post\n  File \"/home/technedict/Desktop/ViralPackage/viralcorelib/lib64/python3.13/site-packages/telegram/request/_baserequest.py\", line 333, in _request_wrapper\n  File \"/home/technedict/Desktop/ViralPackage/viralcorelib/lib64/python3.13/site-packages/telegram/request/_httpxrequest.py\", line 300, in do_request\ntelegram.error.NetworkError: httpx.ReadError: "}
