{"timestamp": "2025-09-28T15:15:41.327027Z", "level": "ERROR", "module": "telegram.ext.Application", "message": "No error handlers are registered, logging exception.", "correlation_id": "none", "exception": "Traceback (most recent call last):\n  File \"/home/technedict/Desktop/ViralPackage/viralcorelib/lib64/python3.13/site-packages/telegram/ext/_application.py\", line 1335, in process_update\n    await coroutine\n  File \"/home/technedict/Desktop/ViralPackage/viralcorelib/lib64/python3.13/site-packages/telegram/ext/_handlers/basehandler.py\", line 157, in handle_update\n    return await self.callback(update, context)\n           ^^^^^^^^^^^^^^^^^^^^^^^^^^^^^^^^^^^^\n  File \"/home/technedict/Desktop/ViralPackage/viralcore/handlers/message_handler.py\", line 57, in message_router\n    await custom_order_handler(update, context) # Or a general_message_handler\n    ^^^^^^^^^^^^^^^^^^^^^^^^^^^^^^^^^^^^^^^^^^^\n  File \"/home/technedict/Desktop/ViralPackage/viralcore/handlers/custom_order_handlers.py\", line 31, in custom_order_handler\n    text = update.message.text.strip()\n           ^^^^^^^^^^^^^^^^^^^\nAttributeError: 'NoneType' object has no attribute 'text'"}
{"timestamp": "2025-09-28T15:15:41.332267Z", "level": "ERROR", "module": "telegram.ext.Application", "message": "No error handlers are registered, logging exception.", "correlation_id": "none", "exception": "Traceback (most recent call last):\n  File \"/home/technedict/Desktop/ViralPackage/viralcorelib/lib64/python3.13/site-packages/telegram/ext/_application.py\", line 1335, in process_update\n    await coroutine\n  File \"/home/technedict/Desktop/ViralPackage/viralcorelib/lib64/python3.13/site-packages/telegram/ext/_handlers/basehandler.py\", line 157, in handle_update\n    return await self.callback(update, context)\n           ^^^^^^^^^^^^^^^^^^^^^^^^^^^^^^^^^^^^\n  File \"/home/technedict/Desktop/ViralPackage/viralcore/handlers/message_handler.py\", line 57, in message_router\n    await custom_order_handler(update, context) # Or a general_message_handler\n    ^^^^^^^^^^^^^^^^^^^^^^^^^^^^^^^^^^^^^^^^^^^\n  File \"/home/technedict/Desktop/ViralPackage/viralcore/handlers/custom_order_handlers.py\", line 31, in custom_order_handler\n    text = update.message.text.strip()\n           ^^^^^^^^^^^^^^^^^^^\nAttributeError: 'NoneType' object has no attribute 'text'"}
{"timestamp": "2025-09-28T15:15:41.337832Z", "level": "ERROR", "module": "telegram.ext.Application", "message": "No error handlers are registered, logging exception.", "correlation_id": "none", "exception": "Traceback (most recent call last):\n  File \"/home/technedict/Desktop/ViralPackage/viralcorelib/lib64/python3.13/site-packages/telegram/ext/_application.py\", line 1335, in process_update\n    await coroutine\n  File \"/home/technedict/Desktop/ViralPackage/viralcorelib/lib64/python3.13/site-packages/telegram/ext/_handlers/basehandler.py\", line 157, in handle_update\n    return await self.callback(update, context)\n           ^^^^^^^^^^^^^^^^^^^^^^^^^^^^^^^^^^^^\n  File \"/home/technedict/Desktop/ViralPackage/viralcore/handlers/message_handler.py\", line 57, in message_router\n    await custom_order_handler(update, context) # Or a general_message_handler\n    ^^^^^^^^^^^^^^^^^^^^^^^^^^^^^^^^^^^^^^^^^^^\n  File \"/home/technedict/Desktop/ViralPackage/viralcore/handlers/custom_order_handlers.py\", line 31, in custom_order_handler\n    text = update.message.text.strip()\n           ^^^^^^^^^^^^^^^^^^^\nAttributeError: 'NoneType' object has no attribute 'text'"}
{"timestamp": "2025-09-28T15:15:41.343687Z", "level": "ERROR", "module": "telegram.ext.Application", "message": "No error handlers are registered, logging exception.", "correlation_id": "none", "exception": "Traceback (most recent call last):\n  File \"/home/technedict/Desktop/ViralPackage/viralcorelib/lib64/python3.13/site-packages/telegram/ext/_application.py\", line 1335, in process_update\n    await coroutine\n  File \"/home/technedict/Desktop/ViralPackage/viralcorelib/lib64/python3.13/site-packages/telegram/ext/_handlers/basehandler.py\", line 157, in handle_update\n    return await self.callback(update, context)\n           ^^^^^^^^^^^^^^^^^^^^^^^^^^^^^^^^^^^^\n  File \"/home/technedict/Desktop/ViralPackage/viralcore/handlers/message_handler.py\", line 57, in message_router\n    await custom_order_handler(update, context) # Or a general_message_handler\n    ^^^^^^^^^^^^^^^^^^^^^^^^^^^^^^^^^^^^^^^^^^^\n  File \"/home/technedict/Desktop/ViralPackage/viralcore/handlers/custom_order_handlers.py\", line 31, in custom_order_handler\n    text = update.message.text.strip()\n           ^^^^^^^^^^^^^^^^^^^\nAttributeError: 'NoneType' object has no attribute 'text'"}
{"timestamp": "2025-09-28T15:15:41.352889Z", "level": "ERROR", "module": "telegram.ext.Application", "message": "No error handlers are registered, logging exception.", "correlation_id": "none", "exception": "Traceback (most recent call last):\n  File \"/home/technedict/Desktop/ViralPackage/viralcorelib/lib64/python3.13/site-packages/telegram/ext/_application.py\", line 1335, in process_update\n    await coroutine\n  File \"/home/technedict/Desktop/ViralPackage/viralcorelib/lib64/python3.13/site-packages/telegram/ext/_handlers/basehandler.py\", line 157, in handle_update\n    return await self.callback(update, context)\n           ^^^^^^^^^^^^^^^^^^^^^^^^^^^^^^^^^^^^\n  File \"/home/technedict/Desktop/ViralPackage/viralcore/handlers/message_handler.py\", line 57, in message_router\n    await custom_order_handler(update, context) # Or a general_message_handler\n    ^^^^^^^^^^^^^^^^^^^^^^^^^^^^^^^^^^^^^^^^^^^\n  File \"/home/technedict/Desktop/ViralPackage/viralcore/handlers/custom_order_handlers.py\", line 31, in custom_order_handler\n    text = update.message.text.strip()\n           ^^^^^^^^^^^^^^^^^^^\nAttributeError: 'NoneType' object has no attribute 'text'"}
{"timestamp": "2025-09-28T15:15:41.361737Z", "level": "ERROR", "module": "telegram.ext.Application", "message": "No error handlers are registered, logging exception.", "correlation_id": "none", "exception": "Traceback (most recent call last):\n  File \"/home/technedict/Desktop/ViralPackage/viralcorelib/lib64/python3.13/site-packages/telegram/ext/_application.py\", line 1335, in process_update\n    await coroutine\n  File \"/home/technedict/Desktop/ViralPackage/viralcorelib/lib64/python3.13/site-packages/telegram/ext/_handlers/basehandler.py\", line 157, in handle_update\n    return await self.callback(update, context)\n           ^^^^^^^^^^^^^^^^^^^^^^^^^^^^^^^^^^^^\n  File \"/home/technedict/Desktop/ViralPackage/viralcore/handlers/message_handler.py\", line 57, in message_router\n    await custom_order_handler(update, context) # Or a general_message_handler\n    ^^^^^^^^^^^^^^^^^^^^^^^^^^^^^^^^^^^^^^^^^^^\n  File \"/home/technedict/Desktop/ViralPackage/viralcore/handlers/custom_order_handlers.py\", line 31, in custom_order_handler\n    text = update.message.text.strip()\n           ^^^^^^^^^^^^^^^^^^^\nAttributeError: 'NoneType' object has no attribute 'text'"}
{"timestamp": "2025-09-28T15:15:41.370500Z", "level": "ERROR", "module": "telegram.ext.Application", "message": "No error handlers are registered, logging exception.", "correlation_id": "none", "exception": "Traceback (most recent call last):\n  File \"/home/technedict/Desktop/ViralPackage/viralcorelib/lib64/python3.13/site-packages/telegram/ext/_application.py\", line 1335, in process_update\n    await coroutine\n  File \"/home/technedict/Desktop/ViralPackage/viralcorelib/lib64/python3.13/site-packages/telegram/ext/_handlers/basehandler.py\", line 157, in handle_update\n    return await self.callback(update, context)\n           ^^^^^^^^^^^^^^^^^^^^^^^^^^^^^^^^^^^^\n  File \"/home/technedict/Desktop/ViralPackage/viralcore/handlers/message_handler.py\", line 57, in message_router\n    await custom_order_handler(update, context) # Or a general_message_handler\n    ^^^^^^^^^^^^^^^^^^^^^^^^^^^^^^^^^^^^^^^^^^^\n  File \"/home/technedict/Desktop/ViralPackage/viralcore/handlers/custom_order_handlers.py\", line 31, in custom_order_handler\n    text = update.message.text.strip()\n           ^^^^^^^^^^^^^^^^^^^\nAttributeError: 'NoneType' object has no attribute 'text'"}
{"timestamp": "2025-09-28T15:15:41.377546Z", "level": "ERROR", "module": "telegram.ext.Application", "message": "No error handlers are registered, logging exception.", "correlation_id": "none", "exception": "Traceback (most recent call last):\n  File \"/home/technedict/Desktop/ViralPackage/viralcorelib/lib64/python3.13/site-packages/telegram/ext/_application.py\", line 1335, in process_update\n    await coroutine\n  File \"/home/technedict/Desktop/ViralPackage/viralcorelib/lib64/python3.13/site-packages/telegram/ext/_handlers/basehandler.py\", line 157, in handle_update\n    return await self.callback(update, context)\n           ^^^^^^^^^^^^^^^^^^^^^^^^^^^^^^^^^^^^\n  File \"/home/technedict/Desktop/ViralPackage/viralcore/handlers/message_handler.py\", line 57, in message_router\n    await custom_order_handler(update, context) # Or a general_message_handler\n    ^^^^^^^^^^^^^^^^^^^^^^^^^^^^^^^^^^^^^^^^^^^\n  File \"/home/technedict/Desktop/ViralPackage/viralcore/handlers/custom_order_handlers.py\", line 31, in custom_order_handler\n    text = update.message.text.strip()\n           ^^^^^^^^^^^^^^^^^^^\nAttributeError: 'NoneType' object has no attribute 'text'"}
{"timestamp": "2025-09-28T15:15:41.386429Z", "level": "ERROR", "module": "telegram.ext.Application", "message": "No error handlers are registered, logging exception.", "correlation_id": "none", "exception": "Traceback (most recent call last):\n  File \"/home/technedict/Desktop/ViralPackage/viralcorelib/lib64/python3.13/site-packages/telegram/ext/_application.py\", line 1335, in process_update\n    await coroutine\n  File \"/home/technedict/Desktop/ViralPackage/viralcorelib/lib64/python3.13/site-packages/telegram/ext/_handlers/basehandler.py\", line 157, in handle_update\n    return await self.callback(update, context)\n           ^^^^^^^^^^^^^^^^^^^^^^^^^^^^^^^^^^^^\n  File \"/home/technedict/Desktop/ViralPackage/viralcore/handlers/message_handler.py\", line 57, in message_router\n    await custom_order_handler(update, context) # Or a general_message_handler\n    ^^^^^^^^^^^^^^^^^^^^^^^^^^^^^^^^^^^^^^^^^^^\n  File \"/home/technedict/Desktop/ViralPackage/viralcore/handlers/custom_order_handlers.py\", line 31, in custom_order_handler\n    text = update.message.text.strip()\n           ^^^^^^^^^^^^^^^^^^^\nAttributeError: 'NoneType' object has no attribute 'text'"}
{"timestamp": "2025-09-28T15:15:41.394804Z", "level": "ERROR", "module": "telegram.ext.Application", "message": "No error handlers are registered, logging exception.", "correlation_id": "none", "exception": "Traceback (most recent call last):\n  File \"/home/technedict/Desktop/ViralPackage/viralcorelib/lib64/python3.13/site-packages/telegram/ext/_application.py\", line 1335, in process_update\n    await coroutine\n  File \"/home/technedict/Desktop/ViralPackage/viralcorelib/lib64/python3.13/site-packages/telegram/ext/_handlers/basehandler.py\", line 157, in handle_update\n    return await self.callback(update, context)\n           ^^^^^^^^^^^^^^^^^^^^^^^^^^^^^^^^^^^^\n  File \"/home/technedict/Desktop/ViralPackage/viralcore/handlers/message_handler.py\", line 57, in message_router\n    await custom_order_handler(update, context) # Or a general_message_handler\n    ^^^^^^^^^^^^^^^^^^^^^^^^^^^^^^^^^^^^^^^^^^^\n  File \"/home/technedict/Desktop/ViralPackage/viralcore/handlers/custom_order_handlers.py\", line 31, in custom_order_handler\n    text = update.message.text.strip()\n           ^^^^^^^^^^^^^^^^^^^\nAttributeError: 'NoneType' object has no attribute 'text'"}
{"timestamp": "2025-09-28T15:15:41.404643Z", "level": "ERROR", "module": "telegram.ext.Application", "message": "No error handlers are registered, logging exception.", "correlation_id": "none", "exception": "Traceback (most recent call last):\n  File \"/home/technedict/Desktop/ViralPackage/viralcorelib/lib64/python3.13/site-packages/telegram/ext/_application.py\", line 1335, in process_update\n    await coroutine\n  File \"/home/technedict/Desktop/ViralPackage/viralcorelib/lib64/python3.13/site-packages/telegram/ext/_handlers/basehandler.py\", line 157, in handle_update\n    return await self.callback(update, context)\n           ^^^^^^^^^^^^^^^^^^^^^^^^^^^^^^^^^^^^\n  File \"/home/technedict/Desktop/ViralPackage/viralcore/handlers/message_handler.py\", line 57, in message_router\n    await custom_order_handler(update, context) # Or a general_message_handler\n    ^^^^^^^^^^^^^^^^^^^^^^^^^^^^^^^^^^^^^^^^^^^\n  File \"/home/technedict/Desktop/ViralPackage/viralcore/handlers/custom_order_handlers.py\", line 31, in custom_order_handler\n    text = update.message.text.strip()\n           ^^^^^^^^^^^^^^^^^^^\nAttributeError: 'NoneType' object has no attribute 'text'"}
{"timestamp": "2025-09-28T15:15:41.414865Z", "level": "ERROR", "module": "telegram.ext.Application", "message": "No error handlers are registered, logging exception.", "correlation_id": "none", "exception": "Traceback (most recent call last):\n  File \"/home/technedict/Desktop/ViralPackage/viralcorelib/lib64/python3.13/site-packages/telegram/ext/_application.py\", line 1335, in process_update\n    await coroutine\n  File \"/home/technedict/Desktop/ViralPackage/viralcorelib/lib64/python3.13/site-packages/telegram/ext/_handlers/basehandler.py\", line 157, in handle_update\n    return await self.callback(update, context)\n           ^^^^^^^^^^^^^^^^^^^^^^^^^^^^^^^^^^^^\n  File \"/home/technedict/Desktop/ViralPackage/viralcore/handlers/message_handler.py\", line 57, in message_router\n    await custom_order_handler(update, context) # Or a general_message_handler\n    ^^^^^^^^^^^^^^^^^^^^^^^^^^^^^^^^^^^^^^^^^^^\n  File \"/home/technedict/Desktop/ViralPackage/viralcore/handlers/custom_order_handlers.py\", line 31, in custom_order_handler\n    text = update.message.text.strip()\n           ^^^^^^^^^^^^^^^^^^^\nAttributeError: 'NoneType' object has no attribute 'text'"}
{"timestamp": "2025-09-28T15:15:41.422985Z", "level": "ERROR", "module": "telegram.ext.Application", "message": "No error handlers are registered, logging exception.", "correlation_id": "none", "exception": "Traceback (most recent call last):\n  File \"/home/technedict/Desktop/ViralPackage/viralcorelib/lib64/python3.13/site-packages/telegram/ext/_application.py\", line 1335, in process_update\n    await coroutine\n  File \"/home/technedict/Desktop/ViralPackage/viralcorelib/lib64/python3.13/site-packages/telegram/ext/_handlers/basehandler.py\", line 157, in handle_update\n    return await self.callback(update, context)\n           ^^^^^^^^^^^^^^^^^^^^^^^^^^^^^^^^^^^^\n  File \"/home/technedict/Desktop/ViralPackage/viralcore/handlers/message_handler.py\", line 57, in message_router\n    await custom_order_handler(update, context) # Or a general_message_handler\n    ^^^^^^^^^^^^^^^^^^^^^^^^^^^^^^^^^^^^^^^^^^^\n  File \"/home/technedict/Desktop/ViralPackage/viralcore/handlers/custom_order_handlers.py\", line 31, in custom_order_handler\n    text = update.message.text.strip()\n           ^^^^^^^^^^^^^^^^^^^\nAttributeError: 'NoneType' object has no attribute 'text'"}
{"timestamp": "2025-09-28T15:15:41.429893Z", "level": "ERROR", "module": "telegram.ext.Application", "message": "No error handlers are registered, logging exception.", "correlation_id": "none", "exception": "Traceback (most recent call last):\n  File \"/home/technedict/Desktop/ViralPackage/viralcorelib/lib64/python3.13/site-packages/telegram/ext/_application.py\", line 1335, in process_update\n    await coroutine\n  File \"/home/technedict/Desktop/ViralPackage/viralcorelib/lib64/python3.13/site-packages/telegram/ext/_handlers/basehandler.py\", line 157, in handle_update\n    return await self.callback(update, context)\n           ^^^^^^^^^^^^^^^^^^^^^^^^^^^^^^^^^^^^\n  File \"/home/technedict/Desktop/ViralPackage/viralcore/handlers/message_handler.py\", line 57, in message_router\n    await custom_order_handler(update, context) # Or a general_message_handler\n    ^^^^^^^^^^^^^^^^^^^^^^^^^^^^^^^^^^^^^^^^^^^\n  File \"/home/technedict/Desktop/ViralPackage/viralcore/handlers/custom_order_handlers.py\", line 31, in custom_order_handler\n    text = update.message.text.strip()\n           ^^^^^^^^^^^^^^^^^^^\nAttributeError: 'NoneType' object has no attribute 'text'"}
{"timestamp": "2025-09-28T15:15:41.439138Z", "level": "ERROR", "module": "telegram.ext.Application", "message": "No error handlers are registered, logging exception.", "correlation_id": "none", "exception": "Traceback (most recent call last):\n  File \"/home/technedict/Desktop/ViralPackage/viralcorelib/lib64/python3.13/site-packages/telegram/ext/_application.py\", line 1335, in process_update\n    await coroutine\n  File \"/home/technedict/Desktop/ViralPackage/viralcorelib/lib64/python3.13/site-packages/telegram/ext/_handlers/basehandler.py\", line 157, in handle_update\n    return await self.callback(update, context)\n           ^^^^^^^^^^^^^^^^^^^^^^^^^^^^^^^^^^^^\n  File \"/home/technedict/Desktop/ViralPackage/viralcore/handlers/message_handler.py\", line 57, in message_router\n    await custom_order_handler(update, context) # Or a general_message_handler\n    ^^^^^^^^^^^^^^^^^^^^^^^^^^^^^^^^^^^^^^^^^^^\n  File \"/home/technedict/Desktop/ViralPackage/viralcore/handlers/custom_order_handlers.py\", line 31, in custom_order_handler\n    text = update.message.text.strip()\n           ^^^^^^^^^^^^^^^^^^^\nAttributeError: 'NoneType' object has no attribute 'text'"}
{"timestamp": "2025-09-28T15:15:41.454764Z", "level": "ERROR", "module": "telegram.ext.Application", "message": "No error handlers are registered, logging exception.", "correlation_id": "none", "exception": "Traceback (most recent call last):\n  File \"/home/technedict/Desktop/ViralPackage/viralcorelib/lib64/python3.13/site-packages/telegram/ext/_application.py\", line 1335, in process_update\n    await coroutine\n  File \"/home/technedict/Desktop/ViralPackage/viralcorelib/lib64/python3.13/site-packages/telegram/ext/_handlers/basehandler.py\", line 157, in handle_update\n    return await self.callback(update, context)\n           ^^^^^^^^^^^^^^^^^^^^^^^^^^^^^^^^^^^^\n  File \"/home/technedict/Desktop/ViralPackage/viralcore/handlers/message_handler.py\", line 57, in message_router\n    await custom_order_handler(update, context) # Or a general_message_handler\n    ^^^^^^^^^^^^^^^^^^^^^^^^^^^^^^^^^^^^^^^^^^^\n  File \"/home/technedict/Desktop/ViralPackage/viralcore/handlers/custom_order_handlers.py\", line 31, in custom_order_handler\n    text = update.message.text.strip()\n           ^^^^^^^^^^^^^^^^^^^\nAttributeError: 'NoneType' object has no attribute 'text'"}
{"timestamp": "2025-09-28T15:15:41.463266Z", "level": "ERROR", "module": "telegram.ext.Application", "message": "No error handlers are registered, logging exception.", "correlation_id": "none", "exception": "Traceback (most recent call last):\n  File \"/home/technedict/Desktop/ViralPackage/viralcorelib/lib64/python3.13/site-packages/telegram/ext/_application.py\", line 1335, in process_update\n    await coroutine\n  File \"/home/technedict/Desktop/ViralPackage/viralcorelib/lib64/python3.13/site-packages/telegram/ext/_handlers/basehandler.py\", line 157, in handle_update\n    return await self.callback(update, context)\n           ^^^^^^^^^^^^^^^^^^^^^^^^^^^^^^^^^^^^\n  File \"/home/technedict/Desktop/ViralPackage/viralcore/handlers/message_handler.py\", line 57, in message_router\n    await custom_order_handler(update, context) # Or a general_message_handler\n    ^^^^^^^^^^^^^^^^^^^^^^^^^^^^^^^^^^^^^^^^^^^\n  File \"/home/technedict/Desktop/ViralPackage/viralcore/handlers/custom_order_handlers.py\", line 31, in custom_order_handler\n    text = update.message.text.strip()\n           ^^^^^^^^^^^^^^^^^^^\nAttributeError: 'NoneType' object has no attribute 'text'"}
{"timestamp": "2025-09-28T15:15:41.470877Z", "level": "ERROR", "module": "telegram.ext.Application", "message": "No error handlers are registered, logging exception.", "correlation_id": "none", "exception": "Traceback (most recent call last):\n  File \"/home/technedict/Desktop/ViralPackage/viralcorelib/lib64/python3.13/site-packages/telegram/ext/_application.py\", line 1335, in process_update\n    await coroutine\n  File \"/home/technedict/Desktop/ViralPackage/viralcorelib/lib64/python3.13/site-packages/telegram/ext/_handlers/basehandler.py\", line 157, in handle_update\n    return await self.callback(update, context)\n           ^^^^^^^^^^^^^^^^^^^^^^^^^^^^^^^^^^^^\n  File \"/home/technedict/Desktop/ViralPackage/viralcore/handlers/message_handler.py\", line 57, in message_router\n    await custom_order_handler(update, context) # Or a general_message_handler\n    ^^^^^^^^^^^^^^^^^^^^^^^^^^^^^^^^^^^^^^^^^^^\n  File \"/home/technedict/Desktop/ViralPackage/viralcore/handlers/custom_order_handlers.py\", line 31, in custom_order_handler\n    text = update.message.text.strip()\n           ^^^^^^^^^^^^^^^^^^^\nAttributeError: 'NoneType' object has no attribute 'text'"}
{"timestamp": "2025-09-28T15:15:41.479003Z", "level": "ERROR", "module": "telegram.ext.Application", "message": "No error handlers are registered, logging exception.", "correlation_id": "none", "exception": "Traceback (most recent call last):\n  File \"/home/technedict/Desktop/ViralPackage/viralcorelib/lib64/python3.13/site-packages/telegram/ext/_application.py\", line 1335, in process_update\n    await coroutine\n  File \"/home/technedict/Desktop/ViralPackage/viralcorelib/lib64/python3.13/site-packages/telegram/ext/_handlers/basehandler.py\", line 157, in handle_update\n    return await self.callback(update, context)\n           ^^^^^^^^^^^^^^^^^^^^^^^^^^^^^^^^^^^^\n  File \"/home/technedict/Desktop/ViralPackage/viralcore/handlers/message_handler.py\", line 57, in message_router\n    await custom_order_handler(update, context) # Or a general_message_handler\n    ^^^^^^^^^^^^^^^^^^^^^^^^^^^^^^^^^^^^^^^^^^^\n  File \"/home/technedict/Desktop/ViralPackage/viralcore/handlers/custom_order_handlers.py\", line 31, in custom_order_handler\n    text = update.message.text.strip()\n           ^^^^^^^^^^^^^^^^^^^\nAttributeError: 'NoneType' object has no attribute 'text'"}
{"timestamp": "2025-09-28T15:15:41.488194Z", "level": "ERROR", "module": "telegram.ext.Application", "message": "No error handlers are registered, logging exception.", "correlation_id": "none", "exception": "Traceback (most recent call last):\n  File \"/home/technedict/Desktop/ViralPackage/viralcorelib/lib64/python3.13/site-packages/telegram/ext/_application.py\", line 1335, in process_update\n    await coroutine\n  File \"/home/technedict/Desktop/ViralPackage/viralcorelib/lib64/python3.13/site-packages/telegram/ext/_handlers/basehandler.py\", line 157, in handle_update\n    return await self.callback(update, context)\n           ^^^^^^^^^^^^^^^^^^^^^^^^^^^^^^^^^^^^\n  File \"/home/technedict/Desktop/ViralPackage/viralcore/handlers/message_handler.py\", line 57, in message_router\n    await custom_order_handler(update, context) # Or a general_message_handler\n    ^^^^^^^^^^^^^^^^^^^^^^^^^^^^^^^^^^^^^^^^^^^\n  File \"/home/technedict/Desktop/ViralPackage/viralcore/handlers/custom_order_handlers.py\", line 31, in custom_order_handler\n    text = update.message.text.strip()\n           ^^^^^^^^^^^^^^^^^^^\nAttributeError: 'NoneType' object has no attribute 'text'"}
{"timestamp": "2025-09-28T15:15:41.495631Z", "level": "ERROR", "module": "telegram.ext.Application", "message": "No error handlers are registered, logging exception.", "correlation_id": "none", "exception": "Traceback (most recent call last):\n  File \"/home/technedict/Desktop/ViralPackage/viralcorelib/lib64/python3.13/site-packages/telegram/ext/_application.py\", line 1335, in process_update\n    await coroutine\n  File \"/home/technedict/Desktop/ViralPackage/viralcorelib/lib64/python3.13/site-packages/telegram/ext/_handlers/basehandler.py\", line 157, in handle_update\n    return await self.callback(update, context)\n           ^^^^^^^^^^^^^^^^^^^^^^^^^^^^^^^^^^^^\n  File \"/home/technedict/Desktop/ViralPackage/viralcore/handlers/message_handler.py\", line 57, in message_router\n    await custom_order_handler(update, context) # Or a general_message_handler\n    ^^^^^^^^^^^^^^^^^^^^^^^^^^^^^^^^^^^^^^^^^^^\n  File \"/home/technedict/Desktop/ViralPackage/viralcore/handlers/custom_order_handlers.py\", line 31, in custom_order_handler\n    text = update.message.text.strip()\n           ^^^^^^^^^^^^^^^^^^^\nAttributeError: 'NoneType' object has no attribute 'text'"}
{"timestamp": "2025-09-28T15:15:41.506658Z", "level": "ERROR", "module": "telegram.ext.Application", "message": "No error handlers are registered, logging exception.", "correlation_id": "none", "exception": "Traceback (most recent call last):\n  File \"/home/technedict/Desktop/ViralPackage/viralcorelib/lib64/python3.13/site-packages/telegram/ext/_application.py\", line 1335, in process_update\n    await coroutine\n  File \"/home/technedict/Desktop/ViralPackage/viralcorelib/lib64/python3.13/site-packages/telegram/ext/_handlers/basehandler.py\", line 157, in handle_update\n    return await self.callback(update, context)\n           ^^^^^^^^^^^^^^^^^^^^^^^^^^^^^^^^^^^^\n  File \"/home/technedict/Desktop/ViralPackage/viralcore/handlers/message_handler.py\", line 57, in message_router\n    await custom_order_handler(update, context) # Or a general_message_handler\n    ^^^^^^^^^^^^^^^^^^^^^^^^^^^^^^^^^^^^^^^^^^^\n  File \"/home/technedict/Desktop/ViralPackage/viralcore/handlers/custom_order_handlers.py\", line 31, in custom_order_handler\n    text = update.message.text.strip()\n           ^^^^^^^^^^^^^^^^^^^\nAttributeError: 'NoneType' object has no attribute 'text'"}
{"timestamp": "2025-09-28T15:15:41.521352Z", "level": "ERROR", "module": "telegram.ext.Application", "message": "No error handlers are registered, logging exception.", "correlation_id": "none", "exception": "Traceback (most recent call last):\n  File \"/home/technedict/Desktop/ViralPackage/viralcorelib/lib64/python3.13/site-packages/telegram/ext/_application.py\", line 1335, in process_update\n    await coroutine\n  File \"/home/technedict/Desktop/ViralPackage/viralcorelib/lib64/python3.13/site-packages/telegram/ext/_handlers/basehandler.py\", line 157, in handle_update\n    return await self.callback(update, context)\n           ^^^^^^^^^^^^^^^^^^^^^^^^^^^^^^^^^^^^\n  File \"/home/technedict/Desktop/ViralPackage/viralcore/handlers/message_handler.py\", line 57, in message_router\n    await custom_order_handler(update, context) # Or a general_message_handler\n    ^^^^^^^^^^^^^^^^^^^^^^^^^^^^^^^^^^^^^^^^^^^\n  File \"/home/technedict/Desktop/ViralPackage/viralcore/handlers/custom_order_handlers.py\", line 31, in custom_order_handler\n    text = update.message.text.strip()\n           ^^^^^^^^^^^^^^^^^^^\nAttributeError: 'NoneType' object has no attribute 'text'"}
{"timestamp": "2025-09-28T15:15:41.549622Z", "level": "ERROR", "module": "telegram.ext.Application", "message": "No error handlers are registered, logging exception.", "correlation_id": "none", "exception": "Traceback (most recent call last):\n  File \"/home/technedict/Desktop/ViralPackage/viralcorelib/lib64/python3.13/site-packages/telegram/ext/_application.py\", line 1335, in process_update\n    await coroutine\n  File \"/home/technedict/Desktop/ViralPackage/viralcorelib/lib64/python3.13/site-packages/telegram/ext/_handlers/basehandler.py\", line 157, in handle_update\n    return await self.callback(update, context)\n           ^^^^^^^^^^^^^^^^^^^^^^^^^^^^^^^^^^^^\n  File \"/home/technedict/Desktop/ViralPackage/viralcore/handlers/message_handler.py\", line 57, in message_router\n    await custom_order_handler(update, context) # Or a general_message_handler\n    ^^^^^^^^^^^^^^^^^^^^^^^^^^^^^^^^^^^^^^^^^^^\n  File \"/home/technedict/Desktop/ViralPackage/viralcore/handlers/custom_order_handlers.py\", line 31, in custom_order_handler\n    text = update.message.text.strip()\n           ^^^^^^^^^^^^^^^^^^^\nAttributeError: 'NoneType' object has no attribute 'text'"}
{"timestamp": "2025-09-28T15:15:41.567284Z", "level": "ERROR", "module": "telegram.ext.Application", "message": "No error handlers are registered, logging exception.", "correlation_id": "none", "exception": "Traceback (most recent call last):\n  File \"/home/technedict/Desktop/ViralPackage/viralcorelib/lib64/python3.13/site-packages/telegram/ext/_application.py\", line 1335, in process_update\n    await coroutine\n  File \"/home/technedict/Desktop/ViralPackage/viralcorelib/lib64/python3.13/site-packages/telegram/ext/_handlers/basehandler.py\", line 157, in handle_update\n    return await self.callback(update, context)\n           ^^^^^^^^^^^^^^^^^^^^^^^^^^^^^^^^^^^^\n  File \"/home/technedict/Desktop/ViralPackage/viralcore/handlers/message_handler.py\", line 57, in message_router\n    await custom_order_handler(update, context) # Or a general_message_handler\n    ^^^^^^^^^^^^^^^^^^^^^^^^^^^^^^^^^^^^^^^^^^^\n  File \"/home/technedict/Desktop/ViralPackage/viralcore/handlers/custom_order_handlers.py\", line 31, in custom_order_handler\n    text = update.message.text.strip()\n           ^^^^^^^^^^^^^^^^^^^\nAttributeError: 'NoneType' object has no attribute 'text'"}
{"timestamp": "2025-09-28T15:16:12.260644Z", "level": "ERROR", "module": "telegram.ext.Application", "message": "No error handlers are registered, logging exception.", "correlation_id": "none", "exception": "Traceback (most recent call last):\n  File \"/home/technedict/Desktop/ViralPackage/viralcorelib/lib64/python3.13/site-packages/telegram/ext/_application.py\", line 1335, in process_update\n    await coroutine\n  File \"/home/technedict/Desktop/ViralPackage/viralcorelib/lib64/python3.13/site-packages/telegram/ext/_handlers/basehandler.py\", line 157, in handle_update\n    return await self.callback(update, context)\n           ^^^^^^^^^^^^^^^^^^^^^^^^^^^^^^^^^^^^\n  File \"/home/technedict/Desktop/ViralPackage/viralcore/handlers/admin_handlers.py\", line 187, in admin_panel_handler\n    await admin_withdrawals_menu_handler(update, context)\n  File \"/home/technedict/Desktop/ViralPackage/viralcore/handlers/admin_withdrawal_handlers.py\", line 27, in admin_withdrawals_menu_handler\n    from utils.admin_db_utils import is_admin\nImportError: cannot import name 'is_admin' from 'utils.admin_db_utils' (/home/technedict/Desktop/ViralPackage/viralcore/utils/admin_db_utils.py)"}
{"timestamp": "2025-09-28T15:17:52.044212Z", "level": "WARNING", "module": "utils.graceful_shutdown", "message": "updater.shutdown() raised: This Updater is still running!", "correlation_id": "none"}
{"timestamp": "2025-09-28T15:17:52.045534Z", "level": "WARNING", "module": "utils.graceful_shutdown", "message": "Shutdown already in progress", "correlation_id": "none"}
{"timestamp": "2025-09-28T15:17:52.062838Z", "level": "ERROR", "module": "__main__", "message": "Error during app.shutdown()", "correlation_id": "none", "exception": "Traceback (most recent call last):\n  File \"/home/technedict/Desktop/ViralPackage/viralcore/main_viral_core_bot.py\", line 301, in main\n    await app.shutdown()\n  File \"/home/technedict/Desktop/ViralPackage/viralcorelib/lib64/python3.13/site-packages/telegram/ext/_application.py\", line 561, in shutdown\n    await self.updater.shutdown()\n  File \"/home/technedict/Desktop/ViralPackage/viralcorelib/lib64/python3.13/site-packages/telegram/ext/_updater.py\", line 204, in shutdown\n    raise RuntimeError(\"This Updater is still running!\")\nRuntimeError: This Updater is still running!"}
{"timestamp": "2025-09-28T15:17:52.162595Z", "level": "ERROR", "module": "asyncio", "message": "Task exception was never retrieved\nfuture: <Task finished name='Task-34' coro=<Updater._start_polling.<locals>.polling_action_cb() done, defined at /home/technedict/Desktop/ViralPackage/viralcorelib/lib64/python3.13/site-packages/telegram/ext/_updater.py:375> exception=NetworkError('httpx.ReadError: ')>", "correlation_id": "none", "exception": "Traceback (most recent call last):\n  File \"/home/technedict/Desktop/ViralPackage/viralcorelib/lib64/python3.13/site-packages/httpx/_transports/default.py\", line 101, in map_httpcore_exceptions\n  File \"/home/technedict/Desktop/ViralPackage/viralcorelib/lib64/python3.13/site-packages/httpx/_transports/default.py\", line 394, in handle_async_request\n  File \"/home/technedict/Desktop/ViralPackage/viralcorelib/lib64/python3.13/site-packages/httpcore/_async/connection_pool.py\", line 256, in handle_async_request\n  File \"/home/technedict/Desktop/ViralPackage/viralcorelib/lib64/python3.13/site-packages/httpcore/_async/connection_pool.py\", line 236, in handle_async_request\n  File \"/home/technedict/Desktop/ViralPackage/viralcorelib/lib64/python3.13/site-packages/httpcore/_async/connection.py\", line 103, in handle_async_request\n  File \"/home/technedict/Desktop/ViralPackage/viralcorelib/lib64/python3.13/site-packages/httpcore/_async/http11.py\", line 136, in handle_async_request\n  File \"/home/technedict/Desktop/ViralPackage/viralcorelib/lib64/python3.13/site-packages/httpcore/_async/http11.py\", line 106, in handle_async_request\n  File \"/home/technedict/Desktop/ViralPackage/viralcorelib/lib64/python3.13/site-packages/httpcore/_async/http11.py\", line 177, in _receive_response_headers\n  File \"/home/technedict/Desktop/ViralPackage/viralcorelib/lib64/python3.13/site-packages/httpcore/_async/http11.py\", line 217, in _receive_event\n  File \"/home/technedict/Desktop/ViralPackage/viralcorelib/lib64/python3.13/site-packages/httpcore/_backends/anyio.py\", line 32, in read\n  File \"/usr/lib64/python3.13/contextlib.py\", line 162, in __exit__\n  File \"/home/technedict/Desktop/ViralPackage/viralcorelib/lib64/python3.13/site-packages/httpcore/_exceptions.py\", line 14, in map_exceptions\nhttpcore.ReadError\n\nThe above exception was the direct cause of the following exception:\n\nTraceback (most recent call last):\n  File \"/home/technedict/Desktop/ViralPackage/viralcorelib/lib64/python3.13/site-packages/telegram/request/_httpxrequest.py\", line 276, in do_request\n  File \"/home/technedict/Desktop/ViralPackage/viralcorelib/lib64/python3.13/site-packages/httpx/_client.py\", line 1540, in request\n  File \"/home/technedict/Desktop/ViralPackage/viralcorelib/lib64/python3.13/site-packages/httpx/_client.py\", line 1629, in send\n  File \"/home/technedict/Desktop/ViralPackage/viralcorelib/lib64/python3.13/site-packages/httpx/_client.py\", line 1657, in _send_handling_auth\n  File \"/home/technedict/Desktop/ViralPackage/viralcorelib/lib64/python3.13/site-packages/httpx/_client.py\", line 1694, in _send_handling_redirects\n  File \"/home/technedict/Desktop/ViralPackage/viralcorelib/lib64/python3.13/site-packages/httpx/_client.py\", line 1730, in _send_single_request\n  File \"/home/technedict/Desktop/ViralPackage/viralcorelib/lib64/python3.13/site-packages/httpx/_transports/default.py\", line 393, in handle_async_request\n  File \"/usr/lib64/python3.13/contextlib.py\", line 162, in __exit__\n  File \"/home/technedict/Desktop/ViralPackage/viralcorelib/lib64/python3.13/site-packages/httpx/_transports/default.py\", line 118, in map_httpcore_exceptions\nhttpx.ReadError\n\nThe above exception was the direct cause of the following exception:\n\nTraceback (most recent call last):\n  File \"/home/technedict/Desktop/ViralPackage/viralcorelib/lib64/python3.13/site-packages/telegram/ext/_updater.py\", line 377, in polling_action_cb\n    updates = await self.bot.get_updates(\n              ^^^^^^^^^^^^^^^^^^^^^^^^^^^\n    ...<7 lines>...\n    )\n    ^\n  File \"/home/technedict/Desktop/ViralPackage/viralcorelib/lib64/python3.13/site-packages/telegram/ext/_extbot.py\", line 649, in get_updates\n  File \"/home/technedict/Desktop/ViralPackage/viralcorelib/lib64/python3.13/site-packages/telegram/_bot.py\", line 4366, in get_updates\n  File \"/home/technedict/Desktop/ViralPackage/viralcorelib/lib64/python3.13/site-packages/telegram/_bot.py\", line 623, in _post\n  File \"/home/technedict/Desktop/ViralPackage/viralcorelib/lib64/python3.13/site-packages/telegram/ext/_extbot.py\", line 355, in _do_post\n  File \"/home/technedict/Desktop/ViralPackage/viralcorelib/lib64/python3.13/site-packages/telegram/_bot.py\", line 652, in _do_post\n  File \"/home/technedict/Desktop/ViralPackage/viralcorelib/lib64/python3.13/site-packages/telegram/request/_baserequest.py\", line 201, in post\n  File \"/home/technedict/Desktop/ViralPackage/viralcorelib/lib64/python3.13/site-packages/telegram/request/_baserequest.py\", line 333, in _request_wrapper\n  File \"/home/technedict/Desktop/ViralPackage/viralcorelib/lib64/python3.13/site-packages/telegram/request/_httpxrequest.py\", line 300, in do_request\ntelegram.error.NetworkError: httpx.ReadError: "}
{"timestamp": "2025-09-28T15:18:04.581773Z", "level": "ERROR", "module": "telegram.ext.Application", "message": "No error handlers are registered, logging exception.", "correlation_id": "none", "exception": "Traceback (most recent call last):\n  File \"/home/technedict/Desktop/ViralPackage/viralcorelib/lib64/python3.13/site-packages/telegram/ext/_application.py\", line 1335, in process_update\n    await coroutine\n  File \"/home/technedict/Desktop/ViralPackage/viralcorelib/lib64/python3.13/site-packages/telegram/ext/_handlers/basehandler.py\", line 157, in handle_update\n    return await self.callback(update, context)\n           ^^^^^^^^^^^^^^^^^^^^^^^^^^^^^^^^^^^^\n  File \"/home/technedict/Desktop/ViralPackage/viralcore/handlers/admin_handlers.py\", line 187, in admin_panel_handler\n    await admin_withdrawals_menu_handler(update, context)\n  File \"/home/technedict/Desktop/ViralPackage/viralcore/handlers/admin_withdrawal_handlers.py\", line 29, in admin_withdrawals_menu_handler\n    await query.edit_message_text(\"\u274c You don't have permission to access this menu.\")\n  File \"/home/technedict/Desktop/ViralPackage/viralcorelib/lib64/python3.13/site-packages/telegram/_callbackquery.py\", line 268, in edit_message_text\n    return await self._get_message().edit_text(\n           ^^^^^^^^^^^^^^^^^^^^^^^^^^^^^^^^^^^^\n    ...<11 lines>...\n    )\n    ^\n  File \"/home/technedict/Desktop/ViralPackage/viralcorelib/lib64/python3.13/site-packages/telegram/_message.py\", line 3659, in edit_text\n    return await self.get_bot().edit_message_text(\n           ^^^^^^^^^^^^^^^^^^^^^^^^^^^^^^^^^^^^^^^\n    ...<15 lines>...\n    )\n    ^\n  File \"/home/technedict/Desktop/ViralPackage/viralcorelib/lib64/python3.13/site-packages/telegram/ext/_extbot.py\", line 1664, in edit_message_text\n    return await super().edit_message_text(\n           ^^^^^^^^^^^^^^^^^^^^^^^^^^^^^^^^\n    ...<15 lines>...\n    )\n    ^\n  File \"/home/technedict/Desktop/ViralPackage/viralcorelib/lib64/python3.13/site-packages/telegram/_bot.py\", line 4047, in edit_message_text\n    return await self._send_message(\n           ^^^^^^^^^^^^^^^^^^^^^^^^^\n    ...<11 lines>...\n    )\n    ^\n  File \"/home/technedict/Desktop/ViralPackage/viralcorelib/lib64/python3.13/site-packages/telegram/ext/_extbot.py\", line 610, in _send_message\n    result = await super()._send_message(\n             ^^^^^^^^^^^^^^^^^^^^^^^^^^^^\n    ...<20 lines>...\n    )\n    ^\n  File \"/home/technedict/Desktop/ViralPackage/viralcorelib/lib64/python3.13/site-packages/telegram/_bot.py\", line 745, in _send_message\n    result = await self._post(\n             ^^^^^^^^^^^^^^^^^\n    ...<7 lines>...\n    )\n    ^\n  File \"/home/technedict/Desktop/ViralPackage/viralcorelib/lib64/python3.13/site-packages/telegram/_bot.py\", line 623, in _post\n    return await self._do_post(\n           ^^^^^^^^^^^^^^^^^^^^\n    ...<6 lines>...\n    )\n    ^\n  File \"/home/technedict/Desktop/ViralPackage/viralcorelib/lib64/python3.13/site-packages/telegram/ext/_extbot.py\", line 355, in _do_post\n    return await super()._do_post(\n           ^^^^^^^^^^^^^^^^^^^^^^^\n    ...<6 lines>...\n    )\n    ^\n  File \"/home/technedict/Desktop/ViralPackage/viralcorelib/lib64/python3.13/site-packages/telegram/_bot.py\", line 652, in _do_post\n    result = await request.post(\n             ^^^^^^^^^^^^^^^^^^^\n    ...<6 lines>...\n    )\n    ^\n  File \"/home/technedict/Desktop/ViralPackage/viralcorelib/lib64/python3.13/site-packages/telegram/request/_baserequest.py\", line 201, in post\n    result = await self._request_wrapper(\n             ^^^^^^^^^^^^^^^^^^^^^^^^^^^^\n    ...<7 lines>...\n    )\n    ^\n  File \"/home/technedict/Desktop/ViralPackage/viralcorelib/lib64/python3.13/site-packages/telegram/request/_baserequest.py\", line 382, in _request_wrapper\n    raise BadRequest(message)\ntelegram.error.BadRequest: There is no text in the message to edit"}
{"timestamp": "2025-09-28T15:18:11.014153Z", "level": "ERROR", "module": "telegram.ext.Application", "message": "No error handlers are registered, logging exception.", "correlation_id": "none", "exception": "Traceback (most recent call last):\n  File \"/home/technedict/Desktop/ViralPackage/viralcorelib/lib64/python3.13/site-packages/telegram/ext/_application.py\", line 1335, in process_update\n    await coroutine\n  File \"/home/technedict/Desktop/ViralPackage/viralcorelib/lib64/python3.13/site-packages/telegram/ext/_handlers/basehandler.py\", line 157, in handle_update\n    return await self.callback(update, context)\n           ^^^^^^^^^^^^^^^^^^^^^^^^^^^^^^^^^^^^\n  File \"/home/technedict/Desktop/ViralPackage/viralcore/handlers/admin_handlers.py\", line 187, in admin_panel_handler\n    await admin_withdrawals_menu_handler(update, context)\n  File \"/home/technedict/Desktop/ViralPackage/viralcore/handlers/admin_withdrawal_handlers.py\", line 29, in admin_withdrawals_menu_handler\n    await query.edit_message_text(\"\u274c You don't have permission to access this menu.\")\n  File \"/home/technedict/Desktop/ViralPackage/viralcorelib/lib64/python3.13/site-packages/telegram/_callbackquery.py\", line 268, in edit_message_text\n    return await self._get_message().edit_text(\n           ^^^^^^^^^^^^^^^^^^^^^^^^^^^^^^^^^^^^\n    ...<11 lines>...\n    )\n    ^\n  File \"/home/technedict/Desktop/ViralPackage/viralcorelib/lib64/python3.13/site-packages/telegram/_message.py\", line 3659, in edit_text\n    return await self.get_bot().edit_message_text(\n           ^^^^^^^^^^^^^^^^^^^^^^^^^^^^^^^^^^^^^^^\n    ...<15 lines>...\n    )\n    ^\n  File \"/home/technedict/Desktop/ViralPackage/viralcorelib/lib64/python3.13/site-packages/telegram/ext/_extbot.py\", line 1664, in edit_message_text\n    return await super().edit_message_text(\n           ^^^^^^^^^^^^^^^^^^^^^^^^^^^^^^^^\n    ...<15 lines>...\n    )\n    ^\n  File \"/home/technedict/Desktop/ViralPackage/viralcorelib/lib64/python3.13/site-packages/telegram/_bot.py\", line 4047, in edit_message_text\n    return await self._send_message(\n           ^^^^^^^^^^^^^^^^^^^^^^^^^\n    ...<11 lines>...\n    )\n    ^\n  File \"/home/technedict/Desktop/ViralPackage/viralcorelib/lib64/python3.13/site-packages/telegram/ext/_extbot.py\", line 610, in _send_message\n    result = await super()._send_message(\n             ^^^^^^^^^^^^^^^^^^^^^^^^^^^^\n    ...<20 lines>...\n    )\n    ^\n  File \"/home/technedict/Desktop/ViralPackage/viralcorelib/lib64/python3.13/site-packages/telegram/_bot.py\", line 745, in _send_message\n    result = await self._post(\n             ^^^^^^^^^^^^^^^^^\n    ...<7 lines>...\n    )\n    ^\n  File \"/home/technedict/Desktop/ViralPackage/viralcorelib/lib64/python3.13/site-packages/telegram/_bot.py\", line 623, in _post\n    return await self._do_post(\n           ^^^^^^^^^^^^^^^^^^^^\n    ...<6 lines>...\n    )\n    ^\n  File \"/home/technedict/Desktop/ViralPackage/viralcorelib/lib64/python3.13/site-packages/telegram/ext/_extbot.py\", line 355, in _do_post\n    return await super()._do_post(\n           ^^^^^^^^^^^^^^^^^^^^^^^\n    ...<6 lines>...\n    )\n    ^\n  File \"/home/technedict/Desktop/ViralPackage/viralcorelib/lib64/python3.13/site-packages/telegram/_bot.py\", line 652, in _do_post\n    result = await request.post(\n             ^^^^^^^^^^^^^^^^^^^\n    ...<6 lines>...\n    )\n    ^\n  File \"/home/technedict/Desktop/ViralPackage/viralcorelib/lib64/python3.13/site-packages/telegram/request/_baserequest.py\", line 201, in post\n    result = await self._request_wrapper(\n             ^^^^^^^^^^^^^^^^^^^^^^^^^^^^\n    ...<7 lines>...\n    )\n    ^\n  File \"/home/technedict/Desktop/ViralPackage/viralcorelib/lib64/python3.13/site-packages/telegram/request/_baserequest.py\", line 382, in _request_wrapper\n    raise BadRequest(message)\ntelegram.error.BadRequest: There is no text in the message to edit"}
{"timestamp": "2025-09-28T15:19:42.839980Z", "level": "WARNING", "module": "utils.graceful_shutdown", "message": "updater.shutdown() raised: This Updater is still running!", "correlation_id": "none"}
{"timestamp": "2025-09-28T15:19:42.841274Z", "level": "WARNING", "module": "utils.graceful_shutdown", "message": "Shutdown already in progress", "correlation_id": "none"}
{"timestamp": "2025-09-28T15:19:42.856896Z", "level": "ERROR", "module": "__main__", "message": "Error during app.shutdown()", "correlation_id": "none", "exception": "Traceback (most recent call last):\n  File \"/home/technedict/Desktop/ViralPackage/viralcore/main_viral_core_bot.py\", line 301, in main\n    await app.shutdown()\n  File \"/home/technedict/Desktop/ViralPackage/viralcorelib/lib64/python3.13/site-packages/telegram/ext/_application.py\", line 561, in shutdown\n    await self.updater.shutdown()\n  File \"/home/technedict/Desktop/ViralPackage/viralcorelib/lib64/python3.13/site-packages/telegram/ext/_updater.py\", line 204, in shutdown\n    raise RuntimeError(\"This Updater is still running!\")\nRuntimeError: This Updater is still running!"}
{"timestamp": "2025-09-28T15:19:42.954757Z", "level": "ERROR", "module": "asyncio", "message": "Task exception was never retrieved\nfuture: <Task finished name='Task-24' coro=<Updater._start_polling.<locals>.polling_action_cb() done, defined at /home/technedict/Desktop/ViralPackage/viralcorelib/lib64/python3.13/site-packages/telegram/ext/_updater.py:375> exception=NetworkError('httpx.ReadError: ')>", "correlation_id": "none", "exception": "Traceback (most recent call last):\n  File \"/home/technedict/Desktop/ViralPackage/viralcorelib/lib64/python3.13/site-packages/httpx/_transports/default.py\", line 101, in map_httpcore_exceptions\n  File \"/home/technedict/Desktop/ViralPackage/viralcorelib/lib64/python3.13/site-packages/httpx/_transports/default.py\", line 394, in handle_async_request\n  File \"/home/technedict/Desktop/ViralPackage/viralcorelib/lib64/python3.13/site-packages/httpcore/_async/connection_pool.py\", line 256, in handle_async_request\n  File \"/home/technedict/Desktop/ViralPackage/viralcorelib/lib64/python3.13/site-packages/httpcore/_async/connection_pool.py\", line 236, in handle_async_request\n  File \"/home/technedict/Desktop/ViralPackage/viralcorelib/lib64/python3.13/site-packages/httpcore/_async/connection.py\", line 103, in handle_async_request\n  File \"/home/technedict/Desktop/ViralPackage/viralcorelib/lib64/python3.13/site-packages/httpcore/_async/http11.py\", line 136, in handle_async_request\n  File \"/home/technedict/Desktop/ViralPackage/viralcorelib/lib64/python3.13/site-packages/httpcore/_async/http11.py\", line 106, in handle_async_request\n  File \"/home/technedict/Desktop/ViralPackage/viralcorelib/lib64/python3.13/site-packages/httpcore/_async/http11.py\", line 177, in _receive_response_headers\n  File \"/home/technedict/Desktop/ViralPackage/viralcorelib/lib64/python3.13/site-packages/httpcore/_async/http11.py\", line 217, in _receive_event\n  File \"/home/technedict/Desktop/ViralPackage/viralcorelib/lib64/python3.13/site-packages/httpcore/_backends/anyio.py\", line 32, in read\n  File \"/usr/lib64/python3.13/contextlib.py\", line 162, in __exit__\n  File \"/home/technedict/Desktop/ViralPackage/viralcorelib/lib64/python3.13/site-packages/httpcore/_exceptions.py\", line 14, in map_exceptions\nhttpcore.ReadError\n\nThe above exception was the direct cause of the following exception:\n\nTraceback (most recent call last):\n  File \"/home/technedict/Desktop/ViralPackage/viralcorelib/lib64/python3.13/site-packages/telegram/request/_httpxrequest.py\", line 276, in do_request\n  File \"/home/technedict/Desktop/ViralPackage/viralcorelib/lib64/python3.13/site-packages/httpx/_client.py\", line 1540, in request\n  File \"/home/technedict/Desktop/ViralPackage/viralcorelib/lib64/python3.13/site-packages/httpx/_client.py\", line 1629, in send\n  File \"/home/technedict/Desktop/ViralPackage/viralcorelib/lib64/python3.13/site-packages/httpx/_client.py\", line 1657, in _send_handling_auth\n  File \"/home/technedict/Desktop/ViralPackage/viralcorelib/lib64/python3.13/site-packages/httpx/_client.py\", line 1694, in _send_handling_redirects\n  File \"/home/technedict/Desktop/ViralPackage/viralcorelib/lib64/python3.13/site-packages/httpx/_client.py\", line 1730, in _send_single_request\n  File \"/home/technedict/Desktop/ViralPackage/viralcorelib/lib64/python3.13/site-packages/httpx/_transports/default.py\", line 393, in handle_async_request\n  File \"/usr/lib64/python3.13/contextlib.py\", line 162, in __exit__\n  File \"/home/technedict/Desktop/ViralPackage/viralcorelib/lib64/python3.13/site-packages/httpx/_transports/default.py\", line 118, in map_httpcore_exceptions\nhttpx.ReadError\n\nThe above exception was the direct cause of the following exception:\n\nTraceback (most recent call last):\n  File \"/home/technedict/Desktop/ViralPackage/viralcorelib/lib64/python3.13/site-packages/telegram/ext/_updater.py\", line 377, in polling_action_cb\n    updates = await self.bot.get_updates(\n              ^^^^^^^^^^^^^^^^^^^^^^^^^^^\n    ...<7 lines>...\n    )\n    ^\n  File \"/home/technedict/Desktop/ViralPackage/viralcorelib/lib64/python3.13/site-packages/telegram/ext/_extbot.py\", line 649, in get_updates\n    updates = await super().get_updates(\n              ^^^^^^^^^^^^^^^^^^^^^^^^^^\n    ...<9 lines>...\n    )\n    ^\n  File \"/home/technedict/Desktop/ViralPackage/viralcorelib/lib64/python3.13/site-packages/telegram/_bot.py\", line 4366, in get_updates\n    await self._post(\n    ^^^^^^^^^^^^^^^^^\n    ...<7 lines>...\n    ),\n    ^\n  File \"/home/technedict/Desktop/ViralPackage/viralcorelib/lib64/python3.13/site-packages/telegram/_bot.py\", line 623, in _post\n    return await self._do_post(\n           ^^^^^^^^^^^^^^^^^^^^\n    ...<6 lines>...\n    )\n    ^\n  File \"/home/technedict/Desktop/ViralPackage/viralcorelib/lib64/python3.13/site-packages/telegram/ext/_extbot.py\", line 355, in _do_post\n    return await super()._do_post(\n           ^^^^^^^^^^^^^^^^^^^^^^^\n    ...<6 lines>...\n    )\n    ^\n  File \"/home/technedict/Desktop/ViralPackage/viralcorelib/lib64/python3.13/site-packages/telegram/_bot.py\", line 652, in _do_post\n    result = await request.post(\n             ^^^^^^^^^^^^^^^^^^^\n    ...<6 lines>...\n    )\n    ^\n  File \"/home/technedict/Desktop/ViralPackage/viralcorelib/lib64/python3.13/site-packages/telegram/request/_baserequest.py\", line 201, in post\n    result = await self._request_wrapper(\n             ^^^^^^^^^^^^^^^^^^^^^^^^^^^^\n    ...<7 lines>...\n    )\n    ^\n  File \"/home/technedict/Desktop/ViralPackage/viralcorelib/lib64/python3.13/site-packages/telegram/request/_baserequest.py\", line 333, in _request_wrapper\n    code, payload = await self.do_request(\n                    ^^^^^^^^^^^^^^^^^^^^^^\n    ...<7 lines>...\n    )\n    ^\n  File \"/home/technedict/Desktop/ViralPackage/viralcorelib/lib64/python3.13/site-packages/telegram/request/_httpxrequest.py\", line 300, in do_request\ntelegram.error.NetworkError: httpx.ReadError: "}
{"timestamp": "2025-09-28T15:19:48.935055Z", "level": "ERROR", "module": "telegram.ext.Application", "message": "No error handlers are registered, logging exception.", "correlation_id": "none", "exception": "Traceback (most recent call last):\n  File \"/home/technedict/Desktop/ViralPackage/viralcorelib/lib64/python3.13/site-packages/telegram/ext/_application.py\", line 1335, in process_update\n    await coroutine\n  File \"/home/technedict/Desktop/ViralPackage/viralcorelib/lib64/python3.13/site-packages/telegram/ext/_handlers/basehandler.py\", line 157, in handle_update\n    return await self.callback(update, context)\n           ^^^^^^^^^^^^^^^^^^^^^^^^^^^^^^^^^^^^\n  File \"/home/technedict/Desktop/ViralPackage/viralcore/handlers/admin_handlers.py\", line 187, in admin_panel_handler\n    await admin_withdrawals_menu_handler(update, context)\n  File \"/home/technedict/Desktop/ViralPackage/viralcore/handlers/admin_withdrawal_handlers.py\", line 31, in admin_withdrawals_menu_handler\n    await query.edit_message_text(\"\u274c You don't have permission to access this menu.\")\n  File \"/home/technedict/Desktop/ViralPackage/viralcorelib/lib64/python3.13/site-packages/telegram/_callbackquery.py\", line 268, in edit_message_text\n    return await self._get_message().edit_text(\n           ^^^^^^^^^^^^^^^^^^^^^^^^^^^^^^^^^^^^\n    ...<11 lines>...\n    )\n    ^\n  File \"/home/technedict/Desktop/ViralPackage/viralcorelib/lib64/python3.13/site-packages/telegram/_message.py\", line 3659, in edit_text\n    return await self.get_bot().edit_message_text(\n           ^^^^^^^^^^^^^^^^^^^^^^^^^^^^^^^^^^^^^^^\n    ...<15 lines>...\n    )\n    ^\n  File \"/home/technedict/Desktop/ViralPackage/viralcorelib/lib64/python3.13/site-packages/telegram/ext/_extbot.py\", line 1664, in edit_message_text\n    return await super().edit_message_text(\n           ^^^^^^^^^^^^^^^^^^^^^^^^^^^^^^^^\n    ...<15 lines>...\n    )\n    ^\n  File \"/home/technedict/Desktop/ViralPackage/viralcorelib/lib64/python3.13/site-packages/telegram/_bot.py\", line 4047, in edit_message_text\n    return await self._send_message(\n           ^^^^^^^^^^^^^^^^^^^^^^^^^\n    ...<11 lines>...\n    )\n    ^\n  File \"/home/technedict/Desktop/ViralPackage/viralcorelib/lib64/python3.13/site-packages/telegram/ext/_extbot.py\", line 610, in _send_message\n    result = await super()._send_message(\n             ^^^^^^^^^^^^^^^^^^^^^^^^^^^^\n    ...<20 lines>...\n    )\n    ^\n  File \"/home/technedict/Desktop/ViralPackage/viralcorelib/lib64/python3.13/site-packages/telegram/_bot.py\", line 745, in _send_message\n    result = await self._post(\n             ^^^^^^^^^^^^^^^^^\n    ...<7 lines>...\n    )\n    ^\n  File \"/home/technedict/Desktop/ViralPackage/viralcorelib/lib64/python3.13/site-packages/telegram/_bot.py\", line 623, in _post\n    return await self._do_post(\n           ^^^^^^^^^^^^^^^^^^^^\n    ...<6 lines>...\n    )\n    ^\n  File \"/home/technedict/Desktop/ViralPackage/viralcorelib/lib64/python3.13/site-packages/telegram/ext/_extbot.py\", line 355, in _do_post\n    return await super()._do_post(\n           ^^^^^^^^^^^^^^^^^^^^^^^\n    ...<6 lines>...\n    )\n    ^\n  File \"/home/technedict/Desktop/ViralPackage/viralcorelib/lib64/python3.13/site-packages/telegram/_bot.py\", line 652, in _do_post\n    result = await request.post(\n             ^^^^^^^^^^^^^^^^^^^\n    ...<6 lines>...\n    )\n    ^\n  File \"/home/technedict/Desktop/ViralPackage/viralcorelib/lib64/python3.13/site-packages/telegram/request/_baserequest.py\", line 201, in post\n    result = await self._request_wrapper(\n             ^^^^^^^^^^^^^^^^^^^^^^^^^^^^\n    ...<7 lines>...\n    )\n    ^\n  File \"/home/technedict/Desktop/ViralPackage/viralcorelib/lib64/python3.13/site-packages/telegram/request/_baserequest.py\", line 382, in _request_wrapper\n    raise BadRequest(message)\ntelegram.error.BadRequest: There is no text in the message to edit"}
{"timestamp": "2025-09-28T15:21:24.286605Z", "level": "WARNING", "module": "utils.graceful_shutdown", "message": "updater.shutdown() raised: This Updater is still running!", "correlation_id": "none"}
{"timestamp": "2025-09-28T15:21:24.287747Z", "level": "WARNING", "module": "utils.graceful_shutdown", "message": "Shutdown already in progress", "correlation_id": "none"}
{"timestamp": "2025-09-28T15:21:24.303928Z", "level": "ERROR", "module": "__main__", "message": "Error during app.shutdown()", "correlation_id": "none", "exception": "Traceback (most recent call last):\n  File \"/home/technedict/Desktop/ViralPackage/viralcore/main_viral_core_bot.py\", line 301, in main\n    await app.shutdown()\n  File \"/home/technedict/Desktop/ViralPackage/viralcorelib/lib64/python3.13/site-packages/telegram/ext/_application.py\", line 561, in shutdown\n    await self.updater.shutdown()\n  File \"/home/technedict/Desktop/ViralPackage/viralcorelib/lib64/python3.13/site-packages/telegram/ext/_updater.py\", line 204, in shutdown\n    raise RuntimeError(\"This Updater is still running!\")\nRuntimeError: This Updater is still running!"}
{"timestamp": "2025-09-28T15:21:24.394235Z", "level": "ERROR", "module": "asyncio", "message": "Task exception was never retrieved\nfuture: <Task finished name='Task-24' coro=<Updater._start_polling.<locals>.polling_action_cb() done, defined at /home/technedict/Desktop/ViralPackage/viralcorelib/lib64/python3.13/site-packages/telegram/ext/_updater.py:375> exception=NetworkError('httpx.ReadError: ')>", "correlation_id": "none", "exception": "Traceback (most recent call last):\n  File \"/home/technedict/Desktop/ViralPackage/viralcorelib/lib64/python3.13/site-packages/httpx/_transports/default.py\", line 101, in map_httpcore_exceptions\n  File \"/home/technedict/Desktop/ViralPackage/viralcorelib/lib64/python3.13/site-packages/httpx/_transports/default.py\", line 394, in handle_async_request\n  File \"/home/technedict/Desktop/ViralPackage/viralcorelib/lib64/python3.13/site-packages/httpcore/_async/connection_pool.py\", line 256, in handle_async_request\n  File \"/home/technedict/Desktop/ViralPackage/viralcorelib/lib64/python3.13/site-packages/httpcore/_async/connection_pool.py\", line 236, in handle_async_request\n  File \"/home/technedict/Desktop/ViralPackage/viralcorelib/lib64/python3.13/site-packages/httpcore/_async/connection.py\", line 103, in handle_async_request\n  File \"/home/technedict/Desktop/ViralPackage/viralcorelib/lib64/python3.13/site-packages/httpcore/_async/http11.py\", line 136, in handle_async_request\n  File \"/home/technedict/Desktop/ViralPackage/viralcorelib/lib64/python3.13/site-packages/httpcore/_async/http11.py\", line 106, in handle_async_request\n  File \"/home/technedict/Desktop/ViralPackage/viralcorelib/lib64/python3.13/site-packages/httpcore/_async/http11.py\", line 177, in _receive_response_headers\n  File \"/home/technedict/Desktop/ViralPackage/viralcorelib/lib64/python3.13/site-packages/httpcore/_async/http11.py\", line 217, in _receive_event\n  File \"/home/technedict/Desktop/ViralPackage/viralcorelib/lib64/python3.13/site-packages/httpcore/_backends/anyio.py\", line 32, in read\n  File \"/usr/lib64/python3.13/contextlib.py\", line 162, in __exit__\n  File \"/home/technedict/Desktop/ViralPackage/viralcorelib/lib64/python3.13/site-packages/httpcore/_exceptions.py\", line 14, in map_exceptions\nhttpcore.ReadError\n\nThe above exception was the direct cause of the following exception:\n\nTraceback (most recent call last):\n  File \"/home/technedict/Desktop/ViralPackage/viralcorelib/lib64/python3.13/site-packages/telegram/request/_httpxrequest.py\", line 276, in do_request\n  File \"/home/technedict/Desktop/ViralPackage/viralcorelib/lib64/python3.13/site-packages/httpx/_client.py\", line 1540, in request\n  File \"/home/technedict/Desktop/ViralPackage/viralcorelib/lib64/python3.13/site-packages/httpx/_client.py\", line 1629, in send\n  File \"/home/technedict/Desktop/ViralPackage/viralcorelib/lib64/python3.13/site-packages/httpx/_client.py\", line 1657, in _send_handling_auth\n  File \"/home/technedict/Desktop/ViralPackage/viralcorelib/lib64/python3.13/site-packages/httpx/_client.py\", line 1694, in _send_handling_redirects\n  File \"/home/technedict/Desktop/ViralPackage/viralcorelib/lib64/python3.13/site-packages/httpx/_client.py\", line 1730, in _send_single_request\n  File \"/home/technedict/Desktop/ViralPackage/viralcorelib/lib64/python3.13/site-packages/httpx/_transports/default.py\", line 393, in handle_async_request\n  File \"/usr/lib64/python3.13/contextlib.py\", line 162, in __exit__\n  File \"/home/technedict/Desktop/ViralPackage/viralcorelib/lib64/python3.13/site-packages/httpx/_transports/default.py\", line 118, in map_httpcore_exceptions\nhttpx.ReadError\n\nThe above exception was the direct cause of the following exception:\n\nTraceback (most recent call last):\n  File \"/home/technedict/Desktop/ViralPackage/viralcorelib/lib64/python3.13/site-packages/telegram/ext/_updater.py\", line 377, in polling_action_cb\n    updates = await self.bot.get_updates(\n              ^^^^^^^^^^^^^^^^^^^^^^^^^^^\n    ...<7 lines>...\n    )\n    ^\n  File \"/home/technedict/Desktop/ViralPackage/viralcorelib/lib64/python3.13/site-packages/telegram/ext/_extbot.py\", line 649, in get_updates\n    updates = await super().get_updates(\n              ^^^^^^^^^^^^^^^^^^^^^^^^^^\n    ...<9 lines>...\n    )\n    ^\n  File \"/home/technedict/Desktop/ViralPackage/viralcorelib/lib64/python3.13/site-packages/telegram/_bot.py\", line 4366, in get_updates\n    await self._post(\n    ^^^^^^^^^^^^^^^^^\n    ...<7 lines>...\n    ),\n    ^\n  File \"/home/technedict/Desktop/ViralPackage/viralcorelib/lib64/python3.13/site-packages/telegram/_bot.py\", line 623, in _post\n    return await self._do_post(\n           ^^^^^^^^^^^^^^^^^^^^\n    ...<6 lines>...\n    )\n    ^\n  File \"/home/technedict/Desktop/ViralPackage/viralcorelib/lib64/python3.13/site-packages/telegram/ext/_extbot.py\", line 355, in _do_post\n    return await super()._do_post(\n           ^^^^^^^^^^^^^^^^^^^^^^^\n    ...<6 lines>...\n    )\n    ^\n  File \"/home/technedict/Desktop/ViralPackage/viralcorelib/lib64/python3.13/site-packages/telegram/_bot.py\", line 652, in _do_post\n    result = await request.post(\n             ^^^^^^^^^^^^^^^^^^^\n    ...<6 lines>...\n    )\n    ^\n  File \"/home/technedict/Desktop/ViralPackage/viralcorelib/lib64/python3.13/site-packages/telegram/request/_baserequest.py\", line 201, in post\n    result = await self._request_wrapper(\n             ^^^^^^^^^^^^^^^^^^^^^^^^^^^^\n    ...<7 lines>...\n    )\n    ^\n  File \"/home/technedict/Desktop/ViralPackage/viralcorelib/lib64/python3.13/site-packages/telegram/request/_baserequest.py\", line 333, in _request_wrapper\n    code, payload = await self.do_request(\n                    ^^^^^^^^^^^^^^^^^^^^^^\n    ...<7 lines>...\n    )\n    ^\n  File \"/home/technedict/Desktop/ViralPackage/viralcorelib/lib64/python3.13/site-packages/telegram/request/_httpxrequest.py\", line 300, in do_request\ntelegram.error.NetworkError: httpx.ReadError: "}
{"timestamp": "2025-09-28T15:21:28.667084Z", "level": "ERROR", "module": "telegram.ext.Application", "message": "No error handlers are registered, logging exception.", "correlation_id": "none", "exception": "Traceback (most recent call last):\n  File \"/home/technedict/Desktop/ViralPackage/viralcorelib/lib64/python3.13/site-packages/telegram/ext/_application.py\", line 1335, in process_update\n    await coroutine\n  File \"/home/technedict/Desktop/ViralPackage/viralcorelib/lib64/python3.13/site-packages/telegram/ext/_handlers/basehandler.py\", line 157, in handle_update\n    return await self.callback(update, context)\n           ^^^^^^^^^^^^^^^^^^^^^^^^^^^^^^^^^^^^\n  File \"/home/technedict/Desktop/ViralPackage/viralcore/handlers/admin_handlers.py\", line 187, in admin_panel_handler\n    await admin_withdrawals_menu_handler(update, context)\n  File \"/home/technedict/Desktop/ViralPackage/viralcore/handlers/admin_withdrawal_handlers.py\", line 31, in admin_withdrawals_menu_handler\n    await query.edit_message_text(\"\u274c You don't have permission to access this menu.\")\n  File \"/home/technedict/Desktop/ViralPackage/viralcorelib/lib64/python3.13/site-packages/telegram/_callbackquery.py\", line 268, in edit_message_text\n    return await self._get_message().edit_text(\n           ^^^^^^^^^^^^^^^^^^^^^^^^^^^^^^^^^^^^\n    ...<11 lines>...\n    )\n    ^\n  File \"/home/technedict/Desktop/ViralPackage/viralcorelib/lib64/python3.13/site-packages/telegram/_message.py\", line 3659, in edit_text\n    return await self.get_bot().edit_message_text(\n           ^^^^^^^^^^^^^^^^^^^^^^^^^^^^^^^^^^^^^^^\n    ...<15 lines>...\n    )\n    ^\n  File \"/home/technedict/Desktop/ViralPackage/viralcorelib/lib64/python3.13/site-packages/telegram/ext/_extbot.py\", line 1664, in edit_message_text\n    return await super().edit_message_text(\n           ^^^^^^^^^^^^^^^^^^^^^^^^^^^^^^^^\n    ...<15 lines>...\n    )\n    ^\n  File \"/home/technedict/Desktop/ViralPackage/viralcorelib/lib64/python3.13/site-packages/telegram/_bot.py\", line 4047, in edit_message_text\n    return await self._send_message(\n           ^^^^^^^^^^^^^^^^^^^^^^^^^\n    ...<11 lines>...\n    )\n    ^\n  File \"/home/technedict/Desktop/ViralPackage/viralcorelib/lib64/python3.13/site-packages/telegram/ext/_extbot.py\", line 610, in _send_message\n    result = await super()._send_message(\n             ^^^^^^^^^^^^^^^^^^^^^^^^^^^^\n    ...<20 lines>...\n    )\n    ^\n  File \"/home/technedict/Desktop/ViralPackage/viralcorelib/lib64/python3.13/site-packages/telegram/_bot.py\", line 745, in _send_message\n    result = await self._post(\n             ^^^^^^^^^^^^^^^^^\n    ...<7 lines>...\n    )\n    ^\n  File \"/home/technedict/Desktop/ViralPackage/viralcorelib/lib64/python3.13/site-packages/telegram/_bot.py\", line 623, in _post\n    return await self._do_post(\n           ^^^^^^^^^^^^^^^^^^^^\n    ...<6 lines>...\n    )\n    ^\n  File \"/home/technedict/Desktop/ViralPackage/viralcorelib/lib64/python3.13/site-packages/telegram/ext/_extbot.py\", line 355, in _do_post\n    return await super()._do_post(\n           ^^^^^^^^^^^^^^^^^^^^^^^\n    ...<6 lines>...\n    )\n    ^\n  File \"/home/technedict/Desktop/ViralPackage/viralcorelib/lib64/python3.13/site-packages/telegram/_bot.py\", line 652, in _do_post\n    result = await request.post(\n             ^^^^^^^^^^^^^^^^^^^\n    ...<6 lines>...\n    )\n    ^\n  File \"/home/technedict/Desktop/ViralPackage/viralcorelib/lib64/python3.13/site-packages/telegram/request/_baserequest.py\", line 201, in post\n    result = await self._request_wrapper(\n             ^^^^^^^^^^^^^^^^^^^^^^^^^^^^\n    ...<7 lines>...\n    )\n    ^\n  File \"/home/technedict/Desktop/ViralPackage/viralcorelib/lib64/python3.13/site-packages/telegram/request/_baserequest.py\", line 382, in _request_wrapper\n    raise BadRequest(message)\ntelegram.error.BadRequest: There is no text in the message to edit"}
{"timestamp": "2025-09-28T15:24:18.290686Z", "level": "WARNING", "module": "utils.graceful_shutdown", "message": "updater.shutdown() raised: This Updater is still running!", "correlation_id": "none"}
{"timestamp": "2025-09-28T15:24:18.295185Z", "level": "WARNING", "module": "utils.graceful_shutdown", "message": "Shutdown already in progress", "correlation_id": "none"}
{"timestamp": "2025-09-28T15:24:18.312942Z", "level": "ERROR", "module": "__main__", "message": "Error during app.shutdown()", "correlation_id": "none", "exception": "Traceback (most recent call last):\n  File \"/home/technedict/Desktop/ViralPackage/viralcore/main_viral_core_bot.py\", line 301, in main\n    await app.shutdown()\n  File \"/home/technedict/Desktop/ViralPackage/viralcorelib/lib64/python3.13/site-packages/telegram/ext/_application.py\", line 561, in shutdown\n    await self.updater.shutdown()\n  File \"/home/technedict/Desktop/ViralPackage/viralcorelib/lib64/python3.13/site-packages/telegram/ext/_updater.py\", line 204, in shutdown\n    raise RuntimeError(\"This Updater is still running!\")\nRuntimeError: This Updater is still running!"}
{"timestamp": "2025-09-28T15:24:18.426364Z", "level": "ERROR", "module": "asyncio", "message": "Task exception was never retrieved\nfuture: <Task finished name='Task-38' coro=<Updater._start_polling.<locals>.polling_action_cb() done, defined at /home/technedict/Desktop/ViralPackage/viralcorelib/lib64/python3.13/site-packages/telegram/ext/_updater.py:375> exception=NetworkError('httpx.ReadError: ')>", "correlation_id": "none", "exception": "Traceback (most recent call last):\n  File \"/home/technedict/Desktop/ViralPackage/viralcorelib/lib64/python3.13/site-packages/httpx/_transports/default.py\", line 101, in map_httpcore_exceptions\n  File \"/home/technedict/Desktop/ViralPackage/viralcorelib/lib64/python3.13/site-packages/httpx/_transports/default.py\", line 394, in handle_async_request\n  File \"/home/technedict/Desktop/ViralPackage/viralcorelib/lib64/python3.13/site-packages/httpcore/_async/connection_pool.py\", line 256, in handle_async_request\n  File \"/home/technedict/Desktop/ViralPackage/viralcorelib/lib64/python3.13/site-packages/httpcore/_async/connection_pool.py\", line 236, in handle_async_request\n  File \"/home/technedict/Desktop/ViralPackage/viralcorelib/lib64/python3.13/site-packages/httpcore/_async/connection.py\", line 103, in handle_async_request\n  File \"/home/technedict/Desktop/ViralPackage/viralcorelib/lib64/python3.13/site-packages/httpcore/_async/http11.py\", line 136, in handle_async_request\n  File \"/home/technedict/Desktop/ViralPackage/viralcorelib/lib64/python3.13/site-packages/httpcore/_async/http11.py\", line 106, in handle_async_request\n  File \"/home/technedict/Desktop/ViralPackage/viralcorelib/lib64/python3.13/site-packages/httpcore/_async/http11.py\", line 177, in _receive_response_headers\n  File \"/home/technedict/Desktop/ViralPackage/viralcorelib/lib64/python3.13/site-packages/httpcore/_async/http11.py\", line 217, in _receive_event\n  File \"/home/technedict/Desktop/ViralPackage/viralcorelib/lib64/python3.13/site-packages/httpcore/_backends/anyio.py\", line 32, in read\n  File \"/usr/lib64/python3.13/contextlib.py\", line 162, in __exit__\n  File \"/home/technedict/Desktop/ViralPackage/viralcorelib/lib64/python3.13/site-packages/httpcore/_exceptions.py\", line 14, in map_exceptions\nhttpcore.ReadError\n\nThe above exception was the direct cause of the following exception:\n\nTraceback (most recent call last):\n  File \"/home/technedict/Desktop/ViralPackage/viralcorelib/lib64/python3.13/site-packages/telegram/request/_httpxrequest.py\", line 276, in do_request\n  File \"/home/technedict/Desktop/ViralPackage/viralcorelib/lib64/python3.13/site-packages/httpx/_client.py\", line 1540, in request\n  File \"/home/technedict/Desktop/ViralPackage/viralcorelib/lib64/python3.13/site-packages/httpx/_client.py\", line 1629, in send\n  File \"/home/technedict/Desktop/ViralPackage/viralcorelib/lib64/python3.13/site-packages/httpx/_client.py\", line 1657, in _send_handling_auth\n  File \"/home/technedict/Desktop/ViralPackage/viralcorelib/lib64/python3.13/site-packages/httpx/_client.py\", line 1694, in _send_handling_redirects\n  File \"/home/technedict/Desktop/ViralPackage/viralcorelib/lib64/python3.13/site-packages/httpx/_client.py\", line 1730, in _send_single_request\n  File \"/home/technedict/Desktop/ViralPackage/viralcorelib/lib64/python3.13/site-packages/httpx/_transports/default.py\", line 393, in handle_async_request\n  File \"/usr/lib64/python3.13/contextlib.py\", line 162, in __exit__\n  File \"/home/technedict/Desktop/ViralPackage/viralcorelib/lib64/python3.13/site-packages/httpx/_transports/default.py\", line 118, in map_httpcore_exceptions\nhttpx.ReadError\n\nThe above exception was the direct cause of the following exception:\n\nTraceback (most recent call last):\n  File \"/home/technedict/Desktop/ViralPackage/viralcorelib/lib64/python3.13/site-packages/telegram/ext/_updater.py\", line 377, in polling_action_cb\n    updates = await self.bot.get_updates(\n              ^^^^^^^^^^^^^^^^^^^^^^^^^^^\n    ...<7 lines>...\n    )\n    ^\n  File \"/home/technedict/Desktop/ViralPackage/viralcorelib/lib64/python3.13/site-packages/telegram/ext/_extbot.py\", line 649, in get_updates\n    updates = await super().get_updates(\n              ^^^^^^^^^^^^^^^^^^^^^^^^^^\n    ...<9 lines>...\n    )\n    ^\n  File \"/home/technedict/Desktop/ViralPackage/viralcorelib/lib64/python3.13/site-packages/telegram/_bot.py\", line 4366, in get_updates\n    await self._post(\n    ^^^^^^^^^^^^^^^^^\n    ...<7 lines>...\n    ),\n    ^\n  File \"/home/technedict/Desktop/ViralPackage/viralcorelib/lib64/python3.13/site-packages/telegram/_bot.py\", line 623, in _post\n    return await self._do_post(\n           ^^^^^^^^^^^^^^^^^^^^\n    ...<6 lines>...\n    )\n    ^\n  File \"/home/technedict/Desktop/ViralPackage/viralcorelib/lib64/python3.13/site-packages/telegram/ext/_extbot.py\", line 355, in _do_post\n    return await super()._do_post(\n           ^^^^^^^^^^^^^^^^^^^^^^^\n    ...<6 lines>...\n    )\n    ^\n  File \"/home/technedict/Desktop/ViralPackage/viralcorelib/lib64/python3.13/site-packages/telegram/_bot.py\", line 652, in _do_post\n    result = await request.post(\n             ^^^^^^^^^^^^^^^^^^^\n    ...<6 lines>...\n    )\n    ^\n  File \"/home/technedict/Desktop/ViralPackage/viralcorelib/lib64/python3.13/site-packages/telegram/request/_baserequest.py\", line 201, in post\n    result = await self._request_wrapper(\n             ^^^^^^^^^^^^^^^^^^^^^^^^^^^^\n    ...<7 lines>...\n    )\n    ^\n  File \"/home/technedict/Desktop/ViralPackage/viralcorelib/lib64/python3.13/site-packages/telegram/request/_baserequest.py\", line 333, in _request_wrapper\n    code, payload = await self.do_request(\n                    ^^^^^^^^^^^^^^^^^^^^^^\n    ...<7 lines>...\n    )\n    ^\n  File \"/home/technedict/Desktop/ViralPackage/viralcorelib/lib64/python3.13/site-packages/telegram/request/_httpxrequest.py\", line 300, in do_request\ntelegram.error.NetworkError: httpx.ReadError: "}
{"timestamp": "2025-09-28T15:24:23.873192Z", "level": "ERROR", "module": "telegram.ext.Application", "message": "No error handlers are registered, logging exception.", "correlation_id": "none", "exception": "Traceback (most recent call last):\n  File \"/home/technedict/Desktop/ViralPackage/viralcorelib/lib64/python3.13/site-packages/telegram/ext/_application.py\", line 1335, in process_update\n    await coroutine\n  File \"/home/technedict/Desktop/ViralPackage/viralcorelib/lib64/python3.13/site-packages/telegram/ext/_handlers/basehandler.py\", line 157, in handle_update\n    return await self.callback(update, context)\n           ^^^^^^^^^^^^^^^^^^^^^^^^^^^^^^^^^^^^\n  File \"/home/technedict/Desktop/ViralPackage/viralcore/handlers/admin_handlers.py\", line 187, in admin_panel_handler\n    await admin_withdrawals_menu_handler(update, context)\n  File \"/home/technedict/Desktop/ViralPackage/viralcore/handlers/admin_withdrawal_handlers.py\", line 31, in admin_withdrawals_menu_handler\n    await query.edit_message_text(\"\u274c You don't have permission to access this menu.\")\n  File \"/home/technedict/Desktop/ViralPackage/viralcorelib/lib64/python3.13/site-packages/telegram/_callbackquery.py\", line 268, in edit_message_text\n    return await self._get_message().edit_text(\n           ^^^^^^^^^^^^^^^^^^^^^^^^^^^^^^^^^^^^\n    ...<11 lines>...\n    )\n    ^\n  File \"/home/technedict/Desktop/ViralPackage/viralcorelib/lib64/python3.13/site-packages/telegram/_message.py\", line 3659, in edit_text\n    return await self.get_bot().edit_message_text(\n           ^^^^^^^^^^^^^^^^^^^^^^^^^^^^^^^^^^^^^^^\n    ...<15 lines>...\n    )\n    ^\n  File \"/home/technedict/Desktop/ViralPackage/viralcorelib/lib64/python3.13/site-packages/telegram/ext/_extbot.py\", line 1664, in edit_message_text\n    return await super().edit_message_text(\n           ^^^^^^^^^^^^^^^^^^^^^^^^^^^^^^^^\n    ...<15 lines>...\n    )\n    ^\n  File \"/home/technedict/Desktop/ViralPackage/viralcorelib/lib64/python3.13/site-packages/telegram/_bot.py\", line 4047, in edit_message_text\n    return await self._send_message(\n           ^^^^^^^^^^^^^^^^^^^^^^^^^\n    ...<11 lines>...\n    )\n    ^\n  File \"/home/technedict/Desktop/ViralPackage/viralcorelib/lib64/python3.13/site-packages/telegram/ext/_extbot.py\", line 610, in _send_message\n    result = await super()._send_message(\n             ^^^^^^^^^^^^^^^^^^^^^^^^^^^^\n    ...<20 lines>...\n    )\n    ^\n  File \"/home/technedict/Desktop/ViralPackage/viralcorelib/lib64/python3.13/site-packages/telegram/_bot.py\", line 745, in _send_message\n    result = await self._post(\n             ^^^^^^^^^^^^^^^^^\n    ...<7 lines>...\n    )\n    ^\n  File \"/home/technedict/Desktop/ViralPackage/viralcorelib/lib64/python3.13/site-packages/telegram/_bot.py\", line 623, in _post\n    return await self._do_post(\n           ^^^^^^^^^^^^^^^^^^^^\n    ...<6 lines>...\n    )\n    ^\n  File \"/home/technedict/Desktop/ViralPackage/viralcorelib/lib64/python3.13/site-packages/telegram/ext/_extbot.py\", line 355, in _do_post\n    return await super()._do_post(\n           ^^^^^^^^^^^^^^^^^^^^^^^\n    ...<6 lines>...\n    )\n    ^\n  File \"/home/technedict/Desktop/ViralPackage/viralcorelib/lib64/python3.13/site-packages/telegram/_bot.py\", line 652, in _do_post\n    result = await request.post(\n             ^^^^^^^^^^^^^^^^^^^\n    ...<6 lines>...\n    )\n    ^\n  File \"/home/technedict/Desktop/ViralPackage/viralcorelib/lib64/python3.13/site-packages/telegram/request/_baserequest.py\", line 201, in post\n    result = await self._request_wrapper(\n             ^^^^^^^^^^^^^^^^^^^^^^^^^^^^\n    ...<7 lines>...\n    )\n    ^\n  File \"/home/technedict/Desktop/ViralPackage/viralcorelib/lib64/python3.13/site-packages/telegram/request/_baserequest.py\", line 382, in _request_wrapper\n    raise BadRequest(message)\ntelegram.error.BadRequest: There is no text in the message to edit"}
{"timestamp": "2025-09-28T15:24:45.502104Z", "level": "WARNING", "module": "utils.graceful_shutdown", "message": "updater.shutdown() raised: This Updater is still running!", "correlation_id": "none"}
{"timestamp": "2025-09-28T15:24:45.505735Z", "level": "WARNING", "module": "utils.graceful_shutdown", "message": "Shutdown already in progress", "correlation_id": "none"}
{"timestamp": "2025-09-28T15:24:45.524623Z", "level": "ERROR", "module": "__main__", "message": "Error during app.shutdown()", "correlation_id": "none", "exception": "Traceback (most recent call last):\n  File \"/home/technedict/Desktop/ViralPackage/viralcore/main_viral_core_bot.py\", line 301, in main\n    await app.shutdown()\n  File \"/home/technedict/Desktop/ViralPackage/viralcorelib/lib64/python3.13/site-packages/telegram/ext/_application.py\", line 561, in shutdown\n    await self.updater.shutdown()\n  File \"/home/technedict/Desktop/ViralPackage/viralcorelib/lib64/python3.13/site-packages/telegram/ext/_updater.py\", line 204, in shutdown\n    raise RuntimeError(\"This Updater is still running!\")\nRuntimeError: This Updater is still running!"}
{"timestamp": "2025-09-28T15:24:45.643449Z", "level": "ERROR", "module": "asyncio", "message": "Task exception was never retrieved\nfuture: <Task finished name='Task-10' coro=<Updater._start_polling.<locals>.polling_action_cb() done, defined at /home/technedict/Desktop/ViralPackage/viralcorelib/lib64/python3.13/site-packages/telegram/ext/_updater.py:375> exception=NetworkError('httpx.ReadError: ')>", "correlation_id": "none", "exception": "Traceback (most recent call last):\n  File \"/home/technedict/Desktop/ViralPackage/viralcorelib/lib64/python3.13/site-packages/httpx/_transports/default.py\", line 101, in map_httpcore_exceptions\n  File \"/home/technedict/Desktop/ViralPackage/viralcorelib/lib64/python3.13/site-packages/httpx/_transports/default.py\", line 394, in handle_async_request\n  File \"/home/technedict/Desktop/ViralPackage/viralcorelib/lib64/python3.13/site-packages/httpcore/_async/connection_pool.py\", line 256, in handle_async_request\n  File \"/home/technedict/Desktop/ViralPackage/viralcorelib/lib64/python3.13/site-packages/httpcore/_async/connection_pool.py\", line 236, in handle_async_request\n  File \"/home/technedict/Desktop/ViralPackage/viralcorelib/lib64/python3.13/site-packages/httpcore/_async/connection.py\", line 103, in handle_async_request\n  File \"/home/technedict/Desktop/ViralPackage/viralcorelib/lib64/python3.13/site-packages/httpcore/_async/http11.py\", line 136, in handle_async_request\n  File \"/home/technedict/Desktop/ViralPackage/viralcorelib/lib64/python3.13/site-packages/httpcore/_async/http11.py\", line 106, in handle_async_request\n  File \"/home/technedict/Desktop/ViralPackage/viralcorelib/lib64/python3.13/site-packages/httpcore/_async/http11.py\", line 177, in _receive_response_headers\n  File \"/home/technedict/Desktop/ViralPackage/viralcorelib/lib64/python3.13/site-packages/httpcore/_async/http11.py\", line 217, in _receive_event\n  File \"/home/technedict/Desktop/ViralPackage/viralcorelib/lib64/python3.13/site-packages/httpcore/_backends/anyio.py\", line 32, in read\n  File \"/usr/lib64/python3.13/contextlib.py\", line 162, in __exit__\n  File \"/home/technedict/Desktop/ViralPackage/viralcorelib/lib64/python3.13/site-packages/httpcore/_exceptions.py\", line 14, in map_exceptions\nhttpcore.ReadError\n\nThe above exception was the direct cause of the following exception:\n\nTraceback (most recent call last):\n  File \"/home/technedict/Desktop/ViralPackage/viralcorelib/lib64/python3.13/site-packages/telegram/request/_httpxrequest.py\", line 276, in do_request\n  File \"/home/technedict/Desktop/ViralPackage/viralcorelib/lib64/python3.13/site-packages/httpx/_client.py\", line 1540, in request\n  File \"/home/technedict/Desktop/ViralPackage/viralcorelib/lib64/python3.13/site-packages/httpx/_client.py\", line 1629, in send\n  File \"/home/technedict/Desktop/ViralPackage/viralcorelib/lib64/python3.13/site-packages/httpx/_client.py\", line 1657, in _send_handling_auth\n  File \"/home/technedict/Desktop/ViralPackage/viralcorelib/lib64/python3.13/site-packages/httpx/_client.py\", line 1694, in _send_handling_redirects\n  File \"/home/technedict/Desktop/ViralPackage/viralcorelib/lib64/python3.13/site-packages/httpx/_client.py\", line 1730, in _send_single_request\n  File \"/home/technedict/Desktop/ViralPackage/viralcorelib/lib64/python3.13/site-packages/httpx/_transports/default.py\", line 393, in handle_async_request\n  File \"/usr/lib64/python3.13/contextlib.py\", line 162, in __exit__\n  File \"/home/technedict/Desktop/ViralPackage/viralcorelib/lib64/python3.13/site-packages/httpx/_transports/default.py\", line 118, in map_httpcore_exceptions\nhttpx.ReadError\n\nThe above exception was the direct cause of the following exception:\n\nTraceback (most recent call last):\n  File \"/home/technedict/Desktop/ViralPackage/viralcorelib/lib64/python3.13/site-packages/telegram/ext/_updater.py\", line 377, in polling_action_cb\n    updates = await self.bot.get_updates(\n              ^^^^^^^^^^^^^^^^^^^^^^^^^^^\n    ...<7 lines>...\n    )\n    ^\n  File \"/home/technedict/Desktop/ViralPackage/viralcorelib/lib64/python3.13/site-packages/telegram/ext/_extbot.py\", line 649, in get_updates\n    updates = await super().get_updates(\n              ^^^^^^^^^^^^^^^^^^^^^^^^^^\n    ...<9 lines>...\n    )\n    ^\n  File \"/home/technedict/Desktop/ViralPackage/viralcorelib/lib64/python3.13/site-packages/telegram/_bot.py\", line 4366, in get_updates\n    await self._post(\n    ^^^^^^^^^^^^^^^^^\n    ...<7 lines>...\n    ),\n    ^\n  File \"/home/technedict/Desktop/ViralPackage/viralcorelib/lib64/python3.13/site-packages/telegram/_bot.py\", line 623, in _post\n    return await self._do_post(\n           ^^^^^^^^^^^^^^^^^^^^\n    ...<6 lines>...\n    )\n    ^\n  File \"/home/technedict/Desktop/ViralPackage/viralcorelib/lib64/python3.13/site-packages/telegram/ext/_extbot.py\", line 355, in _do_post\n    return await super()._do_post(\n           ^^^^^^^^^^^^^^^^^^^^^^^\n    ...<6 lines>...\n    )\n    ^\n  File \"/home/technedict/Desktop/ViralPackage/viralcorelib/lib64/python3.13/site-packages/telegram/_bot.py\", line 652, in _do_post\n    result = await request.post(\n             ^^^^^^^^^^^^^^^^^^^\n    ...<6 lines>...\n    )\n    ^\n  File \"/home/technedict/Desktop/ViralPackage/viralcorelib/lib64/python3.13/site-packages/telegram/request/_baserequest.py\", line 201, in post\n    result = await self._request_wrapper(\n             ^^^^^^^^^^^^^^^^^^^^^^^^^^^^\n    ...<7 lines>...\n    )\n    ^\n  File \"/home/technedict/Desktop/ViralPackage/viralcorelib/lib64/python3.13/site-packages/telegram/request/_baserequest.py\", line 333, in _request_wrapper\n    code, payload = await self.do_request(\n                    ^^^^^^^^^^^^^^^^^^^^^^\n    ...<7 lines>...\n    )\n    ^\n  File \"/home/technedict/Desktop/ViralPackage/viralcorelib/lib64/python3.13/site-packages/telegram/request/_httpxrequest.py\", line 300, in do_request\ntelegram.error.NetworkError: httpx.ReadError: "}
{"timestamp": "2025-09-28T15:24:51.624691Z", "level": "ERROR", "module": "telegram.ext.Application", "message": "No error handlers are registered, logging exception.", "correlation_id": "none", "exception": "Traceback (most recent call last):\n  File \"/home/technedict/Desktop/ViralPackage/viralcorelib/lib64/python3.13/site-packages/telegram/ext/_application.py\", line 1335, in process_update\n    await coroutine\n  File \"/home/technedict/Desktop/ViralPackage/viralcorelib/lib64/python3.13/site-packages/telegram/ext/_handlers/basehandler.py\", line 157, in handle_update\n    return await self.callback(update, context)\n           ^^^^^^^^^^^^^^^^^^^^^^^^^^^^^^^^^^^^\n  File \"/home/technedict/Desktop/ViralPackage/viralcore/handlers/admin_handlers.py\", line 187, in admin_panel_handler\n    await admin_withdrawals_menu_handler(update, context)\n  File \"/home/technedict/Desktop/ViralPackage/viralcore/handlers/admin_withdrawal_handlers.py\", line 31, in admin_withdrawals_menu_handler\n    await query.edit_message_text(\"\u274c You don't have permission to access this menu.\")\n  File \"/home/technedict/Desktop/ViralPackage/viralcorelib/lib64/python3.13/site-packages/telegram/_callbackquery.py\", line 268, in edit_message_text\n    return await self._get_message().edit_text(\n           ^^^^^^^^^^^^^^^^^^^^^^^^^^^^^^^^^^^^\n    ...<11 lines>...\n    )\n    ^\n  File \"/home/technedict/Desktop/ViralPackage/viralcorelib/lib64/python3.13/site-packages/telegram/_message.py\", line 3659, in edit_text\n    return await self.get_bot().edit_message_text(\n           ^^^^^^^^^^^^^^^^^^^^^^^^^^^^^^^^^^^^^^^\n    ...<15 lines>...\n    )\n    ^\n  File \"/home/technedict/Desktop/ViralPackage/viralcorelib/lib64/python3.13/site-packages/telegram/ext/_extbot.py\", line 1664, in edit_message_text\n    return await super().edit_message_text(\n           ^^^^^^^^^^^^^^^^^^^^^^^^^^^^^^^^\n    ...<15 lines>...\n    )\n    ^\n  File \"/home/technedict/Desktop/ViralPackage/viralcorelib/lib64/python3.13/site-packages/telegram/_bot.py\", line 4047, in edit_message_text\n    return await self._send_message(\n           ^^^^^^^^^^^^^^^^^^^^^^^^^\n    ...<11 lines>...\n    )\n    ^\n  File \"/home/technedict/Desktop/ViralPackage/viralcorelib/lib64/python3.13/site-packages/telegram/ext/_extbot.py\", line 610, in _send_message\n    result = await super()._send_message(\n             ^^^^^^^^^^^^^^^^^^^^^^^^^^^^\n    ...<20 lines>...\n    )\n    ^\n  File \"/home/technedict/Desktop/ViralPackage/viralcorelib/lib64/python3.13/site-packages/telegram/_bot.py\", line 745, in _send_message\n    result = await self._post(\n             ^^^^^^^^^^^^^^^^^\n    ...<7 lines>...\n    )\n    ^\n  File \"/home/technedict/Desktop/ViralPackage/viralcorelib/lib64/python3.13/site-packages/telegram/_bot.py\", line 623, in _post\n    return await self._do_post(\n           ^^^^^^^^^^^^^^^^^^^^\n    ...<6 lines>...\n    )\n    ^\n  File \"/home/technedict/Desktop/ViralPackage/viralcorelib/lib64/python3.13/site-packages/telegram/ext/_extbot.py\", line 355, in _do_post\n    return await super()._do_post(\n           ^^^^^^^^^^^^^^^^^^^^^^^\n    ...<6 lines>...\n    )\n    ^\n  File \"/home/technedict/Desktop/ViralPackage/viralcorelib/lib64/python3.13/site-packages/telegram/_bot.py\", line 652, in _do_post\n    result = await request.post(\n             ^^^^^^^^^^^^^^^^^^^\n    ...<6 lines>...\n    )\n    ^\n  File \"/home/technedict/Desktop/ViralPackage/viralcorelib/lib64/python3.13/site-packages/telegram/request/_baserequest.py\", line 201, in post\n    result = await self._request_wrapper(\n             ^^^^^^^^^^^^^^^^^^^^^^^^^^^^\n    ...<7 lines>...\n    )\n    ^\n  File \"/home/technedict/Desktop/ViralPackage/viralcorelib/lib64/python3.13/site-packages/telegram/request/_baserequest.py\", line 382, in _request_wrapper\n    raise BadRequest(message)\ntelegram.error.BadRequest: There is no text in the message to edit"}
{"timestamp": "2025-09-28T15:27:17.874328Z", "level": "WARNING", "module": "utils.graceful_shutdown", "message": "updater.shutdown() raised: This Updater is still running!", "correlation_id": "none"}
{"timestamp": "2025-09-28T15:27:17.878027Z", "level": "WARNING", "module": "utils.graceful_shutdown", "message": "Shutdown already in progress", "correlation_id": "none"}
{"timestamp": "2025-09-28T15:27:17.895908Z", "level": "ERROR", "module": "__main__", "message": "Error during app.shutdown()", "correlation_id": "none", "exception": "Traceback (most recent call last):\n  File \"/home/technedict/Desktop/ViralPackage/viralcore/main_viral_core_bot.py\", line 301, in main\n    await app.shutdown()\n  File \"/home/technedict/Desktop/ViralPackage/viralcorelib/lib64/python3.13/site-packages/telegram/ext/_application.py\", line 561, in shutdown\n    await self.updater.shutdown()\n  File \"/home/technedict/Desktop/ViralPackage/viralcorelib/lib64/python3.13/site-packages/telegram/ext/_updater.py\", line 204, in shutdown\n    raise RuntimeError(\"This Updater is still running!\")\nRuntimeError: This Updater is still running!"}
{"timestamp": "2025-09-28T15:27:18.024758Z", "level": "ERROR", "module": "asyncio", "message": "Task exception was never retrieved\nfuture: <Task finished name='Task-34' coro=<Updater._start_polling.<locals>.polling_action_cb() done, defined at /home/technedict/Desktop/ViralPackage/viralcorelib/lib64/python3.13/site-packages/telegram/ext/_updater.py:375> exception=NetworkError('httpx.ReadError: ')>", "correlation_id": "none", "exception": "Traceback (most recent call last):\n  File \"/home/technedict/Desktop/ViralPackage/viralcorelib/lib64/python3.13/site-packages/httpx/_transports/default.py\", line 101, in map_httpcore_exceptions\n  File \"/home/technedict/Desktop/ViralPackage/viralcorelib/lib64/python3.13/site-packages/httpx/_transports/default.py\", line 394, in handle_async_request\n  File \"/home/technedict/Desktop/ViralPackage/viralcorelib/lib64/python3.13/site-packages/httpcore/_async/connection_pool.py\", line 256, in handle_async_request\n  File \"/home/technedict/Desktop/ViralPackage/viralcorelib/lib64/python3.13/site-packages/httpcore/_async/connection_pool.py\", line 236, in handle_async_request\n  File \"/home/technedict/Desktop/ViralPackage/viralcorelib/lib64/python3.13/site-packages/httpcore/_async/connection.py\", line 103, in handle_async_request\n  File \"/home/technedict/Desktop/ViralPackage/viralcorelib/lib64/python3.13/site-packages/httpcore/_async/http11.py\", line 136, in handle_async_request\n  File \"/home/technedict/Desktop/ViralPackage/viralcorelib/lib64/python3.13/site-packages/httpcore/_async/http11.py\", line 106, in handle_async_request\n  File \"/home/technedict/Desktop/ViralPackage/viralcorelib/lib64/python3.13/site-packages/httpcore/_async/http11.py\", line 177, in _receive_response_headers\n  File \"/home/technedict/Desktop/ViralPackage/viralcorelib/lib64/python3.13/site-packages/httpcore/_async/http11.py\", line 217, in _receive_event\n  File \"/home/technedict/Desktop/ViralPackage/viralcorelib/lib64/python3.13/site-packages/httpcore/_backends/anyio.py\", line 32, in read\n  File \"/usr/lib64/python3.13/contextlib.py\", line 162, in __exit__\n  File \"/home/technedict/Desktop/ViralPackage/viralcorelib/lib64/python3.13/site-packages/httpcore/_exceptions.py\", line 14, in map_exceptions\nhttpcore.ReadError\n\nThe above exception was the direct cause of the following exception:\n\nTraceback (most recent call last):\n  File \"/home/technedict/Desktop/ViralPackage/viralcorelib/lib64/python3.13/site-packages/telegram/request/_httpxrequest.py\", line 276, in do_request\n  File \"/home/technedict/Desktop/ViralPackage/viralcorelib/lib64/python3.13/site-packages/httpx/_client.py\", line 1540, in request\n  File \"/home/technedict/Desktop/ViralPackage/viralcorelib/lib64/python3.13/site-packages/httpx/_client.py\", line 1629, in send\n  File \"/home/technedict/Desktop/ViralPackage/viralcorelib/lib64/python3.13/site-packages/httpx/_client.py\", line 1657, in _send_handling_auth\n  File \"/home/technedict/Desktop/ViralPackage/viralcorelib/lib64/python3.13/site-packages/httpx/_client.py\", line 1694, in _send_handling_redirects\n  File \"/home/technedict/Desktop/ViralPackage/viralcorelib/lib64/python3.13/site-packages/httpx/_client.py\", line 1730, in _send_single_request\n  File \"/home/technedict/Desktop/ViralPackage/viralcorelib/lib64/python3.13/site-packages/httpx/_transports/default.py\", line 393, in handle_async_request\n  File \"/usr/lib64/python3.13/contextlib.py\", line 162, in __exit__\n  File \"/home/technedict/Desktop/ViralPackage/viralcorelib/lib64/python3.13/site-packages/httpx/_transports/default.py\", line 118, in map_httpcore_exceptions\nhttpx.ReadError\n\nThe above exception was the direct cause of the following exception:\n\nTraceback (most recent call last):\n  File \"/home/technedict/Desktop/ViralPackage/viralcorelib/lib64/python3.13/site-packages/telegram/ext/_updater.py\", line 377, in polling_action_cb\n    updates = await self.bot.get_updates(\n              ^^^^^^^^^^^^^^^^^^^^^^^^^^^\n    ...<7 lines>...\n    )\n    ^\n  File \"/home/technedict/Desktop/ViralPackage/viralcorelib/lib64/python3.13/site-packages/telegram/ext/_extbot.py\", line 649, in get_updates\n    updates = await super().get_updates(\n              ^^^^^^^^^^^^^^^^^^^^^^^^^^\n    ...<9 lines>...\n    )\n    ^\n  File \"/home/technedict/Desktop/ViralPackage/viralcorelib/lib64/python3.13/site-packages/telegram/_bot.py\", line 4366, in get_updates\n    await self._post(\n    ^^^^^^^^^^^^^^^^^\n    ...<7 lines>...\n    ),\n    ^\n  File \"/home/technedict/Desktop/ViralPackage/viralcorelib/lib64/python3.13/site-packages/telegram/_bot.py\", line 623, in _post\n    return await self._do_post(\n           ^^^^^^^^^^^^^^^^^^^^\n    ...<6 lines>...\n    )\n    ^\n  File \"/home/technedict/Desktop/ViralPackage/viralcorelib/lib64/python3.13/site-packages/telegram/ext/_extbot.py\", line 355, in _do_post\n    return await super()._do_post(\n           ^^^^^^^^^^^^^^^^^^^^^^^\n    ...<6 lines>...\n    )\n    ^\n  File \"/home/technedict/Desktop/ViralPackage/viralcorelib/lib64/python3.13/site-packages/telegram/_bot.py\", line 652, in _do_post\n    result = await request.post(\n             ^^^^^^^^^^^^^^^^^^^\n    ...<6 lines>...\n    )\n    ^\n  File \"/home/technedict/Desktop/ViralPackage/viralcorelib/lib64/python3.13/site-packages/telegram/request/_baserequest.py\", line 201, in post\n    result = await self._request_wrapper(\n             ^^^^^^^^^^^^^^^^^^^^^^^^^^^^\n    ...<7 lines>...\n    )\n    ^\n  File \"/home/technedict/Desktop/ViralPackage/viralcorelib/lib64/python3.13/site-packages/telegram/request/_baserequest.py\", line 333, in _request_wrapper\n    code, payload = await self.do_request(\n                    ^^^^^^^^^^^^^^^^^^^^^^\n    ...<7 lines>...\n    )\n    ^\n  File \"/home/technedict/Desktop/ViralPackage/viralcorelib/lib64/python3.13/site-packages/telegram/request/_httpxrequest.py\", line 300, in do_request\ntelegram.error.NetworkError: httpx.ReadError: "}
{"timestamp": "2025-09-28T15:27:52.558654Z", "level": "ERROR", "module": "telegram.ext.Application", "message": "No error handlers are registered, logging exception.", "correlation_id": "none", "exception": "Traceback (most recent call last):\n  File \"/home/technedict/Desktop/ViralPackage/viralcorelib/lib64/python3.13/site-packages/telegram/ext/_application.py\", line 1335, in process_update\n    await coroutine\n  File \"/home/technedict/Desktop/ViralPackage/viralcorelib/lib64/python3.13/site-packages/telegram/ext/_handlers/basehandler.py\", line 157, in handle_update\n    return await self.callback(update, context)\n           ^^^^^^^^^^^^^^^^^^^^^^^^^^^^^^^^^^^^\n  File \"/home/technedict/Desktop/ViralPackage/viralcore/handlers/admin_handlers.py\", line 187, in admin_panel_handler\n    await admin_withdrawals_menu_handler(update, context)\n  File \"/home/technedict/Desktop/ViralPackage/viralcore/handlers/admin_withdrawal_handlers.py\", line 48, in admin_withdrawals_menu_handler\n    await query.edit_message_text(\n    ...<3 lines>...\n    )\n  File \"/home/technedict/Desktop/ViralPackage/viralcorelib/lib64/python3.13/site-packages/telegram/_callbackquery.py\", line 268, in edit_message_text\n    return await self._get_message().edit_text(\n           ^^^^^^^^^^^^^^^^^^^^^^^^^^^^^^^^^^^^\n    ...<11 lines>...\n    )\n    ^\n  File \"/home/technedict/Desktop/ViralPackage/viralcorelib/lib64/python3.13/site-packages/telegram/_message.py\", line 3659, in edit_text\n    return await self.get_bot().edit_message_text(\n           ^^^^^^^^^^^^^^^^^^^^^^^^^^^^^^^^^^^^^^^\n    ...<15 lines>...\n    )\n    ^\n  File \"/home/technedict/Desktop/ViralPackage/viralcorelib/lib64/python3.13/site-packages/telegram/ext/_extbot.py\", line 1664, in edit_message_text\n    return await super().edit_message_text(\n           ^^^^^^^^^^^^^^^^^^^^^^^^^^^^^^^^\n    ...<15 lines>...\n    )\n    ^\n  File \"/home/technedict/Desktop/ViralPackage/viralcorelib/lib64/python3.13/site-packages/telegram/_bot.py\", line 4047, in edit_message_text\n    return await self._send_message(\n           ^^^^^^^^^^^^^^^^^^^^^^^^^\n    ...<11 lines>...\n    )\n    ^\n  File \"/home/technedict/Desktop/ViralPackage/viralcorelib/lib64/python3.13/site-packages/telegram/ext/_extbot.py\", line 610, in _send_message\n    result = await super()._send_message(\n             ^^^^^^^^^^^^^^^^^^^^^^^^^^^^\n    ...<20 lines>...\n    )\n    ^\n  File \"/home/technedict/Desktop/ViralPackage/viralcorelib/lib64/python3.13/site-packages/telegram/_bot.py\", line 745, in _send_message\n    result = await self._post(\n             ^^^^^^^^^^^^^^^^^\n    ...<7 lines>...\n    )\n    ^\n  File \"/home/technedict/Desktop/ViralPackage/viralcorelib/lib64/python3.13/site-packages/telegram/_bot.py\", line 623, in _post\n    return await self._do_post(\n           ^^^^^^^^^^^^^^^^^^^^\n    ...<6 lines>...\n    )\n    ^\n  File \"/home/technedict/Desktop/ViralPackage/viralcorelib/lib64/python3.13/site-packages/telegram/ext/_extbot.py\", line 355, in _do_post\n    return await super()._do_post(\n           ^^^^^^^^^^^^^^^^^^^^^^^\n    ...<6 lines>...\n    )\n    ^\n  File \"/home/technedict/Desktop/ViralPackage/viralcorelib/lib64/python3.13/site-packages/telegram/_bot.py\", line 652, in _do_post\n    result = await request.post(\n             ^^^^^^^^^^^^^^^^^^^\n    ...<6 lines>...\n    )\n    ^\n  File \"/home/technedict/Desktop/ViralPackage/viralcorelib/lib64/python3.13/site-packages/telegram/request/_baserequest.py\", line 201, in post\n    result = await self._request_wrapper(\n             ^^^^^^^^^^^^^^^^^^^^^^^^^^^^\n    ...<7 lines>...\n    )\n    ^\n  File \"/home/technedict/Desktop/ViralPackage/viralcorelib/lib64/python3.13/site-packages/telegram/request/_baserequest.py\", line 382, in _request_wrapper\n    raise BadRequest(message)\ntelegram.error.BadRequest: There is no text in the message to edit"}
{"timestamp": "2025-09-28T15:29:36.666865Z", "level": "WARNING", "module": "utils.graceful_shutdown", "message": "updater.shutdown() raised: This Updater is still running!", "correlation_id": "none"}
{"timestamp": "2025-09-28T15:29:36.668904Z", "level": "WARNING", "module": "utils.graceful_shutdown", "message": "Shutdown already in progress", "correlation_id": "none"}
{"timestamp": "2025-09-28T15:29:36.687179Z", "level": "ERROR", "module": "__main__", "message": "Error during app.shutdown()", "correlation_id": "none", "exception": "Traceback (most recent call last):\n  File \"/home/technedict/Desktop/ViralPackage/viralcore/main_viral_core_bot.py\", line 301, in main\n    await app.shutdown()\n  File \"/home/technedict/Desktop/ViralPackage/viralcorelib/lib64/python3.13/site-packages/telegram/ext/_application.py\", line 561, in shutdown\n    await self.updater.shutdown()\n  File \"/home/technedict/Desktop/ViralPackage/viralcorelib/lib64/python3.13/site-packages/telegram/ext/_updater.py\", line 204, in shutdown\n    raise RuntimeError(\"This Updater is still running!\")\nRuntimeError: This Updater is still running!"}
{"timestamp": "2025-09-28T15:29:36.797528Z", "level": "ERROR", "module": "asyncio", "message": "Task exception was never retrieved\nfuture: <Task finished name='Task-30' coro=<Updater._start_polling.<locals>.polling_action_cb() done, defined at /home/technedict/Desktop/ViralPackage/viralcorelib/lib64/python3.13/site-packages/telegram/ext/_updater.py:375> exception=NetworkError('httpx.ReadError: ')>", "correlation_id": "none", "exception": "Traceback (most recent call last):\n  File \"/home/technedict/Desktop/ViralPackage/viralcorelib/lib64/python3.13/site-packages/httpx/_transports/default.py\", line 101, in map_httpcore_exceptions\n  File \"/home/technedict/Desktop/ViralPackage/viralcorelib/lib64/python3.13/site-packages/httpx/_transports/default.py\", line 394, in handle_async_request\n  File \"/home/technedict/Desktop/ViralPackage/viralcorelib/lib64/python3.13/site-packages/httpcore/_async/connection_pool.py\", line 256, in handle_async_request\n  File \"/home/technedict/Desktop/ViralPackage/viralcorelib/lib64/python3.13/site-packages/httpcore/_async/connection_pool.py\", line 236, in handle_async_request\n  File \"/home/technedict/Desktop/ViralPackage/viralcorelib/lib64/python3.13/site-packages/httpcore/_async/connection.py\", line 103, in handle_async_request\n  File \"/home/technedict/Desktop/ViralPackage/viralcorelib/lib64/python3.13/site-packages/httpcore/_async/http11.py\", line 136, in handle_async_request\n  File \"/home/technedict/Desktop/ViralPackage/viralcorelib/lib64/python3.13/site-packages/httpcore/_async/http11.py\", line 106, in handle_async_request\n  File \"/home/technedict/Desktop/ViralPackage/viralcorelib/lib64/python3.13/site-packages/httpcore/_async/http11.py\", line 177, in _receive_response_headers\n  File \"/home/technedict/Desktop/ViralPackage/viralcorelib/lib64/python3.13/site-packages/httpcore/_async/http11.py\", line 217, in _receive_event\n  File \"/home/technedict/Desktop/ViralPackage/viralcorelib/lib64/python3.13/site-packages/httpcore/_backends/anyio.py\", line 32, in read\n  File \"/usr/lib64/python3.13/contextlib.py\", line 162, in __exit__\n  File \"/home/technedict/Desktop/ViralPackage/viralcorelib/lib64/python3.13/site-packages/httpcore/_exceptions.py\", line 14, in map_exceptions\nhttpcore.ReadError\n\nThe above exception was the direct cause of the following exception:\n\nTraceback (most recent call last):\n  File \"/home/technedict/Desktop/ViralPackage/viralcorelib/lib64/python3.13/site-packages/telegram/request/_httpxrequest.py\", line 276, in do_request\n  File \"/home/technedict/Desktop/ViralPackage/viralcorelib/lib64/python3.13/site-packages/httpx/_client.py\", line 1540, in request\n  File \"/home/technedict/Desktop/ViralPackage/viralcorelib/lib64/python3.13/site-packages/httpx/_client.py\", line 1629, in send\n  File \"/home/technedict/Desktop/ViralPackage/viralcorelib/lib64/python3.13/site-packages/httpx/_client.py\", line 1657, in _send_handling_auth\n  File \"/home/technedict/Desktop/ViralPackage/viralcorelib/lib64/python3.13/site-packages/httpx/_client.py\", line 1694, in _send_handling_redirects\n  File \"/home/technedict/Desktop/ViralPackage/viralcorelib/lib64/python3.13/site-packages/httpx/_client.py\", line 1730, in _send_single_request\n  File \"/home/technedict/Desktop/ViralPackage/viralcorelib/lib64/python3.13/site-packages/httpx/_transports/default.py\", line 393, in handle_async_request\n  File \"/usr/lib64/python3.13/contextlib.py\", line 162, in __exit__\n  File \"/home/technedict/Desktop/ViralPackage/viralcorelib/lib64/python3.13/site-packages/httpx/_transports/default.py\", line 118, in map_httpcore_exceptions\nhttpx.ReadError\n\nThe above exception was the direct cause of the following exception:\n\nTraceback (most recent call last):\n  File \"/home/technedict/Desktop/ViralPackage/viralcorelib/lib64/python3.13/site-packages/telegram/ext/_updater.py\", line 377, in polling_action_cb\n    updates = await self.bot.get_updates(\n              ^^^^^^^^^^^^^^^^^^^^^^^^^^^\n    ...<7 lines>...\n    )\n    ^\n  File \"/home/technedict/Desktop/ViralPackage/viralcorelib/lib64/python3.13/site-packages/telegram/ext/_extbot.py\", line 649, in get_updates\n    updates = await super().get_updates(\n              ^^^^^^^^^^^^^^^^^^^^^^^^^^\n    ...<9 lines>...\n    )\n    ^\n  File \"/home/technedict/Desktop/ViralPackage/viralcorelib/lib64/python3.13/site-packages/telegram/_bot.py\", line 4366, in get_updates\n    await self._post(\n    ^^^^^^^^^^^^^^^^^\n    ...<7 lines>...\n    ),\n    ^\n  File \"/home/technedict/Desktop/ViralPackage/viralcorelib/lib64/python3.13/site-packages/telegram/_bot.py\", line 623, in _post\n    return await self._do_post(\n           ^^^^^^^^^^^^^^^^^^^^\n    ...<6 lines>...\n    )\n    ^\n  File \"/home/technedict/Desktop/ViralPackage/viralcorelib/lib64/python3.13/site-packages/telegram/ext/_extbot.py\", line 355, in _do_post\n    return await super()._do_post(\n           ^^^^^^^^^^^^^^^^^^^^^^^\n    ...<6 lines>...\n    )\n    ^\n  File \"/home/technedict/Desktop/ViralPackage/viralcorelib/lib64/python3.13/site-packages/telegram/_bot.py\", line 652, in _do_post\n    result = await request.post(\n             ^^^^^^^^^^^^^^^^^^^\n    ...<6 lines>...\n    )\n    ^\n  File \"/home/technedict/Desktop/ViralPackage/viralcorelib/lib64/python3.13/site-packages/telegram/request/_baserequest.py\", line 201, in post\n    result = await self._request_wrapper(\n             ^^^^^^^^^^^^^^^^^^^^^^^^^^^^\n    ...<7 lines>...\n    )\n    ^\n  File \"/home/technedict/Desktop/ViralPackage/viralcorelib/lib64/python3.13/site-packages/telegram/request/_baserequest.py\", line 333, in _request_wrapper\n    code, payload = await self.do_request(\n                    ^^^^^^^^^^^^^^^^^^^^^^\n    ...<7 lines>...\n    )\n    ^\n  File \"/home/technedict/Desktop/ViralPackage/viralcorelib/lib64/python3.13/site-packages/telegram/request/_httpxrequest.py\", line 300, in do_request\ntelegram.error.NetworkError: httpx.ReadError: "}
{"timestamp": "2025-09-28T15:29:41.517357Z", "level": "ERROR", "module": "telegram.ext.Application", "message": "No error handlers are registered, logging exception.", "correlation_id": "none", "exception": "Traceback (most recent call last):\n  File \"/home/technedict/Desktop/ViralPackage/viralcorelib/lib64/python3.13/site-packages/telegram/ext/_application.py\", line 1335, in process_update\n    await coroutine\n  File \"/home/technedict/Desktop/ViralPackage/viralcorelib/lib64/python3.13/site-packages/telegram/ext/_handlers/basehandler.py\", line 157, in handle_update\n    return await self.callback(update, context)\n           ^^^^^^^^^^^^^^^^^^^^^^^^^^^^^^^^^^^^\n  File \"/home/technedict/Desktop/ViralPackage/viralcore/handlers/admin_handlers.py\", line 187, in admin_panel_handler\n    await admin_withdrawals_menu_handler(update, context)\n  File \"/home/technedict/Desktop/ViralPackage/viralcore/handlers/admin_withdrawal_handlers.py\", line 48, in admin_withdrawals_menu_handler\n    await query.edit_message_reply_markup(\n          ~~~~~~~~~~~~~~~~~~~~~~~~~~~~~~~^\n        menu_text,\n        ^^^^^^^^^^\n        reply_markup=reply_markup,\n        ^^^^^^^^^^^^^^^^^^^^^^^^^^\n        parse_mode=ParseMode.MARKDOWN_V2\n        ^^^^^^^^^^^^^^^^^^^^^^^^^^^^^^^^\n    )\n    ^\nTypeError: CallbackQuery.edit_message_reply_markup() got multiple values for argument 'reply_markup'"}
{"timestamp": "2025-09-28T15:30:38.043317Z", "level": "ERROR", "module": "telegram.ext.Application", "message": "No error handlers are registered, logging exception.", "correlation_id": "none", "exception": "Traceback (most recent call last):\n  File \"/home/technedict/Desktop/ViralPackage/viralcorelib/lib64/python3.13/site-packages/telegram/ext/_application.py\", line 1335, in process_update\n    await coroutine\n  File \"/home/technedict/Desktop/ViralPackage/viralcorelib/lib64/python3.13/site-packages/telegram/ext/_handlers/basehandler.py\", line 157, in handle_update\n    return await self.callback(update, context)\n           ^^^^^^^^^^^^^^^^^^^^^^^^^^^^^^^^^^^^\n  File \"/home/technedict/Desktop/ViralPackage/viralcore/handlers/admin_handlers.py\", line 193, in admin_panel_handler\n    await admin_services_menu_handler(update, context)\n  File \"/home/technedict/Desktop/ViralPackage/viralcore/handlers/admin_service_handlers.py\", line 45, in admin_services_menu_handler\n    await query.edit_message_text(\n    ...<3 lines>...\n    )\n  File \"/home/technedict/Desktop/ViralPackage/viralcorelib/lib64/python3.13/site-packages/telegram/_callbackquery.py\", line 268, in edit_message_text\n    return await self._get_message().edit_text(\n           ^^^^^^^^^^^^^^^^^^^^^^^^^^^^^^^^^^^^\n    ...<11 lines>...\n    )\n    ^\n  File \"/home/technedict/Desktop/ViralPackage/viralcorelib/lib64/python3.13/site-packages/telegram/_message.py\", line 3659, in edit_text\n    return await self.get_bot().edit_message_text(\n           ^^^^^^^^^^^^^^^^^^^^^^^^^^^^^^^^^^^^^^^\n    ...<15 lines>...\n    )\n    ^\n  File \"/home/technedict/Desktop/ViralPackage/viralcorelib/lib64/python3.13/site-packages/telegram/ext/_extbot.py\", line 1664, in edit_message_text\n    return await super().edit_message_text(\n           ^^^^^^^^^^^^^^^^^^^^^^^^^^^^^^^^\n    ...<15 lines>...\n    )\n    ^\n  File \"/home/technedict/Desktop/ViralPackage/viralcorelib/lib64/python3.13/site-packages/telegram/_bot.py\", line 4047, in edit_message_text\n    return await self._send_message(\n           ^^^^^^^^^^^^^^^^^^^^^^^^^\n    ...<11 lines>...\n    )\n    ^\n  File \"/home/technedict/Desktop/ViralPackage/viralcorelib/lib64/python3.13/site-packages/telegram/ext/_extbot.py\", line 610, in _send_message\n    result = await super()._send_message(\n             ^^^^^^^^^^^^^^^^^^^^^^^^^^^^\n    ...<20 lines>...\n    )\n    ^\n  File \"/home/technedict/Desktop/ViralPackage/viralcorelib/lib64/python3.13/site-packages/telegram/_bot.py\", line 745, in _send_message\n    result = await self._post(\n             ^^^^^^^^^^^^^^^^^\n    ...<7 lines>...\n    )\n    ^\n  File \"/home/technedict/Desktop/ViralPackage/viralcorelib/lib64/python3.13/site-packages/telegram/_bot.py\", line 623, in _post\n    return await self._do_post(\n           ^^^^^^^^^^^^^^^^^^^^\n    ...<6 lines>...\n    )\n    ^\n  File \"/home/technedict/Desktop/ViralPackage/viralcorelib/lib64/python3.13/site-packages/telegram/ext/_extbot.py\", line 355, in _do_post\n    return await super()._do_post(\n           ^^^^^^^^^^^^^^^^^^^^^^^\n    ...<6 lines>...\n    )\n    ^\n  File \"/home/technedict/Desktop/ViralPackage/viralcorelib/lib64/python3.13/site-packages/telegram/_bot.py\", line 652, in _do_post\n    result = await request.post(\n             ^^^^^^^^^^^^^^^^^^^\n    ...<6 lines>...\n    )\n    ^\n  File \"/home/technedict/Desktop/ViralPackage/viralcorelib/lib64/python3.13/site-packages/telegram/request/_baserequest.py\", line 201, in post\n    result = await self._request_wrapper(\n             ^^^^^^^^^^^^^^^^^^^^^^^^^^^^\n    ...<7 lines>...\n    )\n    ^\n  File \"/home/technedict/Desktop/ViralPackage/viralcorelib/lib64/python3.13/site-packages/telegram/request/_baserequest.py\", line 382, in _request_wrapper\n    raise BadRequest(message)\ntelegram.error.BadRequest: There is no text in the message to edit"}
{"timestamp": "2025-09-28T15:30:50.023909Z", "level": "WARNING", "module": "utils.graceful_shutdown", "message": "updater.shutdown() raised: This Updater is still running!", "correlation_id": "none"}
{"timestamp": "2025-09-28T15:30:50.025244Z", "level": "WARNING", "module": "utils.graceful_shutdown", "message": "Shutdown already in progress", "correlation_id": "none"}
{"timestamp": "2025-09-28T15:30:50.044777Z", "level": "ERROR", "module": "__main__", "message": "Error during app.shutdown()", "correlation_id": "none", "exception": "Traceback (most recent call last):\n  File \"/home/technedict/Desktop/ViralPackage/viralcore/main_viral_core_bot.py\", line 301, in main\n    await app.shutdown()\n  File \"/home/technedict/Desktop/ViralPackage/viralcorelib/lib64/python3.13/site-packages/telegram/ext/_application.py\", line 561, in shutdown\n    await self.updater.shutdown()\n  File \"/home/technedict/Desktop/ViralPackage/viralcorelib/lib64/python3.13/site-packages/telegram/ext/_updater.py\", line 204, in shutdown\n    raise RuntimeError(\"This Updater is still running!\")\nRuntimeError: This Updater is still running!"}
{"timestamp": "2025-09-28T15:30:50.155753Z", "level": "ERROR", "module": "asyncio", "message": "Task exception was never retrieved\nfuture: <Task finished name='Task-22' coro=<Updater._start_polling.<locals>.polling_action_cb() done, defined at /home/technedict/Desktop/ViralPackage/viralcorelib/lib64/python3.13/site-packages/telegram/ext/_updater.py:375> exception=NetworkError('httpx.ReadError: ')>", "correlation_id": "none", "exception": "Traceback (most recent call last):\n  File \"/home/technedict/Desktop/ViralPackage/viralcorelib/lib64/python3.13/site-packages/httpx/_transports/default.py\", line 101, in map_httpcore_exceptions\n  File \"/home/technedict/Desktop/ViralPackage/viralcorelib/lib64/python3.13/site-packages/httpx/_transports/default.py\", line 394, in handle_async_request\n  File \"/home/technedict/Desktop/ViralPackage/viralcorelib/lib64/python3.13/site-packages/httpcore/_async/connection_pool.py\", line 256, in handle_async_request\n  File \"/home/technedict/Desktop/ViralPackage/viralcorelib/lib64/python3.13/site-packages/httpcore/_async/connection_pool.py\", line 236, in handle_async_request\n  File \"/home/technedict/Desktop/ViralPackage/viralcorelib/lib64/python3.13/site-packages/httpcore/_async/connection.py\", line 103, in handle_async_request\n  File \"/home/technedict/Desktop/ViralPackage/viralcorelib/lib64/python3.13/site-packages/httpcore/_async/http11.py\", line 136, in handle_async_request\n  File \"/home/technedict/Desktop/ViralPackage/viralcorelib/lib64/python3.13/site-packages/httpcore/_async/http11.py\", line 106, in handle_async_request\n  File \"/home/technedict/Desktop/ViralPackage/viralcorelib/lib64/python3.13/site-packages/httpcore/_async/http11.py\", line 177, in _receive_response_headers\n  File \"/home/technedict/Desktop/ViralPackage/viralcorelib/lib64/python3.13/site-packages/httpcore/_async/http11.py\", line 217, in _receive_event\n  File \"/home/technedict/Desktop/ViralPackage/viralcorelib/lib64/python3.13/site-packages/httpcore/_backends/anyio.py\", line 32, in read\n  File \"/usr/lib64/python3.13/contextlib.py\", line 162, in __exit__\n  File \"/home/technedict/Desktop/ViralPackage/viralcorelib/lib64/python3.13/site-packages/httpcore/_exceptions.py\", line 14, in map_exceptions\nhttpcore.ReadError\n\nThe above exception was the direct cause of the following exception:\n\nTraceback (most recent call last):\n  File \"/home/technedict/Desktop/ViralPackage/viralcorelib/lib64/python3.13/site-packages/telegram/request/_httpxrequest.py\", line 276, in do_request\n  File \"/home/technedict/Desktop/ViralPackage/viralcorelib/lib64/python3.13/site-packages/httpx/_client.py\", line 1540, in request\n  File \"/home/technedict/Desktop/ViralPackage/viralcorelib/lib64/python3.13/site-packages/httpx/_client.py\", line 1629, in send\n  File \"/home/technedict/Desktop/ViralPackage/viralcorelib/lib64/python3.13/site-packages/httpx/_client.py\", line 1657, in _send_handling_auth\n  File \"/home/technedict/Desktop/ViralPackage/viralcorelib/lib64/python3.13/site-packages/httpx/_client.py\", line 1694, in _send_handling_redirects\n  File \"/home/technedict/Desktop/ViralPackage/viralcorelib/lib64/python3.13/site-packages/httpx/_client.py\", line 1730, in _send_single_request\n  File \"/home/technedict/Desktop/ViralPackage/viralcorelib/lib64/python3.13/site-packages/httpx/_transports/default.py\", line 393, in handle_async_request\n  File \"/usr/lib64/python3.13/contextlib.py\", line 162, in __exit__\n  File \"/home/technedict/Desktop/ViralPackage/viralcorelib/lib64/python3.13/site-packages/httpx/_transports/default.py\", line 118, in map_httpcore_exceptions\nhttpx.ReadError\n\nThe above exception was the direct cause of the following exception:\n\nTraceback (most recent call last):\n  File \"/home/technedict/Desktop/ViralPackage/viralcorelib/lib64/python3.13/site-packages/telegram/ext/_updater.py\", line 377, in polling_action_cb\n    updates = await self.bot.get_updates(\n              ^^^^^^^^^^^^^^^^^^^^^^^^^^^\n    ...<7 lines>...\n    )\n    ^\n  File \"/home/technedict/Desktop/ViralPackage/viralcorelib/lib64/python3.13/site-packages/telegram/ext/_extbot.py\", line 649, in get_updates\n    updates = await super().get_updates(\n              ^^^^^^^^^^^^^^^^^^^^^^^^^^\n    ...<9 lines>...\n    )\n    ^\n  File \"/home/technedict/Desktop/ViralPackage/viralcorelib/lib64/python3.13/site-packages/telegram/_bot.py\", line 4366, in get_updates\n    await self._post(\n    ^^^^^^^^^^^^^^^^^\n    ...<7 lines>...\n    ),\n    ^\n  File \"/home/technedict/Desktop/ViralPackage/viralcorelib/lib64/python3.13/site-packages/telegram/_bot.py\", line 623, in _post\n    return await self._do_post(\n           ^^^^^^^^^^^^^^^^^^^^\n    ...<6 lines>...\n    )\n    ^\n  File \"/home/technedict/Desktop/ViralPackage/viralcorelib/lib64/python3.13/site-packages/telegram/ext/_extbot.py\", line 355, in _do_post\n    return await super()._do_post(\n           ^^^^^^^^^^^^^^^^^^^^^^^\n    ...<6 lines>...\n    )\n    ^\n  File \"/home/technedict/Desktop/ViralPackage/viralcorelib/lib64/python3.13/site-packages/telegram/_bot.py\", line 652, in _do_post\n    result = await request.post(\n             ^^^^^^^^^^^^^^^^^^^\n    ...<6 lines>...\n    )\n    ^\n  File \"/home/technedict/Desktop/ViralPackage/viralcorelib/lib64/python3.13/site-packages/telegram/request/_baserequest.py\", line 201, in post\n    result = await self._request_wrapper(\n             ^^^^^^^^^^^^^^^^^^^^^^^^^^^^\n    ...<7 lines>...\n    )\n    ^\n  File \"/home/technedict/Desktop/ViralPackage/viralcorelib/lib64/python3.13/site-packages/telegram/request/_baserequest.py\", line 333, in _request_wrapper\n    code, payload = await self.do_request(\n                    ^^^^^^^^^^^^^^^^^^^^^^\n    ...<7 lines>...\n    )\n    ^\n  File \"/home/technedict/Desktop/ViralPackage/viralcorelib/lib64/python3.13/site-packages/telegram/request/_httpxrequest.py\", line 300, in do_request\ntelegram.error.NetworkError: httpx.ReadError: "}
{"timestamp": "2025-09-28T15:30:57.057662Z", "level": "ERROR", "module": "telegram.ext.Application", "message": "No error handlers are registered, logging exception.", "correlation_id": "none", "exception": "Traceback (most recent call last):\n  File \"/home/technedict/Desktop/ViralPackage/viralcorelib/lib64/python3.13/site-packages/telegram/ext/_application.py\", line 1335, in process_update\n    await coroutine\n  File \"/home/technedict/Desktop/ViralPackage/viralcorelib/lib64/python3.13/site-packages/telegram/ext/_handlers/basehandler.py\", line 157, in handle_update\n    return await self.callback(update, context)\n           ^^^^^^^^^^^^^^^^^^^^^^^^^^^^^^^^^^^^\n  File \"/home/technedict/Desktop/ViralPackage/viralcore/handlers/admin_handlers.py\", line 193, in admin_panel_handler\n    await admin_services_menu_handler(update, context)\n  File \"/home/technedict/Desktop/ViralPackage/viralcore/handlers/admin_service_handlers.py\", line 45, in admin_services_menu_handler\n    await query.edit_message_text(\n    ...<3 lines>...\n    )\n  File \"/home/technedict/Desktop/ViralPackage/viralcorelib/lib64/python3.13/site-packages/telegram/_callbackquery.py\", line 268, in edit_message_text\n    return await self._get_message().edit_text(\n           ^^^^^^^^^^^^^^^^^^^^^^^^^^^^^^^^^^^^\n    ...<11 lines>...\n    )\n    ^\n  File \"/home/technedict/Desktop/ViralPackage/viralcorelib/lib64/python3.13/site-packages/telegram/_message.py\", line 3659, in edit_text\n    return await self.get_bot().edit_message_text(\n           ^^^^^^^^^^^^^^^^^^^^^^^^^^^^^^^^^^^^^^^\n    ...<15 lines>...\n    )\n    ^\n  File \"/home/technedict/Desktop/ViralPackage/viralcorelib/lib64/python3.13/site-packages/telegram/ext/_extbot.py\", line 1664, in edit_message_text\n    return await super().edit_message_text(\n           ^^^^^^^^^^^^^^^^^^^^^^^^^^^^^^^^\n    ...<15 lines>...\n    )\n    ^\n  File \"/home/technedict/Desktop/ViralPackage/viralcorelib/lib64/python3.13/site-packages/telegram/_bot.py\", line 4047, in edit_message_text\n    return await self._send_message(\n           ^^^^^^^^^^^^^^^^^^^^^^^^^\n    ...<11 lines>...\n    )\n    ^\n  File \"/home/technedict/Desktop/ViralPackage/viralcorelib/lib64/python3.13/site-packages/telegram/ext/_extbot.py\", line 610, in _send_message\n    result = await super()._send_message(\n             ^^^^^^^^^^^^^^^^^^^^^^^^^^^^\n    ...<20 lines>...\n    )\n    ^\n  File \"/home/technedict/Desktop/ViralPackage/viralcorelib/lib64/python3.13/site-packages/telegram/_bot.py\", line 745, in _send_message\n    result = await self._post(\n             ^^^^^^^^^^^^^^^^^\n    ...<7 lines>...\n    )\n    ^\n  File \"/home/technedict/Desktop/ViralPackage/viralcorelib/lib64/python3.13/site-packages/telegram/_bot.py\", line 623, in _post\n    return await self._do_post(\n           ^^^^^^^^^^^^^^^^^^^^\n    ...<6 lines>...\n    )\n    ^\n  File \"/home/technedict/Desktop/ViralPackage/viralcorelib/lib64/python3.13/site-packages/telegram/ext/_extbot.py\", line 355, in _do_post\n    return await super()._do_post(\n           ^^^^^^^^^^^^^^^^^^^^^^^\n    ...<6 lines>...\n    )\n    ^\n  File \"/home/technedict/Desktop/ViralPackage/viralcorelib/lib64/python3.13/site-packages/telegram/_bot.py\", line 652, in _do_post\n    result = await request.post(\n             ^^^^^^^^^^^^^^^^^^^\n    ...<6 lines>...\n    )\n    ^\n  File \"/home/technedict/Desktop/ViralPackage/viralcorelib/lib64/python3.13/site-packages/telegram/request/_baserequest.py\", line 201, in post\n    result = await self._request_wrapper(\n             ^^^^^^^^^^^^^^^^^^^^^^^^^^^^\n    ...<7 lines>...\n    )\n    ^\n  File \"/home/technedict/Desktop/ViralPackage/viralcorelib/lib64/python3.13/site-packages/telegram/request/_baserequest.py\", line 382, in _request_wrapper\n    raise BadRequest(message)\ntelegram.error.BadRequest: There is no text in the message to edit"}
{"timestamp": "2025-09-28T15:31:15.824717Z", "level": "ERROR", "module": "telegram.ext.Application", "message": "No error handlers are registered, logging exception.", "correlation_id": "none", "exception": "Traceback (most recent call last):\n  File \"/home/technedict/Desktop/ViralPackage/viralcorelib/lib64/python3.13/site-packages/telegram/ext/_application.py\", line 1335, in process_update\n    await coroutine\n  File \"/home/technedict/Desktop/ViralPackage/viralcorelib/lib64/python3.13/site-packages/telegram/ext/_handlers/basehandler.py\", line 157, in handle_update\n    return await self.callback(update, context)\n           ^^^^^^^^^^^^^^^^^^^^^^^^^^^^^^^^^^^^\n  File \"/home/technedict/Desktop/ViralPackage/viralcore/handlers/message_handler.py\", line 57, in message_router\n    await custom_order_handler(update, context) # Or a general_message_handler\n    ^^^^^^^^^^^^^^^^^^^^^^^^^^^^^^^^^^^^^^^^^^^\n  File \"/home/technedict/Desktop/ViralPackage/viralcore/handlers/custom_order_handlers.py\", line 31, in custom_order_handler\n    text = update.message.text.strip()\n           ^^^^^^^^^^^^^^^^^^^\nAttributeError: 'NoneType' object has no attribute 'text'"}
{"timestamp": "2025-09-28T18:01:25.520174Z", "level": "WARNING", "module": "handlers.menu_handlers", "message": "menu_handler edit failed (Invalid file http url specified: unsupported url protocol) for user ***ACCOUNT***. Resending message.", "correlation_id": "none"}
{"timestamp": "2025-09-28T18:01:49.191438Z", "level": "ERROR", "module": "telegram.ext.Application", "message": "No error handlers are registered, logging exception.", "correlation_id": "none", "exception": "Traceback (most recent call last):\n  File \"/home/technedict/Desktop/ViralPackage/viralcorelib/lib64/python3.13/site-packages/telegram/ext/_application.py\", line 1335, in process_update\n    await coroutine\n  File \"/home/technedict/Desktop/ViralPackage/viralcorelib/lib64/python3.13/site-packages/telegram/ext/_handlers/basehandler.py\", line 157, in handle_update\n    return await self.callback(update, context)\n           ^^^^^^^^^^^^^^^^^^^^^^^^^^^^^^^^^^^^\n  File \"/home/technedict/Desktop/ViralPackage/viralcore/handlers/admin_handlers.py\", line 187, in admin_panel_handler\n    await admin_withdrawals_menu_handler(update, context)\n  File \"/home/technedict/Desktop/ViralPackage/viralcore/handlers/admin_withdrawal_handlers.py\", line 112, in admin_withdrawals_menu_handler\n    await query.edit_message_text(\n    ...<3 lines>...\n    )\n  File \"/home/technedict/Desktop/ViralPackage/viralcorelib/lib64/python3.13/site-packages/telegram/_callbackquery.py\", line 268, in edit_message_text\n    return await self._get_message().edit_text(\n           ^^^^^^^^^^^^^^^^^^^^^^^^^^^^^^^^^^^^\n    ...<11 lines>...\n    )\n    ^\n  File \"/home/technedict/Desktop/ViralPackage/viralcorelib/lib64/python3.13/site-packages/telegram/_message.py\", line 3659, in edit_text\n    return await self.get_bot().edit_message_text(\n           ^^^^^^^^^^^^^^^^^^^^^^^^^^^^^^^^^^^^^^^\n    ...<15 lines>...\n    )\n    ^\n  File \"/home/technedict/Desktop/ViralPackage/viralcorelib/lib64/python3.13/site-packages/telegram/ext/_extbot.py\", line 1664, in edit_message_text\n    return await super().edit_message_text(\n           ^^^^^^^^^^^^^^^^^^^^^^^^^^^^^^^^\n    ...<15 lines>...\n    )\n    ^\n  File \"/home/technedict/Desktop/ViralPackage/viralcorelib/lib64/python3.13/site-packages/telegram/_bot.py\", line 4047, in edit_message_text\n    return await self._send_message(\n           ^^^^^^^^^^^^^^^^^^^^^^^^^\n    ...<11 lines>...\n    )\n    ^\n  File \"/home/technedict/Desktop/ViralPackage/viralcorelib/lib64/python3.13/site-packages/telegram/ext/_extbot.py\", line 610, in _send_message\n    result = await super()._send_message(\n             ^^^^^^^^^^^^^^^^^^^^^^^^^^^^\n    ...<20 lines>...\n    )\n    ^\n  File \"/home/technedict/Desktop/ViralPackage/viralcorelib/lib64/python3.13/site-packages/telegram/_bot.py\", line 745, in _send_message\n    result = await self._post(\n             ^^^^^^^^^^^^^^^^^\n    ...<7 lines>...\n    )\n    ^\n  File \"/home/technedict/Desktop/ViralPackage/viralcorelib/lib64/python3.13/site-packages/telegram/_bot.py\", line 623, in _post\n    return await self._do_post(\n           ^^^^^^^^^^^^^^^^^^^^\n    ...<6 lines>...\n    )\n    ^\n  File \"/home/technedict/Desktop/ViralPackage/viralcorelib/lib64/python3.13/site-packages/telegram/ext/_extbot.py\", line 355, in _do_post\n    return await super()._do_post(\n           ^^^^^^^^^^^^^^^^^^^^^^^\n    ...<6 lines>...\n    )\n    ^\n  File \"/home/technedict/Desktop/ViralPackage/viralcorelib/lib64/python3.13/site-packages/telegram/_bot.py\", line 652, in _do_post\n    result = await request.post(\n             ^^^^^^^^^^^^^^^^^^^\n    ...<6 lines>...\n    )\n    ^\n  File \"/home/technedict/Desktop/ViralPackage/viralcorelib/lib64/python3.13/site-packages/telegram/request/_baserequest.py\", line 201, in post\n    result = await self._request_wrapper(\n             ^^^^^^^^^^^^^^^^^^^^^^^^^^^^\n    ...<7 lines>...\n    )\n    ^\n  File \"/home/technedict/Desktop/ViralPackage/viralcorelib/lib64/python3.13/site-packages/telegram/request/_baserequest.py\", line 382, in _request_wrapper\n    raise BadRequest(message)\ntelegram.error.BadRequest: Can't parse entities: character '(' is reserved and must be escaped with the preceding '\\'"}
{"timestamp": "2025-09-28T18:02:51.569594Z", "level": "WARNING", "module": "utils.graceful_shutdown", "message": "updater.shutdown() raised: This Updater is still running!", "correlation_id": "none"}
{"timestamp": "2025-09-28T18:02:51.570843Z", "level": "WARNING", "module": "utils.graceful_shutdown", "message": "Shutdown already in progress", "correlation_id": "none"}
{"timestamp": "2025-09-28T18:02:51.591419Z", "level": "ERROR", "module": "__main__", "message": "Error during app.shutdown()", "correlation_id": "none", "exception": "Traceback (most recent call last):\n  File \"/home/technedict/Desktop/ViralPackage/viralcore/main_viral_core_bot.py\", line 301, in main\n    await app.shutdown()\n  File \"/home/technedict/Desktop/ViralPackage/viralcorelib/lib64/python3.13/site-packages/telegram/ext/_application.py\", line 561, in shutdown\n    await self.updater.shutdown()\n  File \"/home/technedict/Desktop/ViralPackage/viralcorelib/lib64/python3.13/site-packages/telegram/ext/_updater.py\", line 204, in shutdown\n    raise RuntimeError(\"This Updater is still running!\")\nRuntimeError: This Updater is still running!"}
{"timestamp": "2025-09-28T18:02:51.691006Z", "level": "ERROR", "module": "asyncio", "message": "Task exception was never retrieved\nfuture: <Task finished name='Task-26' coro=<Updater._start_polling.<locals>.polling_action_cb() done, defined at /home/technedict/Desktop/ViralPackage/viralcorelib/lib64/python3.13/site-packages/telegram/ext/_updater.py:375> exception=NetworkError('httpx.ReadError: ')>", "correlation_id": "none", "exception": "Traceback (most recent call last):\n  File \"/home/technedict/Desktop/ViralPackage/viralcorelib/lib64/python3.13/site-packages/httpx/_transports/default.py\", line 101, in map_httpcore_exceptions\n  File \"/home/technedict/Desktop/ViralPackage/viralcorelib/lib64/python3.13/site-packages/httpx/_transports/default.py\", line 394, in handle_async_request\n  File \"/home/technedict/Desktop/ViralPackage/viralcorelib/lib64/python3.13/site-packages/httpcore/_async/connection_pool.py\", line 256, in handle_async_request\n  File \"/home/technedict/Desktop/ViralPackage/viralcorelib/lib64/python3.13/site-packages/httpcore/_async/connection_pool.py\", line 236, in handle_async_request\n  File \"/home/technedict/Desktop/ViralPackage/viralcorelib/lib64/python3.13/site-packages/httpcore/_async/connection.py\", line 103, in handle_async_request\n  File \"/home/technedict/Desktop/ViralPackage/viralcorelib/lib64/python3.13/site-packages/httpcore/_async/http11.py\", line 136, in handle_async_request\n  File \"/home/technedict/Desktop/ViralPackage/viralcorelib/lib64/python3.13/site-packages/httpcore/_async/http11.py\", line 106, in handle_async_request\n  File \"/home/technedict/Desktop/ViralPackage/viralcorelib/lib64/python3.13/site-packages/httpcore/_async/http11.py\", line 177, in _receive_response_headers\n  File \"/home/technedict/Desktop/ViralPackage/viralcorelib/lib64/python3.13/site-packages/httpcore/_async/http11.py\", line 217, in _receive_event\n  File \"/home/technedict/Desktop/ViralPackage/viralcorelib/lib64/python3.13/site-packages/httpcore/_backends/anyio.py\", line 32, in read\n  File \"/usr/lib64/python3.13/contextlib.py\", line 162, in __exit__\n  File \"/home/technedict/Desktop/ViralPackage/viralcorelib/lib64/python3.13/site-packages/httpcore/_exceptions.py\", line 14, in map_exceptions\nhttpcore.ReadError\n\nThe above exception was the direct cause of the following exception:\n\nTraceback (most recent call last):\n  File \"/home/technedict/Desktop/ViralPackage/viralcorelib/lib64/python3.13/site-packages/telegram/request/_httpxrequest.py\", line 276, in do_request\n  File \"/home/technedict/Desktop/ViralPackage/viralcorelib/lib64/python3.13/site-packages/httpx/_client.py\", line 1540, in request\n  File \"/home/technedict/Desktop/ViralPackage/viralcorelib/lib64/python3.13/site-packages/httpx/_client.py\", line 1629, in send\n  File \"/home/technedict/Desktop/ViralPackage/viralcorelib/lib64/python3.13/site-packages/httpx/_client.py\", line 1657, in _send_handling_auth\n  File \"/home/technedict/Desktop/ViralPackage/viralcorelib/lib64/python3.13/site-packages/httpx/_client.py\", line 1694, in _send_handling_redirects\n  File \"/home/technedict/Desktop/ViralPackage/viralcorelib/lib64/python3.13/site-packages/httpx/_client.py\", line 1730, in _send_single_request\n  File \"/home/technedict/Desktop/ViralPackage/viralcorelib/lib64/python3.13/site-packages/httpx/_transports/default.py\", line 393, in handle_async_request\n  File \"/usr/lib64/python3.13/contextlib.py\", line 162, in __exit__\n  File \"/home/technedict/Desktop/ViralPackage/viralcorelib/lib64/python3.13/site-packages/httpx/_transports/default.py\", line 118, in map_httpcore_exceptions\nhttpx.ReadError\n\nThe above exception was the direct cause of the following exception:\n\nTraceback (most recent call last):\n  File \"/home/technedict/Desktop/ViralPackage/viralcorelib/lib64/python3.13/site-packages/telegram/ext/_updater.py\", line 377, in polling_action_cb\n    updates = await self.bot.get_updates(\n              ^^^^^^^^^^^^^^^^^^^^^^^^^^^\n    ...<7 lines>...\n    )\n    ^\n  File \"/home/technedict/Desktop/ViralPackage/viralcorelib/lib64/python3.13/site-packages/telegram/ext/_extbot.py\", line 649, in get_updates\n    updates = await super().get_updates(\n              ^^^^^^^^^^^^^^^^^^^^^^^^^^\n    ...<9 lines>...\n    )\n    ^\n  File \"/home/technedict/Desktop/ViralPackage/viralcorelib/lib64/python3.13/site-packages/telegram/_bot.py\", line 4366, in get_updates\n    await self._post(\n    ^^^^^^^^^^^^^^^^^\n    ...<7 lines>...\n    ),\n    ^\n  File \"/home/technedict/Desktop/ViralPackage/viralcorelib/lib64/python3.13/site-packages/telegram/_bot.py\", line 623, in _post\n    return await self._do_post(\n           ^^^^^^^^^^^^^^^^^^^^\n    ...<6 lines>...\n    )\n    ^\n  File \"/home/technedict/Desktop/ViralPackage/viralcorelib/lib64/python3.13/site-packages/telegram/ext/_extbot.py\", line 355, in _do_post\n    return await super()._do_post(\n           ^^^^^^^^^^^^^^^^^^^^^^^\n    ...<6 lines>...\n    )\n    ^\n  File \"/home/technedict/Desktop/ViralPackage/viralcorelib/lib64/python3.13/site-packages/telegram/_bot.py\", line 652, in _do_post\n    result = await request.post(\n             ^^^^^^^^^^^^^^^^^^^\n    ...<6 lines>...\n    )\n    ^\n  File \"/home/technedict/Desktop/ViralPackage/viralcorelib/lib64/python3.13/site-packages/telegram/request/_baserequest.py\", line 201, in post\n    result = await self._request_wrapper(\n             ^^^^^^^^^^^^^^^^^^^^^^^^^^^^\n    ...<7 lines>...\n    )\n    ^\n  File \"/home/technedict/Desktop/ViralPackage/viralcorelib/lib64/python3.13/site-packages/telegram/request/_baserequest.py\", line 333, in _request_wrapper\n    code, payload = await self.do_request(\n                    ^^^^^^^^^^^^^^^^^^^^^^\n    ...<7 lines>...\n    )\n    ^\n  File \"/home/technedict/Desktop/ViralPackage/viralcorelib/lib64/python3.13/site-packages/telegram/request/_httpxrequest.py\", line 300, in do_request\ntelegram.error.NetworkError: httpx.ReadError: "}
{"timestamp": "2025-09-28T18:03:01.896355Z", "level": "ERROR", "module": "telegram.ext.Application", "message": "No error handlers are registered, logging exception.", "correlation_id": "none", "exception": "Traceback (most recent call last):\n  File \"/home/technedict/Desktop/ViralPackage/viralcorelib/lib64/python3.13/site-packages/telegram/ext/_application.py\", line 1335, in process_update\n    await coroutine\n  File \"/home/technedict/Desktop/ViralPackage/viralcorelib/lib64/python3.13/site-packages/telegram/ext/_handlers/basehandler.py\", line 157, in handle_update\n    return await self.callback(update, context)\n           ^^^^^^^^^^^^^^^^^^^^^^^^^^^^^^^^^^^^\n  File \"/home/technedict/Desktop/ViralPackage/viralcore/handlers/admin_handlers.py\", line 187, in admin_panel_handler\n    await admin_withdrawals_menu_handler(update, context)\n  File \"/home/technedict/Desktop/ViralPackage/viralcore/handlers/admin_withdrawal_handlers.py\", line 113, in admin_withdrawals_menu_handler\n    await query.edit_message_text(\n    ...<3 lines>...\n    )\n  File \"/home/technedict/Desktop/ViralPackage/viralcorelib/lib64/python3.13/site-packages/telegram/_callbackquery.py\", line 268, in edit_message_text\n    return await self._get_message().edit_text(\n           ^^^^^^^^^^^^^^^^^^^^^^^^^^^^^^^^^^^^\n    ...<11 lines>...\n    )\n    ^\n  File \"/home/technedict/Desktop/ViralPackage/viralcorelib/lib64/python3.13/site-packages/telegram/_message.py\", line 3659, in edit_text\n    return await self.get_bot().edit_message_text(\n           ^^^^^^^^^^^^^^^^^^^^^^^^^^^^^^^^^^^^^^^\n    ...<15 lines>...\n    )\n    ^\n  File \"/home/technedict/Desktop/ViralPackage/viralcorelib/lib64/python3.13/site-packages/telegram/ext/_extbot.py\", line 1664, in edit_message_text\n    return await super().edit_message_text(\n           ^^^^^^^^^^^^^^^^^^^^^^^^^^^^^^^^\n    ...<15 lines>...\n    )\n    ^\n  File \"/home/technedict/Desktop/ViralPackage/viralcorelib/lib64/python3.13/site-packages/telegram/_bot.py\", line 4047, in edit_message_text\n    return await self._send_message(\n           ^^^^^^^^^^^^^^^^^^^^^^^^^\n    ...<11 lines>...\n    )\n    ^\n  File \"/home/technedict/Desktop/ViralPackage/viralcorelib/lib64/python3.13/site-packages/telegram/ext/_extbot.py\", line 610, in _send_message\n    result = await super()._send_message(\n             ^^^^^^^^^^^^^^^^^^^^^^^^^^^^\n    ...<20 lines>...\n    )\n    ^\n  File \"/home/technedict/Desktop/ViralPackage/viralcorelib/lib64/python3.13/site-packages/telegram/_bot.py\", line 745, in _send_message\n    result = await self._post(\n             ^^^^^^^^^^^^^^^^^\n    ...<7 lines>...\n    )\n    ^\n  File \"/home/technedict/Desktop/ViralPackage/viralcorelib/lib64/python3.13/site-packages/telegram/_bot.py\", line 623, in _post\n    return await self._do_post(\n           ^^^^^^^^^^^^^^^^^^^^\n    ...<6 lines>...\n    )\n    ^\n  File \"/home/technedict/Desktop/ViralPackage/viralcorelib/lib64/python3.13/site-packages/telegram/ext/_extbot.py\", line 355, in _do_post\n    return await super()._do_post(\n           ^^^^^^^^^^^^^^^^^^^^^^^\n    ...<6 lines>...\n    )\n    ^\n  File \"/home/technedict/Desktop/ViralPackage/viralcorelib/lib64/python3.13/site-packages/telegram/_bot.py\", line 652, in _do_post\n    result = await request.post(\n             ^^^^^^^^^^^^^^^^^^^\n    ...<6 lines>...\n    )\n    ^\n  File \"/home/technedict/Desktop/ViralPackage/viralcorelib/lib64/python3.13/site-packages/telegram/request/_baserequest.py\", line 201, in post\n    result = await self._request_wrapper(\n             ^^^^^^^^^^^^^^^^^^^^^^^^^^^^\n    ...<7 lines>...\n    )\n    ^\n  File \"/home/technedict/Desktop/ViralPackage/viralcorelib/lib64/python3.13/site-packages/telegram/request/_baserequest.py\", line 382, in _request_wrapper\n    raise BadRequest(message)\ntelegram.error.BadRequest: There is no text in the message to edit"}
{"timestamp": "2025-09-28T18:08:24.842248Z", "level": "WARNING", "module": "utils.graceful_shutdown", "message": "updater.shutdown() raised: This Updater is still running!", "correlation_id": "none"}
{"timestamp": "2025-09-28T18:08:24.844106Z", "level": "WARNING", "module": "utils.graceful_shutdown", "message": "Shutdown already in progress", "correlation_id": "none"}
{"timestamp": "2025-09-28T18:08:24.860257Z", "level": "ERROR", "module": "__main__", "message": "Error during app.shutdown()", "correlation_id": "none", "exception": "Traceback (most recent call last):\n  File \"/home/technedict/Desktop/ViralPackage/viralcore/main_viral_core_bot.py\", line 301, in main\n    await app.shutdown()\n  File \"/home/technedict/Desktop/ViralPackage/viralcorelib/lib64/python3.13/site-packages/telegram/ext/_application.py\", line 561, in shutdown\n    await self.updater.shutdown()\n  File \"/home/technedict/Desktop/ViralPackage/viralcorelib/lib64/python3.13/site-packages/telegram/ext/_updater.py\", line 204, in shutdown\n    raise RuntimeError(\"This Updater is still running!\")\nRuntimeError: This Updater is still running!"}
{"timestamp": "2025-09-28T18:08:24.976570Z", "level": "ERROR", "module": "asyncio", "message": "Task exception was never retrieved\nfuture: <Task finished name='Task-68' coro=<Updater._start_polling.<locals>.polling_action_cb() done, defined at /home/technedict/Desktop/ViralPackage/viralcorelib/lib64/python3.13/site-packages/telegram/ext/_updater.py:375> exception=NetworkError('httpx.ReadError: ')>", "correlation_id": "none", "exception": "Traceback (most recent call last):\n  File \"/home/technedict/Desktop/ViralPackage/viralcorelib/lib64/python3.13/site-packages/httpx/_transports/default.py\", line 101, in map_httpcore_exceptions\n  File \"/home/technedict/Desktop/ViralPackage/viralcorelib/lib64/python3.13/site-packages/httpx/_transports/default.py\", line 394, in handle_async_request\n  File \"/home/technedict/Desktop/ViralPackage/viralcorelib/lib64/python3.13/site-packages/httpcore/_async/connection_pool.py\", line 256, in handle_async_request\n  File \"/home/technedict/Desktop/ViralPackage/viralcorelib/lib64/python3.13/site-packages/httpcore/_async/connection_pool.py\", line 236, in handle_async_request\n  File \"/home/technedict/Desktop/ViralPackage/viralcorelib/lib64/python3.13/site-packages/httpcore/_async/connection.py\", line 103, in handle_async_request\n  File \"/home/technedict/Desktop/ViralPackage/viralcorelib/lib64/python3.13/site-packages/httpcore/_async/http11.py\", line 136, in handle_async_request\n  File \"/home/technedict/Desktop/ViralPackage/viralcorelib/lib64/python3.13/site-packages/httpcore/_async/http11.py\", line 106, in handle_async_request\n  File \"/home/technedict/Desktop/ViralPackage/viralcorelib/lib64/python3.13/site-packages/httpcore/_async/http11.py\", line 177, in _receive_response_headers\n  File \"/home/technedict/Desktop/ViralPackage/viralcorelib/lib64/python3.13/site-packages/httpcore/_async/http11.py\", line 217, in _receive_event\n  File \"/home/technedict/Desktop/ViralPackage/viralcorelib/lib64/python3.13/site-packages/httpcore/_backends/anyio.py\", line 32, in read\n  File \"/usr/lib64/python3.13/contextlib.py\", line 162, in __exit__\n  File \"/home/technedict/Desktop/ViralPackage/viralcorelib/lib64/python3.13/site-packages/httpcore/_exceptions.py\", line 14, in map_exceptions\nhttpcore.ReadError\n\nThe above exception was the direct cause of the following exception:\n\nTraceback (most recent call last):\n  File \"/home/technedict/Desktop/ViralPackage/viralcorelib/lib64/python3.13/site-packages/telegram/request/_httpxrequest.py\", line 276, in do_request\n  File \"/home/technedict/Desktop/ViralPackage/viralcorelib/lib64/python3.13/site-packages/httpx/_client.py\", line 1540, in request\n  File \"/home/technedict/Desktop/ViralPackage/viralcorelib/lib64/python3.13/site-packages/httpx/_client.py\", line 1629, in send\n  File \"/home/technedict/Desktop/ViralPackage/viralcorelib/lib64/python3.13/site-packages/httpx/_client.py\", line 1657, in _send_handling_auth\n  File \"/home/technedict/Desktop/ViralPackage/viralcorelib/lib64/python3.13/site-packages/httpx/_client.py\", line 1694, in _send_handling_redirects\n  File \"/home/technedict/Desktop/ViralPackage/viralcorelib/lib64/python3.13/site-packages/httpx/_client.py\", line 1730, in _send_single_request\n  File \"/home/technedict/Desktop/ViralPackage/viralcorelib/lib64/python3.13/site-packages/httpx/_transports/default.py\", line 393, in handle_async_request\n  File \"/usr/lib64/python3.13/contextlib.py\", line 162, in __exit__\n  File \"/home/technedict/Desktop/ViralPackage/viralcorelib/lib64/python3.13/site-packages/httpx/_transports/default.py\", line 118, in map_httpcore_exceptions\nhttpx.ReadError\n\nThe above exception was the direct cause of the following exception:\n\nTraceback (most recent call last):\n  File \"/home/technedict/Desktop/ViralPackage/viralcorelib/lib64/python3.13/site-packages/telegram/ext/_updater.py\", line 377, in polling_action_cb\n    updates = await self.bot.get_updates(\n              ^^^^^^^^^^^^^^^^^^^^^^^^^^^\n    ...<7 lines>...\n    )\n    ^\n  File \"/home/technedict/Desktop/ViralPackage/viralcorelib/lib64/python3.13/site-packages/telegram/ext/_extbot.py\", line 649, in get_updates\n    updates = await super().get_updates(\n              ^^^^^^^^^^^^^^^^^^^^^^^^^^\n    ...<9 lines>...\n    )\n    ^\n  File \"/home/technedict/Desktop/ViralPackage/viralcorelib/lib64/python3.13/site-packages/telegram/_bot.py\", line 4366, in get_updates\n    await self._post(\n    ^^^^^^^^^^^^^^^^^\n    ...<7 lines>...\n    ),\n    ^\n  File \"/home/technedict/Desktop/ViralPackage/viralcorelib/lib64/python3.13/site-packages/telegram/_bot.py\", line 623, in _post\n    return await self._do_post(\n           ^^^^^^^^^^^^^^^^^^^^\n    ...<6 lines>...\n    )\n    ^\n  File \"/home/technedict/Desktop/ViralPackage/viralcorelib/lib64/python3.13/site-packages/telegram/ext/_extbot.py\", line 355, in _do_post\n    return await super()._do_post(\n           ^^^^^^^^^^^^^^^^^^^^^^^\n    ...<6 lines>...\n    )\n    ^\n  File \"/home/technedict/Desktop/ViralPackage/viralcorelib/lib64/python3.13/site-packages/telegram/_bot.py\", line 652, in _do_post\n    result = await request.post(\n             ^^^^^^^^^^^^^^^^^^^\n    ...<6 lines>...\n    )\n    ^\n  File \"/home/technedict/Desktop/ViralPackage/viralcorelib/lib64/python3.13/site-packages/telegram/request/_baserequest.py\", line 201, in post\n    result = await self._request_wrapper(\n             ^^^^^^^^^^^^^^^^^^^^^^^^^^^^\n    ...<7 lines>...\n    )\n    ^\n  File \"/home/technedict/Desktop/ViralPackage/viralcorelib/lib64/python3.13/site-packages/telegram/request/_baserequest.py\", line 333, in _request_wrapper\n    code, payload = await self.do_request(\n                    ^^^^^^^^^^^^^^^^^^^^^^\n    ...<7 lines>...\n    )\n    ^\n  File \"/home/technedict/Desktop/ViralPackage/viralcorelib/lib64/python3.13/site-packages/telegram/request/_httpxrequest.py\", line 300, in do_request\ntelegram.error.NetworkError: httpx.ReadError: "}
{"timestamp": "2025-09-28T18:09:21.863026Z", "level": "WARNING", "module": "utils.graceful_shutdown", "message": "updater.shutdown() raised: This Updater is still running!", "correlation_id": "none"}
{"timestamp": "2025-09-28T18:09:21.864242Z", "level": "WARNING", "module": "utils.graceful_shutdown", "message": "Shutdown already in progress", "correlation_id": "none"}
{"timestamp": "2025-09-28T18:09:21.879785Z", "level": "ERROR", "module": "__main__", "message": "Error during app.shutdown()", "correlation_id": "none", "exception": "Traceback (most recent call last):\n  File \"/home/technedict/Desktop/ViralPackage/viralcore/main_viral_core_bot.py\", line 301, in main\n    await app.shutdown()\n  File \"/home/technedict/Desktop/ViralPackage/viralcorelib/lib64/python3.13/site-packages/telegram/ext/_application.py\", line 561, in shutdown\n    await self.updater.shutdown()\n  File \"/home/technedict/Desktop/ViralPackage/viralcorelib/lib64/python3.13/site-packages/telegram/ext/_updater.py\", line 204, in shutdown\n    raise RuntimeError(\"This Updater is still running!\")\nRuntimeError: This Updater is still running!"}
{"timestamp": "2025-09-28T18:09:21.968336Z", "level": "ERROR", "module": "asyncio", "message": "Task exception was never retrieved\nfuture: <Task finished name='Task-14' coro=<Updater._start_polling.<locals>.polling_action_cb() done, defined at /home/technedict/Desktop/ViralPackage/viralcorelib/lib64/python3.13/site-packages/telegram/ext/_updater.py:375> exception=NetworkError('httpx.ReadError: ')>", "correlation_id": "none", "exception": "Traceback (most recent call last):\n  File \"/home/technedict/Desktop/ViralPackage/viralcorelib/lib64/python3.13/site-packages/httpx/_transports/default.py\", line 101, in map_httpcore_exceptions\n  File \"/home/technedict/Desktop/ViralPackage/viralcorelib/lib64/python3.13/site-packages/httpx/_transports/default.py\", line 394, in handle_async_request\n  File \"/home/technedict/Desktop/ViralPackage/viralcorelib/lib64/python3.13/site-packages/httpcore/_async/connection_pool.py\", line 256, in handle_async_request\n  File \"/home/technedict/Desktop/ViralPackage/viralcorelib/lib64/python3.13/site-packages/httpcore/_async/connection_pool.py\", line 236, in handle_async_request\n  File \"/home/technedict/Desktop/ViralPackage/viralcorelib/lib64/python3.13/site-packages/httpcore/_async/connection.py\", line 103, in handle_async_request\n  File \"/home/technedict/Desktop/ViralPackage/viralcorelib/lib64/python3.13/site-packages/httpcore/_async/http11.py\", line 136, in handle_async_request\n  File \"/home/technedict/Desktop/ViralPackage/viralcorelib/lib64/python3.13/site-packages/httpcore/_async/http11.py\", line 106, in handle_async_request\n  File \"/home/technedict/Desktop/ViralPackage/viralcorelib/lib64/python3.13/site-packages/httpcore/_async/http11.py\", line 177, in _receive_response_headers\n  File \"/home/technedict/Desktop/ViralPackage/viralcorelib/lib64/python3.13/site-packages/httpcore/_async/http11.py\", line 217, in _receive_event\n  File \"/home/technedict/Desktop/ViralPackage/viralcorelib/lib64/python3.13/site-packages/httpcore/_backends/anyio.py\", line 32, in read\n  File \"/usr/lib64/python3.13/contextlib.py\", line 162, in __exit__\n  File \"/home/technedict/Desktop/ViralPackage/viralcorelib/lib64/python3.13/site-packages/httpcore/_exceptions.py\", line 14, in map_exceptions\nhttpcore.ReadError\n\nThe above exception was the direct cause of the following exception:\n\nTraceback (most recent call last):\n  File \"/home/technedict/Desktop/ViralPackage/viralcorelib/lib64/python3.13/site-packages/telegram/request/_httpxrequest.py\", line 276, in do_request\n  File \"/home/technedict/Desktop/ViralPackage/viralcorelib/lib64/python3.13/site-packages/httpx/_client.py\", line 1540, in request\n  File \"/home/technedict/Desktop/ViralPackage/viralcorelib/lib64/python3.13/site-packages/httpx/_client.py\", line 1629, in send\n  File \"/home/technedict/Desktop/ViralPackage/viralcorelib/lib64/python3.13/site-packages/httpx/_client.py\", line 1657, in _send_handling_auth\n  File \"/home/technedict/Desktop/ViralPackage/viralcorelib/lib64/python3.13/site-packages/httpx/_client.py\", line 1694, in _send_handling_redirects\n  File \"/home/technedict/Desktop/ViralPackage/viralcorelib/lib64/python3.13/site-packages/httpx/_client.py\", line 1730, in _send_single_request\n  File \"/home/technedict/Desktop/ViralPackage/viralcorelib/lib64/python3.13/site-packages/httpx/_transports/default.py\", line 393, in handle_async_request\n  File \"/usr/lib64/python3.13/contextlib.py\", line 162, in __exit__\n  File \"/home/technedict/Desktop/ViralPackage/viralcorelib/lib64/python3.13/site-packages/httpx/_transports/default.py\", line 118, in map_httpcore_exceptions\nhttpx.ReadError\n\nThe above exception was the direct cause of the following exception:\n\nTraceback (most recent call last):\n  File \"/home/technedict/Desktop/ViralPackage/viralcorelib/lib64/python3.13/site-packages/telegram/ext/_updater.py\", line 377, in polling_action_cb\n    updates = await self.bot.get_updates(\n              ^^^^^^^^^^^^^^^^^^^^^^^^^^^\n    ...<7 lines>...\n    )\n    ^\n  File \"/home/technedict/Desktop/ViralPackage/viralcorelib/lib64/python3.13/site-packages/telegram/ext/_extbot.py\", line 649, in get_updates\n  File \"/home/technedict/Desktop/ViralPackage/viralcorelib/lib64/python3.13/site-packages/telegram/_bot.py\", line 4366, in get_updates\n  File \"/home/technedict/Desktop/ViralPackage/viralcorelib/lib64/python3.13/site-packages/telegram/_bot.py\", line 623, in _post\n  File \"/home/technedict/Desktop/ViralPackage/viralcorelib/lib64/python3.13/site-packages/telegram/ext/_extbot.py\", line 355, in _do_post\n  File \"/home/technedict/Desktop/ViralPackage/viralcorelib/lib64/python3.13/site-packages/telegram/_bot.py\", line 652, in _do_post\n  File \"/home/technedict/Desktop/ViralPackage/viralcorelib/lib64/python3.13/site-packages/telegram/request/_baserequest.py\", line 201, in post\n  File \"/home/technedict/Desktop/ViralPackage/viralcorelib/lib64/python3.13/site-packages/telegram/request/_baserequest.py\", line 333, in _request_wrapper\n  File \"/home/technedict/Desktop/ViralPackage/viralcorelib/lib64/python3.13/site-packages/telegram/request/_httpxrequest.py\", line 300, in do_request\ntelegram.error.NetworkError: httpx.ReadError: "}
{"timestamp": "2025-09-28T18:09:27.645102Z", "level": "ERROR", "module": "telegram.ext.Application", "message": "No error handlers are registered, logging exception.", "correlation_id": "none", "exception": "Traceback (most recent call last):\n  File \"/home/technedict/Desktop/ViralPackage/viralcorelib/lib64/python3.13/site-packages/telegram/ext/_application.py\", line 1335, in process_update\n    await coroutine\n  File \"/home/technedict/Desktop/ViralPackage/viralcorelib/lib64/python3.13/site-packages/telegram/ext/_handlers/basehandler.py\", line 157, in handle_update\n    return await self.callback(update, context)\n           ^^^^^^^^^^^^^^^^^^^^^^^^^^^^^^^^^^^^\n  File \"/home/technedict/Desktop/ViralPackage/viralcore/handlers/admin_handlers.py\", line 187, in admin_panel_handler\n    await admin_withdrawals_menu_handler(update, context)\n  File \"/home/technedict/Desktop/ViralPackage/viralcore/handlers/admin_withdrawal_handlers.py\", line 117, in admin_withdrawals_menu_handler\n    msg = await query.message.reply_text(\n          ^^^^^^^^^^^^^^^^^^^^^^^^^^^^^^^\n    ...<3 lines>...\n    )\n    ^\n  File \"/home/technedict/Desktop/ViralPackage/viralcorelib/lib64/python3.13/site-packages/telegram/_message.py\", line 1762, in reply_text\n    return await self.get_bot().send_message(\n           ^^^^^^^^^^^^^^^^^^^^^^^^^^^^^^^^^^\n    ...<19 lines>...\n    )\n    ^\n  File \"/home/technedict/Desktop/ViralPackage/viralcorelib/lib64/python3.13/site-packages/telegram/ext/_extbot.py\", line 2909, in send_message\n    return await super().send_message(\n           ^^^^^^^^^^^^^^^^^^^^^^^^^^^\n    ...<20 lines>...\n    )\n    ^\n  File \"/home/technedict/Desktop/ViralPackage/viralcorelib/lib64/python3.13/site-packages/telegram/_bot.py\", line 1029, in send_message\n    return await self._send_message(\n           ^^^^^^^^^^^^^^^^^^^^^^^^^\n    ...<18 lines>...\n    )\n    ^\n  File \"/home/technedict/Desktop/ViralPackage/viralcorelib/lib64/python3.13/site-packages/telegram/ext/_extbot.py\", line 610, in _send_message\n    result = await super()._send_message(\n             ^^^^^^^^^^^^^^^^^^^^^^^^^^^^\n    ...<20 lines>...\n    )\n    ^\n  File \"/home/technedict/Desktop/ViralPackage/viralcorelib/lib64/python3.13/site-packages/telegram/_bot.py\", line 745, in _send_message\n    result = await self._post(\n             ^^^^^^^^^^^^^^^^^\n    ...<7 lines>...\n    )\n    ^\n  File \"/home/technedict/Desktop/ViralPackage/viralcorelib/lib64/python3.13/site-packages/telegram/_bot.py\", line 623, in _post\n    return await self._do_post(\n           ^^^^^^^^^^^^^^^^^^^^\n    ...<6 lines>...\n    )\n    ^\n  File \"/home/technedict/Desktop/ViralPackage/viralcorelib/lib64/python3.13/site-packages/telegram/ext/_extbot.py\", line 355, in _do_post\n    return await super()._do_post(\n           ^^^^^^^^^^^^^^^^^^^^^^^\n    ...<6 lines>...\n    )\n    ^\n  File \"/home/technedict/Desktop/ViralPackage/viralcorelib/lib64/python3.13/site-packages/telegram/_bot.py\", line 652, in _do_post\n    result = await request.post(\n             ^^^^^^^^^^^^^^^^^^^\n    ...<6 lines>...\n    )\n    ^\n  File \"/home/technedict/Desktop/ViralPackage/viralcorelib/lib64/python3.13/site-packages/telegram/request/_baserequest.py\", line 201, in post\n    result = await self._request_wrapper(\n             ^^^^^^^^^^^^^^^^^^^^^^^^^^^^\n    ...<7 lines>...\n    )\n    ^\n  File \"/home/technedict/Desktop/ViralPackage/viralcorelib/lib64/python3.13/site-packages/telegram/request/_baserequest.py\", line 382, in _request_wrapper\n    raise BadRequest(message)\ntelegram.error.BadRequest: Can't parse entities: character '(' is reserved and must be escaped with the preceding '\\'"}
{"timestamp": "2025-09-28T18:09:37.558624Z", "level": "ERROR", "module": "telegram.ext.Application", "message": "No error handlers are registered, logging exception.", "correlation_id": "none", "exception": "Traceback (most recent call last):\n  File \"/home/technedict/Desktop/ViralPackage/viralcorelib/lib64/python3.13/site-packages/telegram/ext/_application.py\", line 1335, in process_update\n    await coroutine\n  File \"/home/technedict/Desktop/ViralPackage/viralcorelib/lib64/python3.13/site-packages/telegram/ext/_handlers/basehandler.py\", line 157, in handle_update\n    return await self.callback(update, context)\n           ^^^^^^^^^^^^^^^^^^^^^^^^^^^^^^^^^^^^\n  File \"/home/technedict/Desktop/ViralPackage/viralcore/handlers/admin_handlers.py\", line 187, in admin_panel_handler\n    await admin_withdrawals_menu_handler(update, context)\n  File \"/home/technedict/Desktop/ViralPackage/viralcore/handlers/admin_withdrawal_handlers.py\", line 117, in admin_withdrawals_menu_handler\n    msg = await query.message.reply_text(\n          ^^^^^^^^^^^^^^^^^^^^^^^^^^^^^^^\n    ...<3 lines>...\n    )\n    ^\n  File \"/home/technedict/Desktop/ViralPackage/viralcorelib/lib64/python3.13/site-packages/telegram/_message.py\", line 1762, in reply_text\n    return await self.get_bot().send_message(\n           ^^^^^^^^^^^^^^^^^^^^^^^^^^^^^^^^^^\n    ...<19 lines>...\n    )\n    ^\n  File \"/home/technedict/Desktop/ViralPackage/viralcorelib/lib64/python3.13/site-packages/telegram/ext/_extbot.py\", line 2909, in send_message\n    return await super().send_message(\n           ^^^^^^^^^^^^^^^^^^^^^^^^^^^\n    ...<20 lines>...\n    )\n    ^\n  File \"/home/technedict/Desktop/ViralPackage/viralcorelib/lib64/python3.13/site-packages/telegram/_bot.py\", line 1029, in send_message\n    return await self._send_message(\n           ^^^^^^^^^^^^^^^^^^^^^^^^^\n    ...<18 lines>...\n    )\n    ^\n  File \"/home/technedict/Desktop/ViralPackage/viralcorelib/lib64/python3.13/site-packages/telegram/ext/_extbot.py\", line 610, in _send_message\n    result = await super()._send_message(\n             ^^^^^^^^^^^^^^^^^^^^^^^^^^^^\n    ...<20 lines>...\n    )\n    ^\n  File \"/home/technedict/Desktop/ViralPackage/viralcorelib/lib64/python3.13/site-packages/telegram/_bot.py\", line 745, in _send_message\n    result = await self._post(\n             ^^^^^^^^^^^^^^^^^\n    ...<7 lines>...\n    )\n    ^\n  File \"/home/technedict/Desktop/ViralPackage/viralcorelib/lib64/python3.13/site-packages/telegram/_bot.py\", line 623, in _post\n    return await self._do_post(\n           ^^^^^^^^^^^^^^^^^^^^\n    ...<6 lines>...\n    )\n    ^\n  File \"/home/technedict/Desktop/ViralPackage/viralcorelib/lib64/python3.13/site-packages/telegram/ext/_extbot.py\", line 355, in _do_post\n    return await super()._do_post(\n           ^^^^^^^^^^^^^^^^^^^^^^^\n    ...<6 lines>...\n    )\n    ^\n  File \"/home/technedict/Desktop/ViralPackage/viralcorelib/lib64/python3.13/site-packages/telegram/_bot.py\", line 652, in _do_post\n    result = await request.post(\n             ^^^^^^^^^^^^^^^^^^^\n    ...<6 lines>...\n    )\n    ^\n  File \"/home/technedict/Desktop/ViralPackage/viralcorelib/lib64/python3.13/site-packages/telegram/request/_baserequest.py\", line 201, in post\n    result = await self._request_wrapper(\n             ^^^^^^^^^^^^^^^^^^^^^^^^^^^^\n    ...<7 lines>...\n    )\n    ^\n  File \"/home/technedict/Desktop/ViralPackage/viralcorelib/lib64/python3.13/site-packages/telegram/request/_baserequest.py\", line 382, in _request_wrapper\n    raise BadRequest(message)\ntelegram.error.BadRequest: Can't parse entities: character '(' is reserved and must be escaped with the preceding '\\'"}
{"timestamp": "2025-09-28T18:10:16.935321Z", "level": "WARNING", "module": "utils.graceful_shutdown", "message": "updater.shutdown() raised: This Updater is still running!", "correlation_id": "none"}
{"timestamp": "2025-09-28T18:10:16.936714Z", "level": "WARNING", "module": "utils.graceful_shutdown", "message": "Shutdown already in progress", "correlation_id": "none"}
{"timestamp": "2025-09-28T18:10:16.951812Z", "level": "ERROR", "module": "__main__", "message": "Error during app.shutdown()", "correlation_id": "none", "exception": "Traceback (most recent call last):\n  File \"/home/technedict/Desktop/ViralPackage/viralcore/main_viral_core_bot.py\", line 301, in main\n    await app.shutdown()\n  File \"/home/technedict/Desktop/ViralPackage/viralcorelib/lib64/python3.13/site-packages/telegram/ext/_application.py\", line 561, in shutdown\n    await self.updater.shutdown()\n  File \"/home/technedict/Desktop/ViralPackage/viralcorelib/lib64/python3.13/site-packages/telegram/ext/_updater.py\", line 204, in shutdown\n    raise RuntimeError(\"This Updater is still running!\")\nRuntimeError: This Updater is still running!"}
{"timestamp": "2025-09-28T18:10:17.058681Z", "level": "ERROR", "module": "asyncio", "message": "Task exception was never retrieved\nfuture: <Task finished name='Task-16' coro=<Updater._start_polling.<locals>.polling_action_cb() done, defined at /home/technedict/Desktop/ViralPackage/viralcorelib/lib64/python3.13/site-packages/telegram/ext/_updater.py:375> exception=NetworkError('httpx.ReadError: ')>", "correlation_id": "none", "exception": "Traceback (most recent call last):\n  File \"/home/technedict/Desktop/ViralPackage/viralcorelib/lib64/python3.13/site-packages/httpx/_transports/default.py\", line 101, in map_httpcore_exceptions\n  File \"/home/technedict/Desktop/ViralPackage/viralcorelib/lib64/python3.13/site-packages/httpx/_transports/default.py\", line 394, in handle_async_request\n  File \"/home/technedict/Desktop/ViralPackage/viralcorelib/lib64/python3.13/site-packages/httpcore/_async/connection_pool.py\", line 256, in handle_async_request\n  File \"/home/technedict/Desktop/ViralPackage/viralcorelib/lib64/python3.13/site-packages/httpcore/_async/connection_pool.py\", line 236, in handle_async_request\n  File \"/home/technedict/Desktop/ViralPackage/viralcorelib/lib64/python3.13/site-packages/httpcore/_async/connection.py\", line 103, in handle_async_request\n  File \"/home/technedict/Desktop/ViralPackage/viralcorelib/lib64/python3.13/site-packages/httpcore/_async/http11.py\", line 136, in handle_async_request\n  File \"/home/technedict/Desktop/ViralPackage/viralcorelib/lib64/python3.13/site-packages/httpcore/_async/http11.py\", line 106, in handle_async_request\n  File \"/home/technedict/Desktop/ViralPackage/viralcorelib/lib64/python3.13/site-packages/httpcore/_async/http11.py\", line 177, in _receive_response_headers\n  File \"/home/technedict/Desktop/ViralPackage/viralcorelib/lib64/python3.13/site-packages/httpcore/_async/http11.py\", line 217, in _receive_event\n  File \"/home/technedict/Desktop/ViralPackage/viralcorelib/lib64/python3.13/site-packages/httpcore/_backends/anyio.py\", line 32, in read\n  File \"/usr/lib64/python3.13/contextlib.py\", line 162, in __exit__\n  File \"/home/technedict/Desktop/ViralPackage/viralcorelib/lib64/python3.13/site-packages/httpcore/_exceptions.py\", line 14, in map_exceptions\nhttpcore.ReadError\n\nThe above exception was the direct cause of the following exception:\n\nTraceback (most recent call last):\n  File \"/home/technedict/Desktop/ViralPackage/viralcorelib/lib64/python3.13/site-packages/telegram/request/_httpxrequest.py\", line 276, in do_request\n  File \"/home/technedict/Desktop/ViralPackage/viralcorelib/lib64/python3.13/site-packages/httpx/_client.py\", line 1540, in request\n  File \"/home/technedict/Desktop/ViralPackage/viralcorelib/lib64/python3.13/site-packages/httpx/_client.py\", line 1629, in send\n  File \"/home/technedict/Desktop/ViralPackage/viralcorelib/lib64/python3.13/site-packages/httpx/_client.py\", line 1657, in _send_handling_auth\n  File \"/home/technedict/Desktop/ViralPackage/viralcorelib/lib64/python3.13/site-packages/httpx/_client.py\", line 1694, in _send_handling_redirects\n  File \"/home/technedict/Desktop/ViralPackage/viralcorelib/lib64/python3.13/site-packages/httpx/_client.py\", line 1730, in _send_single_request\n  File \"/home/technedict/Desktop/ViralPackage/viralcorelib/lib64/python3.13/site-packages/httpx/_transports/default.py\", line 393, in handle_async_request\n  File \"/usr/lib64/python3.13/contextlib.py\", line 162, in __exit__\n  File \"/home/technedict/Desktop/ViralPackage/viralcorelib/lib64/python3.13/site-packages/httpx/_transports/default.py\", line 118, in map_httpcore_exceptions\nhttpx.ReadError\n\nThe above exception was the direct cause of the following exception:\n\nTraceback (most recent call last):\n  File \"/home/technedict/Desktop/ViralPackage/viralcorelib/lib64/python3.13/site-packages/telegram/ext/_updater.py\", line 377, in polling_action_cb\n    updates = await self.bot.get_updates(\n              ^^^^^^^^^^^^^^^^^^^^^^^^^^^\n    ...<7 lines>...\n    )\n    ^\n  File \"/home/technedict/Desktop/ViralPackage/viralcorelib/lib64/python3.13/site-packages/telegram/ext/_extbot.py\", line 649, in get_updates\n    updates = await super().get_updates(\n              ^^^^^^^^^^^^^^^^^^^^^^^^^^\n    ...<9 lines>...\n    )\n    ^\n  File \"/home/technedict/Desktop/ViralPackage/viralcorelib/lib64/python3.13/site-packages/telegram/_bot.py\", line 4366, in get_updates\n    await self._post(\n    ^^^^^^^^^^^^^^^^^\n    ...<7 lines>...\n    ),\n    ^\n  File \"/home/technedict/Desktop/ViralPackage/viralcorelib/lib64/python3.13/site-packages/telegram/_bot.py\", line 623, in _post\n    return await self._do_post(\n           ^^^^^^^^^^^^^^^^^^^^\n    ...<6 lines>...\n    )\n    ^\n  File \"/home/technedict/Desktop/ViralPackage/viralcorelib/lib64/python3.13/site-packages/telegram/ext/_extbot.py\", line 355, in _do_post\n    return await super()._do_post(\n           ^^^^^^^^^^^^^^^^^^^^^^^\n    ...<6 lines>...\n    )\n    ^\n  File \"/home/technedict/Desktop/ViralPackage/viralcorelib/lib64/python3.13/site-packages/telegram/_bot.py\", line 652, in _do_post\n    result = await request.post(\n             ^^^^^^^^^^^^^^^^^^^\n    ...<6 lines>...\n    )\n    ^\n  File \"/home/technedict/Desktop/ViralPackage/viralcorelib/lib64/python3.13/site-packages/telegram/request/_baserequest.py\", line 201, in post\n    result = await self._request_wrapper(\n             ^^^^^^^^^^^^^^^^^^^^^^^^^^^^\n    ...<7 lines>...\n    )\n    ^\n  File \"/home/technedict/Desktop/ViralPackage/viralcorelib/lib64/python3.13/site-packages/telegram/request/_baserequest.py\", line 333, in _request_wrapper\n    code, payload = await self.do_request(\n                    ^^^^^^^^^^^^^^^^^^^^^^\n    ...<7 lines>...\n    )\n    ^\n  File \"/home/technedict/Desktop/ViralPackage/viralcorelib/lib64/python3.13/site-packages/telegram/request/_httpxrequest.py\", line 300, in do_request\ntelegram.error.NetworkError: httpx.ReadError: "}
{"timestamp": "2025-09-28T18:10:56.031084Z", "level": "WARNING", "module": "utils.graceful_shutdown", "message": "updater.shutdown() raised: This Updater is still running!", "correlation_id": "none"}
{"timestamp": "2025-09-28T18:10:56.032215Z", "level": "WARNING", "module": "utils.graceful_shutdown", "message": "Shutdown already in progress", "correlation_id": "none"}
{"timestamp": "2025-09-28T18:10:56.049634Z", "level": "ERROR", "module": "__main__", "message": "Error during app.shutdown()", "correlation_id": "none", "exception": "Traceback (most recent call last):\n  File \"/home/technedict/Desktop/ViralPackage/viralcore/main_viral_core_bot.py\", line 301, in main\n    await app.shutdown()\n  File \"/home/technedict/Desktop/ViralPackage/viralcorelib/lib64/python3.13/site-packages/telegram/ext/_application.py\", line 561, in shutdown\n    await self.updater.shutdown()\n  File \"/home/technedict/Desktop/ViralPackage/viralcorelib/lib64/python3.13/site-packages/telegram/ext/_updater.py\", line 204, in shutdown\n    raise RuntimeError(\"This Updater is still running!\")\nRuntimeError: This Updater is still running!"}
{"timestamp": "2025-09-28T18:10:56.151474Z", "level": "ERROR", "module": "asyncio", "message": "Task exception was never retrieved\nfuture: <Task finished name='Task-12' coro=<Updater._start_polling.<locals>.polling_action_cb() done, defined at /home/technedict/Desktop/ViralPackage/viralcorelib/lib64/python3.13/site-packages/telegram/ext/_updater.py:375> exception=NetworkError('httpx.ReadError: ')>", "correlation_id": "none", "exception": "Traceback (most recent call last):\n  File \"/home/technedict/Desktop/ViralPackage/viralcorelib/lib64/python3.13/site-packages/httpx/_transports/default.py\", line 101, in map_httpcore_exceptions\n  File \"/home/technedict/Desktop/ViralPackage/viralcorelib/lib64/python3.13/site-packages/httpx/_transports/default.py\", line 394, in handle_async_request\n  File \"/home/technedict/Desktop/ViralPackage/viralcorelib/lib64/python3.13/site-packages/httpcore/_async/connection_pool.py\", line 256, in handle_async_request\n  File \"/home/technedict/Desktop/ViralPackage/viralcorelib/lib64/python3.13/site-packages/httpcore/_async/connection_pool.py\", line 236, in handle_async_request\n  File \"/home/technedict/Desktop/ViralPackage/viralcorelib/lib64/python3.13/site-packages/httpcore/_async/connection.py\", line 103, in handle_async_request\n  File \"/home/technedict/Desktop/ViralPackage/viralcorelib/lib64/python3.13/site-packages/httpcore/_async/http11.py\", line 136, in handle_async_request\n  File \"/home/technedict/Desktop/ViralPackage/viralcorelib/lib64/python3.13/site-packages/httpcore/_async/http11.py\", line 106, in handle_async_request\n  File \"/home/technedict/Desktop/ViralPackage/viralcorelib/lib64/python3.13/site-packages/httpcore/_async/http11.py\", line 177, in _receive_response_headers\n  File \"/home/technedict/Desktop/ViralPackage/viralcorelib/lib64/python3.13/site-packages/httpcore/_async/http11.py\", line 217, in _receive_event\n  File \"/home/technedict/Desktop/ViralPackage/viralcorelib/lib64/python3.13/site-packages/httpcore/_backends/anyio.py\", line 32, in read\n  File \"/usr/lib64/python3.13/contextlib.py\", line 162, in __exit__\n  File \"/home/technedict/Desktop/ViralPackage/viralcorelib/lib64/python3.13/site-packages/httpcore/_exceptions.py\", line 14, in map_exceptions\nhttpcore.ReadError\n\nThe above exception was the direct cause of the following exception:\n\nTraceback (most recent call last):\n  File \"/home/technedict/Desktop/ViralPackage/viralcorelib/lib64/python3.13/site-packages/telegram/request/_httpxrequest.py\", line 276, in do_request\n  File \"/home/technedict/Desktop/ViralPackage/viralcorelib/lib64/python3.13/site-packages/httpx/_client.py\", line 1540, in request\n  File \"/home/technedict/Desktop/ViralPackage/viralcorelib/lib64/python3.13/site-packages/httpx/_client.py\", line 1629, in send\n  File \"/home/technedict/Desktop/ViralPackage/viralcorelib/lib64/python3.13/site-packages/httpx/_client.py\", line 1657, in _send_handling_auth\n  File \"/home/technedict/Desktop/ViralPackage/viralcorelib/lib64/python3.13/site-packages/httpx/_client.py\", line 1694, in _send_handling_redirects\n  File \"/home/technedict/Desktop/ViralPackage/viralcorelib/lib64/python3.13/site-packages/httpx/_client.py\", line 1730, in _send_single_request\n  File \"/home/technedict/Desktop/ViralPackage/viralcorelib/lib64/python3.13/site-packages/httpx/_transports/default.py\", line 393, in handle_async_request\n  File \"/usr/lib64/python3.13/contextlib.py\", line 162, in __exit__\n  File \"/home/technedict/Desktop/ViralPackage/viralcorelib/lib64/python3.13/site-packages/httpx/_transports/default.py\", line 118, in map_httpcore_exceptions\nhttpx.ReadError\n\nThe above exception was the direct cause of the following exception:\n\nTraceback (most recent call last):\n  File \"/home/technedict/Desktop/ViralPackage/viralcorelib/lib64/python3.13/site-packages/telegram/ext/_updater.py\", line 377, in polling_action_cb\n    updates = await self.bot.get_updates(\n              ^^^^^^^^^^^^^^^^^^^^^^^^^^^\n    ...<7 lines>...\n    )\n    ^\n  File \"/home/technedict/Desktop/ViralPackage/viralcorelib/lib64/python3.13/site-packages/telegram/ext/_extbot.py\", line 649, in get_updates\n  File \"/home/technedict/Desktop/ViralPackage/viralcorelib/lib64/python3.13/site-packages/telegram/_bot.py\", line 4366, in get_updates\n  File \"/home/technedict/Desktop/ViralPackage/viralcorelib/lib64/python3.13/site-packages/telegram/_bot.py\", line 623, in _post\n  File \"/home/technedict/Desktop/ViralPackage/viralcorelib/lib64/python3.13/site-packages/telegram/ext/_extbot.py\", line 355, in _do_post\n  File \"/home/technedict/Desktop/ViralPackage/viralcorelib/lib64/python3.13/site-packages/telegram/_bot.py\", line 652, in _do_post\n  File \"/home/technedict/Desktop/ViralPackage/viralcorelib/lib64/python3.13/site-packages/telegram/request/_baserequest.py\", line 201, in post\n  File \"/home/technedict/Desktop/ViralPackage/viralcorelib/lib64/python3.13/site-packages/telegram/request/_baserequest.py\", line 333, in _request_wrapper\n  File \"/home/technedict/Desktop/ViralPackage/viralcorelib/lib64/python3.13/site-packages/telegram/request/_httpxrequest.py\", line 300, in do_request\ntelegram.error.NetworkError: httpx.ReadError: "}
{"timestamp": "2025-09-28T18:12:01.663993Z", "level": "ERROR", "module": "telegram.ext.Application", "message": "No error handlers are registered, logging exception.", "correlation_id": "none", "exception": "Traceback (most recent call last):\n  File \"/home/technedict/Desktop/ViralPackage/viralcorelib/lib64/python3.13/site-packages/telegram/ext/_application.py\", line 1335, in process_update\n    await coroutine\n  File \"/home/technedict/Desktop/ViralPackage/viralcorelib/lib64/python3.13/site-packages/telegram/ext/_handlers/basehandler.py\", line 157, in handle_update\n    return await self.callback(update, context)\n           ^^^^^^^^^^^^^^^^^^^^^^^^^^^^^^^^^^^^\n  File \"/home/technedict/Desktop/ViralPackage/viralcore/handlers/admin_handlers.py\", line 220, in admin_panel_handler\n    await admin_services_menu_handler(update, context)\n  File \"/home/technedict/Desktop/ViralPackage/viralcore/handlers/admin_service_handlers.py\", line 45, in admin_services_menu_handler\n    await query.edit_message_text(\n    ...<3 lines>...\n    )\n  File \"/home/technedict/Desktop/ViralPackage/viralcorelib/lib64/python3.13/site-packages/telegram/_callbackquery.py\", line 268, in edit_message_text\n    return await self._get_message().edit_text(\n           ^^^^^^^^^^^^^^^^^^^^^^^^^^^^^^^^^^^^\n    ...<11 lines>...\n    )\n    ^\n  File \"/home/technedict/Desktop/ViralPackage/viralcorelib/lib64/python3.13/site-packages/telegram/_message.py\", line 3659, in edit_text\n    return await self.get_bot().edit_message_text(\n           ^^^^^^^^^^^^^^^^^^^^^^^^^^^^^^^^^^^^^^^\n    ...<15 lines>...\n    )\n    ^\n  File \"/home/technedict/Desktop/ViralPackage/viralcorelib/lib64/python3.13/site-packages/telegram/ext/_extbot.py\", line 1664, in edit_message_text\n    return await super().edit_message_text(\n           ^^^^^^^^^^^^^^^^^^^^^^^^^^^^^^^^\n    ...<15 lines>...\n    )\n    ^\n  File \"/home/technedict/Desktop/ViralPackage/viralcorelib/lib64/python3.13/site-packages/telegram/_bot.py\", line 4047, in edit_message_text\n    return await self._send_message(\n           ^^^^^^^^^^^^^^^^^^^^^^^^^\n    ...<11 lines>...\n    )\n    ^\n  File \"/home/technedict/Desktop/ViralPackage/viralcorelib/lib64/python3.13/site-packages/telegram/ext/_extbot.py\", line 610, in _send_message\n    result = await super()._send_message(\n             ^^^^^^^^^^^^^^^^^^^^^^^^^^^^\n    ...<20 lines>...\n    )\n    ^\n  File \"/home/technedict/Desktop/ViralPackage/viralcorelib/lib64/python3.13/site-packages/telegram/_bot.py\", line 745, in _send_message\n    result = await self._post(\n             ^^^^^^^^^^^^^^^^^\n    ...<7 lines>...\n    )\n    ^\n  File \"/home/technedict/Desktop/ViralPackage/viralcorelib/lib64/python3.13/site-packages/telegram/_bot.py\", line 623, in _post\n    return await self._do_post(\n           ^^^^^^^^^^^^^^^^^^^^\n    ...<6 lines>...\n    )\n    ^\n  File \"/home/technedict/Desktop/ViralPackage/viralcorelib/lib64/python3.13/site-packages/telegram/ext/_extbot.py\", line 355, in _do_post\n    return await super()._do_post(\n           ^^^^^^^^^^^^^^^^^^^^^^^\n    ...<6 lines>...\n    )\n    ^\n  File \"/home/technedict/Desktop/ViralPackage/viralcorelib/lib64/python3.13/site-packages/telegram/_bot.py\", line 652, in _do_post\n    result = await request.post(\n             ^^^^^^^^^^^^^^^^^^^\n    ...<6 lines>...\n    )\n    ^\n  File \"/home/technedict/Desktop/ViralPackage/viralcorelib/lib64/python3.13/site-packages/telegram/request/_baserequest.py\", line 201, in post\n    result = await self._request_wrapper(\n             ^^^^^^^^^^^^^^^^^^^^^^^^^^^^\n    ...<7 lines>...\n    )\n    ^\n  File \"/home/technedict/Desktop/ViralPackage/viralcorelib/lib64/python3.13/site-packages/telegram/request/_baserequest.py\", line 382, in _request_wrapper\n    raise BadRequest(message)\ntelegram.error.BadRequest: There is no text in the message to edit"}
{"timestamp": "2025-09-28T18:18:47.555671Z", "level": "WARNING", "module": "utils.graceful_shutdown", "message": "updater.shutdown() raised: This Updater is still running!", "correlation_id": "none"}
{"timestamp": "2025-09-28T18:18:47.556778Z", "level": "WARNING", "module": "utils.graceful_shutdown", "message": "Shutdown already in progress", "correlation_id": "none"}
{"timestamp": "2025-09-28T18:18:47.571940Z", "level": "ERROR", "module": "__main__", "message": "Error during app.shutdown()", "correlation_id": "none", "exception": "Traceback (most recent call last):\n  File \"/home/technedict/Desktop/ViralPackage/viralcore/main_viral_core_bot.py\", line 301, in main\n    await app.shutdown()\n  File \"/home/technedict/Desktop/ViralPackage/viralcorelib/lib64/python3.13/site-packages/telegram/ext/_application.py\", line 561, in shutdown\n    await self.updater.shutdown()\n  File \"/home/technedict/Desktop/ViralPackage/viralcorelib/lib64/python3.13/site-packages/telegram/ext/_updater.py\", line 204, in shutdown\n    raise RuntimeError(\"This Updater is still running!\")\nRuntimeError: This Updater is still running!"}
{"timestamp": "2025-09-28T18:18:47.667194Z", "level": "ERROR", "module": "asyncio", "message": "Task exception was never retrieved\nfuture: <Task finished name='Task-100' coro=<Updater._start_polling.<locals>.polling_action_cb() done, defined at /home/technedict/Desktop/ViralPackage/viralcorelib/lib64/python3.13/site-packages/telegram/ext/_updater.py:375> exception=NetworkError('httpx.ReadError: ')>", "correlation_id": "none", "exception": "Traceback (most recent call last):\n  File \"/home/technedict/Desktop/ViralPackage/viralcorelib/lib64/python3.13/site-packages/httpx/_transports/default.py\", line 101, in map_httpcore_exceptions\n  File \"/home/technedict/Desktop/ViralPackage/viralcorelib/lib64/python3.13/site-packages/httpx/_transports/default.py\", line 394, in handle_async_request\n  File \"/home/technedict/Desktop/ViralPackage/viralcorelib/lib64/python3.13/site-packages/httpcore/_async/connection_pool.py\", line 256, in handle_async_request\n  File \"/home/technedict/Desktop/ViralPackage/viralcorelib/lib64/python3.13/site-packages/httpcore/_async/connection_pool.py\", line 236, in handle_async_request\n  File \"/home/technedict/Desktop/ViralPackage/viralcorelib/lib64/python3.13/site-packages/httpcore/_async/connection.py\", line 103, in handle_async_request\n  File \"/home/technedict/Desktop/ViralPackage/viralcorelib/lib64/python3.13/site-packages/httpcore/_async/http11.py\", line 136, in handle_async_request\n  File \"/home/technedict/Desktop/ViralPackage/viralcorelib/lib64/python3.13/site-packages/httpcore/_async/http11.py\", line 106, in handle_async_request\n  File \"/home/technedict/Desktop/ViralPackage/viralcorelib/lib64/python3.13/site-packages/httpcore/_async/http11.py\", line 177, in _receive_response_headers\n  File \"/home/technedict/Desktop/ViralPackage/viralcorelib/lib64/python3.13/site-packages/httpcore/_async/http11.py\", line 217, in _receive_event\n  File \"/home/technedict/Desktop/ViralPackage/viralcorelib/lib64/python3.13/site-packages/httpcore/_backends/anyio.py\", line 32, in read\n  File \"/usr/lib64/python3.13/contextlib.py\", line 162, in __exit__\n  File \"/home/technedict/Desktop/ViralPackage/viralcorelib/lib64/python3.13/site-packages/httpcore/_exceptions.py\", line 14, in map_exceptions\nhttpcore.ReadError\n\nThe above exception was the direct cause of the following exception:\n\nTraceback (most recent call last):\n  File \"/home/technedict/Desktop/ViralPackage/viralcorelib/lib64/python3.13/site-packages/telegram/request/_httpxrequest.py\", line 276, in do_request\n  File \"/home/technedict/Desktop/ViralPackage/viralcorelib/lib64/python3.13/site-packages/httpx/_client.py\", line 1540, in request\n  File \"/home/technedict/Desktop/ViralPackage/viralcorelib/lib64/python3.13/site-packages/httpx/_client.py\", line 1629, in send\n  File \"/home/technedict/Desktop/ViralPackage/viralcorelib/lib64/python3.13/site-packages/httpx/_client.py\", line 1657, in _send_handling_auth\n  File \"/home/technedict/Desktop/ViralPackage/viralcorelib/lib64/python3.13/site-packages/httpx/_client.py\", line 1694, in _send_handling_redirects\n  File \"/home/technedict/Desktop/ViralPackage/viralcorelib/lib64/python3.13/site-packages/httpx/_client.py\", line 1730, in _send_single_request\n  File \"/home/technedict/Desktop/ViralPackage/viralcorelib/lib64/python3.13/site-packages/httpx/_transports/default.py\", line 393, in handle_async_request\n  File \"/usr/lib64/python3.13/contextlib.py\", line 162, in __exit__\n  File \"/home/technedict/Desktop/ViralPackage/viralcorelib/lib64/python3.13/site-packages/httpx/_transports/default.py\", line 118, in map_httpcore_exceptions\nhttpx.ReadError\n\nThe above exception was the direct cause of the following exception:\n\nTraceback (most recent call last):\n  File \"/home/technedict/Desktop/ViralPackage/viralcorelib/lib64/python3.13/site-packages/telegram/ext/_updater.py\", line 377, in polling_action_cb\n    updates = await self.bot.get_updates(\n              ^^^^^^^^^^^^^^^^^^^^^^^^^^^\n    ...<7 lines>...\n    )\n    ^\n  File \"/home/technedict/Desktop/ViralPackage/viralcorelib/lib64/python3.13/site-packages/telegram/ext/_extbot.py\", line 649, in get_updates\n    updates = await super().get_updates(\n              ^^^^^^^^^^^^^^^^^^^^^^^^^^\n    ...<9 lines>...\n    )\n    ^\n  File \"/home/technedict/Desktop/ViralPackage/viralcorelib/lib64/python3.13/site-packages/telegram/_bot.py\", line 4366, in get_updates\n    await self._post(\n    ^^^^^^^^^^^^^^^^^\n    ...<7 lines>...\n    ),\n    ^\n  File \"/home/technedict/Desktop/ViralPackage/viralcorelib/lib64/python3.13/site-packages/telegram/_bot.py\", line 623, in _post\n    return await self._do_post(\n           ^^^^^^^^^^^^^^^^^^^^\n    ...<6 lines>...\n    )\n    ^\n  File \"/home/technedict/Desktop/ViralPackage/viralcorelib/lib64/python3.13/site-packages/telegram/ext/_extbot.py\", line 355, in _do_post\n    return await super()._do_post(\n           ^^^^^^^^^^^^^^^^^^^^^^^\n    ...<6 lines>...\n    )\n    ^\n  File \"/home/technedict/Desktop/ViralPackage/viralcorelib/lib64/python3.13/site-packages/telegram/_bot.py\", line 652, in _do_post\n    result = await request.post(\n             ^^^^^^^^^^^^^^^^^^^\n    ...<6 lines>...\n    )\n    ^\n  File \"/home/technedict/Desktop/ViralPackage/viralcorelib/lib64/python3.13/site-packages/telegram/request/_baserequest.py\", line 201, in post\n    result = await self._request_wrapper(\n             ^^^^^^^^^^^^^^^^^^^^^^^^^^^^\n    ...<7 lines>...\n    )\n    ^\n  File \"/home/technedict/Desktop/ViralPackage/viralcorelib/lib64/python3.13/site-packages/telegram/request/_baserequest.py\", line 333, in _request_wrapper\n    code, payload = await self.do_request(\n                    ^^^^^^^^^^^^^^^^^^^^^^\n    ...<7 lines>...\n    )\n    ^\n  File \"/home/technedict/Desktop/ViralPackage/viralcorelib/lib64/python3.13/site-packages/telegram/request/_httpxrequest.py\", line 300, in do_request\ntelegram.error.NetworkError: httpx.ReadError: "}
