{"timestamp": "2025-09-26T16:13:50.742708Z", "level": "WARNING", "module": "test", "message": "This should go to bot.log, debug.log and console", "correlation_id": "test123"}
{"timestamp": "2025-09-26T16:13:50.742923Z", "level": "ERROR", "module": "test", "message": "This should go to bot.log, debug.log and console", "correlation_id": "test123"}
{"timestamp": "2025-09-26T16:17:14.415175Z", "level": "ERROR", "module": "__main__", "message": "Error checking job table: no such table: jobs", "correlation_id": "none"}
{"timestamp": "2025-09-26T17:16:15.237358Z", "level": "ERROR", "module": "__main__", "message": "Unexpected error: no running event loop", "correlation_id": "none"}
{"timestamp": "2025-09-26T16:59:44.407548Z", "level": "ERROR", "module": "utils.messaging", "message": "Missing template variable: 'score'", "correlation_id": "none"}
{"timestamp": "2025-09-26T17:00:21.458901Z", "level": "ERROR", "module": "utils.messaging", "message": "Missing template variable: 'score'", "correlation_id": "none"}
{"timestamp": "2025-09-26T17:00:40.487731Z", "level": "ERROR", "module": "utils.messaging", "message": "Missing template variable: 'score'", "correlation_id": "none"}
{"timestamp": "2025-09-26T17:01:11.674865Z", "level": "ERROR", "module": "utils.messaging", "message": "Missing template variable: 'score'", "correlation_id": "none"}
{"timestamp": "2025-09-26T17:01:43.534904Z", "level": "ERROR", "module": "utils.messaging", "message": "Missing template variable: 'score'", "correlation_id": "none"}
{"timestamp": "2025-09-27T09:45:24.091883Z", "level": "ERROR", "module": "__main__", "message": "Unexpected error: There is no current event loop in thread 'MainThread'.", "correlation_id": "none"}
{"timestamp": "2025-09-27T09:51:21.948204Z", "level": "ERROR", "module": "__main__", "message": "Unexpected error: There is no current event loop in thread 'MainThread'.", "correlation_id": "none"}
{"timestamp": "2025-09-27T09:55:30.056816Z", "level": "ERROR", "module": "__main__", "message": "Unexpected error: Cannot close a running event loop", "correlation_id": "none"}
{"timestamp": "2025-09-27T10:03:11.538396Z", "level": "ERROR", "module": "__main__", "message": "Unexpected error while running the bot", "correlation_id": "none", "exception": "Traceback (most recent call last):\n  File \"/home/technedict/Desktop/ViralPackage/viralcorelib/lib64/python3.13/site-packages/telegram/ext/_application.py\", line 1042, in __run\n    loop.run_until_complete(self._bootstrap_initialize(max_retries=bootstrap_retries))\n    ~~~~~~~~~~~~~~~~~~~~~~~^^^^^^^^^^^^^^^^^^^^^^^^^^^^^^^^^^^^^^^^^^^^^^^^^^^^^^^^^^^\n  File \"/usr/lib64/python3.13/asyncio/base_events.py\", line 701, in run_until_complete\n    self._check_running()\n    ~~~~~~~~~~~~~~~~~~~^^\n  File \"/usr/lib64/python3.13/asyncio/base_events.py\", line 637, in _check_running\n    raise RuntimeError('This event loop is already running')\nRuntimeError: This event loop is already running\n\nDuring handling of the above exception, another exception occurred:\n\nTraceback (most recent call last):\n  File \"/home/technedict/Desktop/ViralPackage/viralcorelib/lib64/python3.13/site-packages/telegram/ext/_application.py\", line 1067, in __run\n    loop.run_until_complete(self.shutdown())\n    ~~~~~~~~~~~~~~~~~~~~~~~^^^^^^^^^^^^^^^^^\n  File \"/usr/lib64/python3.13/asyncio/base_events.py\", line 701, in run_until_complete\n    self._check_running()\n    ~~~~~~~~~~~~~~~~~~~^^\n  File \"/usr/lib64/python3.13/asyncio/base_events.py\", line 637, in _check_running\n    raise RuntimeError('This event loop is already running')\nRuntimeError: This event loop is already running\n\nDuring handling of the above exception, another exception occurred:\n\nTraceback (most recent call last):\n  File \"/home/technedict/Desktop/ViralPackage/viralcore/main_viral_core_bot.py\", line 185, in main\n    await app.run_polling()\n          ~~~~~~~~~~~~~~~^^\n  File \"/home/technedict/Desktop/ViralPackage/viralcorelib/lib64/python3.13/site-packages/telegram/ext/_application.py\", line 832, in run_polling\n    return self.__run(\n           ~~~~~~~~~~^\n        updater_coroutine=self.updater.start_polling(\n        ^^^^^^^^^^^^^^^^^^^^^^^^^^^^^^^^^^^^^^^^^^^^^\n    ...<9 lines>...\n        close_loop=close_loop,\n        ^^^^^^^^^^^^^^^^^^^^^^\n    )\n    ^\n  File \"/home/technedict/Desktop/ViralPackage/viralcorelib/lib64/python3.13/site-packages/telegram/ext/_application.py\", line 1072, in __run\n    loop.close()\n    ~~~~~~~~~~^^\n  File \"/usr/lib64/python3.13/asyncio/unix_events.py\", line 70, in close\n    super().close()\n    ~~~~~~~~~~~~~^^\n  File \"/usr/lib64/python3.13/asyncio/selector_events.py\", line 101, in close\n    raise RuntimeError(\"Cannot close a running event loop\")\nRuntimeError: Cannot close a running event loop"}
{"timestamp": "2025-09-27T10:05:40.530947Z", "level": "ERROR", "module": "telegram.ext.Application", "message": "No error handlers are registered, logging exception.", "correlation_id": "none", "exception": "Traceback (most recent call last):\n  File \"/home/technedict/Desktop/ViralPackage/viralcorelib/lib64/python3.13/site-packages/telegram/ext/_application.py\", line 1298, in process_update\n    await coroutine\n  File \"/home/technedict/Desktop/ViralPackage/viralcorelib/lib64/python3.13/site-packages/telegram/ext/_handlers/basehandler.py\", line 158, in handle_update\n    return await self.callback(update, context)\n           ^^^^^^^^^^^^^^^^^^^^^^^^^^^^^^^^^^^^\n  File \"/home/technedict/Desktop/ViralPackage/viralcore/handlers/message_handler.py\", line 11, in message_router\n    flags.get(\"awaiting_broadcast\"),\n    ^^^^^^^^^\nAttributeError: 'NoneType' object has no attribute 'get'"}
{"timestamp": "2025-09-27T10:05:40.534973Z", "level": "ERROR", "module": "telegram.ext.Application", "message": "No error handlers are registered, logging exception.", "correlation_id": "none", "exception": "Traceback (most recent call last):\n  File \"/home/technedict/Desktop/ViralPackage/viralcorelib/lib64/python3.13/site-packages/telegram/ext/_application.py\", line 1298, in process_update\n    await coroutine\n  File \"/home/technedict/Desktop/ViralPackage/viralcorelib/lib64/python3.13/site-packages/telegram/ext/_handlers/basehandler.py\", line 158, in handle_update\n    return await self.callback(update, context)\n           ^^^^^^^^^^^^^^^^^^^^^^^^^^^^^^^^^^^^\n  File \"/home/technedict/Desktop/ViralPackage/viralcore/handlers/message_handler.py\", line 11, in message_router\n    flags.get(\"awaiting_broadcast\"),\n    ^^^^^^^^^\nAttributeError: 'NoneType' object has no attribute 'get'"}
{"timestamp": "2025-09-27T10:05:40.539179Z", "level": "ERROR", "module": "telegram.ext.Application", "message": "No error handlers are registered, logging exception.", "correlation_id": "none", "exception": "Traceback (most recent call last):\n  File \"/home/technedict/Desktop/ViralPackage/viralcorelib/lib64/python3.13/site-packages/telegram/ext/_application.py\", line 1298, in process_update\n    await coroutine\n  File \"/home/technedict/Desktop/ViralPackage/viralcorelib/lib64/python3.13/site-packages/telegram/ext/_handlers/basehandler.py\", line 158, in handle_update\n    return await self.callback(update, context)\n           ^^^^^^^^^^^^^^^^^^^^^^^^^^^^^^^^^^^^\n  File \"/home/technedict/Desktop/ViralPackage/viralcore/handlers/message_handler.py\", line 11, in message_router\n    flags.get(\"awaiting_broadcast\"),\n    ^^^^^^^^^\nAttributeError: 'NoneType' object has no attribute 'get'"}
{"timestamp": "2025-09-27T10:05:40.543199Z", "level": "ERROR", "module": "telegram.ext.Application", "message": "No error handlers are registered, logging exception.", "correlation_id": "none", "exception": "Traceback (most recent call last):\n  File \"/home/technedict/Desktop/ViralPackage/viralcorelib/lib64/python3.13/site-packages/telegram/ext/_application.py\", line 1298, in process_update\n    await coroutine\n  File \"/home/technedict/Desktop/ViralPackage/viralcorelib/lib64/python3.13/site-packages/telegram/ext/_handlers/basehandler.py\", line 158, in handle_update\n    return await self.callback(update, context)\n           ^^^^^^^^^^^^^^^^^^^^^^^^^^^^^^^^^^^^\n  File \"/home/technedict/Desktop/ViralPackage/viralcore/handlers/message_handler.py\", line 11, in message_router\n    flags.get(\"awaiting_broadcast\"),\n    ^^^^^^^^^\nAttributeError: 'NoneType' object has no attribute 'get'"}
{"timestamp": "2025-09-27T10:05:40.547248Z", "level": "ERROR", "module": "telegram.ext.Application", "message": "No error handlers are registered, logging exception.", "correlation_id": "none", "exception": "Traceback (most recent call last):\n  File \"/home/technedict/Desktop/ViralPackage/viralcorelib/lib64/python3.13/site-packages/telegram/ext/_application.py\", line 1298, in process_update\n    await coroutine\n  File \"/home/technedict/Desktop/ViralPackage/viralcorelib/lib64/python3.13/site-packages/telegram/ext/_handlers/basehandler.py\", line 158, in handle_update\n    return await self.callback(update, context)\n           ^^^^^^^^^^^^^^^^^^^^^^^^^^^^^^^^^^^^\n  File \"/home/technedict/Desktop/ViralPackage/viralcore/handlers/message_handler.py\", line 11, in message_router\n    flags.get(\"awaiting_broadcast\"),\n    ^^^^^^^^^\nAttributeError: 'NoneType' object has no attribute 'get'"}
{"timestamp": "2025-09-27T10:05:40.551888Z", "level": "ERROR", "module": "telegram.ext.Application", "message": "No error handlers are registered, logging exception.", "correlation_id": "none", "exception": "Traceback (most recent call last):\n  File \"/home/technedict/Desktop/ViralPackage/viralcorelib/lib64/python3.13/site-packages/telegram/ext/_application.py\", line 1298, in process_update\n    await coroutine\n  File \"/home/technedict/Desktop/ViralPackage/viralcorelib/lib64/python3.13/site-packages/telegram/ext/_handlers/basehandler.py\", line 158, in handle_update\n    return await self.callback(update, context)\n           ^^^^^^^^^^^^^^^^^^^^^^^^^^^^^^^^^^^^\n  File \"/home/technedict/Desktop/ViralPackage/viralcore/handlers/message_handler.py\", line 11, in message_router\n    flags.get(\"awaiting_broadcast\"),\n    ^^^^^^^^^\nAttributeError: 'NoneType' object has no attribute 'get'"}
{"timestamp": "2025-09-27T10:05:40.556255Z", "level": "ERROR", "module": "telegram.ext.Application", "message": "No error handlers are registered, logging exception.", "correlation_id": "none", "exception": "Traceback (most recent call last):\n  File \"/home/technedict/Desktop/ViralPackage/viralcorelib/lib64/python3.13/site-packages/telegram/ext/_application.py\", line 1298, in process_update\n    await coroutine\n  File \"/home/technedict/Desktop/ViralPackage/viralcorelib/lib64/python3.13/site-packages/telegram/ext/_handlers/basehandler.py\", line 158, in handle_update\n    return await self.callback(update, context)\n           ^^^^^^^^^^^^^^^^^^^^^^^^^^^^^^^^^^^^\n  File \"/home/technedict/Desktop/ViralPackage/viralcore/handlers/message_handler.py\", line 11, in message_router\n    flags.get(\"awaiting_broadcast\"),\n    ^^^^^^^^^\nAttributeError: 'NoneType' object has no attribute 'get'"}
{"timestamp": "2025-09-27T10:05:40.560928Z", "level": "ERROR", "module": "telegram.ext.Application", "message": "No error handlers are registered, logging exception.", "correlation_id": "none", "exception": "Traceback (most recent call last):\n  File \"/home/technedict/Desktop/ViralPackage/viralcorelib/lib64/python3.13/site-packages/telegram/ext/_application.py\", line 1298, in process_update\n    await coroutine\n  File \"/home/technedict/Desktop/ViralPackage/viralcorelib/lib64/python3.13/site-packages/telegram/ext/_handlers/basehandler.py\", line 158, in handle_update\n    return await self.callback(update, context)\n           ^^^^^^^^^^^^^^^^^^^^^^^^^^^^^^^^^^^^\n  File \"/home/technedict/Desktop/ViralPackage/viralcore/handlers/message_handler.py\", line 11, in message_router\n    flags.get(\"awaiting_broadcast\"),\n    ^^^^^^^^^\nAttributeError: 'NoneType' object has no attribute 'get'"}
{"timestamp": "2025-09-27T10:05:40.565525Z", "level": "ERROR", "module": "telegram.ext.Application", "message": "No error handlers are registered, logging exception.", "correlation_id": "none", "exception": "Traceback (most recent call last):\n  File \"/home/technedict/Desktop/ViralPackage/viralcorelib/lib64/python3.13/site-packages/telegram/ext/_application.py\", line 1298, in process_update\n    await coroutine\n  File \"/home/technedict/Desktop/ViralPackage/viralcorelib/lib64/python3.13/site-packages/telegram/ext/_handlers/basehandler.py\", line 158, in handle_update\n    return await self.callback(update, context)\n           ^^^^^^^^^^^^^^^^^^^^^^^^^^^^^^^^^^^^\n  File \"/home/technedict/Desktop/ViralPackage/viralcore/handlers/message_handler.py\", line 11, in message_router\n    flags.get(\"awaiting_broadcast\"),\n    ^^^^^^^^^\nAttributeError: 'NoneType' object has no attribute 'get'"}
{"timestamp": "2025-09-27T10:05:40.569987Z", "level": "ERROR", "module": "telegram.ext.Application", "message": "No error handlers are registered, logging exception.", "correlation_id": "none", "exception": "Traceback (most recent call last):\n  File \"/home/technedict/Desktop/ViralPackage/viralcorelib/lib64/python3.13/site-packages/telegram/ext/_application.py\", line 1298, in process_update\n    await coroutine\n  File \"/home/technedict/Desktop/ViralPackage/viralcorelib/lib64/python3.13/site-packages/telegram/ext/_handlers/basehandler.py\", line 158, in handle_update\n    return await self.callback(update, context)\n           ^^^^^^^^^^^^^^^^^^^^^^^^^^^^^^^^^^^^\n  File \"/home/technedict/Desktop/ViralPackage/viralcore/handlers/message_handler.py\", line 11, in message_router\n    flags.get(\"awaiting_broadcast\"),\n    ^^^^^^^^^\nAttributeError: 'NoneType' object has no attribute 'get'"}
{"timestamp": "2025-09-27T10:05:40.575467Z", "level": "ERROR", "module": "telegram.ext.Application", "message": "No error handlers are registered, logging exception.", "correlation_id": "none", "exception": "Traceback (most recent call last):\n  File \"/home/technedict/Desktop/ViralPackage/viralcorelib/lib64/python3.13/site-packages/telegram/ext/_application.py\", line 1298, in process_update\n    await coroutine\n  File \"/home/technedict/Desktop/ViralPackage/viralcorelib/lib64/python3.13/site-packages/telegram/ext/_handlers/basehandler.py\", line 158, in handle_update\n    return await self.callback(update, context)\n           ^^^^^^^^^^^^^^^^^^^^^^^^^^^^^^^^^^^^\n  File \"/home/technedict/Desktop/ViralPackage/viralcore/handlers/message_handler.py\", line 11, in message_router\n    flags.get(\"awaiting_broadcast\"),\n    ^^^^^^^^^\nAttributeError: 'NoneType' object has no attribute 'get'"}
{"timestamp": "2025-09-27T10:05:40.580365Z", "level": "ERROR", "module": "telegram.ext.Application", "message": "No error handlers are registered, logging exception.", "correlation_id": "none", "exception": "Traceback (most recent call last):\n  File \"/home/technedict/Desktop/ViralPackage/viralcorelib/lib64/python3.13/site-packages/telegram/ext/_application.py\", line 1298, in process_update\n    await coroutine\n  File \"/home/technedict/Desktop/ViralPackage/viralcorelib/lib64/python3.13/site-packages/telegram/ext/_handlers/basehandler.py\", line 158, in handle_update\n    return await self.callback(update, context)\n           ^^^^^^^^^^^^^^^^^^^^^^^^^^^^^^^^^^^^\n  File \"/home/technedict/Desktop/ViralPackage/viralcore/handlers/message_handler.py\", line 11, in message_router\n    flags.get(\"awaiting_broadcast\"),\n    ^^^^^^^^^\nAttributeError: 'NoneType' object has no attribute 'get'"}
{"timestamp": "2025-09-27T10:05:40.584691Z", "level": "ERROR", "module": "telegram.ext.Application", "message": "No error handlers are registered, logging exception.", "correlation_id": "none", "exception": "Traceback (most recent call last):\n  File \"/home/technedict/Desktop/ViralPackage/viralcorelib/lib64/python3.13/site-packages/telegram/ext/_application.py\", line 1298, in process_update\n    await coroutine\n  File \"/home/technedict/Desktop/ViralPackage/viralcorelib/lib64/python3.13/site-packages/telegram/ext/_handlers/basehandler.py\", line 158, in handle_update\n    return await self.callback(update, context)\n           ^^^^^^^^^^^^^^^^^^^^^^^^^^^^^^^^^^^^\n  File \"/home/technedict/Desktop/ViralPackage/viralcore/handlers/message_handler.py\", line 11, in message_router\n    flags.get(\"awaiting_broadcast\"),\n    ^^^^^^^^^\nAttributeError: 'NoneType' object has no attribute 'get'"}
{"timestamp": "2025-09-27T10:05:40.591255Z", "level": "ERROR", "module": "telegram.ext.Application", "message": "No error handlers are registered, logging exception.", "correlation_id": "none", "exception": "Traceback (most recent call last):\n  File \"/home/technedict/Desktop/ViralPackage/viralcorelib/lib64/python3.13/site-packages/telegram/ext/_application.py\", line 1298, in process_update\n    await coroutine\n  File \"/home/technedict/Desktop/ViralPackage/viralcorelib/lib64/python3.13/site-packages/telegram/ext/_handlers/basehandler.py\", line 158, in handle_update\n    return await self.callback(update, context)\n           ^^^^^^^^^^^^^^^^^^^^^^^^^^^^^^^^^^^^\n  File \"/home/technedict/Desktop/ViralPackage/viralcore/handlers/message_handler.py\", line 11, in message_router\n    flags.get(\"awaiting_broadcast\"),\n    ^^^^^^^^^\nAttributeError: 'NoneType' object has no attribute 'get'"}
{"timestamp": "2025-09-27T10:05:40.596763Z", "level": "ERROR", "module": "telegram.ext.Application", "message": "No error handlers are registered, logging exception.", "correlation_id": "none", "exception": "Traceback (most recent call last):\n  File \"/home/technedict/Desktop/ViralPackage/viralcorelib/lib64/python3.13/site-packages/telegram/ext/_application.py\", line 1298, in process_update\n    await coroutine\n  File \"/home/technedict/Desktop/ViralPackage/viralcorelib/lib64/python3.13/site-packages/telegram/ext/_handlers/basehandler.py\", line 158, in handle_update\n    return await self.callback(update, context)\n           ^^^^^^^^^^^^^^^^^^^^^^^^^^^^^^^^^^^^\n  File \"/home/technedict/Desktop/ViralPackage/viralcore/handlers/message_handler.py\", line 11, in message_router\n    flags.get(\"awaiting_broadcast\"),\n    ^^^^^^^^^\nAttributeError: 'NoneType' object has no attribute 'get'"}
{"timestamp": "2025-09-27T10:05:40.601658Z", "level": "ERROR", "module": "telegram.ext.Application", "message": "No error handlers are registered, logging exception.", "correlation_id": "none", "exception": "Traceback (most recent call last):\n  File \"/home/technedict/Desktop/ViralPackage/viralcorelib/lib64/python3.13/site-packages/telegram/ext/_application.py\", line 1298, in process_update\n    await coroutine\n  File \"/home/technedict/Desktop/ViralPackage/viralcorelib/lib64/python3.13/site-packages/telegram/ext/_handlers/basehandler.py\", line 158, in handle_update\n    return await self.callback(update, context)\n           ^^^^^^^^^^^^^^^^^^^^^^^^^^^^^^^^^^^^\n  File \"/home/technedict/Desktop/ViralPackage/viralcore/handlers/message_handler.py\", line 11, in message_router\n    flags.get(\"awaiting_broadcast\"),\n    ^^^^^^^^^\nAttributeError: 'NoneType' object has no attribute 'get'"}
{"timestamp": "2025-09-27T10:05:40.606307Z", "level": "ERROR", "module": "telegram.ext.Application", "message": "No error handlers are registered, logging exception.", "correlation_id": "none", "exception": "Traceback (most recent call last):\n  File \"/home/technedict/Desktop/ViralPackage/viralcorelib/lib64/python3.13/site-packages/telegram/ext/_application.py\", line 1298, in process_update\n    await coroutine\n  File \"/home/technedict/Desktop/ViralPackage/viralcorelib/lib64/python3.13/site-packages/telegram/ext/_handlers/basehandler.py\", line 158, in handle_update\n    return await self.callback(update, context)\n           ^^^^^^^^^^^^^^^^^^^^^^^^^^^^^^^^^^^^\n  File \"/home/technedict/Desktop/ViralPackage/viralcore/handlers/message_handler.py\", line 11, in message_router\n    flags.get(\"awaiting_broadcast\"),\n    ^^^^^^^^^\nAttributeError: 'NoneType' object has no attribute 'get'"}
{"timestamp": "2025-09-27T10:05:40.611356Z", "level": "ERROR", "module": "telegram.ext.Application", "message": "No error handlers are registered, logging exception.", "correlation_id": "none", "exception": "Traceback (most recent call last):\n  File \"/home/technedict/Desktop/ViralPackage/viralcorelib/lib64/python3.13/site-packages/telegram/ext/_application.py\", line 1298, in process_update\n    await coroutine\n  File \"/home/technedict/Desktop/ViralPackage/viralcorelib/lib64/python3.13/site-packages/telegram/ext/_handlers/basehandler.py\", line 158, in handle_update\n    return await self.callback(update, context)\n           ^^^^^^^^^^^^^^^^^^^^^^^^^^^^^^^^^^^^\n  File \"/home/technedict/Desktop/ViralPackage/viralcore/handlers/message_handler.py\", line 11, in message_router\n    flags.get(\"awaiting_broadcast\"),\n    ^^^^^^^^^\nAttributeError: 'NoneType' object has no attribute 'get'"}
{"timestamp": "2025-09-27T10:05:40.617067Z", "level": "ERROR", "module": "telegram.ext.Application", "message": "No error handlers are registered, logging exception.", "correlation_id": "none", "exception": "Traceback (most recent call last):\n  File \"/home/technedict/Desktop/ViralPackage/viralcorelib/lib64/python3.13/site-packages/telegram/ext/_application.py\", line 1298, in process_update\n    await coroutine\n  File \"/home/technedict/Desktop/ViralPackage/viralcorelib/lib64/python3.13/site-packages/telegram/ext/_handlers/basehandler.py\", line 158, in handle_update\n    return await self.callback(update, context)\n           ^^^^^^^^^^^^^^^^^^^^^^^^^^^^^^^^^^^^\n  File \"/home/technedict/Desktop/ViralPackage/viralcore/handlers/message_handler.py\", line 11, in message_router\n    flags.get(\"awaiting_broadcast\"),\n    ^^^^^^^^^\nAttributeError: 'NoneType' object has no attribute 'get'"}
{"timestamp": "2025-09-27T10:05:40.623848Z", "level": "ERROR", "module": "telegram.ext.Application", "message": "No error handlers are registered, logging exception.", "correlation_id": "none", "exception": "Traceback (most recent call last):\n  File \"/home/technedict/Desktop/ViralPackage/viralcorelib/lib64/python3.13/site-packages/telegram/ext/_application.py\", line 1298, in process_update\n    await coroutine\n  File \"/home/technedict/Desktop/ViralPackage/viralcorelib/lib64/python3.13/site-packages/telegram/ext/_handlers/basehandler.py\", line 158, in handle_update\n    return await self.callback(update, context)\n           ^^^^^^^^^^^^^^^^^^^^^^^^^^^^^^^^^^^^\n  File \"/home/technedict/Desktop/ViralPackage/viralcore/handlers/message_handler.py\", line 11, in message_router\n    flags.get(\"awaiting_broadcast\"),\n    ^^^^^^^^^\nAttributeError: 'NoneType' object has no attribute 'get'"}
{"timestamp": "2025-09-27T10:05:40.629496Z", "level": "ERROR", "module": "telegram.ext.Application", "message": "No error handlers are registered, logging exception.", "correlation_id": "none", "exception": "Traceback (most recent call last):\n  File \"/home/technedict/Desktop/ViralPackage/viralcorelib/lib64/python3.13/site-packages/telegram/ext/_application.py\", line 1298, in process_update\n    await coroutine\n  File \"/home/technedict/Desktop/ViralPackage/viralcorelib/lib64/python3.13/site-packages/telegram/ext/_handlers/basehandler.py\", line 158, in handle_update\n    return await self.callback(update, context)\n           ^^^^^^^^^^^^^^^^^^^^^^^^^^^^^^^^^^^^\n  File \"/home/technedict/Desktop/ViralPackage/viralcore/handlers/message_handler.py\", line 11, in message_router\n    flags.get(\"awaiting_broadcast\"),\n    ^^^^^^^^^\nAttributeError: 'NoneType' object has no attribute 'get'"}
{"timestamp": "2025-09-27T10:05:40.634115Z", "level": "ERROR", "module": "telegram.ext.Application", "message": "No error handlers are registered, logging exception.", "correlation_id": "none", "exception": "Traceback (most recent call last):\n  File \"/home/technedict/Desktop/ViralPackage/viralcorelib/lib64/python3.13/site-packages/telegram/ext/_application.py\", line 1298, in process_update\n    await coroutine\n  File \"/home/technedict/Desktop/ViralPackage/viralcorelib/lib64/python3.13/site-packages/telegram/ext/_handlers/basehandler.py\", line 158, in handle_update\n    return await self.callback(update, context)\n           ^^^^^^^^^^^^^^^^^^^^^^^^^^^^^^^^^^^^\n  File \"/home/technedict/Desktop/ViralPackage/viralcore/handlers/message_handler.py\", line 11, in message_router\n    flags.get(\"awaiting_broadcast\"),\n    ^^^^^^^^^\nAttributeError: 'NoneType' object has no attribute 'get'"}
{"timestamp": "2025-09-27T10:05:40.639896Z", "level": "ERROR", "module": "telegram.ext.Application", "message": "No error handlers are registered, logging exception.", "correlation_id": "none", "exception": "Traceback (most recent call last):\n  File \"/home/technedict/Desktop/ViralPackage/viralcorelib/lib64/python3.13/site-packages/telegram/ext/_application.py\", line 1298, in process_update\n    await coroutine\n  File \"/home/technedict/Desktop/ViralPackage/viralcorelib/lib64/python3.13/site-packages/telegram/ext/_handlers/basehandler.py\", line 158, in handle_update\n    return await self.callback(update, context)\n           ^^^^^^^^^^^^^^^^^^^^^^^^^^^^^^^^^^^^\n  File \"/home/technedict/Desktop/ViralPackage/viralcore/handlers/message_handler.py\", line 11, in message_router\n    flags.get(\"awaiting_broadcast\"),\n    ^^^^^^^^^\nAttributeError: 'NoneType' object has no attribute 'get'"}
{"timestamp": "2025-09-27T10:05:40.646784Z", "level": "ERROR", "module": "telegram.ext.Application", "message": "No error handlers are registered, logging exception.", "correlation_id": "none", "exception": "Traceback (most recent call last):\n  File \"/home/technedict/Desktop/ViralPackage/viralcorelib/lib64/python3.13/site-packages/telegram/ext/_application.py\", line 1298, in process_update\n    await coroutine\n  File \"/home/technedict/Desktop/ViralPackage/viralcorelib/lib64/python3.13/site-packages/telegram/ext/_handlers/basehandler.py\", line 158, in handle_update\n    return await self.callback(update, context)\n           ^^^^^^^^^^^^^^^^^^^^^^^^^^^^^^^^^^^^\n  File \"/home/technedict/Desktop/ViralPackage/viralcore/handlers/message_handler.py\", line 11, in message_router\n    flags.get(\"awaiting_broadcast\"),\n    ^^^^^^^^^\nAttributeError: 'NoneType' object has no attribute 'get'"}
{"timestamp": "2025-09-27T10:05:40.651067Z", "level": "ERROR", "module": "telegram.ext.Application", "message": "No error handlers are registered, logging exception.", "correlation_id": "none", "exception": "Traceback (most recent call last):\n  File \"/home/technedict/Desktop/ViralPackage/viralcorelib/lib64/python3.13/site-packages/telegram/ext/_application.py\", line 1298, in process_update\n    await coroutine\n  File \"/home/technedict/Desktop/ViralPackage/viralcorelib/lib64/python3.13/site-packages/telegram/ext/_handlers/basehandler.py\", line 158, in handle_update\n    return await self.callback(update, context)\n           ^^^^^^^^^^^^^^^^^^^^^^^^^^^^^^^^^^^^\n  File \"/home/technedict/Desktop/ViralPackage/viralcore/handlers/message_handler.py\", line 11, in message_router\n    flags.get(\"awaiting_broadcast\"),\n    ^^^^^^^^^\nAttributeError: 'NoneType' object has no attribute 'get'"}
{"timestamp": "2025-09-27T10:05:40.655533Z", "level": "ERROR", "module": "telegram.ext.Application", "message": "No error handlers are registered, logging exception.", "correlation_id": "none", "exception": "Traceback (most recent call last):\n  File \"/home/technedict/Desktop/ViralPackage/viralcorelib/lib64/python3.13/site-packages/telegram/ext/_application.py\", line 1298, in process_update\n    await coroutine\n  File \"/home/technedict/Desktop/ViralPackage/viralcorelib/lib64/python3.13/site-packages/telegram/ext/_handlers/basehandler.py\", line 158, in handle_update\n    return await self.callback(update, context)\n           ^^^^^^^^^^^^^^^^^^^^^^^^^^^^^^^^^^^^\n  File \"/home/technedict/Desktop/ViralPackage/viralcore/handlers/message_handler.py\", line 11, in message_router\n    flags.get(\"awaiting_broadcast\"),\n    ^^^^^^^^^\nAttributeError: 'NoneType' object has no attribute 'get'"}
{"timestamp": "2025-09-27T10:05:40.660035Z", "level": "ERROR", "module": "telegram.ext.Application", "message": "No error handlers are registered, logging exception.", "correlation_id": "none", "exception": "Traceback (most recent call last):\n  File \"/home/technedict/Desktop/ViralPackage/viralcorelib/lib64/python3.13/site-packages/telegram/ext/_application.py\", line 1298, in process_update\n    await coroutine\n  File \"/home/technedict/Desktop/ViralPackage/viralcorelib/lib64/python3.13/site-packages/telegram/ext/_handlers/basehandler.py\", line 158, in handle_update\n    return await self.callback(update, context)\n           ^^^^^^^^^^^^^^^^^^^^^^^^^^^^^^^^^^^^\n  File \"/home/technedict/Desktop/ViralPackage/viralcore/handlers/message_handler.py\", line 11, in message_router\n    flags.get(\"awaiting_broadcast\"),\n    ^^^^^^^^^\nAttributeError: 'NoneType' object has no attribute 'get'"}
{"timestamp": "2025-09-27T10:05:40.665201Z", "level": "ERROR", "module": "telegram.ext.Application", "message": "No error handlers are registered, logging exception.", "correlation_id": "none", "exception": "Traceback (most recent call last):\n  File \"/home/technedict/Desktop/ViralPackage/viralcorelib/lib64/python3.13/site-packages/telegram/ext/_application.py\", line 1298, in process_update\n    await coroutine\n  File \"/home/technedict/Desktop/ViralPackage/viralcorelib/lib64/python3.13/site-packages/telegram/ext/_handlers/basehandler.py\", line 158, in handle_update\n    return await self.callback(update, context)\n           ^^^^^^^^^^^^^^^^^^^^^^^^^^^^^^^^^^^^\n  File \"/home/technedict/Desktop/ViralPackage/viralcore/handlers/message_handler.py\", line 11, in message_router\n    flags.get(\"awaiting_broadcast\"),\n    ^^^^^^^^^\nAttributeError: 'NoneType' object has no attribute 'get'"}
{"timestamp": "2025-09-27T10:05:40.670699Z", "level": "ERROR", "module": "telegram.ext.Application", "message": "No error handlers are registered, logging exception.", "correlation_id": "none", "exception": "Traceback (most recent call last):\n  File \"/home/technedict/Desktop/ViralPackage/viralcorelib/lib64/python3.13/site-packages/telegram/ext/_application.py\", line 1298, in process_update\n    await coroutine\n  File \"/home/technedict/Desktop/ViralPackage/viralcorelib/lib64/python3.13/site-packages/telegram/ext/_handlers/basehandler.py\", line 158, in handle_update\n    return await self.callback(update, context)\n           ^^^^^^^^^^^^^^^^^^^^^^^^^^^^^^^^^^^^\n  File \"/home/technedict/Desktop/ViralPackage/viralcore/handlers/message_handler.py\", line 11, in message_router\n    flags.get(\"awaiting_broadcast\"),\n    ^^^^^^^^^\nAttributeError: 'NoneType' object has no attribute 'get'"}
{"timestamp": "2025-09-27T10:05:40.677059Z", "level": "ERROR", "module": "telegram.ext.Application", "message": "No error handlers are registered, logging exception.", "correlation_id": "none", "exception": "Traceback (most recent call last):\n  File \"/home/technedict/Desktop/ViralPackage/viralcorelib/lib64/python3.13/site-packages/telegram/ext/_application.py\", line 1298, in process_update\n    await coroutine\n  File \"/home/technedict/Desktop/ViralPackage/viralcorelib/lib64/python3.13/site-packages/telegram/ext/_handlers/basehandler.py\", line 158, in handle_update\n    return await self.callback(update, context)\n           ^^^^^^^^^^^^^^^^^^^^^^^^^^^^^^^^^^^^\n  File \"/home/technedict/Desktop/ViralPackage/viralcore/handlers/message_handler.py\", line 11, in message_router\n    flags.get(\"awaiting_broadcast\"),\n    ^^^^^^^^^\nAttributeError: 'NoneType' object has no attribute 'get'"}
{"timestamp": "2025-09-27T10:05:40.682142Z", "level": "ERROR", "module": "telegram.ext.Application", "message": "No error handlers are registered, logging exception.", "correlation_id": "none", "exception": "Traceback (most recent call last):\n  File \"/home/technedict/Desktop/ViralPackage/viralcorelib/lib64/python3.13/site-packages/telegram/ext/_application.py\", line 1298, in process_update\n    await coroutine\n  File \"/home/technedict/Desktop/ViralPackage/viralcorelib/lib64/python3.13/site-packages/telegram/ext/_handlers/basehandler.py\", line 158, in handle_update\n    return await self.callback(update, context)\n           ^^^^^^^^^^^^^^^^^^^^^^^^^^^^^^^^^^^^\n  File \"/home/technedict/Desktop/ViralPackage/viralcore/handlers/message_handler.py\", line 11, in message_router\n    flags.get(\"awaiting_broadcast\"),\n    ^^^^^^^^^\nAttributeError: 'NoneType' object has no attribute 'get'"}
{"timestamp": "2025-09-27T10:05:40.687514Z", "level": "ERROR", "module": "telegram.ext.Application", "message": "No error handlers are registered, logging exception.", "correlation_id": "none", "exception": "Traceback (most recent call last):\n  File \"/home/technedict/Desktop/ViralPackage/viralcorelib/lib64/python3.13/site-packages/telegram/ext/_application.py\", line 1298, in process_update\n    await coroutine\n  File \"/home/technedict/Desktop/ViralPackage/viralcorelib/lib64/python3.13/site-packages/telegram/ext/_handlers/basehandler.py\", line 158, in handle_update\n    return await self.callback(update, context)\n           ^^^^^^^^^^^^^^^^^^^^^^^^^^^^^^^^^^^^\n  File \"/home/technedict/Desktop/ViralPackage/viralcore/handlers/message_handler.py\", line 11, in message_router\n    flags.get(\"awaiting_broadcast\"),\n    ^^^^^^^^^\nAttributeError: 'NoneType' object has no attribute 'get'"}
{"timestamp": "2025-09-27T10:05:40.692596Z", "level": "ERROR", "module": "telegram.ext.Application", "message": "No error handlers are registered, logging exception.", "correlation_id": "none", "exception": "Traceback (most recent call last):\n  File \"/home/technedict/Desktop/ViralPackage/viralcorelib/lib64/python3.13/site-packages/telegram/ext/_application.py\", line 1298, in process_update\n    await coroutine\n  File \"/home/technedict/Desktop/ViralPackage/viralcorelib/lib64/python3.13/site-packages/telegram/ext/_handlers/basehandler.py\", line 158, in handle_update\n    return await self.callback(update, context)\n           ^^^^^^^^^^^^^^^^^^^^^^^^^^^^^^^^^^^^\n  File \"/home/technedict/Desktop/ViralPackage/viralcore/handlers/message_handler.py\", line 11, in message_router\n    flags.get(\"awaiting_broadcast\"),\n    ^^^^^^^^^\nAttributeError: 'NoneType' object has no attribute 'get'"}
{"timestamp": "2025-09-27T10:05:40.697740Z", "level": "ERROR", "module": "telegram.ext.Application", "message": "No error handlers are registered, logging exception.", "correlation_id": "none", "exception": "Traceback (most recent call last):\n  File \"/home/technedict/Desktop/ViralPackage/viralcorelib/lib64/python3.13/site-packages/telegram/ext/_application.py\", line 1298, in process_update\n    await coroutine\n  File \"/home/technedict/Desktop/ViralPackage/viralcorelib/lib64/python3.13/site-packages/telegram/ext/_handlers/basehandler.py\", line 158, in handle_update\n    return await self.callback(update, context)\n           ^^^^^^^^^^^^^^^^^^^^^^^^^^^^^^^^^^^^\n  File \"/home/technedict/Desktop/ViralPackage/viralcore/handlers/message_handler.py\", line 11, in message_router\n    flags.get(\"awaiting_broadcast\"),\n    ^^^^^^^^^\nAttributeError: 'NoneType' object has no attribute 'get'"}
{"timestamp": "2025-09-27T10:05:40.702983Z", "level": "ERROR", "module": "telegram.ext.Application", "message": "No error handlers are registered, logging exception.", "correlation_id": "none", "exception": "Traceback (most recent call last):\n  File \"/home/technedict/Desktop/ViralPackage/viralcorelib/lib64/python3.13/site-packages/telegram/ext/_application.py\", line 1298, in process_update\n    await coroutine\n  File \"/home/technedict/Desktop/ViralPackage/viralcorelib/lib64/python3.13/site-packages/telegram/ext/_handlers/basehandler.py\", line 158, in handle_update\n    return await self.callback(update, context)\n           ^^^^^^^^^^^^^^^^^^^^^^^^^^^^^^^^^^^^\n  File \"/home/technedict/Desktop/ViralPackage/viralcore/handlers/message_handler.py\", line 11, in message_router\n    flags.get(\"awaiting_broadcast\"),\n    ^^^^^^^^^\nAttributeError: 'NoneType' object has no attribute 'get'"}
{"timestamp": "2025-09-27T10:05:40.707865Z", "level": "ERROR", "module": "telegram.ext.Application", "message": "No error handlers are registered, logging exception.", "correlation_id": "none", "exception": "Traceback (most recent call last):\n  File \"/home/technedict/Desktop/ViralPackage/viralcorelib/lib64/python3.13/site-packages/telegram/ext/_application.py\", line 1298, in process_update\n    await coroutine\n  File \"/home/technedict/Desktop/ViralPackage/viralcorelib/lib64/python3.13/site-packages/telegram/ext/_handlers/basehandler.py\", line 158, in handle_update\n    return await self.callback(update, context)\n           ^^^^^^^^^^^^^^^^^^^^^^^^^^^^^^^^^^^^\n  File \"/home/technedict/Desktop/ViralPackage/viralcore/handlers/message_handler.py\", line 11, in message_router\n    flags.get(\"awaiting_broadcast\"),\n    ^^^^^^^^^\nAttributeError: 'NoneType' object has no attribute 'get'"}
{"timestamp": "2025-09-27T10:05:40.712852Z", "level": "ERROR", "module": "telegram.ext.Application", "message": "No error handlers are registered, logging exception.", "correlation_id": "none", "exception": "Traceback (most recent call last):\n  File \"/home/technedict/Desktop/ViralPackage/viralcorelib/lib64/python3.13/site-packages/telegram/ext/_application.py\", line 1298, in process_update\n    await coroutine\n  File \"/home/technedict/Desktop/ViralPackage/viralcorelib/lib64/python3.13/site-packages/telegram/ext/_handlers/basehandler.py\", line 158, in handle_update\n    return await self.callback(update, context)\n           ^^^^^^^^^^^^^^^^^^^^^^^^^^^^^^^^^^^^\n  File \"/home/technedict/Desktop/ViralPackage/viralcore/handlers/message_handler.py\", line 11, in message_router\n    flags.get(\"awaiting_broadcast\"),\n    ^^^^^^^^^\nAttributeError: 'NoneType' object has no attribute 'get'"}
{"timestamp": "2025-09-27T10:06:13.927094Z", "level": "WARNING", "module": "handlers.menu_handlers", "message": "menu_handler edit failed (Message to edit not found) for user ***ACCOUNT***. Resending message.", "correlation_id": "none"}
{"timestamp": "2025-09-27T10:09:57.429623Z", "level": "ERROR", "module": "utils.graceful_shutdown", "message": "Error during signal-triggered shutdown: asyncio.run() cannot be called from a running event loop", "correlation_id": "none"}
{"timestamp": "2025-09-27T10:09:57.672698Z", "level": "ERROR", "module": "utils.graceful_shutdown", "message": "Error during signal-triggered shutdown: asyncio.run() cannot be called from a running event loop", "correlation_id": "none"}
{"timestamp": "2025-09-27T10:09:57.905311Z", "level": "ERROR", "module": "utils.graceful_shutdown", "message": "Error during signal-triggered shutdown: asyncio.run() cannot be called from a running event loop", "correlation_id": "none"}
{"timestamp": "2025-09-27T10:09:58.114431Z", "level": "ERROR", "module": "utils.graceful_shutdown", "message": "Error during signal-triggered shutdown: asyncio.run() cannot be called from a running event loop", "correlation_id": "none"}
{"timestamp": "2025-09-27T10:09:58.327548Z", "level": "ERROR", "module": "utils.graceful_shutdown", "message": "Error during signal-triggered shutdown: asyncio.run() cannot be called from a running event loop", "correlation_id": "none"}
{"timestamp": "2025-09-27T10:09:58.495452Z", "level": "ERROR", "module": "utils.graceful_shutdown", "message": "Error during signal-triggered shutdown: asyncio.run() cannot be called from a running event loop", "correlation_id": "none"}
{"timestamp": "2025-09-27T10:09:58.698485Z", "level": "ERROR", "module": "utils.graceful_shutdown", "message": "Error during signal-triggered shutdown: asyncio.run() cannot be called from a running event loop", "correlation_id": "none"}
{"timestamp": "2025-09-27T10:09:59.171637Z", "level": "ERROR", "module": "utils.graceful_shutdown", "message": "Error during signal-triggered shutdown: asyncio.run() cannot be called from a running event loop", "correlation_id": "none"}
{"timestamp": "2025-09-27T10:10:02.014767Z", "level": "ERROR", "module": "utils.graceful_shutdown", "message": "Error during signal-triggered shutdown: asyncio.run() cannot be called from a running event loop", "correlation_id": "none"}
{"timestamp": "2025-09-27T10:10:03.236394Z", "level": "ERROR", "module": "telegram.ext.Application", "message": "No error handlers are registered, logging exception.", "correlation_id": "none", "exception": "Traceback (most recent call last):\n  File \"/home/technedict/Desktop/ViralPackage/viralcorelib/lib64/python3.13/site-packages/telegram/ext/_application.py\", line 1298, in process_update\n    await coroutine\n  File \"/home/technedict/Desktop/ViralPackage/viralcorelib/lib64/python3.13/site-packages/telegram/ext/_handlers/basehandler.py\", line 158, in handle_update\n    return await self.callback(update, context)\n           ^^^^^^^^^^^^^^^^^^^^^^^^^^^^^^^^^^^^\n  File \"/home/technedict/Desktop/ViralPackage/viralcore/handlers/message_handler.py\", line 11, in message_router\n    flags.get(\"awaiting_broadcast\"),\n    ^^^^^^^^^\nAttributeError: 'NoneType' object has no attribute 'get'"}
{"timestamp": "2025-09-27T10:12:23.655677Z", "level": "ERROR", "module": "utils.graceful_shutdown", "message": "Error during signal-triggered shutdown: asyncio.run() cannot be called from a running event loop", "correlation_id": "none"}
{"timestamp": "2025-09-27T10:28:03.135515Z", "level": "ERROR", "module": "telegram.ext.Application", "message": "No error handlers are registered, logging exception.", "correlation_id": "none", "exception": "Traceback (most recent call last):\n  File \"/home/technedict/Desktop/ViralPackage/viralcorelib/lib64/python3.13/site-packages/telegram/ext/_application.py\", line 1298, in process_update\n    await coroutine\n  File \"/home/technedict/Desktop/ViralPackage/viralcorelib/lib64/python3.13/site-packages/telegram/ext/_handlers/basehandler.py\", line 158, in handle_update\n    return await self.callback(update, context)\n           ^^^^^^^^^^^^^^^^^^^^^^^^^^^^^^^^^^^^\n  File \"/home/technedict/Desktop/ViralPackage/viralcore/handlers/message_handler.py\", line 11, in message_router\n    flags.get(\"awaiting_broadcast\"),\n    ^^^^^^^^^\nAttributeError: 'NoneType' object has no attribute 'get'"}
{"timestamp": "2025-09-27T10:30:57.351864Z", "level": "WARNING", "module": "handlers.menu_handlers", "message": "menu_handler edit failed (Message to edit not found) for user ***ACCOUNT***. Resending message.", "correlation_id": "none"}
{"timestamp": "2025-09-27T10:31:01.648513Z", "level": "WARNING", "module": "handlers.menu_handlers", "message": "menu_handler edit failed (Message to edit not found) for user ***ACCOUNT***. Resending message.", "correlation_id": "none"}
{"timestamp": "2025-09-27T10:32:07.343974Z", "level": "WARNING", "module": "handlers.menu_handlers", "message": "menu_handler edit failed (Message to edit not found) for user ***ACCOUNT***. Resending message.", "correlation_id": "none"}
{"timestamp": "2025-09-27T10:32:17.084559Z", "level": "WARNING", "module": "handlers.menu_handlers", "message": "menu_handler edit failed (Message to edit not found) for user ***ACCOUNT***. Resending message.", "correlation_id": "none"}
{"timestamp": "2025-09-27T10:32:22.397027Z", "level": "WARNING", "module": "handlers.menu_handlers", "message": "menu_handler edit failed (Message to edit not found) for user ***ACCOUNT***. Resending message.", "correlation_id": "none"}
{"timestamp": "2025-09-27T10:32:28.386447Z", "level": "WARNING", "module": "handlers.menu_handlers", "message": "menu_handler edit failed (Message to edit not found) for user ***ACCOUNT***. Resending message.", "correlation_id": "none"}
{"timestamp": "2025-09-27T10:32:48.508296Z", "level": "WARNING", "module": "handlers.menu_handlers", "message": "menu_handler edit failed (Message to edit not found) for user ***ACCOUNT***. Resending message.", "correlation_id": "none"}
{"timestamp": "2025-09-27T10:35:17.671055Z", "level": "ERROR", "module": "__main__", "message": "Error during app.shutdown()", "correlation_id": "none", "exception": "Traceback (most recent call last):\n  File \"/home/technedict/Desktop/ViralPackage/viralcore/main_viral_core_bot.py\", line 247, in main\n    await app.shutdown()\n  File \"/home/technedict/Desktop/ViralPackage/viralcorelib/lib64/python3.13/site-packages/telegram/ext/_application.py\", line 544, in shutdown\n    await self.updater.shutdown()\n  File \"/home/technedict/Desktop/ViralPackage/viralcorelib/lib64/python3.13/site-packages/telegram/ext/_updater.py\", line 196, in shutdown\n    raise RuntimeError(\"This Updater is still running!\")\nRuntimeError: This Updater is still running!"}
{"timestamp": "2025-09-27T10:35:17.683638Z", "level": "WARNING", "module": "utils.graceful_shutdown", "message": "Shutdown already in progress", "correlation_id": "none"}
{"timestamp": "2025-09-27T10:35:17.988903Z", "level": "ERROR", "module": "asyncio", "message": "Task exception was never retrieved\nfuture: <Task finished name='Task-64' coro=<Updater._start_polling.<locals>.polling_action_cb() done, defined at /home/technedict/Desktop/ViralPackage/viralcorelib/lib64/python3.13/site-packages/telegram/ext/_updater.py:333> exception=NetworkError('httpx.ReadError: ')>", "correlation_id": "none", "exception": "Traceback (most recent call last):\n  File \"/home/technedict/Desktop/ViralPackage/viralcorelib/lib64/python3.13/site-packages/httpx/_transports/default.py\", line 101, in map_httpcore_exceptions\n    yield\n  File \"/home/technedict/Desktop/ViralPackage/viralcorelib/lib64/python3.13/site-packages/httpx/_transports/default.py\", line 394, in handle_async_request\n    resp = await self._pool.handle_async_request(req)\n           ^^^^^^^^^^^^^^^^^^^^^^^^^^^^^^^^^^^^^^^^^^\n  File \"/home/technedict/Desktop/ViralPackage/viralcorelib/lib64/python3.13/site-packages/httpcore/_async/connection_pool.py\", line 256, in handle_async_request\n    raise exc from None\n  File \"/home/technedict/Desktop/ViralPackage/viralcorelib/lib64/python3.13/site-packages/httpcore/_async/connection_pool.py\", line 236, in handle_async_request\n    response = await connection.handle_async_request(\n               ^^^^^^^^^^^^^^^^^^^^^^^^^^^^^^^^^^^^^^\n        pool_request.request\n        ^^^^^^^^^^^^^^^^^^^^\n    )\n    ^\n  File \"/home/technedict/Desktop/ViralPackage/viralcorelib/lib64/python3.13/site-packages/httpcore/_async/connection.py\", line 103, in handle_async_request\n    return await self._connection.handle_async_request(request)\n           ^^^^^^^^^^^^^^^^^^^^^^^^^^^^^^^^^^^^^^^^^^^^^^^^^^^^\n  File \"/home/technedict/Desktop/ViralPackage/viralcorelib/lib64/python3.13/site-packages/httpcore/_async/http11.py\", line 136, in handle_async_request\n    raise exc\n  File \"/home/technedict/Desktop/ViralPackage/viralcorelib/lib64/python3.13/site-packages/httpcore/_async/http11.py\", line 106, in handle_async_request\n    ) = await self._receive_response_headers(**kwargs)\n        ^^^^^^^^^^^^^^^^^^^^^^^^^^^^^^^^^^^^^^^^^^^^^^\n  File \"/home/technedict/Desktop/ViralPackage/viralcorelib/lib64/python3.13/site-packages/httpcore/_async/http11.py\", line 177, in _receive_response_headers\n    event = await self._receive_event(timeout=timeout)\n            ^^^^^^^^^^^^^^^^^^^^^^^^^^^^^^^^^^^^^^^^^^\n  File \"/home/technedict/Desktop/ViralPackage/viralcorelib/lib64/python3.13/site-packages/httpcore/_async/http11.py\", line 217, in _receive_event\n    data = await self._network_stream.read(\n           ^^^^^^^^^^^^^^^^^^^^^^^^^^^^^^^^\n        self.READ_NUM_BYTES, timeout=timeout\n        ^^^^^^^^^^^^^^^^^^^^^^^^^^^^^^^^^^^^\n    )\n    ^\n  File \"/home/technedict/Desktop/ViralPackage/viralcorelib/lib64/python3.13/site-packages/httpcore/_backends/anyio.py\", line 32, in read\n    with map_exceptions(exc_map):\n         ~~~~~~~~~~~~~~^^^^^^^^^\n  File \"/usr/lib64/python3.13/contextlib.py\", line 162, in __exit__\n    self.gen.throw(value)\n    ~~~~~~~~~~~~~~^^^^^^^\n  File \"/home/technedict/Desktop/ViralPackage/viralcorelib/lib64/python3.13/site-packages/httpcore/_exceptions.py\", line 14, in map_exceptions\n    raise to_exc(exc) from exc\nhttpcore.ReadError\n\nThe above exception was the direct cause of the following exception:\n\nTraceback (most recent call last):\n  File \"/home/technedict/Desktop/ViralPackage/viralcorelib/lib64/python3.13/site-packages/telegram/request/_httpxrequest.py\", line 277, in do_request\n    res = await self._client.request(\n          ^^^^^^^^^^^^^^^^^^^^^^^^^^^\n    ...<6 lines>...\n    )\n    ^\n  File \"/home/technedict/Desktop/ViralPackage/viralcorelib/lib64/python3.13/site-packages/httpx/_client.py\", line 1540, in request\n    return await self.send(request, auth=auth, follow_redirects=follow_redirects)\n           ^^^^^^^^^^^^^^^^^^^^^^^^^^^^^^^^^^^^^^^^^^^^^^^^^^^^^^^^^^^^^^^^^^^^^^\n  File \"/home/technedict/Desktop/ViralPackage/viralcorelib/lib64/python3.13/site-packages/httpx/_client.py\", line 1629, in send\n    response = await self._send_handling_auth(\n               ^^^^^^^^^^^^^^^^^^^^^^^^^^^^^^^\n    ...<4 lines>...\n    )\n    ^\n  File \"/home/technedict/Desktop/ViralPackage/viralcorelib/lib64/python3.13/site-packages/httpx/_client.py\", line 1657, in _send_handling_auth\n    response = await self._send_handling_redirects(\n               ^^^^^^^^^^^^^^^^^^^^^^^^^^^^^^^^^^^^\n    ...<3 lines>...\n    )\n    ^\n  File \"/home/technedict/Desktop/ViralPackage/viralcorelib/lib64/python3.13/site-packages/httpx/_client.py\", line 1694, in _send_handling_redirects\n    response = await self._send_single_request(request)\n               ^^^^^^^^^^^^^^^^^^^^^^^^^^^^^^^^^^^^^^^^\n  File \"/home/technedict/Desktop/ViralPackage/viralcorelib/lib64/python3.13/site-packages/httpx/_client.py\", line 1730, in _send_single_request\n    response = await transport.handle_async_request(request)\n               ^^^^^^^^^^^^^^^^^^^^^^^^^^^^^^^^^^^^^^^^^^^^^\n  File \"/home/technedict/Desktop/ViralPackage/viralcorelib/lib64/python3.13/site-packages/httpx/_transports/default.py\", line 393, in handle_async_request\n    with map_httpcore_exceptions():\n         ~~~~~~~~~~~~~~~~~~~~~~~^^\n  File \"/usr/lib64/python3.13/contextlib.py\", line 162, in __exit__\n    self.gen.throw(value)\n    ~~~~~~~~~~~~~~^^^^^^^\n  File \"/home/technedict/Desktop/ViralPackage/viralcorelib/lib64/python3.13/site-packages/httpx/_transports/default.py\", line 118, in map_httpcore_exceptions\n    raise mapped_exc(message) from exc\nhttpx.ReadError\n\nThe above exception was the direct cause of the following exception:\n\nTraceback (most recent call last):\n  File \"/home/technedict/Desktop/ViralPackage/viralcorelib/lib64/python3.13/site-packages/telegram/ext/_updater.py\", line 335, in polling_action_cb\n    updates = await self.bot.get_updates(\n              ^^^^^^^^^^^^^^^^^^^^^^^^^^^\n    ...<3 lines>...\n    )\n    ^\n  File \"/home/technedict/Desktop/ViralPackage/viralcorelib/lib64/python3.13/site-packages/telegram/ext/_extbot.py\", line 658, in get_updates\n    updates = await super().get_updates(\n              ^^^^^^^^^^^^^^^^^^^^^^^^^^\n    ...<9 lines>...\n    )\n    ^\n  File \"/home/technedict/Desktop/ViralPackage/viralcorelib/lib64/python3.13/site-packages/telegram/_bot.py\", line 4593, in get_updates\n    await self._post(\n    ^^^^^^^^^^^^^^^^^\n    ...<7 lines>...\n    ),\n    ^\n  File \"/home/technedict/Desktop/ViralPackage/viralcorelib/lib64/python3.13/site-packages/telegram/_bot.py\", line 691, in _post\n    return await self._do_post(\n           ^^^^^^^^^^^^^^^^^^^^\n    ...<6 lines>...\n    )\n    ^\n  File \"/home/technedict/Desktop/ViralPackage/viralcorelib/lib64/python3.13/site-packages/telegram/ext/_extbot.py\", line 362, in _do_post\n    return await super()._do_post(\n           ^^^^^^^^^^^^^^^^^^^^^^^\n    ...<6 lines>...\n    )\n    ^\n  File \"/home/technedict/Desktop/ViralPackage/viralcorelib/lib64/python3.13/site-packages/telegram/_bot.py\", line 720, in _do_post\n    result = await request.post(\n             ^^^^^^^^^^^^^^^^^^^\n    ...<6 lines>...\n    )\n    ^\n  File \"/home/technedict/Desktop/ViralPackage/viralcorelib/lib64/python3.13/site-packages/telegram/request/_baserequest.py\", line 197, in post\n    result = await self._request_wrapper(\n             ^^^^^^^^^^^^^^^^^^^^^^^^^^^^\n    ...<7 lines>...\n    )\n    ^\n  File \"/home/technedict/Desktop/ViralPackage/viralcorelib/lib64/python3.13/site-packages/telegram/request/_baserequest.py\", line 304, in _request_wrapper\n    code, payload = await self.do_request(\n                    ^^^^^^^^^^^^^^^^^^^^^^\n    ...<7 lines>...\n    )\n    ^\n  File \"/home/technedict/Desktop/ViralPackage/viralcorelib/lib64/python3.13/site-packages/telegram/request/_httpxrequest.py\", line 301, in do_request\n    raise NetworkError(f\"httpx.{err.__class__.__name__}: {err}\") from err\ntelegram.error.NetworkError: httpx.ReadError: "}
{"timestamp": "2025-09-27T10:35:55.319461Z", "level": "ERROR", "module": "__main__", "message": "Error during app.shutdown()", "correlation_id": "none", "exception": "Traceback (most recent call last):\n  File \"/home/technedict/Desktop/ViralPackage/viralcore/main_viral_core_bot.py\", line 247, in main\n    await app.shutdown()\n  File \"/home/technedict/Desktop/ViralPackage/viralcorelib/lib64/python3.13/site-packages/telegram/ext/_application.py\", line 544, in shutdown\n    await self.updater.shutdown()\n  File \"/home/technedict/Desktop/ViralPackage/viralcorelib/lib64/python3.13/site-packages/telegram/ext/_updater.py\", line 196, in shutdown\n    raise RuntimeError(\"This Updater is still running!\")\nRuntimeError: This Updater is still running!"}
{"timestamp": "2025-09-27T10:35:55.323318Z", "level": "WARNING", "module": "utils.graceful_shutdown", "message": "Shutdown already in progress", "correlation_id": "none"}
{"timestamp": "2025-09-27T10:35:55.382536Z", "level": "ERROR", "module": "asyncio", "message": "Task exception was never retrieved\nfuture: <Task finished name='Task-4' coro=<Updater._start_polling.<locals>.polling_action_cb() done, defined at /home/technedict/Desktop/ViralPackage/viralcorelib/lib64/python3.13/site-packages/telegram/ext/_updater.py:333> exception=NetworkError('httpx.ReadError: ')>", "correlation_id": "none", "exception": "Traceback (most recent call last):\n  File \"/home/technedict/Desktop/ViralPackage/viralcorelib/lib64/python3.13/site-packages/httpx/_transports/default.py\", line 101, in map_httpcore_exceptions\n    yield\n  File \"/home/technedict/Desktop/ViralPackage/viralcorelib/lib64/python3.13/site-packages/httpx/_transports/default.py\", line 394, in handle_async_request\n    resp = await self._pool.handle_async_request(req)\n           ^^^^^^^^^^^^^^^^^^^^^^^^^^^^^^^^^^^^^^^^^^\n  File \"/home/technedict/Desktop/ViralPackage/viralcorelib/lib64/python3.13/site-packages/httpcore/_async/connection_pool.py\", line 256, in handle_async_request\n    raise exc from None\n  File \"/home/technedict/Desktop/ViralPackage/viralcorelib/lib64/python3.13/site-packages/httpcore/_async/connection_pool.py\", line 236, in handle_async_request\n    response = await connection.handle_async_request(\n               ^^^^^^^^^^^^^^^^^^^^^^^^^^^^^^^^^^^^^^\n        pool_request.request\n        ^^^^^^^^^^^^^^^^^^^^\n    )\n    ^\n  File \"/home/technedict/Desktop/ViralPackage/viralcorelib/lib64/python3.13/site-packages/httpcore/_async/connection.py\", line 103, in handle_async_request\n    return await self._connection.handle_async_request(request)\n           ^^^^^^^^^^^^^^^^^^^^^^^^^^^^^^^^^^^^^^^^^^^^^^^^^^^^\n  File \"/home/technedict/Desktop/ViralPackage/viralcorelib/lib64/python3.13/site-packages/httpcore/_async/http11.py\", line 136, in handle_async_request\n    raise exc\n  File \"/home/technedict/Desktop/ViralPackage/viralcorelib/lib64/python3.13/site-packages/httpcore/_async/http11.py\", line 106, in handle_async_request\n    ) = await self._receive_response_headers(**kwargs)\n        ^^^^^^^^^^^^^^^^^^^^^^^^^^^^^^^^^^^^^^^^^^^^^^\n  File \"/home/technedict/Desktop/ViralPackage/viralcorelib/lib64/python3.13/site-packages/httpcore/_async/http11.py\", line 177, in _receive_response_headers\n    event = await self._receive_event(timeout=timeout)\n            ^^^^^^^^^^^^^^^^^^^^^^^^^^^^^^^^^^^^^^^^^^\n  File \"/home/technedict/Desktop/ViralPackage/viralcorelib/lib64/python3.13/site-packages/httpcore/_async/http11.py\", line 217, in _receive_event\n    data = await self._network_stream.read(\n           ^^^^^^^^^^^^^^^^^^^^^^^^^^^^^^^^\n        self.READ_NUM_BYTES, timeout=timeout\n        ^^^^^^^^^^^^^^^^^^^^^^^^^^^^^^^^^^^^\n    )\n    ^\n  File \"/home/technedict/Desktop/ViralPackage/viralcorelib/lib64/python3.13/site-packages/httpcore/_backends/anyio.py\", line 32, in read\n    with map_exceptions(exc_map):\n         ~~~~~~~~~~~~~~^^^^^^^^^\n  File \"/usr/lib64/python3.13/contextlib.py\", line 162, in __exit__\n    self.gen.throw(value)\n    ~~~~~~~~~~~~~~^^^^^^^\n  File \"/home/technedict/Desktop/ViralPackage/viralcorelib/lib64/python3.13/site-packages/httpcore/_exceptions.py\", line 14, in map_exceptions\n    raise to_exc(exc) from exc\nhttpcore.ReadError\n\nThe above exception was the direct cause of the following exception:\n\nTraceback (most recent call last):\n  File \"/home/technedict/Desktop/ViralPackage/viralcorelib/lib64/python3.13/site-packages/telegram/request/_httpxrequest.py\", line 277, in do_request\n    res = await self._client.request(\n          ^^^^^^^^^^^^^^^^^^^^^^^^^^^\n    ...<6 lines>...\n    )\n    ^\n  File \"/home/technedict/Desktop/ViralPackage/viralcorelib/lib64/python3.13/site-packages/httpx/_client.py\", line 1540, in request\n    return await self.send(request, auth=auth, follow_redirects=follow_redirects)\n           ^^^^^^^^^^^^^^^^^^^^^^^^^^^^^^^^^^^^^^^^^^^^^^^^^^^^^^^^^^^^^^^^^^^^^^\n  File \"/home/technedict/Desktop/ViralPackage/viralcorelib/lib64/python3.13/site-packages/httpx/_client.py\", line 1629, in send\n    response = await self._send_handling_auth(\n               ^^^^^^^^^^^^^^^^^^^^^^^^^^^^^^^\n    ...<4 lines>...\n    )\n    ^\n  File \"/home/technedict/Desktop/ViralPackage/viralcorelib/lib64/python3.13/site-packages/httpx/_client.py\", line 1657, in _send_handling_auth\n    response = await self._send_handling_redirects(\n               ^^^^^^^^^^^^^^^^^^^^^^^^^^^^^^^^^^^^\n    ...<3 lines>...\n    )\n    ^\n  File \"/home/technedict/Desktop/ViralPackage/viralcorelib/lib64/python3.13/site-packages/httpx/_client.py\", line 1694, in _send_handling_redirects\n    response = await self._send_single_request(request)\n               ^^^^^^^^^^^^^^^^^^^^^^^^^^^^^^^^^^^^^^^^\n  File \"/home/technedict/Desktop/ViralPackage/viralcorelib/lib64/python3.13/site-packages/httpx/_client.py\", line 1730, in _send_single_request\n    response = await transport.handle_async_request(request)\n               ^^^^^^^^^^^^^^^^^^^^^^^^^^^^^^^^^^^^^^^^^^^^^\n  File \"/home/technedict/Desktop/ViralPackage/viralcorelib/lib64/python3.13/site-packages/httpx/_transports/default.py\", line 393, in handle_async_request\n    with map_httpcore_exceptions():\n         ~~~~~~~~~~~~~~~~~~~~~~~^^\n  File \"/usr/lib64/python3.13/contextlib.py\", line 162, in __exit__\n    self.gen.throw(value)\n    ~~~~~~~~~~~~~~^^^^^^^\n  File \"/home/technedict/Desktop/ViralPackage/viralcorelib/lib64/python3.13/site-packages/httpx/_transports/default.py\", line 118, in map_httpcore_exceptions\n    raise mapped_exc(message) from exc\nhttpx.ReadError\n\nThe above exception was the direct cause of the following exception:\n\nTraceback (most recent call last):\n  File \"/home/technedict/Desktop/ViralPackage/viralcorelib/lib64/python3.13/site-packages/telegram/ext/_updater.py\", line 335, in polling_action_cb\n    updates = await self.bot.get_updates(\n              ^^^^^^^^^^^^^^^^^^^^^^^^^^^\n    ...<3 lines>...\n    )\n    ^\n  File \"/home/technedict/Desktop/ViralPackage/viralcorelib/lib64/python3.13/site-packages/telegram/ext/_extbot.py\", line 658, in get_updates\n    updates = await super().get_updates(\n              ^^^^^^^^^^^^^^^^^^^^^^^^^^\n    ...<9 lines>...\n    )\n    ^\n  File \"/home/technedict/Desktop/ViralPackage/viralcorelib/lib64/python3.13/site-packages/telegram/_bot.py\", line 4593, in get_updates\n    await self._post(\n    ^^^^^^^^^^^^^^^^^\n    ...<7 lines>...\n    ),\n    ^\n  File \"/home/technedict/Desktop/ViralPackage/viralcorelib/lib64/python3.13/site-packages/telegram/_bot.py\", line 691, in _post\n    return await self._do_post(\n           ^^^^^^^^^^^^^^^^^^^^\n    ...<6 lines>...\n    )\n    ^\n  File \"/home/technedict/Desktop/ViralPackage/viralcorelib/lib64/python3.13/site-packages/telegram/ext/_extbot.py\", line 362, in _do_post\n    return await super()._do_post(\n           ^^^^^^^^^^^^^^^^^^^^^^^\n    ...<6 lines>...\n    )\n    ^\n  File \"/home/technedict/Desktop/ViralPackage/viralcorelib/lib64/python3.13/site-packages/telegram/_bot.py\", line 720, in _do_post\n    result = await request.post(\n             ^^^^^^^^^^^^^^^^^^^\n    ...<6 lines>...\n    )\n    ^\n  File \"/home/technedict/Desktop/ViralPackage/viralcorelib/lib64/python3.13/site-packages/telegram/request/_baserequest.py\", line 197, in post\n    result = await self._request_wrapper(\n             ^^^^^^^^^^^^^^^^^^^^^^^^^^^^\n    ...<7 lines>...\n    )\n    ^\n  File \"/home/technedict/Desktop/ViralPackage/viralcorelib/lib64/python3.13/site-packages/telegram/request/_baserequest.py\", line 304, in _request_wrapper\n    code, payload = await self.do_request(\n                    ^^^^^^^^^^^^^^^^^^^^^^\n    ...<7 lines>...\n    )\n    ^\n  File \"/home/technedict/Desktop/ViralPackage/viralcorelib/lib64/python3.13/site-packages/telegram/request/_httpxrequest.py\", line 301, in do_request\n    raise NetworkError(f\"httpx.{err.__class__.__name__}: {err}\") from err\ntelegram.error.NetworkError: httpx.ReadError: "}
{"timestamp": "2025-09-27T10:39:28.552724Z", "level": "ERROR", "module": "__main__", "message": "Error during app.shutdown()", "correlation_id": "none", "exception": "Traceback (most recent call last):\n  File \"/home/technedict/Desktop/ViralPackage/viralcore/main_viral_core_bot.py\", line 251, in main\n    await app.shutdown()\n  File \"/home/technedict/Desktop/ViralPackage/viralcorelib/lib64/python3.13/site-packages/telegram/ext/_application.py\", line 544, in shutdown\n    await self.updater.shutdown()\n  File \"/home/technedict/Desktop/ViralPackage/viralcorelib/lib64/python3.13/site-packages/telegram/ext/_updater.py\", line 196, in shutdown\n    raise RuntimeError(\"This Updater is still running!\")\nRuntimeError: This Updater is still running!"}
{"timestamp": "2025-09-27T10:39:28.556869Z", "level": "WARNING", "module": "utils.graceful_shutdown", "message": "Shutdown already in progress", "correlation_id": "none"}
{"timestamp": "2025-09-27T10:39:28.698015Z", "level": "ERROR", "module": "asyncio", "message": "Task exception was never retrieved\nfuture: <Task finished name='Task-4' coro=<Updater._start_polling.<locals>.polling_action_cb() done, defined at /home/technedict/Desktop/ViralPackage/viralcorelib/lib64/python3.13/site-packages/telegram/ext/_updater.py:333> exception=NetworkError('httpx.ReadError: ')>", "correlation_id": "none", "exception": "Traceback (most recent call last):\n  File \"/home/technedict/Desktop/ViralPackage/viralcorelib/lib64/python3.13/site-packages/httpx/_transports/default.py\", line 101, in map_httpcore_exceptions\n  File \"/home/technedict/Desktop/ViralPackage/viralcorelib/lib64/python3.13/site-packages/httpx/_transports/default.py\", line 394, in handle_async_request\n  File \"/home/technedict/Desktop/ViralPackage/viralcorelib/lib64/python3.13/site-packages/httpcore/_async/connection_pool.py\", line 256, in handle_async_request\n  File \"/home/technedict/Desktop/ViralPackage/viralcorelib/lib64/python3.13/site-packages/httpcore/_async/connection_pool.py\", line 236, in handle_async_request\n  File \"/home/technedict/Desktop/ViralPackage/viralcorelib/lib64/python3.13/site-packages/httpcore/_async/connection.py\", line 103, in handle_async_request\n  File \"/home/technedict/Desktop/ViralPackage/viralcorelib/lib64/python3.13/site-packages/httpcore/_async/http11.py\", line 136, in handle_async_request\n  File \"/home/technedict/Desktop/ViralPackage/viralcorelib/lib64/python3.13/site-packages/httpcore/_async/http11.py\", line 106, in handle_async_request\n  File \"/home/technedict/Desktop/ViralPackage/viralcorelib/lib64/python3.13/site-packages/httpcore/_async/http11.py\", line 177, in _receive_response_headers\n  File \"/home/technedict/Desktop/ViralPackage/viralcorelib/lib64/python3.13/site-packages/httpcore/_async/http11.py\", line 217, in _receive_event\n  File \"/home/technedict/Desktop/ViralPackage/viralcorelib/lib64/python3.13/site-packages/httpcore/_backends/anyio.py\", line 32, in read\n  File \"/usr/lib64/python3.13/contextlib.py\", line 162, in __exit__\n  File \"/home/technedict/Desktop/ViralPackage/viralcorelib/lib64/python3.13/site-packages/httpcore/_exceptions.py\", line 14, in map_exceptions\nhttpcore.ReadError\n\nThe above exception was the direct cause of the following exception:\n\nTraceback (most recent call last):\n  File \"/home/technedict/Desktop/ViralPackage/viralcorelib/lib64/python3.13/site-packages/telegram/request/_httpxrequest.py\", line 277, in do_request\n  File \"/home/technedict/Desktop/ViralPackage/viralcorelib/lib64/python3.13/site-packages/httpx/_client.py\", line 1540, in request\n  File \"/home/technedict/Desktop/ViralPackage/viralcorelib/lib64/python3.13/site-packages/httpx/_client.py\", line 1629, in send\n  File \"/home/technedict/Desktop/ViralPackage/viralcorelib/lib64/python3.13/site-packages/httpx/_client.py\", line 1657, in _send_handling_auth\n  File \"/home/technedict/Desktop/ViralPackage/viralcorelib/lib64/python3.13/site-packages/httpx/_client.py\", line 1694, in _send_handling_redirects\n  File \"/home/technedict/Desktop/ViralPackage/viralcorelib/lib64/python3.13/site-packages/httpx/_client.py\", line 1730, in _send_single_request\n  File \"/home/technedict/Desktop/ViralPackage/viralcorelib/lib64/python3.13/site-packages/httpx/_transports/default.py\", line 393, in handle_async_request\n  File \"/usr/lib64/python3.13/contextlib.py\", line 162, in __exit__\n  File \"/home/technedict/Desktop/ViralPackage/viralcorelib/lib64/python3.13/site-packages/httpx/_transports/default.py\", line 118, in map_httpcore_exceptions\nhttpx.ReadError\n\nThe above exception was the direct cause of the following exception:\n\nTraceback (most recent call last):\n  File \"/home/technedict/Desktop/ViralPackage/viralcorelib/lib64/python3.13/site-packages/telegram/ext/_updater.py\", line 335, in polling_action_cb\n    updates = await self.bot.get_updates(\n              ^^^^^^^^^^^^^^^^^^^^^^^^^^^\n    ...<3 lines>...\n    )\n    ^\n  File \"/home/technedict/Desktop/ViralPackage/viralcorelib/lib64/python3.13/site-packages/telegram/ext/_extbot.py\", line 658, in get_updates\n  File \"/home/technedict/Desktop/ViralPackage/viralcorelib/lib64/python3.13/site-packages/telegram/_bot.py\", line 4593, in get_updates\n  File \"/home/technedict/Desktop/ViralPackage/viralcorelib/lib64/python3.13/site-packages/telegram/_bot.py\", line 691, in _post\n  File \"/home/technedict/Desktop/ViralPackage/viralcorelib/lib64/python3.13/site-packages/telegram/ext/_extbot.py\", line 362, in _do_post\n  File \"/home/technedict/Desktop/ViralPackage/viralcorelib/lib64/python3.13/site-packages/telegram/_bot.py\", line 720, in _do_post\n  File \"/home/technedict/Desktop/ViralPackage/viralcorelib/lib64/python3.13/site-packages/telegram/request/_baserequest.py\", line 197, in post\n  File \"/home/technedict/Desktop/ViralPackage/viralcorelib/lib64/python3.13/site-packages/telegram/request/_baserequest.py\", line 304, in _request_wrapper\n  File \"/home/technedict/Desktop/ViralPackage/viralcorelib/lib64/python3.13/site-packages/telegram/request/_httpxrequest.py\", line 301, in do_request\ntelegram.error.NetworkError: httpx.ReadError: "}
{"timestamp": "2025-09-27T10:41:20.275962Z", "level": "WARNING", "module": "utils.graceful_shutdown", "message": "Shutdown already in progress", "correlation_id": "none"}
{"timestamp": "2025-09-27T10:41:20.301683Z", "level": "ERROR", "module": "__main__", "message": "Error during app.shutdown()", "correlation_id": "none", "exception": "Traceback (most recent call last):\n  File \"/home/technedict/Desktop/ViralPackage/viralcore/main_viral_core_bot.py\", line 247, in main\n    await app.shutdown()\n  File \"/home/technedict/Desktop/ViralPackage/viralcorelib/lib64/python3.13/site-packages/telegram/ext/_application.py\", line 544, in shutdown\n    await self.updater.shutdown()\n  File \"/home/technedict/Desktop/ViralPackage/viralcorelib/lib64/python3.13/site-packages/telegram/ext/_updater.py\", line 196, in shutdown\n    raise RuntimeError(\"This Updater is still running!\")\nRuntimeError: This Updater is still running!"}
{"timestamp": "2025-09-27T10:41:20.413423Z", "level": "ERROR", "module": "asyncio", "message": "Task exception was never retrieved\nfuture: <Task finished name='Task-4' coro=<Updater._start_polling.<locals>.polling_action_cb() done, defined at /home/technedict/Desktop/ViralPackage/viralcorelib/lib64/python3.13/site-packages/telegram/ext/_updater.py:333> exception=NetworkError('httpx.ReadError: ')>", "correlation_id": "none", "exception": "Traceback (most recent call last):\n  File \"/home/technedict/Desktop/ViralPackage/viralcorelib/lib64/python3.13/site-packages/httpx/_transports/default.py\", line 101, in map_httpcore_exceptions\n  File \"/home/technedict/Desktop/ViralPackage/viralcorelib/lib64/python3.13/site-packages/httpx/_transports/default.py\", line 394, in handle_async_request\n  File \"/home/technedict/Desktop/ViralPackage/viralcorelib/lib64/python3.13/site-packages/httpcore/_async/connection_pool.py\", line 256, in handle_async_request\n  File \"/home/technedict/Desktop/ViralPackage/viralcorelib/lib64/python3.13/site-packages/httpcore/_async/connection_pool.py\", line 236, in handle_async_request\n  File \"/home/technedict/Desktop/ViralPackage/viralcorelib/lib64/python3.13/site-packages/httpcore/_async/connection.py\", line 103, in handle_async_request\n  File \"/home/technedict/Desktop/ViralPackage/viralcorelib/lib64/python3.13/site-packages/httpcore/_async/http11.py\", line 136, in handle_async_request\n  File \"/home/technedict/Desktop/ViralPackage/viralcorelib/lib64/python3.13/site-packages/httpcore/_async/http11.py\", line 106, in handle_async_request\n  File \"/home/technedict/Desktop/ViralPackage/viralcorelib/lib64/python3.13/site-packages/httpcore/_async/http11.py\", line 177, in _receive_response_headers\n  File \"/home/technedict/Desktop/ViralPackage/viralcorelib/lib64/python3.13/site-packages/httpcore/_async/http11.py\", line 217, in _receive_event\n  File \"/home/technedict/Desktop/ViralPackage/viralcorelib/lib64/python3.13/site-packages/httpcore/_backends/anyio.py\", line 32, in read\n  File \"/usr/lib64/python3.13/contextlib.py\", line 162, in __exit__\n  File \"/home/technedict/Desktop/ViralPackage/viralcorelib/lib64/python3.13/site-packages/httpcore/_exceptions.py\", line 14, in map_exceptions\nhttpcore.ReadError\n\nThe above exception was the direct cause of the following exception:\n\nTraceback (most recent call last):\n  File \"/home/technedict/Desktop/ViralPackage/viralcorelib/lib64/python3.13/site-packages/telegram/request/_httpxrequest.py\", line 277, in do_request\n  File \"/home/technedict/Desktop/ViralPackage/viralcorelib/lib64/python3.13/site-packages/httpx/_client.py\", line 1540, in request\n  File \"/home/technedict/Desktop/ViralPackage/viralcorelib/lib64/python3.13/site-packages/httpx/_client.py\", line 1629, in send\n  File \"/home/technedict/Desktop/ViralPackage/viralcorelib/lib64/python3.13/site-packages/httpx/_client.py\", line 1657, in _send_handling_auth\n  File \"/home/technedict/Desktop/ViralPackage/viralcorelib/lib64/python3.13/site-packages/httpx/_client.py\", line 1694, in _send_handling_redirects\n  File \"/home/technedict/Desktop/ViralPackage/viralcorelib/lib64/python3.13/site-packages/httpx/_client.py\", line 1730, in _send_single_request\n  File \"/home/technedict/Desktop/ViralPackage/viralcorelib/lib64/python3.13/site-packages/httpx/_transports/default.py\", line 393, in handle_async_request\n  File \"/usr/lib64/python3.13/contextlib.py\", line 162, in __exit__\n  File \"/home/technedict/Desktop/ViralPackage/viralcorelib/lib64/python3.13/site-packages/httpx/_transports/default.py\", line 118, in map_httpcore_exceptions\nhttpx.ReadError\n\nThe above exception was the direct cause of the following exception:\n\nTraceback (most recent call last):\n  File \"/home/technedict/Desktop/ViralPackage/viralcorelib/lib64/python3.13/site-packages/telegram/ext/_updater.py\", line 335, in polling_action_cb\n    updates = await self.bot.get_updates(\n              ^^^^^^^^^^^^^^^^^^^^^^^^^^^\n    ...<3 lines>...\n    )\n    ^\n  File \"/home/technedict/Desktop/ViralPackage/viralcorelib/lib64/python3.13/site-packages/telegram/ext/_extbot.py\", line 658, in get_updates\n  File \"/home/technedict/Desktop/ViralPackage/viralcorelib/lib64/python3.13/site-packages/telegram/_bot.py\", line 4593, in get_updates\n  File \"/home/technedict/Desktop/ViralPackage/viralcorelib/lib64/python3.13/site-packages/telegram/_bot.py\", line 691, in _post\n  File \"/home/technedict/Desktop/ViralPackage/viralcorelib/lib64/python3.13/site-packages/telegram/ext/_extbot.py\", line 362, in _do_post\n  File \"/home/technedict/Desktop/ViralPackage/viralcorelib/lib64/python3.13/site-packages/telegram/_bot.py\", line 720, in _do_post\n  File \"/home/technedict/Desktop/ViralPackage/viralcorelib/lib64/python3.13/site-packages/telegram/request/_baserequest.py\", line 197, in post\n  File \"/home/technedict/Desktop/ViralPackage/viralcorelib/lib64/python3.13/site-packages/telegram/request/_baserequest.py\", line 304, in _request_wrapper\n  File \"/home/technedict/Desktop/ViralPackage/viralcorelib/lib64/python3.13/site-packages/telegram/request/_httpxrequest.py\", line 301, in do_request\ntelegram.error.NetworkError: httpx.ReadError: "}
{"timestamp": "2025-09-27T10:44:09.581900Z", "level": "ERROR", "module": "__main__", "message": "Unexpected error while running the bot", "correlation_id": "none", "exception": "Traceback (most recent call last):\n  File \"/home/technedict/Desktop/ViralPackage/viralcorelib/lib64/python3.13/site-packages/httpx/_transports/default.py\", line 101, in map_httpcore_exceptions\n    yield\n  File \"/home/technedict/Desktop/ViralPackage/viralcorelib/lib64/python3.13/site-packages/httpx/_transports/default.py\", line 394, in handle_async_request\n    resp = await self._pool.handle_async_request(req)\n           ^^^^^^^^^^^^^^^^^^^^^^^^^^^^^^^^^^^^^^^^^^\n  File \"/home/technedict/Desktop/ViralPackage/viralcorelib/lib64/python3.13/site-packages/httpcore/_async/connection_pool.py\", line 256, in handle_async_request\n    raise exc from None\n  File \"/home/technedict/Desktop/ViralPackage/viralcorelib/lib64/python3.13/site-packages/httpcore/_async/connection_pool.py\", line 236, in handle_async_request\n    response = await connection.handle_async_request(\n               ^^^^^^^^^^^^^^^^^^^^^^^^^^^^^^^^^^^^^^\n        pool_request.request\n        ^^^^^^^^^^^^^^^^^^^^\n    )\n    ^\n  File \"/home/technedict/Desktop/ViralPackage/viralcorelib/lib64/python3.13/site-packages/httpcore/_async/connection.py\", line 101, in handle_async_request\n    raise exc\n  File \"/home/technedict/Desktop/ViralPackage/viralcorelib/lib64/python3.13/site-packages/httpcore/_async/connection.py\", line 78, in handle_async_request\n    stream = await self._connect(request)\n             ^^^^^^^^^^^^^^^^^^^^^^^^^^^^\n  File \"/home/technedict/Desktop/ViralPackage/viralcorelib/lib64/python3.13/site-packages/httpcore/_async/connection.py\", line 124, in _connect\n    stream = await self._network_backend.connect_tcp(**kwargs)\n             ^^^^^^^^^^^^^^^^^^^^^^^^^^^^^^^^^^^^^^^^^^^^^^^^^\n  File \"/home/technedict/Desktop/ViralPackage/viralcorelib/lib64/python3.13/site-packages/httpcore/_backends/auto.py\", line 31, in connect_tcp\n    return await self._backend.connect_tcp(\n           ^^^^^^^^^^^^^^^^^^^^^^^^^^^^^^^^\n    ...<5 lines>...\n    )\n    ^\n  File \"/home/technedict/Desktop/ViralPackage/viralcorelib/lib64/python3.13/site-packages/httpcore/_backends/anyio.py\", line 113, in connect_tcp\n    with map_exceptions(exc_map):\n         ~~~~~~~~~~~~~~^^^^^^^^^\n  File \"/usr/lib64/python3.13/contextlib.py\", line 162, in __exit__\n    self.gen.throw(value)\n    ~~~~~~~~~~~~~~^^^^^^^\n  File \"/home/technedict/Desktop/ViralPackage/viralcorelib/lib64/python3.13/site-packages/httpcore/_exceptions.py\", line 14, in map_exceptions\n    raise to_exc(exc) from exc\nhttpcore.ConnectError: [Errno -3] Temporary failure in name resolution\n\nThe above exception was the direct cause of the following exception:\n\nTraceback (most recent call last):\n  File \"/home/technedict/Desktop/ViralPackage/viralcorelib/lib64/python3.13/site-packages/telegram/request/_httpxrequest.py\", line 277, in do_request\n    res = await self._client.request(\n          ^^^^^^^^^^^^^^^^^^^^^^^^^^^\n    ...<6 lines>...\n    )\n    ^\n  File \"/home/technedict/Desktop/ViralPackage/viralcorelib/lib64/python3.13/site-packages/httpx/_client.py\", line 1540, in request\n    return await self.send(request, auth=auth, follow_redirects=follow_redirects)\n           ^^^^^^^^^^^^^^^^^^^^^^^^^^^^^^^^^^^^^^^^^^^^^^^^^^^^^^^^^^^^^^^^^^^^^^\n  File \"/home/technedict/Desktop/ViralPackage/viralcorelib/lib64/python3.13/site-packages/httpx/_client.py\", line 1629, in send\n    response = await self._send_handling_auth(\n               ^^^^^^^^^^^^^^^^^^^^^^^^^^^^^^^\n    ...<4 lines>...\n    )\n    ^\n  File \"/home/technedict/Desktop/ViralPackage/viralcorelib/lib64/python3.13/site-packages/httpx/_client.py\", line 1657, in _send_handling_auth\n    response = await self._send_handling_redirects(\n               ^^^^^^^^^^^^^^^^^^^^^^^^^^^^^^^^^^^^\n    ...<3 lines>...\n    )\n    ^\n  File \"/home/technedict/Desktop/ViralPackage/viralcorelib/lib64/python3.13/site-packages/httpx/_client.py\", line 1694, in _send_handling_redirects\n    response = await self._send_single_request(request)\n               ^^^^^^^^^^^^^^^^^^^^^^^^^^^^^^^^^^^^^^^^\n  File \"/home/technedict/Desktop/ViralPackage/viralcorelib/lib64/python3.13/site-packages/httpx/_client.py\", line 1730, in _send_single_request\n    response = await transport.handle_async_request(request)\n               ^^^^^^^^^^^^^^^^^^^^^^^^^^^^^^^^^^^^^^^^^^^^^\n  File \"/home/technedict/Desktop/ViralPackage/viralcorelib/lib64/python3.13/site-packages/httpx/_transports/default.py\", line 393, in handle_async_request\n    with map_httpcore_exceptions():\n         ~~~~~~~~~~~~~~~~~~~~~~~^^\n  File \"/usr/lib64/python3.13/contextlib.py\", line 162, in __exit__\n    self.gen.throw(value)\n    ~~~~~~~~~~~~~~^^^^^^^\n  File \"/home/technedict/Desktop/ViralPackage/viralcorelib/lib64/python3.13/site-packages/httpx/_transports/default.py\", line 118, in map_httpcore_exceptions\n    raise mapped_exc(message) from exc\nhttpx.ConnectError: [Errno -3] Temporary failure in name resolution\n\nThe above exception was the direct cause of the following exception:\n\nTraceback (most recent call last):\n  File \"/home/technedict/Desktop/ViralPackage/viralcore/main_viral_core_bot.py\", line 191, in main\n    await app.initialize()\n  File \"/home/technedict/Desktop/ViralPackage/viralcorelib/lib64/python3.13/site-packages/telegram/ext/_application.py\", line 486, in initialize\n    await self.bot.initialize()\n  File \"/home/technedict/Desktop/ViralPackage/viralcorelib/lib64/python3.13/site-packages/telegram/ext/_extbot.py\", line 308, in initialize\n    await super().initialize()\n  File \"/home/technedict/Desktop/ViralPackage/viralcorelib/lib64/python3.13/site-packages/telegram/_bot.py\", line 835, in initialize\n    await self.get_me()\n  File \"/home/technedict/Desktop/ViralPackage/viralcorelib/lib64/python3.13/site-packages/telegram/ext/_extbot.py\", line 1969, in get_me\n    return await super().get_me(\n           ^^^^^^^^^^^^^^^^^^^^^\n    ...<5 lines>...\n    )\n    ^\n  File \"/home/technedict/Desktop/ViralPackage/viralcorelib/lib64/python3.13/site-packages/telegram/_bot.py\", line 967, in get_me\n    result = await self._post(\n             ^^^^^^^^^^^^^^^^^\n    ...<6 lines>...\n    )\n    ^\n  File \"/home/technedict/Desktop/ViralPackage/viralcorelib/lib64/python3.13/site-packages/telegram/_bot.py\", line 691, in _post\n    return await self._do_post(\n           ^^^^^^^^^^^^^^^^^^^^\n    ...<6 lines>...\n    )\n    ^\n  File \"/home/technedict/Desktop/ViralPackage/viralcorelib/lib64/python3.13/site-packages/telegram/ext/_extbot.py\", line 362, in _do_post\n    return await super()._do_post(\n           ^^^^^^^^^^^^^^^^^^^^^^^\n    ...<6 lines>...\n    )\n    ^\n  File \"/home/technedict/Desktop/ViralPackage/viralcorelib/lib64/python3.13/site-packages/telegram/_bot.py\", line 720, in _do_post\n    result = await request.post(\n             ^^^^^^^^^^^^^^^^^^^\n    ...<6 lines>...\n    )\n    ^\n  File \"/home/technedict/Desktop/ViralPackage/viralcorelib/lib64/python3.13/site-packages/telegram/request/_baserequest.py\", line 197, in post\n    result = await self._request_wrapper(\n             ^^^^^^^^^^^^^^^^^^^^^^^^^^^^\n    ...<7 lines>...\n    )\n    ^\n  File \"/home/technedict/Desktop/ViralPackage/viralcorelib/lib64/python3.13/site-packages/telegram/request/_baserequest.py\", line 304, in _request_wrapper\n    code, payload = await self.do_request(\n                    ^^^^^^^^^^^^^^^^^^^^^^\n    ...<7 lines>...\n    )\n    ^\n  File \"/home/technedict/Desktop/ViralPackage/viralcorelib/lib64/python3.13/site-packages/telegram/request/_httpxrequest.py\", line 301, in do_request\n    raise NetworkError(f\"httpx.{err.__class__.__name__}: {err}\") from err\ntelegram.error.NetworkError: httpx.ConnectError: [Errno -3] Temporary failure in name resolution"}
{"timestamp": "2025-09-27T10:44:09.606352Z", "level": "ERROR", "module": "__main__", "message": "Error during app.stop()", "correlation_id": "none", "exception": "Traceback (most recent call last):\n  File \"/home/technedict/Desktop/ViralPackage/viralcore/main_viral_core_bot.py\", line 241, in main\n    await app.stop()\n  File \"/home/technedict/Desktop/ViralPackage/viralcorelib/lib64/python3.13/site-packages/telegram/ext/_application.py\", line 660, in stop\n    raise RuntimeError(\"This Application is not running!\")\nRuntimeError: This Application is not running!"}
{"timestamp": "2025-09-27T10:44:24.019262Z", "level": "WARNING", "module": "utils.graceful_shutdown", "message": "updater.shutdown() raised: This Updater is still running!", "correlation_id": "none"}
{"timestamp": "2025-09-27T10:44:24.019906Z", "level": "WARNING", "module": "utils.graceful_shutdown", "message": "Shutdown already in progress", "correlation_id": "none"}
{"timestamp": "2025-09-27T10:44:24.035095Z", "level": "ERROR", "module": "__main__", "message": "Error during app.shutdown()", "correlation_id": "none", "exception": "Traceback (most recent call last):\n  File \"/home/technedict/Desktop/ViralPackage/viralcore/main_viral_core_bot.py\", line 247, in main\n    await app.shutdown()\n  File \"/home/technedict/Desktop/ViralPackage/viralcorelib/lib64/python3.13/site-packages/telegram/ext/_application.py\", line 544, in shutdown\n    await self.updater.shutdown()\n  File \"/home/technedict/Desktop/ViralPackage/viralcorelib/lib64/python3.13/site-packages/telegram/ext/_updater.py\", line 196, in shutdown\n    raise RuntimeError(\"This Updater is still running!\")\nRuntimeError: This Updater is still running!"}
{"timestamp": "2025-09-27T10:44:24.114584Z", "level": "ERROR", "module": "asyncio", "message": "Task exception was never retrieved\nfuture: <Task finished name='Task-4' coro=<Updater._start_polling.<locals>.polling_action_cb() done, defined at /home/technedict/Desktop/ViralPackage/viralcorelib/lib64/python3.13/site-packages/telegram/ext/_updater.py:333> exception=NetworkError('httpx.ReadError: ')>", "correlation_id": "none", "exception": "Traceback (most recent call last):\n  File \"/home/technedict/Desktop/ViralPackage/viralcorelib/lib64/python3.13/site-packages/httpx/_transports/default.py\", line 101, in map_httpcore_exceptions\n  File \"/home/technedict/Desktop/ViralPackage/viralcorelib/lib64/python3.13/site-packages/httpx/_transports/default.py\", line 394, in handle_async_request\n  File \"/home/technedict/Desktop/ViralPackage/viralcorelib/lib64/python3.13/site-packages/httpcore/_async/connection_pool.py\", line 256, in handle_async_request\n  File \"/home/technedict/Desktop/ViralPackage/viralcorelib/lib64/python3.13/site-packages/httpcore/_async/connection_pool.py\", line 236, in handle_async_request\n  File \"/home/technedict/Desktop/ViralPackage/viralcorelib/lib64/python3.13/site-packages/httpcore/_async/connection.py\", line 103, in handle_async_request\n  File \"/home/technedict/Desktop/ViralPackage/viralcorelib/lib64/python3.13/site-packages/httpcore/_async/http11.py\", line 136, in handle_async_request\n  File \"/home/technedict/Desktop/ViralPackage/viralcorelib/lib64/python3.13/site-packages/httpcore/_async/http11.py\", line 106, in handle_async_request\n  File \"/home/technedict/Desktop/ViralPackage/viralcorelib/lib64/python3.13/site-packages/httpcore/_async/http11.py\", line 177, in _receive_response_headers\n  File \"/home/technedict/Desktop/ViralPackage/viralcorelib/lib64/python3.13/site-packages/httpcore/_async/http11.py\", line 217, in _receive_event\n  File \"/home/technedict/Desktop/ViralPackage/viralcorelib/lib64/python3.13/site-packages/httpcore/_backends/anyio.py\", line 32, in read\n  File \"/usr/lib64/python3.13/contextlib.py\", line 162, in __exit__\n  File \"/home/technedict/Desktop/ViralPackage/viralcorelib/lib64/python3.13/site-packages/httpcore/_exceptions.py\", line 14, in map_exceptions\nhttpcore.ReadError\n\nThe above exception was the direct cause of the following exception:\n\nTraceback (most recent call last):\n  File \"/home/technedict/Desktop/ViralPackage/viralcorelib/lib64/python3.13/site-packages/telegram/request/_httpxrequest.py\", line 277, in do_request\n  File \"/home/technedict/Desktop/ViralPackage/viralcorelib/lib64/python3.13/site-packages/httpx/_client.py\", line 1540, in request\n  File \"/home/technedict/Desktop/ViralPackage/viralcorelib/lib64/python3.13/site-packages/httpx/_client.py\", line 1629, in send\n  File \"/home/technedict/Desktop/ViralPackage/viralcorelib/lib64/python3.13/site-packages/httpx/_client.py\", line 1657, in _send_handling_auth\n  File \"/home/technedict/Desktop/ViralPackage/viralcorelib/lib64/python3.13/site-packages/httpx/_client.py\", line 1694, in _send_handling_redirects\n  File \"/home/technedict/Desktop/ViralPackage/viralcorelib/lib64/python3.13/site-packages/httpx/_client.py\", line 1730, in _send_single_request\n  File \"/home/technedict/Desktop/ViralPackage/viralcorelib/lib64/python3.13/site-packages/httpx/_transports/default.py\", line 393, in handle_async_request\n  File \"/usr/lib64/python3.13/contextlib.py\", line 162, in __exit__\n  File \"/home/technedict/Desktop/ViralPackage/viralcorelib/lib64/python3.13/site-packages/httpx/_transports/default.py\", line 118, in map_httpcore_exceptions\nhttpx.ReadError\n\nThe above exception was the direct cause of the following exception:\n\nTraceback (most recent call last):\n  File \"/home/technedict/Desktop/ViralPackage/viralcorelib/lib64/python3.13/site-packages/telegram/ext/_updater.py\", line 335, in polling_action_cb\n    updates = await self.bot.get_updates(\n              ^^^^^^^^^^^^^^^^^^^^^^^^^^^\n    ...<3 lines>...\n    )\n    ^\n  File \"/home/technedict/Desktop/ViralPackage/viralcorelib/lib64/python3.13/site-packages/telegram/ext/_extbot.py\", line 658, in get_updates\n  File \"/home/technedict/Desktop/ViralPackage/viralcorelib/lib64/python3.13/site-packages/telegram/_bot.py\", line 4593, in get_updates\n  File \"/home/technedict/Desktop/ViralPackage/viralcorelib/lib64/python3.13/site-packages/telegram/_bot.py\", line 691, in _post\n  File \"/home/technedict/Desktop/ViralPackage/viralcorelib/lib64/python3.13/site-packages/telegram/ext/_extbot.py\", line 362, in _do_post\n  File \"/home/technedict/Desktop/ViralPackage/viralcorelib/lib64/python3.13/site-packages/telegram/_bot.py\", line 720, in _do_post\n  File \"/home/technedict/Desktop/ViralPackage/viralcorelib/lib64/python3.13/site-packages/telegram/request/_baserequest.py\", line 197, in post\n  File \"/home/technedict/Desktop/ViralPackage/viralcorelib/lib64/python3.13/site-packages/telegram/request/_baserequest.py\", line 304, in _request_wrapper\n  File \"/home/technedict/Desktop/ViralPackage/viralcorelib/lib64/python3.13/site-packages/telegram/request/_httpxrequest.py\", line 301, in do_request\ntelegram.error.NetworkError: httpx.ReadError: "}
{"timestamp": "2025-09-27T10:44:32.264637Z", "level": "WARNING", "module": "utils.graceful_shutdown", "message": "updater.shutdown() raised: This Updater is still running!", "correlation_id": "none"}
{"timestamp": "2025-09-27T10:44:32.266039Z", "level": "WARNING", "module": "utils.graceful_shutdown", "message": "Shutdown already in progress", "correlation_id": "none"}
{"timestamp": "2025-09-27T10:44:32.281605Z", "level": "ERROR", "module": "__main__", "message": "Error during app.shutdown()", "correlation_id": "none", "exception": "Traceback (most recent call last):\n  File \"/home/technedict/Desktop/ViralPackage/viralcore/main_viral_core_bot.py\", line 247, in main\n    await app.shutdown()\n  File \"/home/technedict/Desktop/ViralPackage/viralcorelib/lib64/python3.13/site-packages/telegram/ext/_application.py\", line 544, in shutdown\n    await self.updater.shutdown()\n  File \"/home/technedict/Desktop/ViralPackage/viralcorelib/lib64/python3.13/site-packages/telegram/ext/_updater.py\", line 196, in shutdown\n    raise RuntimeError(\"This Updater is still running!\")\nRuntimeError: This Updater is still running!"}
{"timestamp": "2025-09-27T10:44:32.385883Z", "level": "ERROR", "module": "asyncio", "message": "Task exception was never retrieved\nfuture: <Task finished name='Task-4' coro=<Updater._start_polling.<locals>.polling_action_cb() done, defined at /home/technedict/Desktop/ViralPackage/viralcorelib/lib64/python3.13/site-packages/telegram/ext/_updater.py:333> exception=NetworkError('httpx.ReadError: ')>", "correlation_id": "none", "exception": "Traceback (most recent call last):\n  File \"/home/technedict/Desktop/ViralPackage/viralcorelib/lib64/python3.13/site-packages/httpx/_transports/default.py\", line 101, in map_httpcore_exceptions\n  File \"/home/technedict/Desktop/ViralPackage/viralcorelib/lib64/python3.13/site-packages/httpx/_transports/default.py\", line 394, in handle_async_request\n  File \"/home/technedict/Desktop/ViralPackage/viralcorelib/lib64/python3.13/site-packages/httpcore/_async/connection_pool.py\", line 256, in handle_async_request\n  File \"/home/technedict/Desktop/ViralPackage/viralcorelib/lib64/python3.13/site-packages/httpcore/_async/connection_pool.py\", line 236, in handle_async_request\n  File \"/home/technedict/Desktop/ViralPackage/viralcorelib/lib64/python3.13/site-packages/httpcore/_async/connection.py\", line 103, in handle_async_request\n  File \"/home/technedict/Desktop/ViralPackage/viralcorelib/lib64/python3.13/site-packages/httpcore/_async/http11.py\", line 136, in handle_async_request\n  File \"/home/technedict/Desktop/ViralPackage/viralcorelib/lib64/python3.13/site-packages/httpcore/_async/http11.py\", line 106, in handle_async_request\n  File \"/home/technedict/Desktop/ViralPackage/viralcorelib/lib64/python3.13/site-packages/httpcore/_async/http11.py\", line 177, in _receive_response_headers\n  File \"/home/technedict/Desktop/ViralPackage/viralcorelib/lib64/python3.13/site-packages/httpcore/_async/http11.py\", line 217, in _receive_event\n  File \"/home/technedict/Desktop/ViralPackage/viralcorelib/lib64/python3.13/site-packages/httpcore/_backends/anyio.py\", line 32, in read\n  File \"/usr/lib64/python3.13/contextlib.py\", line 162, in __exit__\n  File \"/home/technedict/Desktop/ViralPackage/viralcorelib/lib64/python3.13/site-packages/httpcore/_exceptions.py\", line 14, in map_exceptions\nhttpcore.ReadError\n\nThe above exception was the direct cause of the following exception:\n\nTraceback (most recent call last):\n  File \"/home/technedict/Desktop/ViralPackage/viralcorelib/lib64/python3.13/site-packages/telegram/request/_httpxrequest.py\", line 277, in do_request\n  File \"/home/technedict/Desktop/ViralPackage/viralcorelib/lib64/python3.13/site-packages/httpx/_client.py\", line 1540, in request\n  File \"/home/technedict/Desktop/ViralPackage/viralcorelib/lib64/python3.13/site-packages/httpx/_client.py\", line 1629, in send\n  File \"/home/technedict/Desktop/ViralPackage/viralcorelib/lib64/python3.13/site-packages/httpx/_client.py\", line 1657, in _send_handling_auth\n  File \"/home/technedict/Desktop/ViralPackage/viralcorelib/lib64/python3.13/site-packages/httpx/_client.py\", line 1694, in _send_handling_redirects\n  File \"/home/technedict/Desktop/ViralPackage/viralcorelib/lib64/python3.13/site-packages/httpx/_client.py\", line 1730, in _send_single_request\n  File \"/home/technedict/Desktop/ViralPackage/viralcorelib/lib64/python3.13/site-packages/httpx/_transports/default.py\", line 393, in handle_async_request\n  File \"/usr/lib64/python3.13/contextlib.py\", line 162, in __exit__\n  File \"/home/technedict/Desktop/ViralPackage/viralcorelib/lib64/python3.13/site-packages/httpx/_transports/default.py\", line 118, in map_httpcore_exceptions\nhttpx.ReadError\n\nThe above exception was the direct cause of the following exception:\n\nTraceback (most recent call last):\n  File \"/home/technedict/Desktop/ViralPackage/viralcorelib/lib64/python3.13/site-packages/telegram/ext/_updater.py\", line 335, in polling_action_cb\n    updates = await self.bot.get_updates(\n              ^^^^^^^^^^^^^^^^^^^^^^^^^^^\n    ...<3 lines>...\n    )\n    ^\n  File \"/home/technedict/Desktop/ViralPackage/viralcorelib/lib64/python3.13/site-packages/telegram/ext/_extbot.py\", line 658, in get_updates\n  File \"/home/technedict/Desktop/ViralPackage/viralcorelib/lib64/python3.13/site-packages/telegram/_bot.py\", line 4593, in get_updates\n  File \"/home/technedict/Desktop/ViralPackage/viralcorelib/lib64/python3.13/site-packages/telegram/_bot.py\", line 691, in _post\n  File \"/home/technedict/Desktop/ViralPackage/viralcorelib/lib64/python3.13/site-packages/telegram/ext/_extbot.py\", line 362, in _do_post\n  File \"/home/technedict/Desktop/ViralPackage/viralcorelib/lib64/python3.13/site-packages/telegram/_bot.py\", line 720, in _do_post\n  File \"/home/technedict/Desktop/ViralPackage/viralcorelib/lib64/python3.13/site-packages/telegram/request/_baserequest.py\", line 197, in post\n  File \"/home/technedict/Desktop/ViralPackage/viralcorelib/lib64/python3.13/site-packages/telegram/request/_baserequest.py\", line 304, in _request_wrapper\n  File \"/home/technedict/Desktop/ViralPackage/viralcorelib/lib64/python3.13/site-packages/telegram/request/_httpxrequest.py\", line 301, in do_request\ntelegram.error.NetworkError: httpx.ReadError: "}
