{"timestamp": "2025-09-28T18:24:27.283667Z", "level": "WARNING", "module": "utils.graceful_shutdown", "message": "updater.shutdown() raised: This Updater is still running!", "correlation_id": "none"}
{"timestamp": "2025-09-28T18:24:27.304491Z", "level": "WARNING", "module": "utils.graceful_shutdown", "message": "Shutdown already in progress", "correlation_id": "none"}
{"timestamp": "2025-09-28T18:24:27.382426Z", "level": "ERROR", "module": "__main__", "message": "Error during app.shutdown()", "correlation_id": "none", "exception": "Traceback (most recent call last):\n  File \"/home/technedict/Desktop/ViralPackage/viralcore/main_viral_core_bot.py\", line 301, in main\n    await app.shutdown()\n  File \"/home/technedict/Desktop/ViralPackage/viralcorelib/lib64/python3.13/site-packages/telegram/ext/_application.py\", line 561, in shutdown\n    await self.updater.shutdown()\n  File \"/home/technedict/Desktop/ViralPackage/viralcorelib/lib64/python3.13/site-packages/telegram/ext/_updater.py\", line 204, in shutdown\n    raise RuntimeError(\"This Updater is still running!\")\nRuntimeError: This Updater is still running!"}
{"timestamp": "2025-09-28T18:24:28.241802Z", "level": "ERROR", "module": "asyncio", "message": "Task exception was never retrieved\nfuture: <Task finished name='Task-4' coro=<Updater._start_polling.<locals>.polling_action_cb() done, defined at /home/technedict/Desktop/ViralPackage/viralcorelib/lib64/python3.13/site-packages/telegram/ext/_updater.py:375> exception=NetworkError('httpx.ReadError: ')>", "correlation_id": "none", "exception": "Traceback (most recent call last):\n  File \"/home/technedict/Desktop/ViralPackage/viralcorelib/lib64/python3.13/site-packages/httpx/_transports/default.py\", line 101, in map_httpcore_exceptions\n  File \"/home/technedict/Desktop/ViralPackage/viralcorelib/lib64/python3.13/site-packages/httpx/_transports/default.py\", line 394, in handle_async_request\n  File \"/home/technedict/Desktop/ViralPackage/viralcorelib/lib64/python3.13/site-packages/httpcore/_async/connection_pool.py\", line 256, in handle_async_request\n  File \"/home/technedict/Desktop/ViralPackage/viralcorelib/lib64/python3.13/site-packages/httpcore/_async/connection_pool.py\", line 236, in handle_async_request\n  File \"/home/technedict/Desktop/ViralPackage/viralcorelib/lib64/python3.13/site-packages/httpcore/_async/connection.py\", line 103, in handle_async_request\n  File \"/home/technedict/Desktop/ViralPackage/viralcorelib/lib64/python3.13/site-packages/httpcore/_async/http11.py\", line 136, in handle_async_request\n  File \"/home/technedict/Desktop/ViralPackage/viralcorelib/lib64/python3.13/site-packages/httpcore/_async/http11.py\", line 106, in handle_async_request\n  File \"/home/technedict/Desktop/ViralPackage/viralcorelib/lib64/python3.13/site-packages/httpcore/_async/http11.py\", line 177, in _receive_response_headers\n  File \"/home/technedict/Desktop/ViralPackage/viralcorelib/lib64/python3.13/site-packages/httpcore/_async/http11.py\", line 217, in _receive_event\n  File \"/home/technedict/Desktop/ViralPackage/viralcorelib/lib64/python3.13/site-packages/httpcore/_backends/anyio.py\", line 32, in read\n  File \"/usr/lib64/python3.13/contextlib.py\", line 162, in __exit__\n  File \"/home/technedict/Desktop/ViralPackage/viralcorelib/lib64/python3.13/site-packages/httpcore/_exceptions.py\", line 14, in map_exceptions\nhttpcore.ReadError\n\nThe above exception was the direct cause of the following exception:\n\nTraceback (most recent call last):\n  File \"/home/technedict/Desktop/ViralPackage/viralcorelib/lib64/python3.13/site-packages/telegram/request/_httpxrequest.py\", line 276, in do_request\n  File \"/home/technedict/Desktop/ViralPackage/viralcorelib/lib64/python3.13/site-packages/httpx/_client.py\", line 1540, in request\n  File \"/home/technedict/Desktop/ViralPackage/viralcorelib/lib64/python3.13/site-packages/httpx/_client.py\", line 1629, in send\n  File \"/home/technedict/Desktop/ViralPackage/viralcorelib/lib64/python3.13/site-packages/httpx/_client.py\", line 1657, in _send_handling_auth\n  File \"/home/technedict/Desktop/ViralPackage/viralcorelib/lib64/python3.13/site-packages/httpx/_client.py\", line 1694, in _send_handling_redirects\n  File \"/home/technedict/Desktop/ViralPackage/viralcorelib/lib64/python3.13/site-packages/httpx/_client.py\", line 1730, in _send_single_request\n  File \"/home/technedict/Desktop/ViralPackage/viralcorelib/lib64/python3.13/site-packages/httpx/_transports/default.py\", line 393, in handle_async_request\n  File \"/usr/lib64/python3.13/contextlib.py\", line 162, in __exit__\n  File \"/home/technedict/Desktop/ViralPackage/viralcorelib/lib64/python3.13/site-packages/httpx/_transports/default.py\", line 118, in map_httpcore_exceptions\nhttpx.ReadError\n\nThe above exception was the direct cause of the following exception:\n\nTraceback (most recent call last):\n  File \"/home/technedict/Desktop/ViralPackage/viralcorelib/lib64/python3.13/site-packages/telegram/ext/_updater.py\", line 377, in polling_action_cb\n    updates = await self.bot.get_updates(\n              ^^^^^^^^^^^^^^^^^^^^^^^^^^^\n    ...<7 lines>...\n    )\n    ^\n  File \"/home/technedict/Desktop/ViralPackage/viralcorelib/lib64/python3.13/site-packages/telegram/ext/_extbot.py\", line 649, in get_updates\n  File \"/home/technedict/Desktop/ViralPackage/viralcorelib/lib64/python3.13/site-packages/telegram/_bot.py\", line 4366, in get_updates\n  File \"/home/technedict/Desktop/ViralPackage/viralcorelib/lib64/python3.13/site-packages/telegram/_bot.py\", line 623, in _post\n  File \"/home/technedict/Desktop/ViralPackage/viralcorelib/lib64/python3.13/site-packages/telegram/ext/_extbot.py\", line 355, in _do_post\n  File \"/home/technedict/Desktop/ViralPackage/viralcorelib/lib64/python3.13/site-packages/telegram/_bot.py\", line 652, in _do_post\n  File \"/home/technedict/Desktop/ViralPackage/viralcorelib/lib64/python3.13/site-packages/telegram/request/_baserequest.py\", line 201, in post\n  File \"/home/technedict/Desktop/ViralPackage/viralcorelib/lib64/python3.13/site-packages/telegram/request/_baserequest.py\", line 333, in _request_wrapper\n  File \"/home/technedict/Desktop/ViralPackage/viralcorelib/lib64/python3.13/site-packages/telegram/request/_httpxrequest.py\", line 300, in do_request\ntelegram.error.NetworkError: httpx.ReadError: "}
{"timestamp": "2025-09-29T08:18:28.718947Z", "level": "ERROR", "module": "telegram.ext.Application", "message": "No error handlers are registered, logging exception.", "correlation_id": "none", "exception": "Traceback (most recent call last):\n  File \"/home/technedict/Desktop/ViralPackage/viralcorelib/lib64/python3.13/site-packages/telegram/ext/_application.py\", line 1335, in process_update\n    await coroutine\n  File \"/home/technedict/Desktop/ViralPackage/viralcorelib/lib64/python3.13/site-packages/telegram/ext/_handlers/basehandler.py\", line 157, in handle_update\n    return await self.callback(update, context)\n           ^^^^^^^^^^^^^^^^^^^^^^^^^^^^^^^^^^^^\n  File \"/home/technedict/Desktop/ViralPackage/viralcore/handlers/message_handler.py\", line 57, in message_router\n    await custom_order_handler(update, context) # Or a general_message_handler\n    ^^^^^^^^^^^^^^^^^^^^^^^^^^^^^^^^^^^^^^^^^^^\n  File \"/home/technedict/Desktop/ViralPackage/viralcore/handlers/custom_order_handlers.py\", line 31, in custom_order_handler\n    text = update.message.text.strip()\n           ^^^^^^^^^^^^^^^^^^^\nAttributeError: 'NoneType' object has no attribute 'text'"}
{"timestamp": "2025-09-29T08:18:28.725068Z", "level": "ERROR", "module": "telegram.ext.Application", "message": "No error handlers are registered, logging exception.", "correlation_id": "none", "exception": "Traceback (most recent call last):\n  File \"/home/technedict/Desktop/ViralPackage/viralcorelib/lib64/python3.13/site-packages/telegram/ext/_application.py\", line 1335, in process_update\n    await coroutine\n  File \"/home/technedict/Desktop/ViralPackage/viralcorelib/lib64/python3.13/site-packages/telegram/ext/_handlers/basehandler.py\", line 157, in handle_update\n    return await self.callback(update, context)\n           ^^^^^^^^^^^^^^^^^^^^^^^^^^^^^^^^^^^^\n  File \"/home/technedict/Desktop/ViralPackage/viralcore/handlers/message_handler.py\", line 57, in message_router\n    await custom_order_handler(update, context) # Or a general_message_handler\n    ^^^^^^^^^^^^^^^^^^^^^^^^^^^^^^^^^^^^^^^^^^^\n  File \"/home/technedict/Desktop/ViralPackage/viralcore/handlers/custom_order_handlers.py\", line 31, in custom_order_handler\n    text = update.message.text.strip()\n           ^^^^^^^^^^^^^^^^^^^\nAttributeError: 'NoneType' object has no attribute 'text'"}
{"timestamp": "2025-09-29T08:18:28.731147Z", "level": "ERROR", "module": "telegram.ext.Application", "message": "No error handlers are registered, logging exception.", "correlation_id": "none", "exception": "Traceback (most recent call last):\n  File \"/home/technedict/Desktop/ViralPackage/viralcorelib/lib64/python3.13/site-packages/telegram/ext/_application.py\", line 1335, in process_update\n    await coroutine\n  File \"/home/technedict/Desktop/ViralPackage/viralcorelib/lib64/python3.13/site-packages/telegram/ext/_handlers/basehandler.py\", line 157, in handle_update\n    return await self.callback(update, context)\n           ^^^^^^^^^^^^^^^^^^^^^^^^^^^^^^^^^^^^\n  File \"/home/technedict/Desktop/ViralPackage/viralcore/handlers/message_handler.py\", line 57, in message_router\n    await custom_order_handler(update, context) # Or a general_message_handler\n    ^^^^^^^^^^^^^^^^^^^^^^^^^^^^^^^^^^^^^^^^^^^\n  File \"/home/technedict/Desktop/ViralPackage/viralcore/handlers/custom_order_handlers.py\", line 31, in custom_order_handler\n    text = update.message.text.strip()\n           ^^^^^^^^^^^^^^^^^^^\nAttributeError: 'NoneType' object has no attribute 'text'"}
{"timestamp": "2025-09-29T08:18:28.738517Z", "level": "ERROR", "module": "telegram.ext.Application", "message": "No error handlers are registered, logging exception.", "correlation_id": "none", "exception": "Traceback (most recent call last):\n  File \"/home/technedict/Desktop/ViralPackage/viralcorelib/lib64/python3.13/site-packages/telegram/ext/_application.py\", line 1335, in process_update\n    await coroutine\n  File \"/home/technedict/Desktop/ViralPackage/viralcorelib/lib64/python3.13/site-packages/telegram/ext/_handlers/basehandler.py\", line 157, in handle_update\n    return await self.callback(update, context)\n           ^^^^^^^^^^^^^^^^^^^^^^^^^^^^^^^^^^^^\n  File \"/home/technedict/Desktop/ViralPackage/viralcore/handlers/message_handler.py\", line 57, in message_router\n    await custom_order_handler(update, context) # Or a general_message_handler\n    ^^^^^^^^^^^^^^^^^^^^^^^^^^^^^^^^^^^^^^^^^^^\n  File \"/home/technedict/Desktop/ViralPackage/viralcore/handlers/custom_order_handlers.py\", line 31, in custom_order_handler\n    text = update.message.text.strip()\n           ^^^^^^^^^^^^^^^^^^^\nAttributeError: 'NoneType' object has no attribute 'text'"}
{"timestamp": "2025-09-29T08:18:28.746503Z", "level": "ERROR", "module": "telegram.ext.Application", "message": "No error handlers are registered, logging exception.", "correlation_id": "none", "exception": "Traceback (most recent call last):\n  File \"/home/technedict/Desktop/ViralPackage/viralcorelib/lib64/python3.13/site-packages/telegram/ext/_application.py\", line 1335, in process_update\n    await coroutine\n  File \"/home/technedict/Desktop/ViralPackage/viralcorelib/lib64/python3.13/site-packages/telegram/ext/_handlers/basehandler.py\", line 157, in handle_update\n    return await self.callback(update, context)\n           ^^^^^^^^^^^^^^^^^^^^^^^^^^^^^^^^^^^^\n  File \"/home/technedict/Desktop/ViralPackage/viralcore/handlers/message_handler.py\", line 57, in message_router\n    await custom_order_handler(update, context) # Or a general_message_handler\n    ^^^^^^^^^^^^^^^^^^^^^^^^^^^^^^^^^^^^^^^^^^^\n  File \"/home/technedict/Desktop/ViralPackage/viralcore/handlers/custom_order_handlers.py\", line 31, in custom_order_handler\n    text = update.message.text.strip()\n           ^^^^^^^^^^^^^^^^^^^\nAttributeError: 'NoneType' object has no attribute 'text'"}
{"timestamp": "2025-09-29T08:18:28.756838Z", "level": "ERROR", "module": "telegram.ext.Application", "message": "No error handlers are registered, logging exception.", "correlation_id": "none", "exception": "Traceback (most recent call last):\n  File \"/home/technedict/Desktop/ViralPackage/viralcorelib/lib64/python3.13/site-packages/telegram/ext/_application.py\", line 1335, in process_update\n    await coroutine\n  File \"/home/technedict/Desktop/ViralPackage/viralcorelib/lib64/python3.13/site-packages/telegram/ext/_handlers/basehandler.py\", line 157, in handle_update\n    return await self.callback(update, context)\n           ^^^^^^^^^^^^^^^^^^^^^^^^^^^^^^^^^^^^\n  File \"/home/technedict/Desktop/ViralPackage/viralcore/handlers/message_handler.py\", line 57, in message_router\n    await custom_order_handler(update, context) # Or a general_message_handler\n    ^^^^^^^^^^^^^^^^^^^^^^^^^^^^^^^^^^^^^^^^^^^\n  File \"/home/technedict/Desktop/ViralPackage/viralcore/handlers/custom_order_handlers.py\", line 31, in custom_order_handler\n    text = update.message.text.strip()\n           ^^^^^^^^^^^^^^^^^^^\nAttributeError: 'NoneType' object has no attribute 'text'"}
{"timestamp": "2025-09-29T08:18:28.765074Z", "level": "ERROR", "module": "telegram.ext.Application", "message": "No error handlers are registered, logging exception.", "correlation_id": "none", "exception": "Traceback (most recent call last):\n  File \"/home/technedict/Desktop/ViralPackage/viralcorelib/lib64/python3.13/site-packages/telegram/ext/_application.py\", line 1335, in process_update\n    await coroutine\n  File \"/home/technedict/Desktop/ViralPackage/viralcorelib/lib64/python3.13/site-packages/telegram/ext/_handlers/basehandler.py\", line 157, in handle_update\n    return await self.callback(update, context)\n           ^^^^^^^^^^^^^^^^^^^^^^^^^^^^^^^^^^^^\n  File \"/home/technedict/Desktop/ViralPackage/viralcore/handlers/message_handler.py\", line 57, in message_router\n    await custom_order_handler(update, context) # Or a general_message_handler\n    ^^^^^^^^^^^^^^^^^^^^^^^^^^^^^^^^^^^^^^^^^^^\n  File \"/home/technedict/Desktop/ViralPackage/viralcore/handlers/custom_order_handlers.py\", line 31, in custom_order_handler\n    text = update.message.text.strip()\n           ^^^^^^^^^^^^^^^^^^^\nAttributeError: 'NoneType' object has no attribute 'text'"}
{"timestamp": "2025-09-29T08:18:28.771111Z", "level": "ERROR", "module": "telegram.ext.Application", "message": "No error handlers are registered, logging exception.", "correlation_id": "none", "exception": "Traceback (most recent call last):\n  File \"/home/technedict/Desktop/ViralPackage/viralcorelib/lib64/python3.13/site-packages/telegram/ext/_application.py\", line 1335, in process_update\n    await coroutine\n  File \"/home/technedict/Desktop/ViralPackage/viralcorelib/lib64/python3.13/site-packages/telegram/ext/_handlers/basehandler.py\", line 157, in handle_update\n    return await self.callback(update, context)\n           ^^^^^^^^^^^^^^^^^^^^^^^^^^^^^^^^^^^^\n  File \"/home/technedict/Desktop/ViralPackage/viralcore/handlers/message_handler.py\", line 57, in message_router\n    await custom_order_handler(update, context) # Or a general_message_handler\n    ^^^^^^^^^^^^^^^^^^^^^^^^^^^^^^^^^^^^^^^^^^^\n  File \"/home/technedict/Desktop/ViralPackage/viralcore/handlers/custom_order_handlers.py\", line 31, in custom_order_handler\n    text = update.message.text.strip()\n           ^^^^^^^^^^^^^^^^^^^\nAttributeError: 'NoneType' object has no attribute 'text'"}
{"timestamp": "2025-09-29T08:18:28.776261Z", "level": "ERROR", "module": "telegram.ext.Application", "message": "No error handlers are registered, logging exception.", "correlation_id": "none", "exception": "Traceback (most recent call last):\n  File \"/home/technedict/Desktop/ViralPackage/viralcorelib/lib64/python3.13/site-packages/telegram/ext/_application.py\", line 1335, in process_update\n    await coroutine\n  File \"/home/technedict/Desktop/ViralPackage/viralcorelib/lib64/python3.13/site-packages/telegram/ext/_handlers/basehandler.py\", line 157, in handle_update\n    return await self.callback(update, context)\n           ^^^^^^^^^^^^^^^^^^^^^^^^^^^^^^^^^^^^\n  File \"/home/technedict/Desktop/ViralPackage/viralcore/handlers/message_handler.py\", line 57, in message_router\n    await custom_order_handler(update, context) # Or a general_message_handler\n    ^^^^^^^^^^^^^^^^^^^^^^^^^^^^^^^^^^^^^^^^^^^\n  File \"/home/technedict/Desktop/ViralPackage/viralcore/handlers/custom_order_handlers.py\", line 31, in custom_order_handler\n    text = update.message.text.strip()\n           ^^^^^^^^^^^^^^^^^^^\nAttributeError: 'NoneType' object has no attribute 'text'"}
{"timestamp": "2025-09-29T08:18:28.781464Z", "level": "ERROR", "module": "telegram.ext.Application", "message": "No error handlers are registered, logging exception.", "correlation_id": "none", "exception": "Traceback (most recent call last):\n  File \"/home/technedict/Desktop/ViralPackage/viralcorelib/lib64/python3.13/site-packages/telegram/ext/_application.py\", line 1335, in process_update\n    await coroutine\n  File \"/home/technedict/Desktop/ViralPackage/viralcorelib/lib64/python3.13/site-packages/telegram/ext/_handlers/basehandler.py\", line 157, in handle_update\n    return await self.callback(update, context)\n           ^^^^^^^^^^^^^^^^^^^^^^^^^^^^^^^^^^^^\n  File \"/home/technedict/Desktop/ViralPackage/viralcore/handlers/message_handler.py\", line 57, in message_router\n    await custom_order_handler(update, context) # Or a general_message_handler\n    ^^^^^^^^^^^^^^^^^^^^^^^^^^^^^^^^^^^^^^^^^^^\n  File \"/home/technedict/Desktop/ViralPackage/viralcore/handlers/custom_order_handlers.py\", line 31, in custom_order_handler\n    text = update.message.text.strip()\n           ^^^^^^^^^^^^^^^^^^^\nAttributeError: 'NoneType' object has no attribute 'text'"}
{"timestamp": "2025-09-29T08:18:28.787611Z", "level": "ERROR", "module": "telegram.ext.Application", "message": "No error handlers are registered, logging exception.", "correlation_id": "none", "exception": "Traceback (most recent call last):\n  File \"/home/technedict/Desktop/ViralPackage/viralcorelib/lib64/python3.13/site-packages/telegram/ext/_application.py\", line 1335, in process_update\n    await coroutine\n  File \"/home/technedict/Desktop/ViralPackage/viralcorelib/lib64/python3.13/site-packages/telegram/ext/_handlers/basehandler.py\", line 157, in handle_update\n    return await self.callback(update, context)\n           ^^^^^^^^^^^^^^^^^^^^^^^^^^^^^^^^^^^^\n  File \"/home/technedict/Desktop/ViralPackage/viralcore/handlers/message_handler.py\", line 57, in message_router\n    await custom_order_handler(update, context) # Or a general_message_handler\n    ^^^^^^^^^^^^^^^^^^^^^^^^^^^^^^^^^^^^^^^^^^^\n  File \"/home/technedict/Desktop/ViralPackage/viralcore/handlers/custom_order_handlers.py\", line 31, in custom_order_handler\n    text = update.message.text.strip()\n           ^^^^^^^^^^^^^^^^^^^\nAttributeError: 'NoneType' object has no attribute 'text'"}
{"timestamp": "2025-09-29T08:18:28.793824Z", "level": "ERROR", "module": "telegram.ext.Application", "message": "No error handlers are registered, logging exception.", "correlation_id": "none", "exception": "Traceback (most recent call last):\n  File \"/home/technedict/Desktop/ViralPackage/viralcorelib/lib64/python3.13/site-packages/telegram/ext/_application.py\", line 1335, in process_update\n    await coroutine\n  File \"/home/technedict/Desktop/ViralPackage/viralcorelib/lib64/python3.13/site-packages/telegram/ext/_handlers/basehandler.py\", line 157, in handle_update\n    return await self.callback(update, context)\n           ^^^^^^^^^^^^^^^^^^^^^^^^^^^^^^^^^^^^\n  File \"/home/technedict/Desktop/ViralPackage/viralcore/handlers/message_handler.py\", line 57, in message_router\n    await custom_order_handler(update, context) # Or a general_message_handler\n    ^^^^^^^^^^^^^^^^^^^^^^^^^^^^^^^^^^^^^^^^^^^\n  File \"/home/technedict/Desktop/ViralPackage/viralcore/handlers/custom_order_handlers.py\", line 31, in custom_order_handler\n    text = update.message.text.strip()\n           ^^^^^^^^^^^^^^^^^^^\nAttributeError: 'NoneType' object has no attribute 'text'"}
{"timestamp": "2025-09-29T08:18:28.799510Z", "level": "ERROR", "module": "telegram.ext.Application", "message": "No error handlers are registered, logging exception.", "correlation_id": "none", "exception": "Traceback (most recent call last):\n  File \"/home/technedict/Desktop/ViralPackage/viralcorelib/lib64/python3.13/site-packages/telegram/ext/_application.py\", line 1335, in process_update\n    await coroutine\n  File \"/home/technedict/Desktop/ViralPackage/viralcorelib/lib64/python3.13/site-packages/telegram/ext/_handlers/basehandler.py\", line 157, in handle_update\n    return await self.callback(update, context)\n           ^^^^^^^^^^^^^^^^^^^^^^^^^^^^^^^^^^^^\n  File \"/home/technedict/Desktop/ViralPackage/viralcore/handlers/message_handler.py\", line 57, in message_router\n    await custom_order_handler(update, context) # Or a general_message_handler\n    ^^^^^^^^^^^^^^^^^^^^^^^^^^^^^^^^^^^^^^^^^^^\n  File \"/home/technedict/Desktop/ViralPackage/viralcore/handlers/custom_order_handlers.py\", line 31, in custom_order_handler\n    text = update.message.text.strip()\n           ^^^^^^^^^^^^^^^^^^^\nAttributeError: 'NoneType' object has no attribute 'text'"}
{"timestamp": "2025-09-29T08:18:28.806332Z", "level": "ERROR", "module": "telegram.ext.Application", "message": "No error handlers are registered, logging exception.", "correlation_id": "none", "exception": "Traceback (most recent call last):\n  File \"/home/technedict/Desktop/ViralPackage/viralcorelib/lib64/python3.13/site-packages/telegram/ext/_application.py\", line 1335, in process_update\n    await coroutine\n  File \"/home/technedict/Desktop/ViralPackage/viralcorelib/lib64/python3.13/site-packages/telegram/ext/_handlers/basehandler.py\", line 157, in handle_update\n    return await self.callback(update, context)\n           ^^^^^^^^^^^^^^^^^^^^^^^^^^^^^^^^^^^^\n  File \"/home/technedict/Desktop/ViralPackage/viralcore/handlers/message_handler.py\", line 57, in message_router\n    await custom_order_handler(update, context) # Or a general_message_handler\n    ^^^^^^^^^^^^^^^^^^^^^^^^^^^^^^^^^^^^^^^^^^^\n  File \"/home/technedict/Desktop/ViralPackage/viralcore/handlers/custom_order_handlers.py\", line 31, in custom_order_handler\n    text = update.message.text.strip()\n           ^^^^^^^^^^^^^^^^^^^\nAttributeError: 'NoneType' object has no attribute 'text'"}
{"timestamp": "2025-09-29T08:18:28.814975Z", "level": "ERROR", "module": "telegram.ext.Application", "message": "No error handlers are registered, logging exception.", "correlation_id": "none", "exception": "Traceback (most recent call last):\n  File \"/home/technedict/Desktop/ViralPackage/viralcorelib/lib64/python3.13/site-packages/telegram/ext/_application.py\", line 1335, in process_update\n    await coroutine\n  File \"/home/technedict/Desktop/ViralPackage/viralcorelib/lib64/python3.13/site-packages/telegram/ext/_handlers/basehandler.py\", line 157, in handle_update\n    return await self.callback(update, context)\n           ^^^^^^^^^^^^^^^^^^^^^^^^^^^^^^^^^^^^\n  File \"/home/technedict/Desktop/ViralPackage/viralcore/handlers/message_handler.py\", line 57, in message_router\n    await custom_order_handler(update, context) # Or a general_message_handler\n    ^^^^^^^^^^^^^^^^^^^^^^^^^^^^^^^^^^^^^^^^^^^\n  File \"/home/technedict/Desktop/ViralPackage/viralcore/handlers/custom_order_handlers.py\", line 31, in custom_order_handler\n    text = update.message.text.strip()\n           ^^^^^^^^^^^^^^^^^^^\nAttributeError: 'NoneType' object has no attribute 'text'"}
{"timestamp": "2025-09-29T08:18:28.826391Z", "level": "ERROR", "module": "telegram.ext.Application", "message": "No error handlers are registered, logging exception.", "correlation_id": "none", "exception": "Traceback (most recent call last):\n  File \"/home/technedict/Desktop/ViralPackage/viralcorelib/lib64/python3.13/site-packages/telegram/ext/_application.py\", line 1335, in process_update\n    await coroutine\n  File \"/home/technedict/Desktop/ViralPackage/viralcorelib/lib64/python3.13/site-packages/telegram/ext/_handlers/basehandler.py\", line 157, in handle_update\n    return await self.callback(update, context)\n           ^^^^^^^^^^^^^^^^^^^^^^^^^^^^^^^^^^^^\n  File \"/home/technedict/Desktop/ViralPackage/viralcore/handlers/message_handler.py\", line 57, in message_router\n    await custom_order_handler(update, context) # Or a general_message_handler\n    ^^^^^^^^^^^^^^^^^^^^^^^^^^^^^^^^^^^^^^^^^^^\n  File \"/home/technedict/Desktop/ViralPackage/viralcore/handlers/custom_order_handlers.py\", line 31, in custom_order_handler\n    text = update.message.text.strip()\n           ^^^^^^^^^^^^^^^^^^^\nAttributeError: 'NoneType' object has no attribute 'text'"}
{"timestamp": "2025-09-29T08:18:28.835524Z", "level": "ERROR", "module": "telegram.ext.Application", "message": "No error handlers are registered, logging exception.", "correlation_id": "none", "exception": "Traceback (most recent call last):\n  File \"/home/technedict/Desktop/ViralPackage/viralcorelib/lib64/python3.13/site-packages/telegram/ext/_application.py\", line 1335, in process_update\n    await coroutine\n  File \"/home/technedict/Desktop/ViralPackage/viralcorelib/lib64/python3.13/site-packages/telegram/ext/_handlers/basehandler.py\", line 157, in handle_update\n    return await self.callback(update, context)\n           ^^^^^^^^^^^^^^^^^^^^^^^^^^^^^^^^^^^^\n  File \"/home/technedict/Desktop/ViralPackage/viralcore/handlers/message_handler.py\", line 57, in message_router\n    await custom_order_handler(update, context) # Or a general_message_handler\n    ^^^^^^^^^^^^^^^^^^^^^^^^^^^^^^^^^^^^^^^^^^^\n  File \"/home/technedict/Desktop/ViralPackage/viralcore/handlers/custom_order_handlers.py\", line 31, in custom_order_handler\n    text = update.message.text.strip()\n           ^^^^^^^^^^^^^^^^^^^\nAttributeError: 'NoneType' object has no attribute 'text'"}
{"timestamp": "2025-09-29T08:18:28.843710Z", "level": "ERROR", "module": "telegram.ext.Application", "message": "No error handlers are registered, logging exception.", "correlation_id": "none", "exception": "Traceback (most recent call last):\n  File \"/home/technedict/Desktop/ViralPackage/viralcorelib/lib64/python3.13/site-packages/telegram/ext/_application.py\", line 1335, in process_update\n    await coroutine\n  File \"/home/technedict/Desktop/ViralPackage/viralcorelib/lib64/python3.13/site-packages/telegram/ext/_handlers/basehandler.py\", line 157, in handle_update\n    return await self.callback(update, context)\n           ^^^^^^^^^^^^^^^^^^^^^^^^^^^^^^^^^^^^\n  File \"/home/technedict/Desktop/ViralPackage/viralcore/handlers/message_handler.py\", line 57, in message_router\n    await custom_order_handler(update, context) # Or a general_message_handler\n    ^^^^^^^^^^^^^^^^^^^^^^^^^^^^^^^^^^^^^^^^^^^\n  File \"/home/technedict/Desktop/ViralPackage/viralcore/handlers/custom_order_handlers.py\", line 31, in custom_order_handler\n    text = update.message.text.strip()\n           ^^^^^^^^^^^^^^^^^^^\nAttributeError: 'NoneType' object has no attribute 'text'"}
{"timestamp": "2025-09-29T08:18:28.852345Z", "level": "ERROR", "module": "telegram.ext.Application", "message": "No error handlers are registered, logging exception.", "correlation_id": "none", "exception": "Traceback (most recent call last):\n  File \"/home/technedict/Desktop/ViralPackage/viralcorelib/lib64/python3.13/site-packages/telegram/ext/_application.py\", line 1335, in process_update\n    await coroutine\n  File \"/home/technedict/Desktop/ViralPackage/viralcorelib/lib64/python3.13/site-packages/telegram/ext/_handlers/basehandler.py\", line 157, in handle_update\n    return await self.callback(update, context)\n           ^^^^^^^^^^^^^^^^^^^^^^^^^^^^^^^^^^^^\n  File \"/home/technedict/Desktop/ViralPackage/viralcore/handlers/message_handler.py\", line 57, in message_router\n    await custom_order_handler(update, context) # Or a general_message_handler\n    ^^^^^^^^^^^^^^^^^^^^^^^^^^^^^^^^^^^^^^^^^^^\n  File \"/home/technedict/Desktop/ViralPackage/viralcore/handlers/custom_order_handlers.py\", line 31, in custom_order_handler\n    text = update.message.text.strip()\n           ^^^^^^^^^^^^^^^^^^^\nAttributeError: 'NoneType' object has no attribute 'text'"}
{"timestamp": "2025-09-29T08:18:28.868452Z", "level": "ERROR", "module": "telegram.ext.Application", "message": "No error handlers are registered, logging exception.", "correlation_id": "none", "exception": "Traceback (most recent call last):\n  File \"/home/technedict/Desktop/ViralPackage/viralcorelib/lib64/python3.13/site-packages/telegram/ext/_application.py\", line 1335, in process_update\n    await coroutine\n  File \"/home/technedict/Desktop/ViralPackage/viralcorelib/lib64/python3.13/site-packages/telegram/ext/_handlers/basehandler.py\", line 157, in handle_update\n    return await self.callback(update, context)\n           ^^^^^^^^^^^^^^^^^^^^^^^^^^^^^^^^^^^^\n  File \"/home/technedict/Desktop/ViralPackage/viralcore/handlers/message_handler.py\", line 57, in message_router\n    await custom_order_handler(update, context) # Or a general_message_handler\n    ^^^^^^^^^^^^^^^^^^^^^^^^^^^^^^^^^^^^^^^^^^^\n  File \"/home/technedict/Desktop/ViralPackage/viralcore/handlers/custom_order_handlers.py\", line 31, in custom_order_handler\n    text = update.message.text.strip()\n           ^^^^^^^^^^^^^^^^^^^\nAttributeError: 'NoneType' object has no attribute 'text'"}
{"timestamp": "2025-09-29T08:18:28.886824Z", "level": "ERROR", "module": "telegram.ext.Application", "message": "No error handlers are registered, logging exception.", "correlation_id": "none", "exception": "Traceback (most recent call last):\n  File \"/home/technedict/Desktop/ViralPackage/viralcorelib/lib64/python3.13/site-packages/telegram/ext/_application.py\", line 1335, in process_update\n    await coroutine\n  File \"/home/technedict/Desktop/ViralPackage/viralcorelib/lib64/python3.13/site-packages/telegram/ext/_handlers/basehandler.py\", line 157, in handle_update\n    return await self.callback(update, context)\n           ^^^^^^^^^^^^^^^^^^^^^^^^^^^^^^^^^^^^\n  File \"/home/technedict/Desktop/ViralPackage/viralcore/handlers/message_handler.py\", line 57, in message_router\n    await custom_order_handler(update, context) # Or a general_message_handler\n    ^^^^^^^^^^^^^^^^^^^^^^^^^^^^^^^^^^^^^^^^^^^\n  File \"/home/technedict/Desktop/ViralPackage/viralcore/handlers/custom_order_handlers.py\", line 31, in custom_order_handler\n    text = update.message.text.strip()\n           ^^^^^^^^^^^^^^^^^^^\nAttributeError: 'NoneType' object has no attribute 'text'"}
{"timestamp": "2025-09-29T08:18:28.895694Z", "level": "ERROR", "module": "telegram.ext.Application", "message": "No error handlers are registered, logging exception.", "correlation_id": "none", "exception": "Traceback (most recent call last):\n  File \"/home/technedict/Desktop/ViralPackage/viralcorelib/lib64/python3.13/site-packages/telegram/ext/_application.py\", line 1335, in process_update\n    await coroutine\n  File \"/home/technedict/Desktop/ViralPackage/viralcorelib/lib64/python3.13/site-packages/telegram/ext/_handlers/basehandler.py\", line 157, in handle_update\n    return await self.callback(update, context)\n           ^^^^^^^^^^^^^^^^^^^^^^^^^^^^^^^^^^^^\n  File \"/home/technedict/Desktop/ViralPackage/viralcore/handlers/message_handler.py\", line 57, in message_router\n    await custom_order_handler(update, context) # Or a general_message_handler\n    ^^^^^^^^^^^^^^^^^^^^^^^^^^^^^^^^^^^^^^^^^^^\n  File \"/home/technedict/Desktop/ViralPackage/viralcore/handlers/custom_order_handlers.py\", line 31, in custom_order_handler\n    text = update.message.text.strip()\n           ^^^^^^^^^^^^^^^^^^^\nAttributeError: 'NoneType' object has no attribute 'text'"}
{"timestamp": "2025-09-29T08:18:28.911878Z", "level": "ERROR", "module": "telegram.ext.Application", "message": "No error handlers are registered, logging exception.", "correlation_id": "none", "exception": "Traceback (most recent call last):\n  File \"/home/technedict/Desktop/ViralPackage/viralcorelib/lib64/python3.13/site-packages/telegram/ext/_application.py\", line 1335, in process_update\n    await coroutine\n  File \"/home/technedict/Desktop/ViralPackage/viralcorelib/lib64/python3.13/site-packages/telegram/ext/_handlers/basehandler.py\", line 157, in handle_update\n    return await self.callback(update, context)\n           ^^^^^^^^^^^^^^^^^^^^^^^^^^^^^^^^^^^^\n  File \"/home/technedict/Desktop/ViralPackage/viralcore/handlers/message_handler.py\", line 57, in message_router\n    await custom_order_handler(update, context) # Or a general_message_handler\n    ^^^^^^^^^^^^^^^^^^^^^^^^^^^^^^^^^^^^^^^^^^^\n  File \"/home/technedict/Desktop/ViralPackage/viralcore/handlers/custom_order_handlers.py\", line 31, in custom_order_handler\n    text = update.message.text.strip()\n           ^^^^^^^^^^^^^^^^^^^\nAttributeError: 'NoneType' object has no attribute 'text'"}
{"timestamp": "2025-09-29T08:18:28.922553Z", "level": "ERROR", "module": "telegram.ext.Application", "message": "No error handlers are registered, logging exception.", "correlation_id": "none", "exception": "Traceback (most recent call last):\n  File \"/home/technedict/Desktop/ViralPackage/viralcorelib/lib64/python3.13/site-packages/telegram/ext/_application.py\", line 1335, in process_update\n    await coroutine\n  File \"/home/technedict/Desktop/ViralPackage/viralcorelib/lib64/python3.13/site-packages/telegram/ext/_handlers/basehandler.py\", line 157, in handle_update\n    return await self.callback(update, context)\n           ^^^^^^^^^^^^^^^^^^^^^^^^^^^^^^^^^^^^\n  File \"/home/technedict/Desktop/ViralPackage/viralcore/handlers/message_handler.py\", line 57, in message_router\n    await custom_order_handler(update, context) # Or a general_message_handler\n    ^^^^^^^^^^^^^^^^^^^^^^^^^^^^^^^^^^^^^^^^^^^\n  File \"/home/technedict/Desktop/ViralPackage/viralcore/handlers/custom_order_handlers.py\", line 31, in custom_order_handler\n    text = update.message.text.strip()\n           ^^^^^^^^^^^^^^^^^^^\nAttributeError: 'NoneType' object has no attribute 'text'"}
{"timestamp": "2025-09-29T08:18:28.935487Z", "level": "ERROR", "module": "telegram.ext.Application", "message": "No error handlers are registered, logging exception.", "correlation_id": "none", "exception": "Traceback (most recent call last):\n  File \"/home/technedict/Desktop/ViralPackage/viralcorelib/lib64/python3.13/site-packages/telegram/ext/_application.py\", line 1335, in process_update\n    await coroutine\n  File \"/home/technedict/Desktop/ViralPackage/viralcorelib/lib64/python3.13/site-packages/telegram/ext/_handlers/basehandler.py\", line 157, in handle_update\n    return await self.callback(update, context)\n           ^^^^^^^^^^^^^^^^^^^^^^^^^^^^^^^^^^^^\n  File \"/home/technedict/Desktop/ViralPackage/viralcore/handlers/message_handler.py\", line 57, in message_router\n    await custom_order_handler(update, context) # Or a general_message_handler\n    ^^^^^^^^^^^^^^^^^^^^^^^^^^^^^^^^^^^^^^^^^^^\n  File \"/home/technedict/Desktop/ViralPackage/viralcore/handlers/custom_order_handlers.py\", line 31, in custom_order_handler\n    text = update.message.text.strip()\n           ^^^^^^^^^^^^^^^^^^^\nAttributeError: 'NoneType' object has no attribute 'text'"}
{"timestamp": "2025-09-29T08:18:28.943692Z", "level": "ERROR", "module": "telegram.ext.Application", "message": "No error handlers are registered, logging exception.", "correlation_id": "none", "exception": "Traceback (most recent call last):\n  File \"/home/technedict/Desktop/ViralPackage/viralcorelib/lib64/python3.13/site-packages/telegram/ext/_application.py\", line 1335, in process_update\n    await coroutine\n  File \"/home/technedict/Desktop/ViralPackage/viralcorelib/lib64/python3.13/site-packages/telegram/ext/_handlers/basehandler.py\", line 157, in handle_update\n    return await self.callback(update, context)\n           ^^^^^^^^^^^^^^^^^^^^^^^^^^^^^^^^^^^^\n  File \"/home/technedict/Desktop/ViralPackage/viralcore/handlers/message_handler.py\", line 57, in message_router\n    await custom_order_handler(update, context) # Or a general_message_handler\n    ^^^^^^^^^^^^^^^^^^^^^^^^^^^^^^^^^^^^^^^^^^^\n  File \"/home/technedict/Desktop/ViralPackage/viralcore/handlers/custom_order_handlers.py\", line 31, in custom_order_handler\n    text = update.message.text.strip()\n           ^^^^^^^^^^^^^^^^^^^\nAttributeError: 'NoneType' object has no attribute 'text'"}
{"timestamp": "2025-09-29T08:18:28.949888Z", "level": "ERROR", "module": "telegram.ext.Application", "message": "No error handlers are registered, logging exception.", "correlation_id": "none", "exception": "Traceback (most recent call last):\n  File \"/home/technedict/Desktop/ViralPackage/viralcorelib/lib64/python3.13/site-packages/telegram/ext/_application.py\", line 1335, in process_update\n    await coroutine\n  File \"/home/technedict/Desktop/ViralPackage/viralcorelib/lib64/python3.13/site-packages/telegram/ext/_handlers/basehandler.py\", line 157, in handle_update\n    return await self.callback(update, context)\n           ^^^^^^^^^^^^^^^^^^^^^^^^^^^^^^^^^^^^\n  File \"/home/technedict/Desktop/ViralPackage/viralcore/handlers/message_handler.py\", line 57, in message_router\n    await custom_order_handler(update, context) # Or a general_message_handler\n    ^^^^^^^^^^^^^^^^^^^^^^^^^^^^^^^^^^^^^^^^^^^\n  File \"/home/technedict/Desktop/ViralPackage/viralcore/handlers/custom_order_handlers.py\", line 31, in custom_order_handler\n    text = update.message.text.strip()\n           ^^^^^^^^^^^^^^^^^^^\nAttributeError: 'NoneType' object has no attribute 'text'"}
{"timestamp": "2025-09-29T08:21:24.173722Z", "level": "WARNING", "module": "utils.graceful_shutdown", "message": "updater.shutdown() raised: This Updater is still running!", "correlation_id": "none"}
{"timestamp": "2025-09-29T08:21:24.174965Z", "level": "WARNING", "module": "utils.graceful_shutdown", "message": "Shutdown already in progress", "correlation_id": "none"}
{"timestamp": "2025-09-29T08:21:24.194893Z", "level": "ERROR", "module": "__main__", "message": "Error during app.shutdown()", "correlation_id": "none", "exception": "Traceback (most recent call last):\n  File \"/home/technedict/Desktop/ViralPackage/viralcore/main_viral_core_bot.py\", line 301, in main\n    await app.shutdown()\n  File \"/home/technedict/Desktop/ViralPackage/viralcorelib/lib64/python3.13/site-packages/telegram/ext/_application.py\", line 561, in shutdown\n    await self.updater.shutdown()\n  File \"/home/technedict/Desktop/ViralPackage/viralcorelib/lib64/python3.13/site-packages/telegram/ext/_updater.py\", line 204, in shutdown\n    raise RuntimeError(\"This Updater is still running!\")\nRuntimeError: This Updater is still running!"}
{"timestamp": "2025-09-29T08:21:24.306887Z", "level": "ERROR", "module": "asyncio", "message": "Task exception was never retrieved\nfuture: <Task finished name='Task-40' coro=<Updater._start_polling.<locals>.polling_action_cb() done, defined at /home/technedict/Desktop/ViralPackage/viralcorelib/lib64/python3.13/site-packages/telegram/ext/_updater.py:375> exception=NetworkError('httpx.ReadError: ')>", "correlation_id": "none", "exception": "Traceback (most recent call last):\n  File \"/home/technedict/Desktop/ViralPackage/viralcorelib/lib64/python3.13/site-packages/httpx/_transports/default.py\", line 101, in map_httpcore_exceptions\n  File \"/home/technedict/Desktop/ViralPackage/viralcorelib/lib64/python3.13/site-packages/httpx/_transports/default.py\", line 394, in handle_async_request\n  File \"/home/technedict/Desktop/ViralPackage/viralcorelib/lib64/python3.13/site-packages/httpcore/_async/connection_pool.py\", line 256, in handle_async_request\n  File \"/home/technedict/Desktop/ViralPackage/viralcorelib/lib64/python3.13/site-packages/httpcore/_async/connection_pool.py\", line 236, in handle_async_request\n  File \"/home/technedict/Desktop/ViralPackage/viralcorelib/lib64/python3.13/site-packages/httpcore/_async/connection.py\", line 103, in handle_async_request\n  File \"/home/technedict/Desktop/ViralPackage/viralcorelib/lib64/python3.13/site-packages/httpcore/_async/http11.py\", line 136, in handle_async_request\n  File \"/home/technedict/Desktop/ViralPackage/viralcorelib/lib64/python3.13/site-packages/httpcore/_async/http11.py\", line 106, in handle_async_request\n  File \"/home/technedict/Desktop/ViralPackage/viralcorelib/lib64/python3.13/site-packages/httpcore/_async/http11.py\", line 177, in _receive_response_headers\n  File \"/home/technedict/Desktop/ViralPackage/viralcorelib/lib64/python3.13/site-packages/httpcore/_async/http11.py\", line 217, in _receive_event\n  File \"/home/technedict/Desktop/ViralPackage/viralcorelib/lib64/python3.13/site-packages/httpcore/_backends/anyio.py\", line 32, in read\n  File \"/usr/lib64/python3.13/contextlib.py\", line 162, in __exit__\n  File \"/home/technedict/Desktop/ViralPackage/viralcorelib/lib64/python3.13/site-packages/httpcore/_exceptions.py\", line 14, in map_exceptions\nhttpcore.ReadError\n\nThe above exception was the direct cause of the following exception:\n\nTraceback (most recent call last):\n  File \"/home/technedict/Desktop/ViralPackage/viralcorelib/lib64/python3.13/site-packages/telegram/request/_httpxrequest.py\", line 276, in do_request\n  File \"/home/technedict/Desktop/ViralPackage/viralcorelib/lib64/python3.13/site-packages/httpx/_client.py\", line 1540, in request\n  File \"/home/technedict/Desktop/ViralPackage/viralcorelib/lib64/python3.13/site-packages/httpx/_client.py\", line 1629, in send\n  File \"/home/technedict/Desktop/ViralPackage/viralcorelib/lib64/python3.13/site-packages/httpx/_client.py\", line 1657, in _send_handling_auth\n  File \"/home/technedict/Desktop/ViralPackage/viralcorelib/lib64/python3.13/site-packages/httpx/_client.py\", line 1694, in _send_handling_redirects\n  File \"/home/technedict/Desktop/ViralPackage/viralcorelib/lib64/python3.13/site-packages/httpx/_client.py\", line 1730, in _send_single_request\n  File \"/home/technedict/Desktop/ViralPackage/viralcorelib/lib64/python3.13/site-packages/httpx/_transports/default.py\", line 393, in handle_async_request\n  File \"/usr/lib64/python3.13/contextlib.py\", line 162, in __exit__\n  File \"/home/technedict/Desktop/ViralPackage/viralcorelib/lib64/python3.13/site-packages/httpx/_transports/default.py\", line 118, in map_httpcore_exceptions\nhttpx.ReadError\n\nThe above exception was the direct cause of the following exception:\n\nTraceback (most recent call last):\n  File \"/home/technedict/Desktop/ViralPackage/viralcorelib/lib64/python3.13/site-packages/telegram/ext/_updater.py\", line 377, in polling_action_cb\n    updates = await self.bot.get_updates(\n              ^^^^^^^^^^^^^^^^^^^^^^^^^^^\n    ...<7 lines>...\n    )\n    ^\n  File \"/home/technedict/Desktop/ViralPackage/viralcorelib/lib64/python3.13/site-packages/telegram/ext/_extbot.py\", line 649, in get_updates\n  File \"/home/technedict/Desktop/ViralPackage/viralcorelib/lib64/python3.13/site-packages/telegram/_bot.py\", line 4366, in get_updates\n  File \"/home/technedict/Desktop/ViralPackage/viralcorelib/lib64/python3.13/site-packages/telegram/_bot.py\", line 623, in _post\n  File \"/home/technedict/Desktop/ViralPackage/viralcorelib/lib64/python3.13/site-packages/telegram/ext/_extbot.py\", line 355, in _do_post\n  File \"/home/technedict/Desktop/ViralPackage/viralcorelib/lib64/python3.13/site-packages/telegram/_bot.py\", line 652, in _do_post\n  File \"/home/technedict/Desktop/ViralPackage/viralcorelib/lib64/python3.13/site-packages/telegram/request/_baserequest.py\", line 201, in post\n  File \"/home/technedict/Desktop/ViralPackage/viralcorelib/lib64/python3.13/site-packages/telegram/request/_baserequest.py\", line 333, in _request_wrapper\n  File \"/home/technedict/Desktop/ViralPackage/viralcorelib/lib64/python3.13/site-packages/telegram/request/_httpxrequest.py\", line 300, in do_request\ntelegram.error.NetworkError: httpx.ReadError: "}
{"timestamp": "2025-09-29T08:21:50.020056Z", "level": "WARNING", "module": "utils.graceful_shutdown", "message": "updater.shutdown() raised: This Updater is still running!", "correlation_id": "none"}
{"timestamp": "2025-09-29T08:21:50.021429Z", "level": "WARNING", "module": "utils.graceful_shutdown", "message": "Shutdown already in progress", "correlation_id": "none"}
{"timestamp": "2025-09-29T08:21:50.041010Z", "level": "ERROR", "module": "__main__", "message": "Error during app.shutdown()", "correlation_id": "none", "exception": "Traceback (most recent call last):\n  File \"/home/technedict/Desktop/ViralPackage/viralcore/main_viral_core_bot.py\", line 301, in main\n    await app.shutdown()\n  File \"/home/technedict/Desktop/ViralPackage/viralcorelib/lib64/python3.13/site-packages/telegram/ext/_application.py\", line 561, in shutdown\n    await self.updater.shutdown()\n  File \"/home/technedict/Desktop/ViralPackage/viralcorelib/lib64/python3.13/site-packages/telegram/ext/_updater.py\", line 204, in shutdown\n    raise RuntimeError(\"This Updater is still running!\")\nRuntimeError: This Updater is still running!"}
{"timestamp": "2025-09-29T08:21:50.147492Z", "level": "ERROR", "module": "asyncio", "message": "Task exception was never retrieved\nfuture: <Task finished name='Task-6' coro=<Updater._start_polling.<locals>.polling_action_cb() done, defined at /home/technedict/Desktop/ViralPackage/viralcorelib/lib64/python3.13/site-packages/telegram/ext/_updater.py:375> exception=NetworkError('httpx.ReadError: ')>", "correlation_id": "none", "exception": "Traceback (most recent call last):\n  File \"/home/technedict/Desktop/ViralPackage/viralcorelib/lib64/python3.13/site-packages/httpx/_transports/default.py\", line 101, in map_httpcore_exceptions\n  File \"/home/technedict/Desktop/ViralPackage/viralcorelib/lib64/python3.13/site-packages/httpx/_transports/default.py\", line 394, in handle_async_request\n  File \"/home/technedict/Desktop/ViralPackage/viralcorelib/lib64/python3.13/site-packages/httpcore/_async/connection_pool.py\", line 256, in handle_async_request\n  File \"/home/technedict/Desktop/ViralPackage/viralcorelib/lib64/python3.13/site-packages/httpcore/_async/connection_pool.py\", line 236, in handle_async_request\n  File \"/home/technedict/Desktop/ViralPackage/viralcorelib/lib64/python3.13/site-packages/httpcore/_async/connection.py\", line 103, in handle_async_request\n  File \"/home/technedict/Desktop/ViralPackage/viralcorelib/lib64/python3.13/site-packages/httpcore/_async/http11.py\", line 136, in handle_async_request\n  File \"/home/technedict/Desktop/ViralPackage/viralcorelib/lib64/python3.13/site-packages/httpcore/_async/http11.py\", line 106, in handle_async_request\n  File \"/home/technedict/Desktop/ViralPackage/viralcorelib/lib64/python3.13/site-packages/httpcore/_async/http11.py\", line 177, in _receive_response_headers\n  File \"/home/technedict/Desktop/ViralPackage/viralcorelib/lib64/python3.13/site-packages/httpcore/_async/http11.py\", line 217, in _receive_event\n  File \"/home/technedict/Desktop/ViralPackage/viralcorelib/lib64/python3.13/site-packages/httpcore/_backends/anyio.py\", line 32, in read\n  File \"/usr/lib64/python3.13/contextlib.py\", line 162, in __exit__\n  File \"/home/technedict/Desktop/ViralPackage/viralcorelib/lib64/python3.13/site-packages/httpcore/_exceptions.py\", line 14, in map_exceptions\nhttpcore.ReadError\n\nThe above exception was the direct cause of the following exception:\n\nTraceback (most recent call last):\n  File \"/home/technedict/Desktop/ViralPackage/viralcorelib/lib64/python3.13/site-packages/telegram/request/_httpxrequest.py\", line 276, in do_request\n  File \"/home/technedict/Desktop/ViralPackage/viralcorelib/lib64/python3.13/site-packages/httpx/_client.py\", line 1540, in request\n  File \"/home/technedict/Desktop/ViralPackage/viralcorelib/lib64/python3.13/site-packages/httpx/_client.py\", line 1629, in send\n  File \"/home/technedict/Desktop/ViralPackage/viralcorelib/lib64/python3.13/site-packages/httpx/_client.py\", line 1657, in _send_handling_auth\n  File \"/home/technedict/Desktop/ViralPackage/viralcorelib/lib64/python3.13/site-packages/httpx/_client.py\", line 1694, in _send_handling_redirects\n  File \"/home/technedict/Desktop/ViralPackage/viralcorelib/lib64/python3.13/site-packages/httpx/_client.py\", line 1730, in _send_single_request\n  File \"/home/technedict/Desktop/ViralPackage/viralcorelib/lib64/python3.13/site-packages/httpx/_transports/default.py\", line 393, in handle_async_request\n  File \"/usr/lib64/python3.13/contextlib.py\", line 162, in __exit__\n  File \"/home/technedict/Desktop/ViralPackage/viralcorelib/lib64/python3.13/site-packages/httpx/_transports/default.py\", line 118, in map_httpcore_exceptions\nhttpx.ReadError\n\nThe above exception was the direct cause of the following exception:\n\nTraceback (most recent call last):\n  File \"/home/technedict/Desktop/ViralPackage/viralcorelib/lib64/python3.13/site-packages/telegram/ext/_updater.py\", line 377, in polling_action_cb\n    updates = await self.bot.get_updates(\n              ^^^^^^^^^^^^^^^^^^^^^^^^^^^\n    ...<7 lines>...\n    )\n    ^\n  File \"/home/technedict/Desktop/ViralPackage/viralcorelib/lib64/python3.13/site-packages/telegram/ext/_extbot.py\", line 649, in get_updates\n  File \"/home/technedict/Desktop/ViralPackage/viralcorelib/lib64/python3.13/site-packages/telegram/_bot.py\", line 4366, in get_updates\n  File \"/home/technedict/Desktop/ViralPackage/viralcorelib/lib64/python3.13/site-packages/telegram/_bot.py\", line 623, in _post\n  File \"/home/technedict/Desktop/ViralPackage/viralcorelib/lib64/python3.13/site-packages/telegram/ext/_extbot.py\", line 355, in _do_post\n  File \"/home/technedict/Desktop/ViralPackage/viralcorelib/lib64/python3.13/site-packages/telegram/_bot.py\", line 652, in _do_post\n  File \"/home/technedict/Desktop/ViralPackage/viralcorelib/lib64/python3.13/site-packages/telegram/request/_baserequest.py\", line 201, in post\n  File \"/home/technedict/Desktop/ViralPackage/viralcorelib/lib64/python3.13/site-packages/telegram/request/_baserequest.py\", line 333, in _request_wrapper\n  File \"/home/technedict/Desktop/ViralPackage/viralcorelib/lib64/python3.13/site-packages/telegram/request/_httpxrequest.py\", line 300, in do_request\ntelegram.error.NetworkError: httpx.ReadError: "}
{"timestamp": "2025-09-29T08:29:51.877012Z", "level": "WARNING", "module": "handlers.menu_handlers", "message": "menu_handler edit failed (Invalid file http url specified: unsupported url protocol) for user ***ACCOUNT***. Resending message.", "correlation_id": "none"}
{"timestamp": "2025-09-29T08:30:06.786826Z", "level": "WARNING", "module": "handlers.menu_handlers", "message": "menu_handler edit failed (Message to edit not found) for user ***ACCOUNT***. Resending message.", "correlation_id": "none"}
{"timestamp": "2025-09-29T08:30:11.168216Z", "level": "WARNING", "module": "handlers.menu_handlers", "message": "menu_handler edit failed (Message to edit not found) for user ***ACCOUNT***. Resending message.", "correlation_id": "none"}
{"timestamp": "2025-09-29T08:31:39.976217Z", "level": "WARNING", "module": "handlers.menu_handlers", "message": "menu_handler edit failed (Message to edit not found) for user ***ACCOUNT***. Resending message.", "correlation_id": "none"}
{"timestamp": "2025-09-29T08:31:48.807448Z", "level": "WARNING", "module": "handlers.menu_handlers", "message": "menu_handler edit failed (Message to edit not found) for user ***ACCOUNT***. Resending message.", "correlation_id": "none"}
{"timestamp": "2025-09-29T08:32:27.360269Z", "level": "WARNING", "module": "handlers.menu_handlers", "message": "menu_handler edit failed (Message to edit not found) for user ***ACCOUNT***. Resending message.", "correlation_id": "none"}
{"timestamp": "2025-09-29T08:32:31.917849Z", "level": "WARNING", "module": "handlers.menu_handlers", "message": "menu_handler edit failed (Message to edit not found) for user ***ACCOUNT***. Resending message.", "correlation_id": "none"}
{"timestamp": "2025-09-29T08:33:33.203791Z", "level": "WARNING", "module": "handlers.menu_handlers", "message": "menu_handler edit failed (Message to edit not found) for user ***ACCOUNT***. Resending message.", "correlation_id": "none"}
{"timestamp": "2025-09-29T08:33:40.882962Z", "level": "WARNING", "module": "handlers.menu_handlers", "message": "menu_handler edit failed (Message to edit not found) for user ***ACCOUNT***. Resending message.", "correlation_id": "none"}
{"timestamp": "2025-09-29T08:34:38.265713Z", "level": "WARNING", "module": "utils.graceful_shutdown", "message": "updater.shutdown() raised: This Updater is still running!", "correlation_id": "none"}
{"timestamp": "2025-09-29T08:34:38.266841Z", "level": "WARNING", "module": "utils.graceful_shutdown", "message": "Shutdown already in progress", "correlation_id": "none"}
{"timestamp": "2025-09-29T08:34:38.287754Z", "level": "ERROR", "module": "__main__", "message": "Error during app.shutdown()", "correlation_id": "none", "exception": "Traceback (most recent call last):\n  File \"/home/technedict/Desktop/ViralPackage/viralcore/main_viral_core_bot.py\", line 301, in main\n    await app.shutdown()\n  File \"/home/technedict/Desktop/ViralPackage/viralcorelib/lib64/python3.13/site-packages/telegram/ext/_application.py\", line 561, in shutdown\n    await self.updater.shutdown()\n  File \"/home/technedict/Desktop/ViralPackage/viralcorelib/lib64/python3.13/site-packages/telegram/ext/_updater.py\", line 204, in shutdown\n    raise RuntimeError(\"This Updater is still running!\")\nRuntimeError: This Updater is still running!"}
{"timestamp": "2025-09-29T08:34:38.406369Z", "level": "ERROR", "module": "asyncio", "message": "Task exception was never retrieved\nfuture: <Task finished name='Task-68' coro=<Updater._start_polling.<locals>.polling_action_cb() done, defined at /home/technedict/Desktop/ViralPackage/viralcorelib/lib64/python3.13/site-packages/telegram/ext/_updater.py:375> exception=NetworkError('httpx.ReadError: ')>", "correlation_id": "none", "exception": "Traceback (most recent call last):\n  File \"/home/technedict/Desktop/ViralPackage/viralcorelib/lib64/python3.13/site-packages/httpx/_transports/default.py\", line 101, in map_httpcore_exceptions\n  File \"/home/technedict/Desktop/ViralPackage/viralcorelib/lib64/python3.13/site-packages/httpx/_transports/default.py\", line 394, in handle_async_request\n  File \"/home/technedict/Desktop/ViralPackage/viralcorelib/lib64/python3.13/site-packages/httpcore/_async/connection_pool.py\", line 256, in handle_async_request\n  File \"/home/technedict/Desktop/ViralPackage/viralcorelib/lib64/python3.13/site-packages/httpcore/_async/connection_pool.py\", line 236, in handle_async_request\n  File \"/home/technedict/Desktop/ViralPackage/viralcorelib/lib64/python3.13/site-packages/httpcore/_async/connection.py\", line 103, in handle_async_request\n  File \"/home/technedict/Desktop/ViralPackage/viralcorelib/lib64/python3.13/site-packages/httpcore/_async/http11.py\", line 136, in handle_async_request\n  File \"/home/technedict/Desktop/ViralPackage/viralcorelib/lib64/python3.13/site-packages/httpcore/_async/http11.py\", line 106, in handle_async_request\n  File \"/home/technedict/Desktop/ViralPackage/viralcorelib/lib64/python3.13/site-packages/httpcore/_async/http11.py\", line 177, in _receive_response_headers\n  File \"/home/technedict/Desktop/ViralPackage/viralcorelib/lib64/python3.13/site-packages/httpcore/_async/http11.py\", line 217, in _receive_event\n  File \"/home/technedict/Desktop/ViralPackage/viralcorelib/lib64/python3.13/site-packages/httpcore/_backends/anyio.py\", line 32, in read\n  File \"/usr/lib64/python3.13/contextlib.py\", line 162, in __exit__\n  File \"/home/technedict/Desktop/ViralPackage/viralcorelib/lib64/python3.13/site-packages/httpcore/_exceptions.py\", line 14, in map_exceptions\nhttpcore.ReadError\n\nThe above exception was the direct cause of the following exception:\n\nTraceback (most recent call last):\n  File \"/home/technedict/Desktop/ViralPackage/viralcorelib/lib64/python3.13/site-packages/telegram/request/_httpxrequest.py\", line 276, in do_request\n  File \"/home/technedict/Desktop/ViralPackage/viralcorelib/lib64/python3.13/site-packages/httpx/_client.py\", line 1540, in request\n  File \"/home/technedict/Desktop/ViralPackage/viralcorelib/lib64/python3.13/site-packages/httpx/_client.py\", line 1629, in send\n  File \"/home/technedict/Desktop/ViralPackage/viralcorelib/lib64/python3.13/site-packages/httpx/_client.py\", line 1657, in _send_handling_auth\n  File \"/home/technedict/Desktop/ViralPackage/viralcorelib/lib64/python3.13/site-packages/httpx/_client.py\", line 1694, in _send_handling_redirects\n  File \"/home/technedict/Desktop/ViralPackage/viralcorelib/lib64/python3.13/site-packages/httpx/_client.py\", line 1730, in _send_single_request\n  File \"/home/technedict/Desktop/ViralPackage/viralcorelib/lib64/python3.13/site-packages/httpx/_transports/default.py\", line 393, in handle_async_request\n  File \"/usr/lib64/python3.13/contextlib.py\", line 162, in __exit__\n  File \"/home/technedict/Desktop/ViralPackage/viralcorelib/lib64/python3.13/site-packages/httpx/_transports/default.py\", line 118, in map_httpcore_exceptions\nhttpx.ReadError\n\nThe above exception was the direct cause of the following exception:\n\nTraceback (most recent call last):\n  File \"/home/technedict/Desktop/ViralPackage/viralcorelib/lib64/python3.13/site-packages/telegram/ext/_updater.py\", line 377, in polling_action_cb\n    updates = await self.bot.get_updates(\n              ^^^^^^^^^^^^^^^^^^^^^^^^^^^\n    ...<7 lines>...\n    )\n    ^\n  File \"/home/technedict/Desktop/ViralPackage/viralcorelib/lib64/python3.13/site-packages/telegram/ext/_extbot.py\", line 649, in get_updates\n  File \"/home/technedict/Desktop/ViralPackage/viralcorelib/lib64/python3.13/site-packages/telegram/_bot.py\", line 4366, in get_updates\n  File \"/home/technedict/Desktop/ViralPackage/viralcorelib/lib64/python3.13/site-packages/telegram/_bot.py\", line 623, in _post\n  File \"/home/technedict/Desktop/ViralPackage/viralcorelib/lib64/python3.13/site-packages/telegram/ext/_extbot.py\", line 355, in _do_post\n  File \"/home/technedict/Desktop/ViralPackage/viralcorelib/lib64/python3.13/site-packages/telegram/_bot.py\", line 652, in _do_post\n  File \"/home/technedict/Desktop/ViralPackage/viralcorelib/lib64/python3.13/site-packages/telegram/request/_baserequest.py\", line 201, in post\n  File \"/home/technedict/Desktop/ViralPackage/viralcorelib/lib64/python3.13/site-packages/telegram/request/_baserequest.py\", line 333, in _request_wrapper\n  File \"/home/technedict/Desktop/ViralPackage/viralcorelib/lib64/python3.13/site-packages/telegram/request/_httpxrequest.py\", line 300, in do_request\ntelegram.error.NetworkError: httpx.ReadError: "}
{"timestamp": "2025-09-29T08:34:58.719944Z", "level": "WARNING", "module": "utils.graceful_shutdown", "message": "updater.shutdown() raised: This Updater is still running!", "correlation_id": "none"}
{"timestamp": "2025-09-29T08:34:58.722584Z", "level": "WARNING", "module": "utils.graceful_shutdown", "message": "Shutdown already in progress", "correlation_id": "none"}
{"timestamp": "2025-09-29T08:34:58.754854Z", "level": "ERROR", "module": "__main__", "message": "Error during app.shutdown()", "correlation_id": "none", "exception": "Traceback (most recent call last):\n  File \"/home/technedict/Desktop/ViralPackage/viralcore/main_viral_core_bot.py\", line 301, in main\n    await app.shutdown()\n  File \"/home/technedict/Desktop/ViralPackage/viralcorelib/lib64/python3.13/site-packages/telegram/ext/_application.py\", line 561, in shutdown\n    await self.updater.shutdown()\n  File \"/home/technedict/Desktop/ViralPackage/viralcorelib/lib64/python3.13/site-packages/telegram/ext/_updater.py\", line 204, in shutdown\n    raise RuntimeError(\"This Updater is still running!\")\nRuntimeError: This Updater is still running!"}
{"timestamp": "2025-09-29T08:34:58.883982Z", "level": "ERROR", "module": "asyncio", "message": "Task exception was never retrieved\nfuture: <Task finished name='Task-6' coro=<Updater._start_polling.<locals>.polling_action_cb() done, defined at /home/technedict/Desktop/ViralPackage/viralcorelib/lib64/python3.13/site-packages/telegram/ext/_updater.py:375> exception=NetworkError('httpx.ReadError: ')>", "correlation_id": "none", "exception": "Traceback (most recent call last):\n  File \"/home/technedict/Desktop/ViralPackage/viralcorelib/lib64/python3.13/site-packages/httpx/_transports/default.py\", line 101, in map_httpcore_exceptions\n  File \"/home/technedict/Desktop/ViralPackage/viralcorelib/lib64/python3.13/site-packages/httpx/_transports/default.py\", line 394, in handle_async_request\n  File \"/home/technedict/Desktop/ViralPackage/viralcorelib/lib64/python3.13/site-packages/httpcore/_async/connection_pool.py\", line 256, in handle_async_request\n  File \"/home/technedict/Desktop/ViralPackage/viralcorelib/lib64/python3.13/site-packages/httpcore/_async/connection_pool.py\", line 236, in handle_async_request\n  File \"/home/technedict/Desktop/ViralPackage/viralcorelib/lib64/python3.13/site-packages/httpcore/_async/connection.py\", line 103, in handle_async_request\n  File \"/home/technedict/Desktop/ViralPackage/viralcorelib/lib64/python3.13/site-packages/httpcore/_async/http11.py\", line 136, in handle_async_request\n  File \"/home/technedict/Desktop/ViralPackage/viralcorelib/lib64/python3.13/site-packages/httpcore/_async/http11.py\", line 106, in handle_async_request\n  File \"/home/technedict/Desktop/ViralPackage/viralcorelib/lib64/python3.13/site-packages/httpcore/_async/http11.py\", line 177, in _receive_response_headers\n  File \"/home/technedict/Desktop/ViralPackage/viralcorelib/lib64/python3.13/site-packages/httpcore/_async/http11.py\", line 217, in _receive_event\n  File \"/home/technedict/Desktop/ViralPackage/viralcorelib/lib64/python3.13/site-packages/httpcore/_backends/anyio.py\", line 32, in read\n  File \"/usr/lib64/python3.13/contextlib.py\", line 162, in __exit__\n  File \"/home/technedict/Desktop/ViralPackage/viralcorelib/lib64/python3.13/site-packages/httpcore/_exceptions.py\", line 14, in map_exceptions\nhttpcore.ReadError\n\nThe above exception was the direct cause of the following exception:\n\nTraceback (most recent call last):\n  File \"/home/technedict/Desktop/ViralPackage/viralcorelib/lib64/python3.13/site-packages/telegram/request/_httpxrequest.py\", line 276, in do_request\n  File \"/home/technedict/Desktop/ViralPackage/viralcorelib/lib64/python3.13/site-packages/httpx/_client.py\", line 1540, in request\n  File \"/home/technedict/Desktop/ViralPackage/viralcorelib/lib64/python3.13/site-packages/httpx/_client.py\", line 1629, in send\n  File \"/home/technedict/Desktop/ViralPackage/viralcorelib/lib64/python3.13/site-packages/httpx/_client.py\", line 1657, in _send_handling_auth\n  File \"/home/technedict/Desktop/ViralPackage/viralcorelib/lib64/python3.13/site-packages/httpx/_client.py\", line 1694, in _send_handling_redirects\n  File \"/home/technedict/Desktop/ViralPackage/viralcorelib/lib64/python3.13/site-packages/httpx/_client.py\", line 1730, in _send_single_request\n  File \"/home/technedict/Desktop/ViralPackage/viralcorelib/lib64/python3.13/site-packages/httpx/_transports/default.py\", line 393, in handle_async_request\n  File \"/usr/lib64/python3.13/contextlib.py\", line 162, in __exit__\n  File \"/home/technedict/Desktop/ViralPackage/viralcorelib/lib64/python3.13/site-packages/httpx/_transports/default.py\", line 118, in map_httpcore_exceptions\nhttpx.ReadError\n\nThe above exception was the direct cause of the following exception:\n\nTraceback (most recent call last):\n  File \"/home/technedict/Desktop/ViralPackage/viralcorelib/lib64/python3.13/site-packages/telegram/ext/_updater.py\", line 377, in polling_action_cb\n    updates = await self.bot.get_updates(\n              ^^^^^^^^^^^^^^^^^^^^^^^^^^^\n    ...<7 lines>...\n    )\n    ^\n  File \"/home/technedict/Desktop/ViralPackage/viralcorelib/lib64/python3.13/site-packages/telegram/ext/_extbot.py\", line 649, in get_updates\n  File \"/home/technedict/Desktop/ViralPackage/viralcorelib/lib64/python3.13/site-packages/telegram/_bot.py\", line 4366, in get_updates\n  File \"/home/technedict/Desktop/ViralPackage/viralcorelib/lib64/python3.13/site-packages/telegram/_bot.py\", line 623, in _post\n  File \"/home/technedict/Desktop/ViralPackage/viralcorelib/lib64/python3.13/site-packages/telegram/ext/_extbot.py\", line 355, in _do_post\n  File \"/home/technedict/Desktop/ViralPackage/viralcorelib/lib64/python3.13/site-packages/telegram/_bot.py\", line 652, in _do_post\n  File \"/home/technedict/Desktop/ViralPackage/viralcorelib/lib64/python3.13/site-packages/telegram/request/_baserequest.py\", line 201, in post\n  File \"/home/technedict/Desktop/ViralPackage/viralcorelib/lib64/python3.13/site-packages/telegram/request/_baserequest.py\", line 333, in _request_wrapper\n  File \"/home/technedict/Desktop/ViralPackage/viralcorelib/lib64/python3.13/site-packages/telegram/request/_httpxrequest.py\", line 300, in do_request\ntelegram.error.NetworkError: httpx.ReadError: "}
{"timestamp": "2025-09-29T08:59:06.794490Z", "level": "WARNING", "module": "utils.config", "message": "Missing required environment variables: TELEGRAM_BOT_TOKEN, FLUTTERWAVE_API_KEY, EXCHANGE_API_KEY", "correlation_id": "none"}
{"timestamp": "2025-09-29T08:59:06.794894Z", "level": "WARNING", "module": "utils.config", "message": "Please check your .env file or environment variable configuration", "correlation_id": "none"}
{"timestamp": "2025-09-29T08:59:07.786428Z", "level": "ERROR", "module": "__main__", "message": "Unexpected error while running the bot", "correlation_id": "none", "exception": "Traceback (most recent call last):\n  File \"/home/technedict/Desktop/ViralPackage/viralcorelib/lib64/python3.13/site-packages/telegram/_bot.py\", line 777, in initialize\n    await self.get_me()\n  File \"/home/technedict/Desktop/ViralPackage/viralcorelib/lib64/python3.13/site-packages/telegram/ext/_extbot.py\", line 1920, in get_me\n    return await super().get_me(\n           ^^^^^^^^^^^^^^^^^^^^^\n    ...<5 lines>...\n    )\n    ^\n  File \"/home/technedict/Desktop/ViralPackage/viralcorelib/lib64/python3.13/site-packages/telegram/_bot.py\", line 909, in get_me\n    result = await self._post(\n             ^^^^^^^^^^^^^^^^^\n    ...<6 lines>...\n    )\n    ^\n  File \"/home/technedict/Desktop/ViralPackage/viralcorelib/lib64/python3.13/site-packages/telegram/_bot.py\", line 623, in _post\n    return await self._do_post(\n           ^^^^^^^^^^^^^^^^^^^^\n    ...<6 lines>...\n    )\n    ^\n  File \"/home/technedict/Desktop/ViralPackage/viralcorelib/lib64/python3.13/site-packages/telegram/ext/_extbot.py\", line 355, in _do_post\n    return await super()._do_post(\n           ^^^^^^^^^^^^^^^^^^^^^^^\n    ...<6 lines>...\n    )\n    ^\n  File \"/home/technedict/Desktop/ViralPackage/viralcorelib/lib64/python3.13/site-packages/telegram/_bot.py\", line 652, in _do_post\n    result = await request.post(\n             ^^^^^^^^^^^^^^^^^^^\n    ...<6 lines>...\n    )\n    ^\n  File \"/home/technedict/Desktop/ViralPackage/viralcorelib/lib64/python3.13/site-packages/telegram/request/_baserequest.py\", line 201, in post\n    result = await self._request_wrapper(\n             ^^^^^^^^^^^^^^^^^^^^^^^^^^^^\n    ...<7 lines>...\n    )\n    ^\n  File \"/home/technedict/Desktop/ViralPackage/viralcorelib/lib64/python3.13/site-packages/telegram/request/_baserequest.py\", line 380, in _request_wrapper\n    raise InvalidToken(message)\ntelegram.error.InvalidToken: ***REDACTED***\"/home/technedict/Desktop/ViralPackage/viralcore/main_viral_core_bot.py\", line 245, in main\n    await app.initialize()\n  File \"/home/technedict/Desktop/ViralPackage/viralcorelib/lib64/python3.13/site-packages/telegram/ext/_application.py\", line 503, in initialize\n    await self.bot.initialize()\n  File \"/home/technedict/Desktop/ViralPackage/viralcorelib/lib64/python3.13/site-packages/telegram/ext/_extbot.py\", line 301, in initialize\n    await super().initialize()\n  File \"/home/technedict/Desktop/ViralPackage/viralcorelib/lib64/python3.13/site-packages/telegram/_bot.py\", line 779, in initialize\n    raise InvalidToken(f\"The token `{self._token}` was rejected by the server.\") from exc\ntelegram.error.InvalidToken: ***REDACTED***"}
{"timestamp": "2025-09-29T08:59:07.802035Z", "level": "ERROR", "module": "__main__", "message": "Error during app.stop()", "correlation_id": "none", "exception": "Traceback (most recent call last):\n  File \"/home/technedict/Desktop/ViralPackage/viralcore/main_viral_core_bot.py\", line 295, in main\n    await app.stop()\n  File \"/home/technedict/Desktop/ViralPackage/viralcorelib/lib64/python3.13/site-packages/telegram/ext/_application.py\", line 677, in stop\n    raise RuntimeError(\"This Application is not running!\")\nRuntimeError: This Application is not running!"}
{"timestamp": "2025-09-29T08:59:12.354236Z", "level": "WARNING", "module": "utils.config", "message": "Missing required environment variables: TELEGRAM_BOT_TOKEN, FLUTTERWAVE_API_KEY, EXCHANGE_API_KEY", "correlation_id": "none"}
{"timestamp": "2025-09-29T08:59:12.354682Z", "level": "WARNING", "module": "utils.config", "message": "Please check your .env file or environment variable configuration", "correlation_id": "none"}
{"timestamp": "2025-09-29T08:59:13.131707Z", "level": "ERROR", "module": "__main__", "message": "Unexpected error while running the bot", "correlation_id": "none", "exception": "Traceback (most recent call last):\n  File \"/home/technedict/Desktop/ViralPackage/viralcorelib/lib64/python3.13/site-packages/telegram/_bot.py\", line 777, in initialize\n    await self.get_me()\n  File \"/home/technedict/Desktop/ViralPackage/viralcorelib/lib64/python3.13/site-packages/telegram/ext/_extbot.py\", line 1920, in get_me\n    return await super().get_me(\n           ^^^^^^^^^^^^^^^^^^^^^\n    ...<5 lines>...\n    )\n    ^\n  File \"/home/technedict/Desktop/ViralPackage/viralcorelib/lib64/python3.13/site-packages/telegram/_bot.py\", line 909, in get_me\n    result = await self._post(\n             ^^^^^^^^^^^^^^^^^\n    ...<6 lines>...\n    )\n    ^\n  File \"/home/technedict/Desktop/ViralPackage/viralcorelib/lib64/python3.13/site-packages/telegram/_bot.py\", line 623, in _post\n    return await self._do_post(\n           ^^^^^^^^^^^^^^^^^^^^\n    ...<6 lines>...\n    )\n    ^\n  File \"/home/technedict/Desktop/ViralPackage/viralcorelib/lib64/python3.13/site-packages/telegram/ext/_extbot.py\", line 355, in _do_post\n    return await super()._do_post(\n           ^^^^^^^^^^^^^^^^^^^^^^^\n    ...<6 lines>...\n    )\n    ^\n  File \"/home/technedict/Desktop/ViralPackage/viralcorelib/lib64/python3.13/site-packages/telegram/_bot.py\", line 652, in _do_post\n    result = await request.post(\n             ^^^^^^^^^^^^^^^^^^^\n    ...<6 lines>...\n    )\n    ^\n  File \"/home/technedict/Desktop/ViralPackage/viralcorelib/lib64/python3.13/site-packages/telegram/request/_baserequest.py\", line 201, in post\n    result = await self._request_wrapper(\n             ^^^^^^^^^^^^^^^^^^^^^^^^^^^^\n    ...<7 lines>...\n    )\n    ^\n  File \"/home/technedict/Desktop/ViralPackage/viralcorelib/lib64/python3.13/site-packages/telegram/request/_baserequest.py\", line 380, in _request_wrapper\n    raise InvalidToken(message)\ntelegram.error.InvalidToken: ***REDACTED***\"/home/technedict/Desktop/ViralPackage/viralcore/main_viral_core_bot.py\", line 245, in main\n    await app.initialize()\n  File \"/home/technedict/Desktop/ViralPackage/viralcorelib/lib64/python3.13/site-packages/telegram/ext/_application.py\", line 503, in initialize\n    await self.bot.initialize()\n  File \"/home/technedict/Desktop/ViralPackage/viralcorelib/lib64/python3.13/site-packages/telegram/ext/_extbot.py\", line 301, in initialize\n    await super().initialize()\n  File \"/home/technedict/Desktop/ViralPackage/viralcorelib/lib64/python3.13/site-packages/telegram/_bot.py\", line 779, in initialize\n    raise InvalidToken(f\"The token `{self._token}` was rejected by the server.\") from exc\ntelegram.error.InvalidToken: ***REDACTED***"}
{"timestamp": "2025-09-29T08:59:13.154176Z", "level": "ERROR", "module": "__main__", "message": "Error during app.stop()", "correlation_id": "none", "exception": "Traceback (most recent call last):\n  File \"/home/technedict/Desktop/ViralPackage/viralcore/main_viral_core_bot.py\", line 295, in main\n    await app.stop()\n  File \"/home/technedict/Desktop/ViralPackage/viralcorelib/lib64/python3.13/site-packages/telegram/ext/_application.py\", line 677, in stop\n    raise RuntimeError(\"This Application is not running!\")\nRuntimeError: This Application is not running!"}
{"timestamp": "2025-09-29T08:59:52.831346Z", "level": "WARNING", "module": "utils.config", "message": "Missing required environment variables: TELEGRAM_BOT_TOKEN, FLUTTERWAVE_API_KEY, EXCHANGE_API_KEY", "correlation_id": "none"}
{"timestamp": "2025-09-29T08:59:52.832303Z", "level": "WARNING", "module": "utils.config", "message": "Please check your .env file or environment variable configuration", "correlation_id": "none"}
{"timestamp": "2025-09-29T08:59:53.507953Z", "level": "ERROR", "module": "__main__", "message": "Unexpected error while running the bot", "correlation_id": "none", "exception": "Traceback (most recent call last):\n  File \"/home/technedict/Desktop/ViralPackage/viralcorelib/lib64/python3.13/site-packages/telegram/_bot.py\", line 777, in initialize\n    await self.get_me()\n  File \"/home/technedict/Desktop/ViralPackage/viralcorelib/lib64/python3.13/site-packages/telegram/ext/_extbot.py\", line 1920, in get_me\n    return await super().get_me(\n           ^^^^^^^^^^^^^^^^^^^^^\n    ...<5 lines>...\n    )\n    ^\n  File \"/home/technedict/Desktop/ViralPackage/viralcorelib/lib64/python3.13/site-packages/telegram/_bot.py\", line 909, in get_me\n    result = await self._post(\n             ^^^^^^^^^^^^^^^^^\n    ...<6 lines>...\n    )\n    ^\n  File \"/home/technedict/Desktop/ViralPackage/viralcorelib/lib64/python3.13/site-packages/telegram/_bot.py\", line 623, in _post\n    return await self._do_post(\n           ^^^^^^^^^^^^^^^^^^^^\n    ...<6 lines>...\n    )\n    ^\n  File \"/home/technedict/Desktop/ViralPackage/viralcorelib/lib64/python3.13/site-packages/telegram/ext/_extbot.py\", line 355, in _do_post\n    return await super()._do_post(\n           ^^^^^^^^^^^^^^^^^^^^^^^\n    ...<6 lines>...\n    )\n    ^\n  File \"/home/technedict/Desktop/ViralPackage/viralcorelib/lib64/python3.13/site-packages/telegram/_bot.py\", line 652, in _do_post\n    result = await request.post(\n             ^^^^^^^^^^^^^^^^^^^\n    ...<6 lines>...\n    )\n    ^\n  File \"/home/technedict/Desktop/ViralPackage/viralcorelib/lib64/python3.13/site-packages/telegram/request/_baserequest.py\", line 201, in post\n    result = await self._request_wrapper(\n             ^^^^^^^^^^^^^^^^^^^^^^^^^^^^\n    ...<7 lines>...\n    )\n    ^\n  File \"/home/technedict/Desktop/ViralPackage/viralcorelib/lib64/python3.13/site-packages/telegram/request/_baserequest.py\", line 380, in _request_wrapper\n    raise InvalidToken(message)\ntelegram.error.InvalidToken: ***REDACTED***\"/home/technedict/Desktop/ViralPackage/viralcore/main_viral_core_bot.py\", line 245, in main\n    await app.initialize()\n  File \"/home/technedict/Desktop/ViralPackage/viralcorelib/lib64/python3.13/site-packages/telegram/ext/_application.py\", line 503, in initialize\n    await self.bot.initialize()\n  File \"/home/technedict/Desktop/ViralPackage/viralcorelib/lib64/python3.13/site-packages/telegram/ext/_extbot.py\", line 301, in initialize\n    await super().initialize()\n  File \"/home/technedict/Desktop/ViralPackage/viralcorelib/lib64/python3.13/site-packages/telegram/_bot.py\", line 779, in initialize\n    raise InvalidToken(f\"The token `{self._token}` was rejected by the server.\") from exc\ntelegram.error.InvalidToken: ***REDACTED***"}
{"timestamp": "2025-09-29T08:59:53.523438Z", "level": "ERROR", "module": "__main__", "message": "Error during app.stop()", "correlation_id": "none", "exception": "Traceback (most recent call last):\n  File \"/home/technedict/Desktop/ViralPackage/viralcore/main_viral_core_bot.py\", line 295, in main\n    await app.stop()\n  File \"/home/technedict/Desktop/ViralPackage/viralcorelib/lib64/python3.13/site-packages/telegram/ext/_application.py\", line 677, in stop\n    raise RuntimeError(\"This Application is not running!\")\nRuntimeError: This Application is not running!"}
{"timestamp": "2025-09-29T09:00:34.792432Z", "level": "ERROR", "module": "telegram.ext.Updater", "message": "Exception happened while polling for updates.", "correlation_id": "none", "exception": "Traceback (most recent call last):\n  File \"/home/technedict/Desktop/ViralPackage/viralcorelib/lib64/python3.13/site-packages/telegram/ext/_updater.py\", line 753, in _network_loop_retry\n    if not await do_action():\n           ^^^^^^^^^^^^^^^^^\n  File \"/home/technedict/Desktop/ViralPackage/viralcorelib/lib64/python3.13/site-packages/telegram/ext/_updater.py\", line 747, in do_action\n    return action_cb_task.result()\n           ~~~~~~~~~~~~~~~~~~~~~^^\n  File \"/home/technedict/Desktop/ViralPackage/viralcorelib/lib64/python3.13/site-packages/telegram/ext/_updater.py\", line 377, in polling_action_cb\n    updates = await self.bot.get_updates(\n              ^^^^^^^^^^^^^^^^^^^^^^^^^^^\n    ...<7 lines>...\n    )\n    ^\n  File \"/home/technedict/Desktop/ViralPackage/viralcorelib/lib64/python3.13/site-packages/telegram/ext/_extbot.py\", line 649, in get_updates\n    updates = await super().get_updates(\n              ^^^^^^^^^^^^^^^^^^^^^^^^^^\n    ...<9 lines>...\n    )\n    ^\n  File \"/home/technedict/Desktop/ViralPackage/viralcorelib/lib64/python3.13/site-packages/telegram/_bot.py\", line 4366, in get_updates\n    await self._post(\n    ^^^^^^^^^^^^^^^^^\n    ...<7 lines>...\n    ),\n    ^\n  File \"/home/technedict/Desktop/ViralPackage/viralcorelib/lib64/python3.13/site-packages/telegram/_bot.py\", line 623, in _post\n    return await self._do_post(\n           ^^^^^^^^^^^^^^^^^^^^\n    ...<6 lines>...\n    )\n    ^\n  File \"/home/technedict/Desktop/ViralPackage/viralcorelib/lib64/python3.13/site-packages/telegram/ext/_extbot.py\", line 355, in _do_post\n    return await super()._do_post(\n           ^^^^^^^^^^^^^^^^^^^^^^^\n    ...<6 lines>...\n    )\n    ^\n  File \"/home/technedict/Desktop/ViralPackage/viralcorelib/lib64/python3.13/site-packages/telegram/_bot.py\", line 652, in _do_post\n    result = await request.post(\n             ^^^^^^^^^^^^^^^^^^^\n    ...<6 lines>...\n    )\n    ^\n  File \"/home/technedict/Desktop/ViralPackage/viralcorelib/lib64/python3.13/site-packages/telegram/request/_baserequest.py\", line 201, in post\n    result = await self._request_wrapper(\n             ^^^^^^^^^^^^^^^^^^^^^^^^^^^^\n    ...<7 lines>...\n    )\n    ^\n  File \"/home/technedict/Desktop/ViralPackage/viralcorelib/lib64/python3.13/site-packages/telegram/request/_baserequest.py\", line 384, in _request_wrapper\n    raise Conflict(message)\ntelegram.error.Conflict: Conflict: terminated by other getUpdates request; make sure that only one bot instance is running"}
{"timestamp": "2025-09-29T09:00:40.654020Z", "level": "ERROR", "module": "telegram.ext.Updater", "message": "Exception happened while polling for updates.", "correlation_id": "none", "exception": "Traceback (most recent call last):\n  File \"/home/technedict/Desktop/ViralPackage/viralcorelib/lib64/python3.13/site-packages/telegram/ext/_updater.py\", line 753, in _network_loop_retry\n    if not await do_action():\n           ^^^^^^^^^^^^^^^^^\n  File \"/home/technedict/Desktop/ViralPackage/viralcorelib/lib64/python3.13/site-packages/telegram/ext/_updater.py\", line 747, in do_action\n    return action_cb_task.result()\n           ~~~~~~~~~~~~~~~~~~~~~^^\n  File \"/home/technedict/Desktop/ViralPackage/viralcorelib/lib64/python3.13/site-packages/telegram/ext/_updater.py\", line 377, in polling_action_cb\n    updates = await self.bot.get_updates(\n              ^^^^^^^^^^^^^^^^^^^^^^^^^^^\n    ...<7 lines>...\n    )\n    ^\n  File \"/home/technedict/Desktop/ViralPackage/viralcorelib/lib64/python3.13/site-packages/telegram/ext/_extbot.py\", line 649, in get_updates\n    updates = await super().get_updates(\n              ^^^^^^^^^^^^^^^^^^^^^^^^^^\n    ...<9 lines>...\n    )\n    ^\n  File \"/home/technedict/Desktop/ViralPackage/viralcorelib/lib64/python3.13/site-packages/telegram/_bot.py\", line 4366, in get_updates\n    await self._post(\n    ^^^^^^^^^^^^^^^^^\n    ...<7 lines>...\n    ),\n    ^\n  File \"/home/technedict/Desktop/ViralPackage/viralcorelib/lib64/python3.13/site-packages/telegram/_bot.py\", line 623, in _post\n    return await self._do_post(\n           ^^^^^^^^^^^^^^^^^^^^\n    ...<6 lines>...\n    )\n    ^\n  File \"/home/technedict/Desktop/ViralPackage/viralcorelib/lib64/python3.13/site-packages/telegram/ext/_extbot.py\", line 355, in _do_post\n    return await super()._do_post(\n           ^^^^^^^^^^^^^^^^^^^^^^^\n    ...<6 lines>...\n    )\n    ^\n  File \"/home/technedict/Desktop/ViralPackage/viralcorelib/lib64/python3.13/site-packages/telegram/_bot.py\", line 652, in _do_post\n    result = await request.post(\n             ^^^^^^^^^^^^^^^^^^^\n    ...<6 lines>...\n    )\n    ^\n  File \"/home/technedict/Desktop/ViralPackage/viralcorelib/lib64/python3.13/site-packages/telegram/request/_baserequest.py\", line 201, in post\n    result = await self._request_wrapper(\n             ^^^^^^^^^^^^^^^^^^^^^^^^^^^^\n    ...<7 lines>...\n    )\n    ^\n  File \"/home/technedict/Desktop/ViralPackage/viralcorelib/lib64/python3.13/site-packages/telegram/request/_baserequest.py\", line 384, in _request_wrapper\n    raise Conflict(message)\ntelegram.error.Conflict: Conflict: terminated by other getUpdates request; make sure that only one bot instance is running"}
{"timestamp": "2025-09-29T09:00:47.620565Z", "level": "ERROR", "module": "telegram.ext.Updater", "message": "Exception happened while polling for updates.", "correlation_id": "none", "exception": "Traceback (most recent call last):\n  File \"/home/technedict/Desktop/ViralPackage/viralcorelib/lib64/python3.13/site-packages/telegram/ext/_updater.py\", line 753, in _network_loop_retry\n    if not await do_action():\n           ^^^^^^^^^^^^^^^^^\n  File \"/home/technedict/Desktop/ViralPackage/viralcorelib/lib64/python3.13/site-packages/telegram/ext/_updater.py\", line 747, in do_action\n    return action_cb_task.result()\n           ~~~~~~~~~~~~~~~~~~~~~^^\n  File \"/home/technedict/Desktop/ViralPackage/viralcorelib/lib64/python3.13/site-packages/telegram/ext/_updater.py\", line 377, in polling_action_cb\n    updates = await self.bot.get_updates(\n              ^^^^^^^^^^^^^^^^^^^^^^^^^^^\n    ...<7 lines>...\n    )\n    ^\n  File \"/home/technedict/Desktop/ViralPackage/viralcorelib/lib64/python3.13/site-packages/telegram/ext/_extbot.py\", line 649, in get_updates\n    updates = await super().get_updates(\n              ^^^^^^^^^^^^^^^^^^^^^^^^^^\n    ...<9 lines>...\n    )\n    ^\n  File \"/home/technedict/Desktop/ViralPackage/viralcorelib/lib64/python3.13/site-packages/telegram/_bot.py\", line 4366, in get_updates\n    await self._post(\n    ^^^^^^^^^^^^^^^^^\n    ...<7 lines>...\n    ),\n    ^\n  File \"/home/technedict/Desktop/ViralPackage/viralcorelib/lib64/python3.13/site-packages/telegram/_bot.py\", line 623, in _post\n    return await self._do_post(\n           ^^^^^^^^^^^^^^^^^^^^\n    ...<6 lines>...\n    )\n    ^\n  File \"/home/technedict/Desktop/ViralPackage/viralcorelib/lib64/python3.13/site-packages/telegram/ext/_extbot.py\", line 355, in _do_post\n    return await super()._do_post(\n           ^^^^^^^^^^^^^^^^^^^^^^^\n    ...<6 lines>...\n    )\n    ^\n  File \"/home/technedict/Desktop/ViralPackage/viralcorelib/lib64/python3.13/site-packages/telegram/_bot.py\", line 652, in _do_post\n    result = await request.post(\n             ^^^^^^^^^^^^^^^^^^^\n    ...<6 lines>...\n    )\n    ^\n  File \"/home/technedict/Desktop/ViralPackage/viralcorelib/lib64/python3.13/site-packages/telegram/request/_baserequest.py\", line 201, in post\n    result = await self._request_wrapper(\n             ^^^^^^^^^^^^^^^^^^^^^^^^^^^^\n    ...<7 lines>...\n    )\n    ^\n  File \"/home/technedict/Desktop/ViralPackage/viralcorelib/lib64/python3.13/site-packages/telegram/request/_baserequest.py\", line 384, in _request_wrapper\n    raise Conflict(message)\ntelegram.error.Conflict: Conflict: terminated by other getUpdates request; make sure that only one bot instance is running"}
{"timestamp": "2025-09-29T09:00:53.560000Z", "level": "ERROR", "module": "telegram.ext.Updater", "message": "Exception happened while polling for updates.", "correlation_id": "none", "exception": "Traceback (most recent call last):\n  File \"/home/technedict/Desktop/ViralPackage/viralcorelib/lib64/python3.13/site-packages/telegram/ext/_updater.py\", line 753, in _network_loop_retry\n    if not await do_action():\n           ^^^^^^^^^^^^^^^^^\n  File \"/home/technedict/Desktop/ViralPackage/viralcorelib/lib64/python3.13/site-packages/telegram/ext/_updater.py\", line 747, in do_action\n    return action_cb_task.result()\n           ~~~~~~~~~~~~~~~~~~~~~^^\n  File \"/home/technedict/Desktop/ViralPackage/viralcorelib/lib64/python3.13/site-packages/telegram/ext/_updater.py\", line 377, in polling_action_cb\n    updates = await self.bot.get_updates(\n              ^^^^^^^^^^^^^^^^^^^^^^^^^^^\n    ...<7 lines>...\n    )\n    ^\n  File \"/home/technedict/Desktop/ViralPackage/viralcorelib/lib64/python3.13/site-packages/telegram/ext/_extbot.py\", line 649, in get_updates\n    updates = await super().get_updates(\n              ^^^^^^^^^^^^^^^^^^^^^^^^^^\n    ...<9 lines>...\n    )\n    ^\n  File \"/home/technedict/Desktop/ViralPackage/viralcorelib/lib64/python3.13/site-packages/telegram/_bot.py\", line 4366, in get_updates\n    await self._post(\n    ^^^^^^^^^^^^^^^^^\n    ...<7 lines>...\n    ),\n    ^\n  File \"/home/technedict/Desktop/ViralPackage/viralcorelib/lib64/python3.13/site-packages/telegram/_bot.py\", line 623, in _post\n    return await self._do_post(\n           ^^^^^^^^^^^^^^^^^^^^\n    ...<6 lines>...\n    )\n    ^\n  File \"/home/technedict/Desktop/ViralPackage/viralcorelib/lib64/python3.13/site-packages/telegram/ext/_extbot.py\", line 355, in _do_post\n    return await super()._do_post(\n           ^^^^^^^^^^^^^^^^^^^^^^^\n    ...<6 lines>...\n    )\n    ^\n  File \"/home/technedict/Desktop/ViralPackage/viralcorelib/lib64/python3.13/site-packages/telegram/_bot.py\", line 652, in _do_post\n    result = await request.post(\n             ^^^^^^^^^^^^^^^^^^^\n    ...<6 lines>...\n    )\n    ^\n  File \"/home/technedict/Desktop/ViralPackage/viralcorelib/lib64/python3.13/site-packages/telegram/request/_baserequest.py\", line 201, in post\n    result = await self._request_wrapper(\n             ^^^^^^^^^^^^^^^^^^^^^^^^^^^^\n    ...<7 lines>...\n    )\n    ^\n  File \"/home/technedict/Desktop/ViralPackage/viralcorelib/lib64/python3.13/site-packages/telegram/request/_baserequest.py\", line 384, in _request_wrapper\n    raise Conflict(message)\ntelegram.error.Conflict: Conflict: terminated by other getUpdates request; make sure that only one bot instance is running"}
{"timestamp": "2025-09-29T09:00:55.783867Z", "level": "WARNING", "module": "utils.graceful_shutdown", "message": "updater.shutdown() raised: This Updater is still running!", "correlation_id": "none"}
{"timestamp": "2025-09-29T09:00:55.784801Z", "level": "WARNING", "module": "utils.graceful_shutdown", "message": "Shutdown already in progress", "correlation_id": "none"}
{"timestamp": "2025-09-29T09:00:55.799771Z", "level": "ERROR", "module": "__main__", "message": "Error during app.shutdown()", "correlation_id": "none", "exception": "Traceback (most recent call last):\n  File \"/home/technedict/Desktop/ViralPackage/viralcore/main_viral_core_bot.py\", line 301, in main\n    await app.shutdown()\n  File \"/home/technedict/Desktop/ViralPackage/viralcorelib/lib64/python3.13/site-packages/telegram/ext/_application.py\", line 561, in shutdown\n    await self.updater.shutdown()\n  File \"/home/technedict/Desktop/ViralPackage/viralcorelib/lib64/python3.13/site-packages/telegram/ext/_updater.py\", line 204, in shutdown\n    raise RuntimeError(\"This Updater is still running!\")\nRuntimeError: This Updater is still running!"}
{"timestamp": "2025-09-29T09:01:44.352584Z", "level": "ERROR", "module": "telegram.ext.Application", "message": "No error handlers are registered, logging exception.", "correlation_id": "none", "exception": "Traceback (most recent call last):\n  File \"/home/technedict/Desktop/ViralPackage/viralcorelib/lib64/python3.13/site-packages/telegram/ext/_application.py\", line 1335, in process_update\n    await coroutine\n  File \"/home/technedict/Desktop/ViralPackage/viralcorelib/lib64/python3.13/site-packages/telegram/ext/_handlers/basehandler.py\", line 157, in handle_update\n    return await self.callback(update, context)\n           ^^^^^^^^^^^^^^^^^^^^^^^^^^^^^^^^^^^^\n  File \"/home/technedict/Desktop/ViralPackage/viralcore/handlers/message_handler.py\", line 57, in message_router\n    await custom_order_handler(update, context) # Or a general_message_handler\n    ^^^^^^^^^^^^^^^^^^^^^^^^^^^^^^^^^^^^^^^^^^^\n  File \"/home/technedict/Desktop/ViralPackage/viralcore/handlers/custom_order_handlers.py\", line 37, in custom_order_handler\n    text = update.message.text.strip()\n           ^^^^^^^^^^^^^^^^^^^\nAttributeError: 'NoneType' object has no attribute 'text'"}
{"timestamp": "2025-09-29T09:01:44.559770Z", "level": "ERROR", "module": "telegram.ext.Application", "message": "No error handlers are registered, logging exception.", "correlation_id": "none", "exception": "Traceback (most recent call last):\n  File \"/home/technedict/Desktop/ViralPackage/viralcorelib/lib64/python3.13/site-packages/telegram/ext/_application.py\", line 1335, in process_update\n    await coroutine\n  File \"/home/technedict/Desktop/ViralPackage/viralcorelib/lib64/python3.13/site-packages/telegram/ext/_handlers/basehandler.py\", line 157, in handle_update\n    return await self.callback(update, context)\n           ^^^^^^^^^^^^^^^^^^^^^^^^^^^^^^^^^^^^\n  File \"/home/technedict/Desktop/ViralPackage/viralcore/handlers/admin_handlers.py\", line 60, in admin_panel_handler\n    await query.answer()\n  File \"/home/technedict/Desktop/ViralPackage/viralcorelib/lib64/python3.13/site-packages/telegram/_callbackquery.py\", line 189, in answer\n    return await self.get_bot().answer_callback_query(\n           ^^^^^^^^^^^^^^^^^^^^^^^^^^^^^^^^^^^^^^^^^^^\n    ...<10 lines>...\n    )\n    ^\n  File \"/home/technedict/Desktop/ViralPackage/viralcorelib/lib64/python3.13/site-packages/telegram/ext/_extbot.py\", line 935, in answer_callback_query\n    return await super().answer_callback_query(\n           ^^^^^^^^^^^^^^^^^^^^^^^^^^^^^^^^^^^^\n    ...<10 lines>...\n    )\n    ^\n  File \"/home/technedict/Desktop/ViralPackage/viralcorelib/lib64/python3.13/site-packages/telegram/_bot.py\", line 3944, in answer_callback_query\n    return await self._post(\n           ^^^^^^^^^^^^^^^^^\n    ...<7 lines>...\n    )\n    ^\n  File \"/home/technedict/Desktop/ViralPackage/viralcorelib/lib64/python3.13/site-packages/telegram/_bot.py\", line 623, in _post\n    return await self._do_post(\n           ^^^^^^^^^^^^^^^^^^^^\n    ...<6 lines>...\n    )\n    ^\n  File \"/home/technedict/Desktop/ViralPackage/viralcorelib/lib64/python3.13/site-packages/telegram/ext/_extbot.py\", line 355, in _do_post\n    return await super()._do_post(\n           ^^^^^^^^^^^^^^^^^^^^^^^\n    ...<6 lines>...\n    )\n    ^\n  File \"/home/technedict/Desktop/ViralPackage/viralcorelib/lib64/python3.13/site-packages/telegram/_bot.py\", line 652, in _do_post\n    result = await request.post(\n             ^^^^^^^^^^^^^^^^^^^\n    ...<6 lines>...\n    )\n    ^\n  File \"/home/technedict/Desktop/ViralPackage/viralcorelib/lib64/python3.13/site-packages/telegram/request/_baserequest.py\", line 201, in post\n    result = await self._request_wrapper(\n             ^^^^^^^^^^^^^^^^^^^^^^^^^^^^\n    ...<7 lines>...\n    )\n    ^\n  File \"/home/technedict/Desktop/ViralPackage/viralcorelib/lib64/python3.13/site-packages/telegram/request/_baserequest.py\", line 382, in _request_wrapper\n    raise BadRequest(message)\ntelegram.error.BadRequest: Query is too old and response timeout expired or query id is invalid"}
{"timestamp": "2025-09-29T09:01:57.841647Z", "level": "ERROR", "module": "utils.boost_utils", "message": "[Boost] Network or HTTP error fetching balance for plugsmms: Cannot connect to host panel.plugsmmservice.com:443 ssl:True [SSLCertVerificationError: (1, \"[SSL: CERTIFICATE_VERIFY_FAILED] certificate verify failed: Hostname mismatch, certificate is not valid for 'panel.plugsmmservice.com'. (_ssl.c:1032)\")]", "correlation_id": "none"}
{"timestamp": "2025-09-29T09:03:07.269396Z", "level": "ERROR", "module": "telegram.ext.Application", "message": "No error handlers are registered, logging exception.", "correlation_id": "none", "exception": "Traceback (most recent call last):\n  File \"/home/technedict/Desktop/ViralPackage/viralcorelib/lib64/python3.13/site-packages/telegram/ext/_application.py\", line 1335, in process_update\n    await coroutine\n  File \"/home/technedict/Desktop/ViralPackage/viralcorelib/lib64/python3.13/site-packages/telegram/ext/_handlers/basehandler.py\", line 157, in handle_update\n    return await self.callback(update, context)\n           ^^^^^^^^^^^^^^^^^^^^^^^^^^^^^^^^^^^^\n  File \"/home/technedict/Desktop/ViralPackage/viralcore/handlers/admin_service_handlers.py\", line 127, in admin_services_edit_handler\n    mappings = get_boosting_service_manager().get_current_provider_mappings_summary()\n  File \"/home/technedict/Desktop/ViralPackage/viralcore/utils/boosting_service_manager.py\", line 228, in get_current_provider_mappings_summary\n    c.execute('''\n    ~~~~~~~~~^^^^\n        SELECT bs.service_type, bsp.provider_name, bsp.provider_service_id\n        ^^^^^^^^^^^^^^^^^^^^^^^^^^^^^^^^^^^^^^^^^^^^^^^^^^^^^^^^^^^^^^^^^^\n    ...<3 lines>...\n        ORDER BY bs.service_type, bsp.provider_name\n        ^^^^^^^^^^^^^^^^^^^^^^^^^^^^^^^^^^^^^^^^^^^\n    ''')\n    ^^^^\nsqlite3.OperationalError: no such table: boosting_services"}
{"timestamp": "2025-09-29T09:03:14.022280Z", "level": "WARNING", "module": "utils.graceful_shutdown", "message": "updater.shutdown() raised: This Updater is still running!", "correlation_id": "none"}
{"timestamp": "2025-09-29T09:03:14.022991Z", "level": "WARNING", "module": "utils.graceful_shutdown", "message": "Shutdown already in progress", "correlation_id": "none"}
{"timestamp": "2025-09-29T09:03:14.037043Z", "level": "ERROR", "module": "__main__", "message": "Error during app.shutdown()", "correlation_id": "none", "exception": "Traceback (most recent call last):\n  File \"/home/technedict/Desktop/ViralPackage/viralcore/main_viral_core_bot.py\", line 301, in main\n    await app.shutdown()\n  File \"/home/technedict/Desktop/ViralPackage/viralcorelib/lib64/python3.13/site-packages/telegram/ext/_application.py\", line 561, in shutdown\n    await self.updater.shutdown()\n  File \"/home/technedict/Desktop/ViralPackage/viralcorelib/lib64/python3.13/site-packages/telegram/ext/_updater.py\", line 204, in shutdown\n    raise RuntimeError(\"This Updater is still running!\")\nRuntimeError: This Updater is still running!"}
{"timestamp": "2025-09-29T09:03:14.124521Z", "level": "ERROR", "module": "asyncio", "message": "Task exception was never retrieved\nfuture: <Task finished name='Task-42' coro=<Updater._start_polling.<locals>.polling_action_cb() done, defined at /home/technedict/Desktop/ViralPackage/viralcorelib/lib64/python3.13/site-packages/telegram/ext/_updater.py:375> exception=NetworkError('httpx.ReadError: ')>", "correlation_id": "none", "exception": "Traceback (most recent call last):\n  File \"/home/technedict/Desktop/ViralPackage/viralcorelib/lib64/python3.13/site-packages/httpx/_transports/default.py\", line 101, in map_httpcore_exceptions\n  File \"/home/technedict/Desktop/ViralPackage/viralcorelib/lib64/python3.13/site-packages/httpx/_transports/default.py\", line 394, in handle_async_request\n  File \"/home/technedict/Desktop/ViralPackage/viralcorelib/lib64/python3.13/site-packages/httpcore/_async/connection_pool.py\", line 256, in handle_async_request\n  File \"/home/technedict/Desktop/ViralPackage/viralcorelib/lib64/python3.13/site-packages/httpcore/_async/connection_pool.py\", line 236, in handle_async_request\n  File \"/home/technedict/Desktop/ViralPackage/viralcorelib/lib64/python3.13/site-packages/httpcore/_async/connection.py\", line 103, in handle_async_request\n  File \"/home/technedict/Desktop/ViralPackage/viralcorelib/lib64/python3.13/site-packages/httpcore/_async/http11.py\", line 136, in handle_async_request\n  File \"/home/technedict/Desktop/ViralPackage/viralcorelib/lib64/python3.13/site-packages/httpcore/_async/http11.py\", line 106, in handle_async_request\n  File \"/home/technedict/Desktop/ViralPackage/viralcorelib/lib64/python3.13/site-packages/httpcore/_async/http11.py\", line 177, in _receive_response_headers\n  File \"/home/technedict/Desktop/ViralPackage/viralcorelib/lib64/python3.13/site-packages/httpcore/_async/http11.py\", line 217, in _receive_event\n  File \"/home/technedict/Desktop/ViralPackage/viralcorelib/lib64/python3.13/site-packages/httpcore/_backends/anyio.py\", line 32, in read\n  File \"/usr/lib64/python3.13/contextlib.py\", line 162, in __exit__\n  File \"/home/technedict/Desktop/ViralPackage/viralcorelib/lib64/python3.13/site-packages/httpcore/_exceptions.py\", line 14, in map_exceptions\nhttpcore.ReadError\n\nThe above exception was the direct cause of the following exception:\n\nTraceback (most recent call last):\n  File \"/home/technedict/Desktop/ViralPackage/viralcorelib/lib64/python3.13/site-packages/telegram/request/_httpxrequest.py\", line 276, in do_request\n  File \"/home/technedict/Desktop/ViralPackage/viralcorelib/lib64/python3.13/site-packages/httpx/_client.py\", line 1540, in request\n  File \"/home/technedict/Desktop/ViralPackage/viralcorelib/lib64/python3.13/site-packages/httpx/_client.py\", line 1629, in send\n  File \"/home/technedict/Desktop/ViralPackage/viralcorelib/lib64/python3.13/site-packages/httpx/_client.py\", line 1657, in _send_handling_auth\n  File \"/home/technedict/Desktop/ViralPackage/viralcorelib/lib64/python3.13/site-packages/httpx/_client.py\", line 1694, in _send_handling_redirects\n  File \"/home/technedict/Desktop/ViralPackage/viralcorelib/lib64/python3.13/site-packages/httpx/_client.py\", line 1730, in _send_single_request\n  File \"/home/technedict/Desktop/ViralPackage/viralcorelib/lib64/python3.13/site-packages/httpx/_transports/default.py\", line 393, in handle_async_request\n  File \"/usr/lib64/python3.13/contextlib.py\", line 162, in __exit__\n  File \"/home/technedict/Desktop/ViralPackage/viralcorelib/lib64/python3.13/site-packages/httpx/_transports/default.py\", line 118, in map_httpcore_exceptions\nhttpx.ReadError\n\nThe above exception was the direct cause of the following exception:\n\nTraceback (most recent call last):\n  File \"/home/technedict/Desktop/ViralPackage/viralcorelib/lib64/python3.13/site-packages/telegram/ext/_updater.py\", line 377, in polling_action_cb\n    updates = await self.bot.get_updates(\n              ^^^^^^^^^^^^^^^^^^^^^^^^^^^\n    ...<7 lines>...\n    )\n    ^\n  File \"/home/technedict/Desktop/ViralPackage/viralcorelib/lib64/python3.13/site-packages/telegram/ext/_extbot.py\", line 649, in get_updates\n    updates = await super().get_updates(\n              ^^^^^^^^^^^^^^^^^^^^^^^^^^\n    ...<9 lines>...\n    )\n    ^\n  File \"/home/technedict/Desktop/ViralPackage/viralcorelib/lib64/python3.13/site-packages/telegram/_bot.py\", line 4366, in get_updates\n    await self._post(\n    ^^^^^^^^^^^^^^^^^\n    ...<7 lines>...\n    ),\n    ^\n  File \"/home/technedict/Desktop/ViralPackage/viralcorelib/lib64/python3.13/site-packages/telegram/_bot.py\", line 623, in _post\n    return await self._do_post(\n           ^^^^^^^^^^^^^^^^^^^^\n    ...<6 lines>...\n    )\n    ^\n  File \"/home/technedict/Desktop/ViralPackage/viralcorelib/lib64/python3.13/site-packages/telegram/ext/_extbot.py\", line 355, in _do_post\n    return await super()._do_post(\n           ^^^^^^^^^^^^^^^^^^^^^^^\n    ...<6 lines>...\n    )\n    ^\n  File \"/home/technedict/Desktop/ViralPackage/viralcorelib/lib64/python3.13/site-packages/telegram/_bot.py\", line 652, in _do_post\n    result = await request.post(\n             ^^^^^^^^^^^^^^^^^^^\n    ...<6 lines>...\n    )\n    ^\n  File \"/home/technedict/Desktop/ViralPackage/viralcorelib/lib64/python3.13/site-packages/telegram/request/_baserequest.py\", line 201, in post\n    result = await self._request_wrapper(\n             ^^^^^^^^^^^^^^^^^^^^^^^^^^^^\n    ...<7 lines>...\n    )\n    ^\n  File \"/home/technedict/Desktop/ViralPackage/viralcorelib/lib64/python3.13/site-packages/telegram/request/_baserequest.py\", line 333, in _request_wrapper\n    code, payload = await self.do_request(\n                    ^^^^^^^^^^^^^^^^^^^^^^\n    ...<7 lines>...\n    )\n    ^\n  File \"/home/technedict/Desktop/ViralPackage/viralcorelib/lib64/python3.13/site-packages/telegram/request/_httpxrequest.py\", line 300, in do_request\ntelegram.error.NetworkError: httpx.ReadError: "}
{"timestamp": "2025-09-29T09:17:07.054188Z", "level": "WARNING", "module": "utils.graceful_shutdown", "message": "updater.shutdown() raised: This Updater is still running!", "correlation_id": "none"}
{"timestamp": "2025-09-29T09:17:07.055118Z", "level": "WARNING", "module": "utils.graceful_shutdown", "message": "Shutdown already in progress", "correlation_id": "none"}
{"timestamp": "2025-09-29T09:17:07.070282Z", "level": "ERROR", "module": "__main__", "message": "Error during app.shutdown()", "correlation_id": "none", "exception": "Traceback (most recent call last):\n  File \"/home/technedict/Desktop/ViralPackage/viralcore/main_viral_core_bot.py\", line 301, in main\n    await app.shutdown()\n  File \"/home/technedict/Desktop/ViralPackage/viralcorelib/lib64/python3.13/site-packages/telegram/ext/_application.py\", line 561, in shutdown\n    await self.updater.shutdown()\n  File \"/home/technedict/Desktop/ViralPackage/viralcorelib/lib64/python3.13/site-packages/telegram/ext/_updater.py\", line 204, in shutdown\n    raise RuntimeError(\"This Updater is still running!\")\nRuntimeError: This Updater is still running!"}
{"timestamp": "2025-09-29T09:17:07.152543Z", "level": "ERROR", "module": "asyncio", "message": "Task exception was never retrieved\nfuture: <Task finished name='Task-90' coro=<Updater._start_polling.<locals>.polling_action_cb() done, defined at /home/technedict/Desktop/ViralPackage/viralcorelib/lib64/python3.13/site-packages/telegram/ext/_updater.py:375> exception=NetworkError('httpx.ReadError: ')>", "correlation_id": "none", "exception": "Traceback (most recent call last):\n  File \"/home/technedict/Desktop/ViralPackage/viralcorelib/lib64/python3.13/site-packages/httpx/_transports/default.py\", line 101, in map_httpcore_exceptions\n  File \"/home/technedict/Desktop/ViralPackage/viralcorelib/lib64/python3.13/site-packages/httpx/_transports/default.py\", line 394, in handle_async_request\n  File \"/home/technedict/Desktop/ViralPackage/viralcorelib/lib64/python3.13/site-packages/httpcore/_async/connection_pool.py\", line 256, in handle_async_request\n  File \"/home/technedict/Desktop/ViralPackage/viralcorelib/lib64/python3.13/site-packages/httpcore/_async/connection_pool.py\", line 236, in handle_async_request\n  File \"/home/technedict/Desktop/ViralPackage/viralcorelib/lib64/python3.13/site-packages/httpcore/_async/connection.py\", line 103, in handle_async_request\n  File \"/home/technedict/Desktop/ViralPackage/viralcorelib/lib64/python3.13/site-packages/httpcore/_async/http11.py\", line 136, in handle_async_request\n  File \"/home/technedict/Desktop/ViralPackage/viralcorelib/lib64/python3.13/site-packages/httpcore/_async/http11.py\", line 106, in handle_async_request\n  File \"/home/technedict/Desktop/ViralPackage/viralcorelib/lib64/python3.13/site-packages/httpcore/_async/http11.py\", line 177, in _receive_response_headers\n  File \"/home/technedict/Desktop/ViralPackage/viralcorelib/lib64/python3.13/site-packages/httpcore/_async/http11.py\", line 217, in _receive_event\n  File \"/home/technedict/Desktop/ViralPackage/viralcorelib/lib64/python3.13/site-packages/httpcore/_backends/anyio.py\", line 32, in read\n  File \"/usr/lib64/python3.13/contextlib.py\", line 162, in __exit__\n  File \"/home/technedict/Desktop/ViralPackage/viralcorelib/lib64/python3.13/site-packages/httpcore/_exceptions.py\", line 14, in map_exceptions\nhttpcore.ReadError\n\nThe above exception was the direct cause of the following exception:\n\nTraceback (most recent call last):\n  File \"/home/technedict/Desktop/ViralPackage/viralcorelib/lib64/python3.13/site-packages/telegram/request/_httpxrequest.py\", line 276, in do_request\n  File \"/home/technedict/Desktop/ViralPackage/viralcorelib/lib64/python3.13/site-packages/httpx/_client.py\", line 1540, in request\n  File \"/home/technedict/Desktop/ViralPackage/viralcorelib/lib64/python3.13/site-packages/httpx/_client.py\", line 1629, in send\n  File \"/home/technedict/Desktop/ViralPackage/viralcorelib/lib64/python3.13/site-packages/httpx/_client.py\", line 1657, in _send_handling_auth\n  File \"/home/technedict/Desktop/ViralPackage/viralcorelib/lib64/python3.13/site-packages/httpx/_client.py\", line 1694, in _send_handling_redirects\n  File \"/home/technedict/Desktop/ViralPackage/viralcorelib/lib64/python3.13/site-packages/httpx/_client.py\", line 1730, in _send_single_request\n  File \"/home/technedict/Desktop/ViralPackage/viralcorelib/lib64/python3.13/site-packages/httpx/_transports/default.py\", line 393, in handle_async_request\n  File \"/usr/lib64/python3.13/contextlib.py\", line 162, in __exit__\n  File \"/home/technedict/Desktop/ViralPackage/viralcorelib/lib64/python3.13/site-packages/httpx/_transports/default.py\", line 118, in map_httpcore_exceptions\nhttpx.ReadError\n\nThe above exception was the direct cause of the following exception:\n\nTraceback (most recent call last):\n  File \"/home/technedict/Desktop/ViralPackage/viralcorelib/lib64/python3.13/site-packages/telegram/ext/_updater.py\", line 377, in polling_action_cb\n    updates = await self.bot.get_updates(\n              ^^^^^^^^^^^^^^^^^^^^^^^^^^^\n    ...<7 lines>...\n    )\n    ^\n  File \"/home/technedict/Desktop/ViralPackage/viralcorelib/lib64/python3.13/site-packages/telegram/ext/_extbot.py\", line 649, in get_updates\n  File \"/home/technedict/Desktop/ViralPackage/viralcorelib/lib64/python3.13/site-packages/telegram/_bot.py\", line 4366, in get_updates\n  File \"/home/technedict/Desktop/ViralPackage/viralcorelib/lib64/python3.13/site-packages/telegram/_bot.py\", line 623, in _post\n  File \"/home/technedict/Desktop/ViralPackage/viralcorelib/lib64/python3.13/site-packages/telegram/ext/_extbot.py\", line 355, in _do_post\n  File \"/home/technedict/Desktop/ViralPackage/viralcorelib/lib64/python3.13/site-packages/telegram/_bot.py\", line 652, in _do_post\n  File \"/home/technedict/Desktop/ViralPackage/viralcorelib/lib64/python3.13/site-packages/telegram/request/_baserequest.py\", line 201, in post\n  File \"/home/technedict/Desktop/ViralPackage/viralcorelib/lib64/python3.13/site-packages/telegram/request/_baserequest.py\", line 333, in _request_wrapper\n  File \"/home/technedict/Desktop/ViralPackage/viralcorelib/lib64/python3.13/site-packages/telegram/request/_httpxrequest.py\", line 300, in do_request\ntelegram.error.NetworkError: httpx.ReadError: "}
{"timestamp": "2025-09-29T09:18:53.748717Z", "level": "ERROR", "module": "telegram.ext.Application", "message": "No error handlers are registered, logging exception.", "correlation_id": "none", "exception": "Traceback (most recent call last):\n  File \"/home/technedict/Desktop/ViralPackage/viralcorelib/lib64/python3.13/site-packages/telegram/ext/_application.py\", line 1335, in process_update\n    await coroutine\n  File \"/home/technedict/Desktop/ViralPackage/viralcorelib/lib64/python3.13/site-packages/telegram/ext/_handlers/basehandler.py\", line 157, in handle_update\n    return await self.callback(update, context)\n           ^^^^^^^^^^^^^^^^^^^^^^^^^^^^^^^^^^^^\n  File \"/home/technedict/Desktop/ViralPackage/viralcore/handlers/admin_handlers.py\", line 60, in admin_panel_handler\n    await query.answer()\n  File \"/home/technedict/Desktop/ViralPackage/viralcorelib/lib64/python3.13/site-packages/telegram/_callbackquery.py\", line 189, in answer\n    return await self.get_bot().answer_callback_query(\n           ^^^^^^^^^^^^^^^^^^^^^^^^^^^^^^^^^^^^^^^^^^^\n    ...<10 lines>...\n    )\n    ^\n  File \"/home/technedict/Desktop/ViralPackage/viralcorelib/lib64/python3.13/site-packages/telegram/ext/_extbot.py\", line 935, in answer_callback_query\n    return await super().answer_callback_query(\n           ^^^^^^^^^^^^^^^^^^^^^^^^^^^^^^^^^^^^\n    ...<10 lines>...\n    )\n    ^\n  File \"/home/technedict/Desktop/ViralPackage/viralcorelib/lib64/python3.13/site-packages/telegram/_bot.py\", line 3944, in answer_callback_query\n    return await self._post(\n           ^^^^^^^^^^^^^^^^^\n    ...<7 lines>...\n    )\n    ^\n  File \"/home/technedict/Desktop/ViralPackage/viralcorelib/lib64/python3.13/site-packages/telegram/_bot.py\", line 623, in _post\n    return await self._do_post(\n           ^^^^^^^^^^^^^^^^^^^^\n    ...<6 lines>...\n    )\n    ^\n  File \"/home/technedict/Desktop/ViralPackage/viralcorelib/lib64/python3.13/site-packages/telegram/ext/_extbot.py\", line 355, in _do_post\n    return await super()._do_post(\n           ^^^^^^^^^^^^^^^^^^^^^^^\n    ...<6 lines>...\n    )\n    ^\n  File \"/home/technedict/Desktop/ViralPackage/viralcorelib/lib64/python3.13/site-packages/telegram/_bot.py\", line 652, in _do_post\n    result = await request.post(\n             ^^^^^^^^^^^^^^^^^^^\n    ...<6 lines>...\n    )\n    ^\n  File \"/home/technedict/Desktop/ViralPackage/viralcorelib/lib64/python3.13/site-packages/telegram/request/_baserequest.py\", line 201, in post\n    result = await self._request_wrapper(\n             ^^^^^^^^^^^^^^^^^^^^^^^^^^^^\n    ...<7 lines>...\n    )\n    ^\n  File \"/home/technedict/Desktop/ViralPackage/viralcorelib/lib64/python3.13/site-packages/telegram/request/_baserequest.py\", line 382, in _request_wrapper\n    raise BadRequest(message)\ntelegram.error.BadRequest: Query is too old and response timeout expired or query id is invalid"}
{"timestamp": "2025-09-29T09:18:59.230507Z", "level": "WARNING", "module": "viralmonitor.utils.db", "message": "Invalid usid found: ''. Deleting from user_posts.", "correlation_id": "none"}
{"timestamp": "2025-09-29T09:18:59.599090Z", "level": "ERROR", "module": "viralmonitor.utils.db", "message": "Skipping invalid usid: ''", "correlation_id": "none"}
{"timestamp": "2025-09-29T09:19:22.305042Z", "level": "WARNING", "module": "utils.graceful_shutdown", "message": "updater.shutdown() raised: This Updater is still running!", "correlation_id": "none"}
{"timestamp": "2025-09-29T09:19:22.305943Z", "level": "WARNING", "module": "utils.graceful_shutdown", "message": "Shutdown already in progress", "correlation_id": "none"}
{"timestamp": "2025-09-29T09:19:22.322495Z", "level": "ERROR", "module": "__main__", "message": "Error during app.shutdown()", "correlation_id": "none", "exception": "Traceback (most recent call last):\n  File \"/home/technedict/Desktop/ViralPackage/viralcore/main_viral_core_bot.py\", line 301, in main\n    await app.shutdown()\n  File \"/home/technedict/Desktop/ViralPackage/viralcorelib/lib64/python3.13/site-packages/telegram/ext/_application.py\", line 561, in shutdown\n    await self.updater.shutdown()\n  File \"/home/technedict/Desktop/ViralPackage/viralcorelib/lib64/python3.13/site-packages/telegram/ext/_updater.py\", line 204, in shutdown\n    raise RuntimeError(\"This Updater is still running!\")\nRuntimeError: This Updater is still running!"}
{"timestamp": "2025-09-29T09:19:22.406691Z", "level": "ERROR", "module": "asyncio", "message": "Task exception was never retrieved\nfuture: <Task finished name='Task-14' coro=<Updater._start_polling.<locals>.polling_action_cb() done, defined at /home/technedict/Desktop/ViralPackage/viralcorelib/lib64/python3.13/site-packages/telegram/ext/_updater.py:375> exception=NetworkError('httpx.ReadError: ')>", "correlation_id": "none", "exception": "Traceback (most recent call last):\n  File \"/home/technedict/Desktop/ViralPackage/viralcorelib/lib64/python3.13/site-packages/httpx/_transports/default.py\", line 101, in map_httpcore_exceptions\n  File \"/home/technedict/Desktop/ViralPackage/viralcorelib/lib64/python3.13/site-packages/httpx/_transports/default.py\", line 394, in handle_async_request\n  File \"/home/technedict/Desktop/ViralPackage/viralcorelib/lib64/python3.13/site-packages/httpcore/_async/connection_pool.py\", line 256, in handle_async_request\n  File \"/home/technedict/Desktop/ViralPackage/viralcorelib/lib64/python3.13/site-packages/httpcore/_async/connection_pool.py\", line 236, in handle_async_request\n  File \"/home/technedict/Desktop/ViralPackage/viralcorelib/lib64/python3.13/site-packages/httpcore/_async/connection.py\", line 103, in handle_async_request\n  File \"/home/technedict/Desktop/ViralPackage/viralcorelib/lib64/python3.13/site-packages/httpcore/_async/http11.py\", line 136, in handle_async_request\n  File \"/home/technedict/Desktop/ViralPackage/viralcorelib/lib64/python3.13/site-packages/httpcore/_async/http11.py\", line 106, in handle_async_request\n  File \"/home/technedict/Desktop/ViralPackage/viralcorelib/lib64/python3.13/site-packages/httpcore/_async/http11.py\", line 177, in _receive_response_headers\n  File \"/home/technedict/Desktop/ViralPackage/viralcorelib/lib64/python3.13/site-packages/httpcore/_async/http11.py\", line 217, in _receive_event\n  File \"/home/technedict/Desktop/ViralPackage/viralcorelib/lib64/python3.13/site-packages/httpcore/_backends/anyio.py\", line 32, in read\n  File \"/usr/lib64/python3.13/contextlib.py\", line 162, in __exit__\n  File \"/home/technedict/Desktop/ViralPackage/viralcorelib/lib64/python3.13/site-packages/httpcore/_exceptions.py\", line 14, in map_exceptions\nhttpcore.ReadError\n\nThe above exception was the direct cause of the following exception:\n\nTraceback (most recent call last):\n  File \"/home/technedict/Desktop/ViralPackage/viralcorelib/lib64/python3.13/site-packages/telegram/request/_httpxrequest.py\", line 276, in do_request\n  File \"/home/technedict/Desktop/ViralPackage/viralcorelib/lib64/python3.13/site-packages/httpx/_client.py\", line 1540, in request\n  File \"/home/technedict/Desktop/ViralPackage/viralcorelib/lib64/python3.13/site-packages/httpx/_client.py\", line 1629, in send\n  File \"/home/technedict/Desktop/ViralPackage/viralcorelib/lib64/python3.13/site-packages/httpx/_client.py\", line 1657, in _send_handling_auth\n  File \"/home/technedict/Desktop/ViralPackage/viralcorelib/lib64/python3.13/site-packages/httpx/_client.py\", line 1694, in _send_handling_redirects\n  File \"/home/technedict/Desktop/ViralPackage/viralcorelib/lib64/python3.13/site-packages/httpx/_client.py\", line 1730, in _send_single_request\n  File \"/home/technedict/Desktop/ViralPackage/viralcorelib/lib64/python3.13/site-packages/httpx/_transports/default.py\", line 393, in handle_async_request\n  File \"/usr/lib64/python3.13/contextlib.py\", line 162, in __exit__\n  File \"/home/technedict/Desktop/ViralPackage/viralcorelib/lib64/python3.13/site-packages/httpx/_transports/default.py\", line 118, in map_httpcore_exceptions\nhttpx.ReadError\n\nThe above exception was the direct cause of the following exception:\n\nTraceback (most recent call last):\n  File \"/home/technedict/Desktop/ViralPackage/viralcorelib/lib64/python3.13/site-packages/telegram/ext/_updater.py\", line 377, in polling_action_cb\n    updates = await self.bot.get_updates(\n              ^^^^^^^^^^^^^^^^^^^^^^^^^^^\n    ...<7 lines>...\n    )\n    ^\n  File \"/home/technedict/Desktop/ViralPackage/viralcorelib/lib64/python3.13/site-packages/telegram/ext/_extbot.py\", line 649, in get_updates\n    updates = await super().get_updates(\n              ^^^^^^^^^^^^^^^^^^^^^^^^^^\n    ...<9 lines>...\n    )\n    ^\n  File \"/home/technedict/Desktop/ViralPackage/viralcorelib/lib64/python3.13/site-packages/telegram/_bot.py\", line 4366, in get_updates\n    await self._post(\n    ^^^^^^^^^^^^^^^^^\n    ...<7 lines>...\n    ),\n    ^\n  File \"/home/technedict/Desktop/ViralPackage/viralcorelib/lib64/python3.13/site-packages/telegram/_bot.py\", line 623, in _post\n    return await self._do_post(\n           ^^^^^^^^^^^^^^^^^^^^\n    ...<6 lines>...\n    )\n    ^\n  File \"/home/technedict/Desktop/ViralPackage/viralcorelib/lib64/python3.13/site-packages/telegram/ext/_extbot.py\", line 355, in _do_post\n    return await super()._do_post(\n           ^^^^^^^^^^^^^^^^^^^^^^^\n    ...<6 lines>...\n    )\n    ^\n  File \"/home/technedict/Desktop/ViralPackage/viralcorelib/lib64/python3.13/site-packages/telegram/_bot.py\", line 652, in _do_post\n    result = await request.post(\n             ^^^^^^^^^^^^^^^^^^^\n    ...<6 lines>...\n    )\n    ^\n  File \"/home/technedict/Desktop/ViralPackage/viralcorelib/lib64/python3.13/site-packages/telegram/request/_baserequest.py\", line 201, in post\n    result = await self._request_wrapper(\n             ^^^^^^^^^^^^^^^^^^^^^^^^^^^^\n    ...<7 lines>...\n    )\n    ^\n  File \"/home/technedict/Desktop/ViralPackage/viralcorelib/lib64/python3.13/site-packages/telegram/request/_baserequest.py\", line 333, in _request_wrapper\n    code, payload = await self.do_request(\n                    ^^^^^^^^^^^^^^^^^^^^^^\n    ...<7 lines>...\n    )\n    ^\n  File \"/home/technedict/Desktop/ViralPackage/viralcorelib/lib64/python3.13/site-packages/telegram/request/_httpxrequest.py\", line 300, in do_request\ntelegram.error.NetworkError: httpx.ReadError: "}
