{"timestamp": "2025-09-28T18:24:27.283667Z", "level": "WARNING", "module": "utils.graceful_shutdown", "message": "updater.shutdown() raised: This Updater is still running!", "correlation_id": "none"}
{"timestamp": "2025-09-28T18:24:27.304491Z", "level": "WARNING", "module": "utils.graceful_shutdown", "message": "Shutdown already in progress", "correlation_id": "none"}
{"timestamp": "2025-09-28T18:24:27.382426Z", "level": "ERROR", "module": "__main__", "message": "Error during app.shutdown()", "correlation_id": "none", "exception": "Traceback (most recent call last):\n  File \"/home/technedict/Desktop/ViralPackage/viralcore/main_viral_core_bot.py\", line 301, in main\n    await app.shutdown()\n  File \"/home/technedict/Desktop/ViralPackage/viralcorelib/lib64/python3.13/site-packages/telegram/ext/_application.py\", line 561, in shutdown\n    await self.updater.shutdown()\n  File \"/home/technedict/Desktop/ViralPackage/viralcorelib/lib64/python3.13/site-packages/telegram/ext/_updater.py\", line 204, in shutdown\n    raise RuntimeError(\"This Updater is still running!\")\nRuntimeError: This Updater is still running!"}
{"timestamp": "2025-09-28T18:24:28.241802Z", "level": "ERROR", "module": "asyncio", "message": "Task exception was never retrieved\nfuture: <Task finished name='Task-4' coro=<Updater._start_polling.<locals>.polling_action_cb() done, defined at /home/technedict/Desktop/ViralPackage/viralcorelib/lib64/python3.13/site-packages/telegram/ext/_updater.py:375> exception=NetworkError('httpx.ReadError: ')>", "correlation_id": "none", "exception": "Traceback (most recent call last):\n  File \"/home/technedict/Desktop/ViralPackage/viralcorelib/lib64/python3.13/site-packages/httpx/_transports/default.py\", line 101, in map_httpcore_exceptions\n  File \"/home/technedict/Desktop/ViralPackage/viralcorelib/lib64/python3.13/site-packages/httpx/_transports/default.py\", line 394, in handle_async_request\n  File \"/home/technedict/Desktop/ViralPackage/viralcorelib/lib64/python3.13/site-packages/httpcore/_async/connection_pool.py\", line 256, in handle_async_request\n  File \"/home/technedict/Desktop/ViralPackage/viralcorelib/lib64/python3.13/site-packages/httpcore/_async/connection_pool.py\", line 236, in handle_async_request\n  File \"/home/technedict/Desktop/ViralPackage/viralcorelib/lib64/python3.13/site-packages/httpcore/_async/connection.py\", line 103, in handle_async_request\n  File \"/home/technedict/Desktop/ViralPackage/viralcorelib/lib64/python3.13/site-packages/httpcore/_async/http11.py\", line 136, in handle_async_request\n  File \"/home/technedict/Desktop/ViralPackage/viralcorelib/lib64/python3.13/site-packages/httpcore/_async/http11.py\", line 106, in handle_async_request\n  File \"/home/technedict/Desktop/ViralPackage/viralcorelib/lib64/python3.13/site-packages/httpcore/_async/http11.py\", line 177, in _receive_response_headers\n  File \"/home/technedict/Desktop/ViralPackage/viralcorelib/lib64/python3.13/site-packages/httpcore/_async/http11.py\", line 217, in _receive_event\n  File \"/home/technedict/Desktop/ViralPackage/viralcorelib/lib64/python3.13/site-packages/httpcore/_backends/anyio.py\", line 32, in read\n  File \"/usr/lib64/python3.13/contextlib.py\", line 162, in __exit__\n  File \"/home/technedict/Desktop/ViralPackage/viralcorelib/lib64/python3.13/site-packages/httpcore/_exceptions.py\", line 14, in map_exceptions\nhttpcore.ReadError\n\nThe above exception was the direct cause of the following exception:\n\nTraceback (most recent call last):\n  File \"/home/technedict/Desktop/ViralPackage/viralcorelib/lib64/python3.13/site-packages/telegram/request/_httpxrequest.py\", line 276, in do_request\n  File \"/home/technedict/Desktop/ViralPackage/viralcorelib/lib64/python3.13/site-packages/httpx/_client.py\", line 1540, in request\n  File \"/home/technedict/Desktop/ViralPackage/viralcorelib/lib64/python3.13/site-packages/httpx/_client.py\", line 1629, in send\n  File \"/home/technedict/Desktop/ViralPackage/viralcorelib/lib64/python3.13/site-packages/httpx/_client.py\", line 1657, in _send_handling_auth\n  File \"/home/technedict/Desktop/ViralPackage/viralcorelib/lib64/python3.13/site-packages/httpx/_client.py\", line 1694, in _send_handling_redirects\n  File \"/home/technedict/Desktop/ViralPackage/viralcorelib/lib64/python3.13/site-packages/httpx/_client.py\", line 1730, in _send_single_request\n  File \"/home/technedict/Desktop/ViralPackage/viralcorelib/lib64/python3.13/site-packages/httpx/_transports/default.py\", line 393, in handle_async_request\n  File \"/usr/lib64/python3.13/contextlib.py\", line 162, in __exit__\n  File \"/home/technedict/Desktop/ViralPackage/viralcorelib/lib64/python3.13/site-packages/httpx/_transports/default.py\", line 118, in map_httpcore_exceptions\nhttpx.ReadError\n\nThe above exception was the direct cause of the following exception:\n\nTraceback (most recent call last):\n  File \"/home/technedict/Desktop/ViralPackage/viralcorelib/lib64/python3.13/site-packages/telegram/ext/_updater.py\", line 377, in polling_action_cb\n    updates = await self.bot.get_updates(\n              ^^^^^^^^^^^^^^^^^^^^^^^^^^^\n    ...<7 lines>...\n    )\n    ^\n  File \"/home/technedict/Desktop/ViralPackage/viralcorelib/lib64/python3.13/site-packages/telegram/ext/_extbot.py\", line 649, in get_updates\n  File \"/home/technedict/Desktop/ViralPackage/viralcorelib/lib64/python3.13/site-packages/telegram/_bot.py\", line 4366, in get_updates\n  File \"/home/technedict/Desktop/ViralPackage/viralcorelib/lib64/python3.13/site-packages/telegram/_bot.py\", line 623, in _post\n  File \"/home/technedict/Desktop/ViralPackage/viralcorelib/lib64/python3.13/site-packages/telegram/ext/_extbot.py\", line 355, in _do_post\n  File \"/home/technedict/Desktop/ViralPackage/viralcorelib/lib64/python3.13/site-packages/telegram/_bot.py\", line 652, in _do_post\n  File \"/home/technedict/Desktop/ViralPackage/viralcorelib/lib64/python3.13/site-packages/telegram/request/_baserequest.py\", line 201, in post\n  File \"/home/technedict/Desktop/ViralPackage/viralcorelib/lib64/python3.13/site-packages/telegram/request/_baserequest.py\", line 333, in _request_wrapper\n  File \"/home/technedict/Desktop/ViralPackage/viralcorelib/lib64/python3.13/site-packages/telegram/request/_httpxrequest.py\", line 300, in do_request\ntelegram.error.NetworkError: httpx.ReadError: "}
{"timestamp": "2025-09-29T08:18:28.718947Z", "level": "ERROR", "module": "telegram.ext.Application", "message": "No error handlers are registered, logging exception.", "correlation_id": "none", "exception": "Traceback (most recent call last):\n  File \"/home/technedict/Desktop/ViralPackage/viralcorelib/lib64/python3.13/site-packages/telegram/ext/_application.py\", line 1335, in process_update\n    await coroutine\n  File \"/home/technedict/Desktop/ViralPackage/viralcorelib/lib64/python3.13/site-packages/telegram/ext/_handlers/basehandler.py\", line 157, in handle_update\n    return await self.callback(update, context)\n           ^^^^^^^^^^^^^^^^^^^^^^^^^^^^^^^^^^^^\n  File \"/home/technedict/Desktop/ViralPackage/viralcore/handlers/message_handler.py\", line 57, in message_router\n    await custom_order_handler(update, context) # Or a general_message_handler\n    ^^^^^^^^^^^^^^^^^^^^^^^^^^^^^^^^^^^^^^^^^^^\n  File \"/home/technedict/Desktop/ViralPackage/viralcore/handlers/custom_order_handlers.py\", line 31, in custom_order_handler\n    text = update.message.text.strip()\n           ^^^^^^^^^^^^^^^^^^^\nAttributeError: 'NoneType' object has no attribute 'text'"}
{"timestamp": "2025-09-29T08:18:28.725068Z", "level": "ERROR", "module": "telegram.ext.Application", "message": "No error handlers are registered, logging exception.", "correlation_id": "none", "exception": "Traceback (most recent call last):\n  File \"/home/technedict/Desktop/ViralPackage/viralcorelib/lib64/python3.13/site-packages/telegram/ext/_application.py\", line 1335, in process_update\n    await coroutine\n  File \"/home/technedict/Desktop/ViralPackage/viralcorelib/lib64/python3.13/site-packages/telegram/ext/_handlers/basehandler.py\", line 157, in handle_update\n    return await self.callback(update, context)\n           ^^^^^^^^^^^^^^^^^^^^^^^^^^^^^^^^^^^^\n  File \"/home/technedict/Desktop/ViralPackage/viralcore/handlers/message_handler.py\", line 57, in message_router\n    await custom_order_handler(update, context) # Or a general_message_handler\n    ^^^^^^^^^^^^^^^^^^^^^^^^^^^^^^^^^^^^^^^^^^^\n  File \"/home/technedict/Desktop/ViralPackage/viralcore/handlers/custom_order_handlers.py\", line 31, in custom_order_handler\n    text = update.message.text.strip()\n           ^^^^^^^^^^^^^^^^^^^\nAttributeError: 'NoneType' object has no attribute 'text'"}
{"timestamp": "2025-09-29T08:18:28.731147Z", "level": "ERROR", "module": "telegram.ext.Application", "message": "No error handlers are registered, logging exception.", "correlation_id": "none", "exception": "Traceback (most recent call last):\n  File \"/home/technedict/Desktop/ViralPackage/viralcorelib/lib64/python3.13/site-packages/telegram/ext/_application.py\", line 1335, in process_update\n    await coroutine\n  File \"/home/technedict/Desktop/ViralPackage/viralcorelib/lib64/python3.13/site-packages/telegram/ext/_handlers/basehandler.py\", line 157, in handle_update\n    return await self.callback(update, context)\n           ^^^^^^^^^^^^^^^^^^^^^^^^^^^^^^^^^^^^\n  File \"/home/technedict/Desktop/ViralPackage/viralcore/handlers/message_handler.py\", line 57, in message_router\n    await custom_order_handler(update, context) # Or a general_message_handler\n    ^^^^^^^^^^^^^^^^^^^^^^^^^^^^^^^^^^^^^^^^^^^\n  File \"/home/technedict/Desktop/ViralPackage/viralcore/handlers/custom_order_handlers.py\", line 31, in custom_order_handler\n    text = update.message.text.strip()\n           ^^^^^^^^^^^^^^^^^^^\nAttributeError: 'NoneType' object has no attribute 'text'"}
{"timestamp": "2025-09-29T08:18:28.738517Z", "level": "ERROR", "module": "telegram.ext.Application", "message": "No error handlers are registered, logging exception.", "correlation_id": "none", "exception": "Traceback (most recent call last):\n  File \"/home/technedict/Desktop/ViralPackage/viralcorelib/lib64/python3.13/site-packages/telegram/ext/_application.py\", line 1335, in process_update\n    await coroutine\n  File \"/home/technedict/Desktop/ViralPackage/viralcorelib/lib64/python3.13/site-packages/telegram/ext/_handlers/basehandler.py\", line 157, in handle_update\n    return await self.callback(update, context)\n           ^^^^^^^^^^^^^^^^^^^^^^^^^^^^^^^^^^^^\n  File \"/home/technedict/Desktop/ViralPackage/viralcore/handlers/message_handler.py\", line 57, in message_router\n    await custom_order_handler(update, context) # Or a general_message_handler\n    ^^^^^^^^^^^^^^^^^^^^^^^^^^^^^^^^^^^^^^^^^^^\n  File \"/home/technedict/Desktop/ViralPackage/viralcore/handlers/custom_order_handlers.py\", line 31, in custom_order_handler\n    text = update.message.text.strip()\n           ^^^^^^^^^^^^^^^^^^^\nAttributeError: 'NoneType' object has no attribute 'text'"}
{"timestamp": "2025-09-29T08:18:28.746503Z", "level": "ERROR", "module": "telegram.ext.Application", "message": "No error handlers are registered, logging exception.", "correlation_id": "none", "exception": "Traceback (most recent call last):\n  File \"/home/technedict/Desktop/ViralPackage/viralcorelib/lib64/python3.13/site-packages/telegram/ext/_application.py\", line 1335, in process_update\n    await coroutine\n  File \"/home/technedict/Desktop/ViralPackage/viralcorelib/lib64/python3.13/site-packages/telegram/ext/_handlers/basehandler.py\", line 157, in handle_update\n    return await self.callback(update, context)\n           ^^^^^^^^^^^^^^^^^^^^^^^^^^^^^^^^^^^^\n  File \"/home/technedict/Desktop/ViralPackage/viralcore/handlers/message_handler.py\", line 57, in message_router\n    await custom_order_handler(update, context) # Or a general_message_handler\n    ^^^^^^^^^^^^^^^^^^^^^^^^^^^^^^^^^^^^^^^^^^^\n  File \"/home/technedict/Desktop/ViralPackage/viralcore/handlers/custom_order_handlers.py\", line 31, in custom_order_handler\n    text = update.message.text.strip()\n           ^^^^^^^^^^^^^^^^^^^\nAttributeError: 'NoneType' object has no attribute 'text'"}
{"timestamp": "2025-09-29T08:18:28.756838Z", "level": "ERROR", "module": "telegram.ext.Application", "message": "No error handlers are registered, logging exception.", "correlation_id": "none", "exception": "Traceback (most recent call last):\n  File \"/home/technedict/Desktop/ViralPackage/viralcorelib/lib64/python3.13/site-packages/telegram/ext/_application.py\", line 1335, in process_update\n    await coroutine\n  File \"/home/technedict/Desktop/ViralPackage/viralcorelib/lib64/python3.13/site-packages/telegram/ext/_handlers/basehandler.py\", line 157, in handle_update\n    return await self.callback(update, context)\n           ^^^^^^^^^^^^^^^^^^^^^^^^^^^^^^^^^^^^\n  File \"/home/technedict/Desktop/ViralPackage/viralcore/handlers/message_handler.py\", line 57, in message_router\n    await custom_order_handler(update, context) # Or a general_message_handler\n    ^^^^^^^^^^^^^^^^^^^^^^^^^^^^^^^^^^^^^^^^^^^\n  File \"/home/technedict/Desktop/ViralPackage/viralcore/handlers/custom_order_handlers.py\", line 31, in custom_order_handler\n    text = update.message.text.strip()\n           ^^^^^^^^^^^^^^^^^^^\nAttributeError: 'NoneType' object has no attribute 'text'"}
{"timestamp": "2025-09-29T08:18:28.765074Z", "level": "ERROR", "module": "telegram.ext.Application", "message": "No error handlers are registered, logging exception.", "correlation_id": "none", "exception": "Traceback (most recent call last):\n  File \"/home/technedict/Desktop/ViralPackage/viralcorelib/lib64/python3.13/site-packages/telegram/ext/_application.py\", line 1335, in process_update\n    await coroutine\n  File \"/home/technedict/Desktop/ViralPackage/viralcorelib/lib64/python3.13/site-packages/telegram/ext/_handlers/basehandler.py\", line 157, in handle_update\n    return await self.callback(update, context)\n           ^^^^^^^^^^^^^^^^^^^^^^^^^^^^^^^^^^^^\n  File \"/home/technedict/Desktop/ViralPackage/viralcore/handlers/message_handler.py\", line 57, in message_router\n    await custom_order_handler(update, context) # Or a general_message_handler\n    ^^^^^^^^^^^^^^^^^^^^^^^^^^^^^^^^^^^^^^^^^^^\n  File \"/home/technedict/Desktop/ViralPackage/viralcore/handlers/custom_order_handlers.py\", line 31, in custom_order_handler\n    text = update.message.text.strip()\n           ^^^^^^^^^^^^^^^^^^^\nAttributeError: 'NoneType' object has no attribute 'text'"}
{"timestamp": "2025-09-29T08:18:28.771111Z", "level": "ERROR", "module": "telegram.ext.Application", "message": "No error handlers are registered, logging exception.", "correlation_id": "none", "exception": "Traceback (most recent call last):\n  File \"/home/technedict/Desktop/ViralPackage/viralcorelib/lib64/python3.13/site-packages/telegram/ext/_application.py\", line 1335, in process_update\n    await coroutine\n  File \"/home/technedict/Desktop/ViralPackage/viralcorelib/lib64/python3.13/site-packages/telegram/ext/_handlers/basehandler.py\", line 157, in handle_update\n    return await self.callback(update, context)\n           ^^^^^^^^^^^^^^^^^^^^^^^^^^^^^^^^^^^^\n  File \"/home/technedict/Desktop/ViralPackage/viralcore/handlers/message_handler.py\", line 57, in message_router\n    await custom_order_handler(update, context) # Or a general_message_handler\n    ^^^^^^^^^^^^^^^^^^^^^^^^^^^^^^^^^^^^^^^^^^^\n  File \"/home/technedict/Desktop/ViralPackage/viralcore/handlers/custom_order_handlers.py\", line 31, in custom_order_handler\n    text = update.message.text.strip()\n           ^^^^^^^^^^^^^^^^^^^\nAttributeError: 'NoneType' object has no attribute 'text'"}
{"timestamp": "2025-09-29T08:18:28.776261Z", "level": "ERROR", "module": "telegram.ext.Application", "message": "No error handlers are registered, logging exception.", "correlation_id": "none", "exception": "Traceback (most recent call last):\n  File \"/home/technedict/Desktop/ViralPackage/viralcorelib/lib64/python3.13/site-packages/telegram/ext/_application.py\", line 1335, in process_update\n    await coroutine\n  File \"/home/technedict/Desktop/ViralPackage/viralcorelib/lib64/python3.13/site-packages/telegram/ext/_handlers/basehandler.py\", line 157, in handle_update\n    return await self.callback(update, context)\n           ^^^^^^^^^^^^^^^^^^^^^^^^^^^^^^^^^^^^\n  File \"/home/technedict/Desktop/ViralPackage/viralcore/handlers/message_handler.py\", line 57, in message_router\n    await custom_order_handler(update, context) # Or a general_message_handler\n    ^^^^^^^^^^^^^^^^^^^^^^^^^^^^^^^^^^^^^^^^^^^\n  File \"/home/technedict/Desktop/ViralPackage/viralcore/handlers/custom_order_handlers.py\", line 31, in custom_order_handler\n    text = update.message.text.strip()\n           ^^^^^^^^^^^^^^^^^^^\nAttributeError: 'NoneType' object has no attribute 'text'"}
{"timestamp": "2025-09-29T08:18:28.781464Z", "level": "ERROR", "module": "telegram.ext.Application", "message": "No error handlers are registered, logging exception.", "correlation_id": "none", "exception": "Traceback (most recent call last):\n  File \"/home/technedict/Desktop/ViralPackage/viralcorelib/lib64/python3.13/site-packages/telegram/ext/_application.py\", line 1335, in process_update\n    await coroutine\n  File \"/home/technedict/Desktop/ViralPackage/viralcorelib/lib64/python3.13/site-packages/telegram/ext/_handlers/basehandler.py\", line 157, in handle_update\n    return await self.callback(update, context)\n           ^^^^^^^^^^^^^^^^^^^^^^^^^^^^^^^^^^^^\n  File \"/home/technedict/Desktop/ViralPackage/viralcore/handlers/message_handler.py\", line 57, in message_router\n    await custom_order_handler(update, context) # Or a general_message_handler\n    ^^^^^^^^^^^^^^^^^^^^^^^^^^^^^^^^^^^^^^^^^^^\n  File \"/home/technedict/Desktop/ViralPackage/viralcore/handlers/custom_order_handlers.py\", line 31, in custom_order_handler\n    text = update.message.text.strip()\n           ^^^^^^^^^^^^^^^^^^^\nAttributeError: 'NoneType' object has no attribute 'text'"}
{"timestamp": "2025-09-29T08:18:28.787611Z", "level": "ERROR", "module": "telegram.ext.Application", "message": "No error handlers are registered, logging exception.", "correlation_id": "none", "exception": "Traceback (most recent call last):\n  File \"/home/technedict/Desktop/ViralPackage/viralcorelib/lib64/python3.13/site-packages/telegram/ext/_application.py\", line 1335, in process_update\n    await coroutine\n  File \"/home/technedict/Desktop/ViralPackage/viralcorelib/lib64/python3.13/site-packages/telegram/ext/_handlers/basehandler.py\", line 157, in handle_update\n    return await self.callback(update, context)\n           ^^^^^^^^^^^^^^^^^^^^^^^^^^^^^^^^^^^^\n  File \"/home/technedict/Desktop/ViralPackage/viralcore/handlers/message_handler.py\", line 57, in message_router\n    await custom_order_handler(update, context) # Or a general_message_handler\n    ^^^^^^^^^^^^^^^^^^^^^^^^^^^^^^^^^^^^^^^^^^^\n  File \"/home/technedict/Desktop/ViralPackage/viralcore/handlers/custom_order_handlers.py\", line 31, in custom_order_handler\n    text = update.message.text.strip()\n           ^^^^^^^^^^^^^^^^^^^\nAttributeError: 'NoneType' object has no attribute 'text'"}
{"timestamp": "2025-09-29T08:18:28.793824Z", "level": "ERROR", "module": "telegram.ext.Application", "message": "No error handlers are registered, logging exception.", "correlation_id": "none", "exception": "Traceback (most recent call last):\n  File \"/home/technedict/Desktop/ViralPackage/viralcorelib/lib64/python3.13/site-packages/telegram/ext/_application.py\", line 1335, in process_update\n    await coroutine\n  File \"/home/technedict/Desktop/ViralPackage/viralcorelib/lib64/python3.13/site-packages/telegram/ext/_handlers/basehandler.py\", line 157, in handle_update\n    return await self.callback(update, context)\n           ^^^^^^^^^^^^^^^^^^^^^^^^^^^^^^^^^^^^\n  File \"/home/technedict/Desktop/ViralPackage/viralcore/handlers/message_handler.py\", line 57, in message_router\n    await custom_order_handler(update, context) # Or a general_message_handler\n    ^^^^^^^^^^^^^^^^^^^^^^^^^^^^^^^^^^^^^^^^^^^\n  File \"/home/technedict/Desktop/ViralPackage/viralcore/handlers/custom_order_handlers.py\", line 31, in custom_order_handler\n    text = update.message.text.strip()\n           ^^^^^^^^^^^^^^^^^^^\nAttributeError: 'NoneType' object has no attribute 'text'"}
{"timestamp": "2025-09-29T08:18:28.799510Z", "level": "ERROR", "module": "telegram.ext.Application", "message": "No error handlers are registered, logging exception.", "correlation_id": "none", "exception": "Traceback (most recent call last):\n  File \"/home/technedict/Desktop/ViralPackage/viralcorelib/lib64/python3.13/site-packages/telegram/ext/_application.py\", line 1335, in process_update\n    await coroutine\n  File \"/home/technedict/Desktop/ViralPackage/viralcorelib/lib64/python3.13/site-packages/telegram/ext/_handlers/basehandler.py\", line 157, in handle_update\n    return await self.callback(update, context)\n           ^^^^^^^^^^^^^^^^^^^^^^^^^^^^^^^^^^^^\n  File \"/home/technedict/Desktop/ViralPackage/viralcore/handlers/message_handler.py\", line 57, in message_router\n    await custom_order_handler(update, context) # Or a general_message_handler\n    ^^^^^^^^^^^^^^^^^^^^^^^^^^^^^^^^^^^^^^^^^^^\n  File \"/home/technedict/Desktop/ViralPackage/viralcore/handlers/custom_order_handlers.py\", line 31, in custom_order_handler\n    text = update.message.text.strip()\n           ^^^^^^^^^^^^^^^^^^^\nAttributeError: 'NoneType' object has no attribute 'text'"}
{"timestamp": "2025-09-29T08:18:28.806332Z", "level": "ERROR", "module": "telegram.ext.Application", "message": "No error handlers are registered, logging exception.", "correlation_id": "none", "exception": "Traceback (most recent call last):\n  File \"/home/technedict/Desktop/ViralPackage/viralcorelib/lib64/python3.13/site-packages/telegram/ext/_application.py\", line 1335, in process_update\n    await coroutine\n  File \"/home/technedict/Desktop/ViralPackage/viralcorelib/lib64/python3.13/site-packages/telegram/ext/_handlers/basehandler.py\", line 157, in handle_update\n    return await self.callback(update, context)\n           ^^^^^^^^^^^^^^^^^^^^^^^^^^^^^^^^^^^^\n  File \"/home/technedict/Desktop/ViralPackage/viralcore/handlers/message_handler.py\", line 57, in message_router\n    await custom_order_handler(update, context) # Or a general_message_handler\n    ^^^^^^^^^^^^^^^^^^^^^^^^^^^^^^^^^^^^^^^^^^^\n  File \"/home/technedict/Desktop/ViralPackage/viralcore/handlers/custom_order_handlers.py\", line 31, in custom_order_handler\n    text = update.message.text.strip()\n           ^^^^^^^^^^^^^^^^^^^\nAttributeError: 'NoneType' object has no attribute 'text'"}
{"timestamp": "2025-09-29T08:18:28.814975Z", "level": "ERROR", "module": "telegram.ext.Application", "message": "No error handlers are registered, logging exception.", "correlation_id": "none", "exception": "Traceback (most recent call last):\n  File \"/home/technedict/Desktop/ViralPackage/viralcorelib/lib64/python3.13/site-packages/telegram/ext/_application.py\", line 1335, in process_update\n    await coroutine\n  File \"/home/technedict/Desktop/ViralPackage/viralcorelib/lib64/python3.13/site-packages/telegram/ext/_handlers/basehandler.py\", line 157, in handle_update\n    return await self.callback(update, context)\n           ^^^^^^^^^^^^^^^^^^^^^^^^^^^^^^^^^^^^\n  File \"/home/technedict/Desktop/ViralPackage/viralcore/handlers/message_handler.py\", line 57, in message_router\n    await custom_order_handler(update, context) # Or a general_message_handler\n    ^^^^^^^^^^^^^^^^^^^^^^^^^^^^^^^^^^^^^^^^^^^\n  File \"/home/technedict/Desktop/ViralPackage/viralcore/handlers/custom_order_handlers.py\", line 31, in custom_order_handler\n    text = update.message.text.strip()\n           ^^^^^^^^^^^^^^^^^^^\nAttributeError: 'NoneType' object has no attribute 'text'"}
{"timestamp": "2025-09-29T08:18:28.826391Z", "level": "ERROR", "module": "telegram.ext.Application", "message": "No error handlers are registered, logging exception.", "correlation_id": "none", "exception": "Traceback (most recent call last):\n  File \"/home/technedict/Desktop/ViralPackage/viralcorelib/lib64/python3.13/site-packages/telegram/ext/_application.py\", line 1335, in process_update\n    await coroutine\n  File \"/home/technedict/Desktop/ViralPackage/viralcorelib/lib64/python3.13/site-packages/telegram/ext/_handlers/basehandler.py\", line 157, in handle_update\n    return await self.callback(update, context)\n           ^^^^^^^^^^^^^^^^^^^^^^^^^^^^^^^^^^^^\n  File \"/home/technedict/Desktop/ViralPackage/viralcore/handlers/message_handler.py\", line 57, in message_router\n    await custom_order_handler(update, context) # Or a general_message_handler\n    ^^^^^^^^^^^^^^^^^^^^^^^^^^^^^^^^^^^^^^^^^^^\n  File \"/home/technedict/Desktop/ViralPackage/viralcore/handlers/custom_order_handlers.py\", line 31, in custom_order_handler\n    text = update.message.text.strip()\n           ^^^^^^^^^^^^^^^^^^^\nAttributeError: 'NoneType' object has no attribute 'text'"}
{"timestamp": "2025-09-29T08:18:28.835524Z", "level": "ERROR", "module": "telegram.ext.Application", "message": "No error handlers are registered, logging exception.", "correlation_id": "none", "exception": "Traceback (most recent call last):\n  File \"/home/technedict/Desktop/ViralPackage/viralcorelib/lib64/python3.13/site-packages/telegram/ext/_application.py\", line 1335, in process_update\n    await coroutine\n  File \"/home/technedict/Desktop/ViralPackage/viralcorelib/lib64/python3.13/site-packages/telegram/ext/_handlers/basehandler.py\", line 157, in handle_update\n    return await self.callback(update, context)\n           ^^^^^^^^^^^^^^^^^^^^^^^^^^^^^^^^^^^^\n  File \"/home/technedict/Desktop/ViralPackage/viralcore/handlers/message_handler.py\", line 57, in message_router\n    await custom_order_handler(update, context) # Or a general_message_handler\n    ^^^^^^^^^^^^^^^^^^^^^^^^^^^^^^^^^^^^^^^^^^^\n  File \"/home/technedict/Desktop/ViralPackage/viralcore/handlers/custom_order_handlers.py\", line 31, in custom_order_handler\n    text = update.message.text.strip()\n           ^^^^^^^^^^^^^^^^^^^\nAttributeError: 'NoneType' object has no attribute 'text'"}
{"timestamp": "2025-09-29T08:18:28.843710Z", "level": "ERROR", "module": "telegram.ext.Application", "message": "No error handlers are registered, logging exception.", "correlation_id": "none", "exception": "Traceback (most recent call last):\n  File \"/home/technedict/Desktop/ViralPackage/viralcorelib/lib64/python3.13/site-packages/telegram/ext/_application.py\", line 1335, in process_update\n    await coroutine\n  File \"/home/technedict/Desktop/ViralPackage/viralcorelib/lib64/python3.13/site-packages/telegram/ext/_handlers/basehandler.py\", line 157, in handle_update\n    return await self.callback(update, context)\n           ^^^^^^^^^^^^^^^^^^^^^^^^^^^^^^^^^^^^\n  File \"/home/technedict/Desktop/ViralPackage/viralcore/handlers/message_handler.py\", line 57, in message_router\n    await custom_order_handler(update, context) # Or a general_message_handler\n    ^^^^^^^^^^^^^^^^^^^^^^^^^^^^^^^^^^^^^^^^^^^\n  File \"/home/technedict/Desktop/ViralPackage/viralcore/handlers/custom_order_handlers.py\", line 31, in custom_order_handler\n    text = update.message.text.strip()\n           ^^^^^^^^^^^^^^^^^^^\nAttributeError: 'NoneType' object has no attribute 'text'"}
{"timestamp": "2025-09-29T08:18:28.852345Z", "level": "ERROR", "module": "telegram.ext.Application", "message": "No error handlers are registered, logging exception.", "correlation_id": "none", "exception": "Traceback (most recent call last):\n  File \"/home/technedict/Desktop/ViralPackage/viralcorelib/lib64/python3.13/site-packages/telegram/ext/_application.py\", line 1335, in process_update\n    await coroutine\n  File \"/home/technedict/Desktop/ViralPackage/viralcorelib/lib64/python3.13/site-packages/telegram/ext/_handlers/basehandler.py\", line 157, in handle_update\n    return await self.callback(update, context)\n           ^^^^^^^^^^^^^^^^^^^^^^^^^^^^^^^^^^^^\n  File \"/home/technedict/Desktop/ViralPackage/viralcore/handlers/message_handler.py\", line 57, in message_router\n    await custom_order_handler(update, context) # Or a general_message_handler\n    ^^^^^^^^^^^^^^^^^^^^^^^^^^^^^^^^^^^^^^^^^^^\n  File \"/home/technedict/Desktop/ViralPackage/viralcore/handlers/custom_order_handlers.py\", line 31, in custom_order_handler\n    text = update.message.text.strip()\n           ^^^^^^^^^^^^^^^^^^^\nAttributeError: 'NoneType' object has no attribute 'text'"}
{"timestamp": "2025-09-29T08:18:28.868452Z", "level": "ERROR", "module": "telegram.ext.Application", "message": "No error handlers are registered, logging exception.", "correlation_id": "none", "exception": "Traceback (most recent call last):\n  File \"/home/technedict/Desktop/ViralPackage/viralcorelib/lib64/python3.13/site-packages/telegram/ext/_application.py\", line 1335, in process_update\n    await coroutine\n  File \"/home/technedict/Desktop/ViralPackage/viralcorelib/lib64/python3.13/site-packages/telegram/ext/_handlers/basehandler.py\", line 157, in handle_update\n    return await self.callback(update, context)\n           ^^^^^^^^^^^^^^^^^^^^^^^^^^^^^^^^^^^^\n  File \"/home/technedict/Desktop/ViralPackage/viralcore/handlers/message_handler.py\", line 57, in message_router\n    await custom_order_handler(update, context) # Or a general_message_handler\n    ^^^^^^^^^^^^^^^^^^^^^^^^^^^^^^^^^^^^^^^^^^^\n  File \"/home/technedict/Desktop/ViralPackage/viralcore/handlers/custom_order_handlers.py\", line 31, in custom_order_handler\n    text = update.message.text.strip()\n           ^^^^^^^^^^^^^^^^^^^\nAttributeError: 'NoneType' object has no attribute 'text'"}
{"timestamp": "2025-09-29T08:18:28.886824Z", "level": "ERROR", "module": "telegram.ext.Application", "message": "No error handlers are registered, logging exception.", "correlation_id": "none", "exception": "Traceback (most recent call last):\n  File \"/home/technedict/Desktop/ViralPackage/viralcorelib/lib64/python3.13/site-packages/telegram/ext/_application.py\", line 1335, in process_update\n    await coroutine\n  File \"/home/technedict/Desktop/ViralPackage/viralcorelib/lib64/python3.13/site-packages/telegram/ext/_handlers/basehandler.py\", line 157, in handle_update\n    return await self.callback(update, context)\n           ^^^^^^^^^^^^^^^^^^^^^^^^^^^^^^^^^^^^\n  File \"/home/technedict/Desktop/ViralPackage/viralcore/handlers/message_handler.py\", line 57, in message_router\n    await custom_order_handler(update, context) # Or a general_message_handler\n    ^^^^^^^^^^^^^^^^^^^^^^^^^^^^^^^^^^^^^^^^^^^\n  File \"/home/technedict/Desktop/ViralPackage/viralcore/handlers/custom_order_handlers.py\", line 31, in custom_order_handler\n    text = update.message.text.strip()\n           ^^^^^^^^^^^^^^^^^^^\nAttributeError: 'NoneType' object has no attribute 'text'"}
{"timestamp": "2025-09-29T08:18:28.895694Z", "level": "ERROR", "module": "telegram.ext.Application", "message": "No error handlers are registered, logging exception.", "correlation_id": "none", "exception": "Traceback (most recent call last):\n  File \"/home/technedict/Desktop/ViralPackage/viralcorelib/lib64/python3.13/site-packages/telegram/ext/_application.py\", line 1335, in process_update\n    await coroutine\n  File \"/home/technedict/Desktop/ViralPackage/viralcorelib/lib64/python3.13/site-packages/telegram/ext/_handlers/basehandler.py\", line 157, in handle_update\n    return await self.callback(update, context)\n           ^^^^^^^^^^^^^^^^^^^^^^^^^^^^^^^^^^^^\n  File \"/home/technedict/Desktop/ViralPackage/viralcore/handlers/message_handler.py\", line 57, in message_router\n    await custom_order_handler(update, context) # Or a general_message_handler\n    ^^^^^^^^^^^^^^^^^^^^^^^^^^^^^^^^^^^^^^^^^^^\n  File \"/home/technedict/Desktop/ViralPackage/viralcore/handlers/custom_order_handlers.py\", line 31, in custom_order_handler\n    text = update.message.text.strip()\n           ^^^^^^^^^^^^^^^^^^^\nAttributeError: 'NoneType' object has no attribute 'text'"}
{"timestamp": "2025-09-29T08:18:28.911878Z", "level": "ERROR", "module": "telegram.ext.Application", "message": "No error handlers are registered, logging exception.", "correlation_id": "none", "exception": "Traceback (most recent call last):\n  File \"/home/technedict/Desktop/ViralPackage/viralcorelib/lib64/python3.13/site-packages/telegram/ext/_application.py\", line 1335, in process_update\n    await coroutine\n  File \"/home/technedict/Desktop/ViralPackage/viralcorelib/lib64/python3.13/site-packages/telegram/ext/_handlers/basehandler.py\", line 157, in handle_update\n    return await self.callback(update, context)\n           ^^^^^^^^^^^^^^^^^^^^^^^^^^^^^^^^^^^^\n  File \"/home/technedict/Desktop/ViralPackage/viralcore/handlers/message_handler.py\", line 57, in message_router\n    await custom_order_handler(update, context) # Or a general_message_handler\n    ^^^^^^^^^^^^^^^^^^^^^^^^^^^^^^^^^^^^^^^^^^^\n  File \"/home/technedict/Desktop/ViralPackage/viralcore/handlers/custom_order_handlers.py\", line 31, in custom_order_handler\n    text = update.message.text.strip()\n           ^^^^^^^^^^^^^^^^^^^\nAttributeError: 'NoneType' object has no attribute 'text'"}
{"timestamp": "2025-09-29T08:18:28.922553Z", "level": "ERROR", "module": "telegram.ext.Application", "message": "No error handlers are registered, logging exception.", "correlation_id": "none", "exception": "Traceback (most recent call last):\n  File \"/home/technedict/Desktop/ViralPackage/viralcorelib/lib64/python3.13/site-packages/telegram/ext/_application.py\", line 1335, in process_update\n    await coroutine\n  File \"/home/technedict/Desktop/ViralPackage/viralcorelib/lib64/python3.13/site-packages/telegram/ext/_handlers/basehandler.py\", line 157, in handle_update\n    return await self.callback(update, context)\n           ^^^^^^^^^^^^^^^^^^^^^^^^^^^^^^^^^^^^\n  File \"/home/technedict/Desktop/ViralPackage/viralcore/handlers/message_handler.py\", line 57, in message_router\n    await custom_order_handler(update, context) # Or a general_message_handler\n    ^^^^^^^^^^^^^^^^^^^^^^^^^^^^^^^^^^^^^^^^^^^\n  File \"/home/technedict/Desktop/ViralPackage/viralcore/handlers/custom_order_handlers.py\", line 31, in custom_order_handler\n    text = update.message.text.strip()\n           ^^^^^^^^^^^^^^^^^^^\nAttributeError: 'NoneType' object has no attribute 'text'"}
{"timestamp": "2025-09-29T08:18:28.935487Z", "level": "ERROR", "module": "telegram.ext.Application", "message": "No error handlers are registered, logging exception.", "correlation_id": "none", "exception": "Traceback (most recent call last):\n  File \"/home/technedict/Desktop/ViralPackage/viralcorelib/lib64/python3.13/site-packages/telegram/ext/_application.py\", line 1335, in process_update\n    await coroutine\n  File \"/home/technedict/Desktop/ViralPackage/viralcorelib/lib64/python3.13/site-packages/telegram/ext/_handlers/basehandler.py\", line 157, in handle_update\n    return await self.callback(update, context)\n           ^^^^^^^^^^^^^^^^^^^^^^^^^^^^^^^^^^^^\n  File \"/home/technedict/Desktop/ViralPackage/viralcore/handlers/message_handler.py\", line 57, in message_router\n    await custom_order_handler(update, context) # Or a general_message_handler\n    ^^^^^^^^^^^^^^^^^^^^^^^^^^^^^^^^^^^^^^^^^^^\n  File \"/home/technedict/Desktop/ViralPackage/viralcore/handlers/custom_order_handlers.py\", line 31, in custom_order_handler\n    text = update.message.text.strip()\n           ^^^^^^^^^^^^^^^^^^^\nAttributeError: 'NoneType' object has no attribute 'text'"}
{"timestamp": "2025-09-29T08:18:28.943692Z", "level": "ERROR", "module": "telegram.ext.Application", "message": "No error handlers are registered, logging exception.", "correlation_id": "none", "exception": "Traceback (most recent call last):\n  File \"/home/technedict/Desktop/ViralPackage/viralcorelib/lib64/python3.13/site-packages/telegram/ext/_application.py\", line 1335, in process_update\n    await coroutine\n  File \"/home/technedict/Desktop/ViralPackage/viralcorelib/lib64/python3.13/site-packages/telegram/ext/_handlers/basehandler.py\", line 157, in handle_update\n    return await self.callback(update, context)\n           ^^^^^^^^^^^^^^^^^^^^^^^^^^^^^^^^^^^^\n  File \"/home/technedict/Desktop/ViralPackage/viralcore/handlers/message_handler.py\", line 57, in message_router\n    await custom_order_handler(update, context) # Or a general_message_handler\n    ^^^^^^^^^^^^^^^^^^^^^^^^^^^^^^^^^^^^^^^^^^^\n  File \"/home/technedict/Desktop/ViralPackage/viralcore/handlers/custom_order_handlers.py\", line 31, in custom_order_handler\n    text = update.message.text.strip()\n           ^^^^^^^^^^^^^^^^^^^\nAttributeError: 'NoneType' object has no attribute 'text'"}
{"timestamp": "2025-09-29T08:18:28.949888Z", "level": "ERROR", "module": "telegram.ext.Application", "message": "No error handlers are registered, logging exception.", "correlation_id": "none", "exception": "Traceback (most recent call last):\n  File \"/home/technedict/Desktop/ViralPackage/viralcorelib/lib64/python3.13/site-packages/telegram/ext/_application.py\", line 1335, in process_update\n    await coroutine\n  File \"/home/technedict/Desktop/ViralPackage/viralcorelib/lib64/python3.13/site-packages/telegram/ext/_handlers/basehandler.py\", line 157, in handle_update\n    return await self.callback(update, context)\n           ^^^^^^^^^^^^^^^^^^^^^^^^^^^^^^^^^^^^\n  File \"/home/technedict/Desktop/ViralPackage/viralcore/handlers/message_handler.py\", line 57, in message_router\n    await custom_order_handler(update, context) # Or a general_message_handler\n    ^^^^^^^^^^^^^^^^^^^^^^^^^^^^^^^^^^^^^^^^^^^\n  File \"/home/technedict/Desktop/ViralPackage/viralcore/handlers/custom_order_handlers.py\", line 31, in custom_order_handler\n    text = update.message.text.strip()\n           ^^^^^^^^^^^^^^^^^^^\nAttributeError: 'NoneType' object has no attribute 'text'"}
{"timestamp": "2025-09-29T08:21:24.173722Z", "level": "WARNING", "module": "utils.graceful_shutdown", "message": "updater.shutdown() raised: This Updater is still running!", "correlation_id": "none"}
{"timestamp": "2025-09-29T08:21:24.174965Z", "level": "WARNING", "module": "utils.graceful_shutdown", "message": "Shutdown already in progress", "correlation_id": "none"}
{"timestamp": "2025-09-29T08:21:24.194893Z", "level": "ERROR", "module": "__main__", "message": "Error during app.shutdown()", "correlation_id": "none", "exception": "Traceback (most recent call last):\n  File \"/home/technedict/Desktop/ViralPackage/viralcore/main_viral_core_bot.py\", line 301, in main\n    await app.shutdown()\n  File \"/home/technedict/Desktop/ViralPackage/viralcorelib/lib64/python3.13/site-packages/telegram/ext/_application.py\", line 561, in shutdown\n    await self.updater.shutdown()\n  File \"/home/technedict/Desktop/ViralPackage/viralcorelib/lib64/python3.13/site-packages/telegram/ext/_updater.py\", line 204, in shutdown\n    raise RuntimeError(\"This Updater is still running!\")\nRuntimeError: This Updater is still running!"}
{"timestamp": "2025-09-29T08:21:24.306887Z", "level": "ERROR", "module": "asyncio", "message": "Task exception was never retrieved\nfuture: <Task finished name='Task-40' coro=<Updater._start_polling.<locals>.polling_action_cb() done, defined at /home/technedict/Desktop/ViralPackage/viralcorelib/lib64/python3.13/site-packages/telegram/ext/_updater.py:375> exception=NetworkError('httpx.ReadError: ')>", "correlation_id": "none", "exception": "Traceback (most recent call last):\n  File \"/home/technedict/Desktop/ViralPackage/viralcorelib/lib64/python3.13/site-packages/httpx/_transports/default.py\", line 101, in map_httpcore_exceptions\n  File \"/home/technedict/Desktop/ViralPackage/viralcorelib/lib64/python3.13/site-packages/httpx/_transports/default.py\", line 394, in handle_async_request\n  File \"/home/technedict/Desktop/ViralPackage/viralcorelib/lib64/python3.13/site-packages/httpcore/_async/connection_pool.py\", line 256, in handle_async_request\n  File \"/home/technedict/Desktop/ViralPackage/viralcorelib/lib64/python3.13/site-packages/httpcore/_async/connection_pool.py\", line 236, in handle_async_request\n  File \"/home/technedict/Desktop/ViralPackage/viralcorelib/lib64/python3.13/site-packages/httpcore/_async/connection.py\", line 103, in handle_async_request\n  File \"/home/technedict/Desktop/ViralPackage/viralcorelib/lib64/python3.13/site-packages/httpcore/_async/http11.py\", line 136, in handle_async_request\n  File \"/home/technedict/Desktop/ViralPackage/viralcorelib/lib64/python3.13/site-packages/httpcore/_async/http11.py\", line 106, in handle_async_request\n  File \"/home/technedict/Desktop/ViralPackage/viralcorelib/lib64/python3.13/site-packages/httpcore/_async/http11.py\", line 177, in _receive_response_headers\n  File \"/home/technedict/Desktop/ViralPackage/viralcorelib/lib64/python3.13/site-packages/httpcore/_async/http11.py\", line 217, in _receive_event\n  File \"/home/technedict/Desktop/ViralPackage/viralcorelib/lib64/python3.13/site-packages/httpcore/_backends/anyio.py\", line 32, in read\n  File \"/usr/lib64/python3.13/contextlib.py\", line 162, in __exit__\n  File \"/home/technedict/Desktop/ViralPackage/viralcorelib/lib64/python3.13/site-packages/httpcore/_exceptions.py\", line 14, in map_exceptions\nhttpcore.ReadError\n\nThe above exception was the direct cause of the following exception:\n\nTraceback (most recent call last):\n  File \"/home/technedict/Desktop/ViralPackage/viralcorelib/lib64/python3.13/site-packages/telegram/request/_httpxrequest.py\", line 276, in do_request\n  File \"/home/technedict/Desktop/ViralPackage/viralcorelib/lib64/python3.13/site-packages/httpx/_client.py\", line 1540, in request\n  File \"/home/technedict/Desktop/ViralPackage/viralcorelib/lib64/python3.13/site-packages/httpx/_client.py\", line 1629, in send\n  File \"/home/technedict/Desktop/ViralPackage/viralcorelib/lib64/python3.13/site-packages/httpx/_client.py\", line 1657, in _send_handling_auth\n  File \"/home/technedict/Desktop/ViralPackage/viralcorelib/lib64/python3.13/site-packages/httpx/_client.py\", line 1694, in _send_handling_redirects\n  File \"/home/technedict/Desktop/ViralPackage/viralcorelib/lib64/python3.13/site-packages/httpx/_client.py\", line 1730, in _send_single_request\n  File \"/home/technedict/Desktop/ViralPackage/viralcorelib/lib64/python3.13/site-packages/httpx/_transports/default.py\", line 393, in handle_async_request\n  File \"/usr/lib64/python3.13/contextlib.py\", line 162, in __exit__\n  File \"/home/technedict/Desktop/ViralPackage/viralcorelib/lib64/python3.13/site-packages/httpx/_transports/default.py\", line 118, in map_httpcore_exceptions\nhttpx.ReadError\n\nThe above exception was the direct cause of the following exception:\n\nTraceback (most recent call last):\n  File \"/home/technedict/Desktop/ViralPackage/viralcorelib/lib64/python3.13/site-packages/telegram/ext/_updater.py\", line 377, in polling_action_cb\n    updates = await self.bot.get_updates(\n              ^^^^^^^^^^^^^^^^^^^^^^^^^^^\n    ...<7 lines>...\n    )\n    ^\n  File \"/home/technedict/Desktop/ViralPackage/viralcorelib/lib64/python3.13/site-packages/telegram/ext/_extbot.py\", line 649, in get_updates\n  File \"/home/technedict/Desktop/ViralPackage/viralcorelib/lib64/python3.13/site-packages/telegram/_bot.py\", line 4366, in get_updates\n  File \"/home/technedict/Desktop/ViralPackage/viralcorelib/lib64/python3.13/site-packages/telegram/_bot.py\", line 623, in _post\n  File \"/home/technedict/Desktop/ViralPackage/viralcorelib/lib64/python3.13/site-packages/telegram/ext/_extbot.py\", line 355, in _do_post\n  File \"/home/technedict/Desktop/ViralPackage/viralcorelib/lib64/python3.13/site-packages/telegram/_bot.py\", line 652, in _do_post\n  File \"/home/technedict/Desktop/ViralPackage/viralcorelib/lib64/python3.13/site-packages/telegram/request/_baserequest.py\", line 201, in post\n  File \"/home/technedict/Desktop/ViralPackage/viralcorelib/lib64/python3.13/site-packages/telegram/request/_baserequest.py\", line 333, in _request_wrapper\n  File \"/home/technedict/Desktop/ViralPackage/viralcorelib/lib64/python3.13/site-packages/telegram/request/_httpxrequest.py\", line 300, in do_request\ntelegram.error.NetworkError: httpx.ReadError: "}
{"timestamp": "2025-09-29T08:21:50.020056Z", "level": "WARNING", "module": "utils.graceful_shutdown", "message": "updater.shutdown() raised: This Updater is still running!", "correlation_id": "none"}
{"timestamp": "2025-09-29T08:21:50.021429Z", "level": "WARNING", "module": "utils.graceful_shutdown", "message": "Shutdown already in progress", "correlation_id": "none"}
{"timestamp": "2025-09-29T08:21:50.041010Z", "level": "ERROR", "module": "__main__", "message": "Error during app.shutdown()", "correlation_id": "none", "exception": "Traceback (most recent call last):\n  File \"/home/technedict/Desktop/ViralPackage/viralcore/main_viral_core_bot.py\", line 301, in main\n    await app.shutdown()\n  File \"/home/technedict/Desktop/ViralPackage/viralcorelib/lib64/python3.13/site-packages/telegram/ext/_application.py\", line 561, in shutdown\n    await self.updater.shutdown()\n  File \"/home/technedict/Desktop/ViralPackage/viralcorelib/lib64/python3.13/site-packages/telegram/ext/_updater.py\", line 204, in shutdown\n    raise RuntimeError(\"This Updater is still running!\")\nRuntimeError: This Updater is still running!"}
{"timestamp": "2025-09-29T08:21:50.147492Z", "level": "ERROR", "module": "asyncio", "message": "Task exception was never retrieved\nfuture: <Task finished name='Task-6' coro=<Updater._start_polling.<locals>.polling_action_cb() done, defined at /home/technedict/Desktop/ViralPackage/viralcorelib/lib64/python3.13/site-packages/telegram/ext/_updater.py:375> exception=NetworkError('httpx.ReadError: ')>", "correlation_id": "none", "exception": "Traceback (most recent call last):\n  File \"/home/technedict/Desktop/ViralPackage/viralcorelib/lib64/python3.13/site-packages/httpx/_transports/default.py\", line 101, in map_httpcore_exceptions\n  File \"/home/technedict/Desktop/ViralPackage/viralcorelib/lib64/python3.13/site-packages/httpx/_transports/default.py\", line 394, in handle_async_request\n  File \"/home/technedict/Desktop/ViralPackage/viralcorelib/lib64/python3.13/site-packages/httpcore/_async/connection_pool.py\", line 256, in handle_async_request\n  File \"/home/technedict/Desktop/ViralPackage/viralcorelib/lib64/python3.13/site-packages/httpcore/_async/connection_pool.py\", line 236, in handle_async_request\n  File \"/home/technedict/Desktop/ViralPackage/viralcorelib/lib64/python3.13/site-packages/httpcore/_async/connection.py\", line 103, in handle_async_request\n  File \"/home/technedict/Desktop/ViralPackage/viralcorelib/lib64/python3.13/site-packages/httpcore/_async/http11.py\", line 136, in handle_async_request\n  File \"/home/technedict/Desktop/ViralPackage/viralcorelib/lib64/python3.13/site-packages/httpcore/_async/http11.py\", line 106, in handle_async_request\n  File \"/home/technedict/Desktop/ViralPackage/viralcorelib/lib64/python3.13/site-packages/httpcore/_async/http11.py\", line 177, in _receive_response_headers\n  File \"/home/technedict/Desktop/ViralPackage/viralcorelib/lib64/python3.13/site-packages/httpcore/_async/http11.py\", line 217, in _receive_event\n  File \"/home/technedict/Desktop/ViralPackage/viralcorelib/lib64/python3.13/site-packages/httpcore/_backends/anyio.py\", line 32, in read\n  File \"/usr/lib64/python3.13/contextlib.py\", line 162, in __exit__\n  File \"/home/technedict/Desktop/ViralPackage/viralcorelib/lib64/python3.13/site-packages/httpcore/_exceptions.py\", line 14, in map_exceptions\nhttpcore.ReadError\n\nThe above exception was the direct cause of the following exception:\n\nTraceback (most recent call last):\n  File \"/home/technedict/Desktop/ViralPackage/viralcorelib/lib64/python3.13/site-packages/telegram/request/_httpxrequest.py\", line 276, in do_request\n  File \"/home/technedict/Desktop/ViralPackage/viralcorelib/lib64/python3.13/site-packages/httpx/_client.py\", line 1540, in request\n  File \"/home/technedict/Desktop/ViralPackage/viralcorelib/lib64/python3.13/site-packages/httpx/_client.py\", line 1629, in send\n  File \"/home/technedict/Desktop/ViralPackage/viralcorelib/lib64/python3.13/site-packages/httpx/_client.py\", line 1657, in _send_handling_auth\n  File \"/home/technedict/Desktop/ViralPackage/viralcorelib/lib64/python3.13/site-packages/httpx/_client.py\", line 1694, in _send_handling_redirects\n  File \"/home/technedict/Desktop/ViralPackage/viralcorelib/lib64/python3.13/site-packages/httpx/_client.py\", line 1730, in _send_single_request\n  File \"/home/technedict/Desktop/ViralPackage/viralcorelib/lib64/python3.13/site-packages/httpx/_transports/default.py\", line 393, in handle_async_request\n  File \"/usr/lib64/python3.13/contextlib.py\", line 162, in __exit__\n  File \"/home/technedict/Desktop/ViralPackage/viralcorelib/lib64/python3.13/site-packages/httpx/_transports/default.py\", line 118, in map_httpcore_exceptions\nhttpx.ReadError\n\nThe above exception was the direct cause of the following exception:\n\nTraceback (most recent call last):\n  File \"/home/technedict/Desktop/ViralPackage/viralcorelib/lib64/python3.13/site-packages/telegram/ext/_updater.py\", line 377, in polling_action_cb\n    updates = await self.bot.get_updates(\n              ^^^^^^^^^^^^^^^^^^^^^^^^^^^\n    ...<7 lines>...\n    )\n    ^\n  File \"/home/technedict/Desktop/ViralPackage/viralcorelib/lib64/python3.13/site-packages/telegram/ext/_extbot.py\", line 649, in get_updates\n  File \"/home/technedict/Desktop/ViralPackage/viralcorelib/lib64/python3.13/site-packages/telegram/_bot.py\", line 4366, in get_updates\n  File \"/home/technedict/Desktop/ViralPackage/viralcorelib/lib64/python3.13/site-packages/telegram/_bot.py\", line 623, in _post\n  File \"/home/technedict/Desktop/ViralPackage/viralcorelib/lib64/python3.13/site-packages/telegram/ext/_extbot.py\", line 355, in _do_post\n  File \"/home/technedict/Desktop/ViralPackage/viralcorelib/lib64/python3.13/site-packages/telegram/_bot.py\", line 652, in _do_post\n  File \"/home/technedict/Desktop/ViralPackage/viralcorelib/lib64/python3.13/site-packages/telegram/request/_baserequest.py\", line 201, in post\n  File \"/home/technedict/Desktop/ViralPackage/viralcorelib/lib64/python3.13/site-packages/telegram/request/_baserequest.py\", line 333, in _request_wrapper\n  File \"/home/technedict/Desktop/ViralPackage/viralcorelib/lib64/python3.13/site-packages/telegram/request/_httpxrequest.py\", line 300, in do_request\ntelegram.error.NetworkError: httpx.ReadError: "}
{"timestamp": "2025-09-29T08:29:51.877012Z", "level": "WARNING", "module": "handlers.menu_handlers", "message": "menu_handler edit failed (Invalid file http url specified: unsupported url protocol) for user ***ACCOUNT***. Resending message.", "correlation_id": "none"}
{"timestamp": "2025-09-29T08:30:06.786826Z", "level": "WARNING", "module": "handlers.menu_handlers", "message": "menu_handler edit failed (Message to edit not found) for user ***ACCOUNT***. Resending message.", "correlation_id": "none"}
{"timestamp": "2025-09-29T08:30:11.168216Z", "level": "WARNING", "module": "handlers.menu_handlers", "message": "menu_handler edit failed (Message to edit not found) for user ***ACCOUNT***. Resending message.", "correlation_id": "none"}
{"timestamp": "2025-09-29T08:31:39.976217Z", "level": "WARNING", "module": "handlers.menu_handlers", "message": "menu_handler edit failed (Message to edit not found) for user ***ACCOUNT***. Resending message.", "correlation_id": "none"}
{"timestamp": "2025-09-29T08:31:48.807448Z", "level": "WARNING", "module": "handlers.menu_handlers", "message": "menu_handler edit failed (Message to edit not found) for user ***ACCOUNT***. Resending message.", "correlation_id": "none"}
{"timestamp": "2025-09-29T08:32:27.360269Z", "level": "WARNING", "module": "handlers.menu_handlers", "message": "menu_handler edit failed (Message to edit not found) for user ***ACCOUNT***. Resending message.", "correlation_id": "none"}
{"timestamp": "2025-09-29T08:32:31.917849Z", "level": "WARNING", "module": "handlers.menu_handlers", "message": "menu_handler edit failed (Message to edit not found) for user ***ACCOUNT***. Resending message.", "correlation_id": "none"}
{"timestamp": "2025-09-29T08:33:33.203791Z", "level": "WARNING", "module": "handlers.menu_handlers", "message": "menu_handler edit failed (Message to edit not found) for user ***ACCOUNT***. Resending message.", "correlation_id": "none"}
{"timestamp": "2025-09-29T08:33:40.882962Z", "level": "WARNING", "module": "handlers.menu_handlers", "message": "menu_handler edit failed (Message to edit not found) for user ***ACCOUNT***. Resending message.", "correlation_id": "none"}
{"timestamp": "2025-09-29T08:34:38.265713Z", "level": "WARNING", "module": "utils.graceful_shutdown", "message": "updater.shutdown() raised: This Updater is still running!", "correlation_id": "none"}
{"timestamp": "2025-09-29T08:34:38.266841Z", "level": "WARNING", "module": "utils.graceful_shutdown", "message": "Shutdown already in progress", "correlation_id": "none"}
{"timestamp": "2025-09-29T08:34:38.287754Z", "level": "ERROR", "module": "__main__", "message": "Error during app.shutdown()", "correlation_id": "none", "exception": "Traceback (most recent call last):\n  File \"/home/technedict/Desktop/ViralPackage/viralcore/main_viral_core_bot.py\", line 301, in main\n    await app.shutdown()\n  File \"/home/technedict/Desktop/ViralPackage/viralcorelib/lib64/python3.13/site-packages/telegram/ext/_application.py\", line 561, in shutdown\n    await self.updater.shutdown()\n  File \"/home/technedict/Desktop/ViralPackage/viralcorelib/lib64/python3.13/site-packages/telegram/ext/_updater.py\", line 204, in shutdown\n    raise RuntimeError(\"This Updater is still running!\")\nRuntimeError: This Updater is still running!"}
{"timestamp": "2025-09-29T08:34:38.406369Z", "level": "ERROR", "module": "asyncio", "message": "Task exception was never retrieved\nfuture: <Task finished name='Task-68' coro=<Updater._start_polling.<locals>.polling_action_cb() done, defined at /home/technedict/Desktop/ViralPackage/viralcorelib/lib64/python3.13/site-packages/telegram/ext/_updater.py:375> exception=NetworkError('httpx.ReadError: ')>", "correlation_id": "none", "exception": "Traceback (most recent call last):\n  File \"/home/technedict/Desktop/ViralPackage/viralcorelib/lib64/python3.13/site-packages/httpx/_transports/default.py\", line 101, in map_httpcore_exceptions\n  File \"/home/technedict/Desktop/ViralPackage/viralcorelib/lib64/python3.13/site-packages/httpx/_transports/default.py\", line 394, in handle_async_request\n  File \"/home/technedict/Desktop/ViralPackage/viralcorelib/lib64/python3.13/site-packages/httpcore/_async/connection_pool.py\", line 256, in handle_async_request\n  File \"/home/technedict/Desktop/ViralPackage/viralcorelib/lib64/python3.13/site-packages/httpcore/_async/connection_pool.py\", line 236, in handle_async_request\n  File \"/home/technedict/Desktop/ViralPackage/viralcorelib/lib64/python3.13/site-packages/httpcore/_async/connection.py\", line 103, in handle_async_request\n  File \"/home/technedict/Desktop/ViralPackage/viralcorelib/lib64/python3.13/site-packages/httpcore/_async/http11.py\", line 136, in handle_async_request\n  File \"/home/technedict/Desktop/ViralPackage/viralcorelib/lib64/python3.13/site-packages/httpcore/_async/http11.py\", line 106, in handle_async_request\n  File \"/home/technedict/Desktop/ViralPackage/viralcorelib/lib64/python3.13/site-packages/httpcore/_async/http11.py\", line 177, in _receive_response_headers\n  File \"/home/technedict/Desktop/ViralPackage/viralcorelib/lib64/python3.13/site-packages/httpcore/_async/http11.py\", line 217, in _receive_event\n  File \"/home/technedict/Desktop/ViralPackage/viralcorelib/lib64/python3.13/site-packages/httpcore/_backends/anyio.py\", line 32, in read\n  File \"/usr/lib64/python3.13/contextlib.py\", line 162, in __exit__\n  File \"/home/technedict/Desktop/ViralPackage/viralcorelib/lib64/python3.13/site-packages/httpcore/_exceptions.py\", line 14, in map_exceptions\nhttpcore.ReadError\n\nThe above exception was the direct cause of the following exception:\n\nTraceback (most recent call last):\n  File \"/home/technedict/Desktop/ViralPackage/viralcorelib/lib64/python3.13/site-packages/telegram/request/_httpxrequest.py\", line 276, in do_request\n  File \"/home/technedict/Desktop/ViralPackage/viralcorelib/lib64/python3.13/site-packages/httpx/_client.py\", line 1540, in request\n  File \"/home/technedict/Desktop/ViralPackage/viralcorelib/lib64/python3.13/site-packages/httpx/_client.py\", line 1629, in send\n  File \"/home/technedict/Desktop/ViralPackage/viralcorelib/lib64/python3.13/site-packages/httpx/_client.py\", line 1657, in _send_handling_auth\n  File \"/home/technedict/Desktop/ViralPackage/viralcorelib/lib64/python3.13/site-packages/httpx/_client.py\", line 1694, in _send_handling_redirects\n  File \"/home/technedict/Desktop/ViralPackage/viralcorelib/lib64/python3.13/site-packages/httpx/_client.py\", line 1730, in _send_single_request\n  File \"/home/technedict/Desktop/ViralPackage/viralcorelib/lib64/python3.13/site-packages/httpx/_transports/default.py\", line 393, in handle_async_request\n  File \"/usr/lib64/python3.13/contextlib.py\", line 162, in __exit__\n  File \"/home/technedict/Desktop/ViralPackage/viralcorelib/lib64/python3.13/site-packages/httpx/_transports/default.py\", line 118, in map_httpcore_exceptions\nhttpx.ReadError\n\nThe above exception was the direct cause of the following exception:\n\nTraceback (most recent call last):\n  File \"/home/technedict/Desktop/ViralPackage/viralcorelib/lib64/python3.13/site-packages/telegram/ext/_updater.py\", line 377, in polling_action_cb\n    updates = await self.bot.get_updates(\n              ^^^^^^^^^^^^^^^^^^^^^^^^^^^\n    ...<7 lines>...\n    )\n    ^\n  File \"/home/technedict/Desktop/ViralPackage/viralcorelib/lib64/python3.13/site-packages/telegram/ext/_extbot.py\", line 649, in get_updates\n  File \"/home/technedict/Desktop/ViralPackage/viralcorelib/lib64/python3.13/site-packages/telegram/_bot.py\", line 4366, in get_updates\n  File \"/home/technedict/Desktop/ViralPackage/viralcorelib/lib64/python3.13/site-packages/telegram/_bot.py\", line 623, in _post\n  File \"/home/technedict/Desktop/ViralPackage/viralcorelib/lib64/python3.13/site-packages/telegram/ext/_extbot.py\", line 355, in _do_post\n  File \"/home/technedict/Desktop/ViralPackage/viralcorelib/lib64/python3.13/site-packages/telegram/_bot.py\", line 652, in _do_post\n  File \"/home/technedict/Desktop/ViralPackage/viralcorelib/lib64/python3.13/site-packages/telegram/request/_baserequest.py\", line 201, in post\n  File \"/home/technedict/Desktop/ViralPackage/viralcorelib/lib64/python3.13/site-packages/telegram/request/_baserequest.py\", line 333, in _request_wrapper\n  File \"/home/technedict/Desktop/ViralPackage/viralcorelib/lib64/python3.13/site-packages/telegram/request/_httpxrequest.py\", line 300, in do_request\ntelegram.error.NetworkError: httpx.ReadError: "}
{"timestamp": "2025-09-29T08:34:58.719944Z", "level": "WARNING", "module": "utils.graceful_shutdown", "message": "updater.shutdown() raised: This Updater is still running!", "correlation_id": "none"}
{"timestamp": "2025-09-29T08:34:58.722584Z", "level": "WARNING", "module": "utils.graceful_shutdown", "message": "Shutdown already in progress", "correlation_id": "none"}
{"timestamp": "2025-09-29T08:34:58.754854Z", "level": "ERROR", "module": "__main__", "message": "Error during app.shutdown()", "correlation_id": "none", "exception": "Traceback (most recent call last):\n  File \"/home/technedict/Desktop/ViralPackage/viralcore/main_viral_core_bot.py\", line 301, in main\n    await app.shutdown()\n  File \"/home/technedict/Desktop/ViralPackage/viralcorelib/lib64/python3.13/site-packages/telegram/ext/_application.py\", line 561, in shutdown\n    await self.updater.shutdown()\n  File \"/home/technedict/Desktop/ViralPackage/viralcorelib/lib64/python3.13/site-packages/telegram/ext/_updater.py\", line 204, in shutdown\n    raise RuntimeError(\"This Updater is still running!\")\nRuntimeError: This Updater is still running!"}
{"timestamp": "2025-09-29T08:34:58.883982Z", "level": "ERROR", "module": "asyncio", "message": "Task exception was never retrieved\nfuture: <Task finished name='Task-6' coro=<Updater._start_polling.<locals>.polling_action_cb() done, defined at /home/technedict/Desktop/ViralPackage/viralcorelib/lib64/python3.13/site-packages/telegram/ext/_updater.py:375> exception=NetworkError('httpx.ReadError: ')>", "correlation_id": "none", "exception": "Traceback (most recent call last):\n  File \"/home/technedict/Desktop/ViralPackage/viralcorelib/lib64/python3.13/site-packages/httpx/_transports/default.py\", line 101, in map_httpcore_exceptions\n  File \"/home/technedict/Desktop/ViralPackage/viralcorelib/lib64/python3.13/site-packages/httpx/_transports/default.py\", line 394, in handle_async_request\n  File \"/home/technedict/Desktop/ViralPackage/viralcorelib/lib64/python3.13/site-packages/httpcore/_async/connection_pool.py\", line 256, in handle_async_request\n  File \"/home/technedict/Desktop/ViralPackage/viralcorelib/lib64/python3.13/site-packages/httpcore/_async/connection_pool.py\", line 236, in handle_async_request\n  File \"/home/technedict/Desktop/ViralPackage/viralcorelib/lib64/python3.13/site-packages/httpcore/_async/connection.py\", line 103, in handle_async_request\n  File \"/home/technedict/Desktop/ViralPackage/viralcorelib/lib64/python3.13/site-packages/httpcore/_async/http11.py\", line 136, in handle_async_request\n  File \"/home/technedict/Desktop/ViralPackage/viralcorelib/lib64/python3.13/site-packages/httpcore/_async/http11.py\", line 106, in handle_async_request\n  File \"/home/technedict/Desktop/ViralPackage/viralcorelib/lib64/python3.13/site-packages/httpcore/_async/http11.py\", line 177, in _receive_response_headers\n  File \"/home/technedict/Desktop/ViralPackage/viralcorelib/lib64/python3.13/site-packages/httpcore/_async/http11.py\", line 217, in _receive_event\n  File \"/home/technedict/Desktop/ViralPackage/viralcorelib/lib64/python3.13/site-packages/httpcore/_backends/anyio.py\", line 32, in read\n  File \"/usr/lib64/python3.13/contextlib.py\", line 162, in __exit__\n  File \"/home/technedict/Desktop/ViralPackage/viralcorelib/lib64/python3.13/site-packages/httpcore/_exceptions.py\", line 14, in map_exceptions\nhttpcore.ReadError\n\nThe above exception was the direct cause of the following exception:\n\nTraceback (most recent call last):\n  File \"/home/technedict/Desktop/ViralPackage/viralcorelib/lib64/python3.13/site-packages/telegram/request/_httpxrequest.py\", line 276, in do_request\n  File \"/home/technedict/Desktop/ViralPackage/viralcorelib/lib64/python3.13/site-packages/httpx/_client.py\", line 1540, in request\n  File \"/home/technedict/Desktop/ViralPackage/viralcorelib/lib64/python3.13/site-packages/httpx/_client.py\", line 1629, in send\n  File \"/home/technedict/Desktop/ViralPackage/viralcorelib/lib64/python3.13/site-packages/httpx/_client.py\", line 1657, in _send_handling_auth\n  File \"/home/technedict/Desktop/ViralPackage/viralcorelib/lib64/python3.13/site-packages/httpx/_client.py\", line 1694, in _send_handling_redirects\n  File \"/home/technedict/Desktop/ViralPackage/viralcorelib/lib64/python3.13/site-packages/httpx/_client.py\", line 1730, in _send_single_request\n  File \"/home/technedict/Desktop/ViralPackage/viralcorelib/lib64/python3.13/site-packages/httpx/_transports/default.py\", line 393, in handle_async_request\n  File \"/usr/lib64/python3.13/contextlib.py\", line 162, in __exit__\n  File \"/home/technedict/Desktop/ViralPackage/viralcorelib/lib64/python3.13/site-packages/httpx/_transports/default.py\", line 118, in map_httpcore_exceptions\nhttpx.ReadError\n\nThe above exception was the direct cause of the following exception:\n\nTraceback (most recent call last):\n  File \"/home/technedict/Desktop/ViralPackage/viralcorelib/lib64/python3.13/site-packages/telegram/ext/_updater.py\", line 377, in polling_action_cb\n    updates = await self.bot.get_updates(\n              ^^^^^^^^^^^^^^^^^^^^^^^^^^^\n    ...<7 lines>...\n    )\n    ^\n  File \"/home/technedict/Desktop/ViralPackage/viralcorelib/lib64/python3.13/site-packages/telegram/ext/_extbot.py\", line 649, in get_updates\n  File \"/home/technedict/Desktop/ViralPackage/viralcorelib/lib64/python3.13/site-packages/telegram/_bot.py\", line 4366, in get_updates\n  File \"/home/technedict/Desktop/ViralPackage/viralcorelib/lib64/python3.13/site-packages/telegram/_bot.py\", line 623, in _post\n  File \"/home/technedict/Desktop/ViralPackage/viralcorelib/lib64/python3.13/site-packages/telegram/ext/_extbot.py\", line 355, in _do_post\n  File \"/home/technedict/Desktop/ViralPackage/viralcorelib/lib64/python3.13/site-packages/telegram/_bot.py\", line 652, in _do_post\n  File \"/home/technedict/Desktop/ViralPackage/viralcorelib/lib64/python3.13/site-packages/telegram/request/_baserequest.py\", line 201, in post\n  File \"/home/technedict/Desktop/ViralPackage/viralcorelib/lib64/python3.13/site-packages/telegram/request/_baserequest.py\", line 333, in _request_wrapper\n  File \"/home/technedict/Desktop/ViralPackage/viralcorelib/lib64/python3.13/site-packages/telegram/request/_httpxrequest.py\", line 300, in do_request\ntelegram.error.NetworkError: httpx.ReadError: "}
